File: MT-DataAnalysis-JupyterNotebook/TensionPlots/TensionTests/CoilDiameter/Specimen_RawData_12.csv
End date,"8/16/2018"
Specimen label,"D25L40N5d4"
Maximum Load,"25.20402",N
Extension at Maximum Load,"27.35096",mm
Maximum Slope (Automatic Young's),"1.01552",N/mm
Rate 1,"30.00000",mm/min

Time,Extension,Load
(s),(mm),(N)
"0.00000","0.00000","0.01045"
"0.10000","0.02744","0.03779"
"0.20000","0.08950","0.10056"
"0.30000","0.14923","0.17018"
"0.40000","0.20167","0.21125"
"0.50000","0.25159","0.27559"
"0.60000","0.30122","0.33510"
"0.70000","0.35108","0.39718"
"0.80000","0.40107","0.43742"
"0.90000","0.45111","0.48948"
"1.00000","0.50104","0.55101"
"1.10000","0.55102","0.60014"
"1.20000","0.60100","0.64400"
"1.30000","0.65087","0.70011"
"1.40000","0.70103","0.74994"
"1.50000","0.75102","0.80007"
"1.60000","0.80112","0.84253"
"1.70000","0.85104","0.89371"
"1.80000","0.90097","0.94664"
"1.90000","0.95095","1.00071"
"2.00000","1.00094","1.03935"
"2.10000","1.05110","1.10109"
"2.20000","1.10102","1.16448"
"2.30000","1.15095","1.21522"
"2.40000","1.20099","1.25645"
"2.50000","1.25092","1.31248"
"2.60000","1.30102","1.37040"
"2.70000","1.35100","1.42391"
"2.80000","1.40093","1.46794"
"2.90000","1.45103","1.52224"
"3.00000","1.50096","1.57303"
"3.10000","1.55100","1.61932"
"3.20000","1.60104","1.66623"
"3.30000","1.65103","1.73012"
"3.40000","1.70107","1.79162"
"3.50000","1.75094","1.83907"
"3.60000","1.80098","1.86531"
"3.70000","1.85096","1.92464"
"3.80000","1.90107","1.99153"
"3.90000","1.95099","2.04867"
"4.00000","2.00098","2.09553"
"4.10000","2.05096","2.14596"
"4.20000","2.10100","2.20034"
"4.30000","2.15093","2.24894"
"4.40000","2.20103","2.29991"
"4.50000","2.25096","2.35979"
"4.60000","2.30100","2.41153"
"4.70000","2.35104","2.44910"
"4.80000","2.40103","2.48274"
"4.90000","2.45101","2.55524"
"5.00000","2.50106","2.61742"
"5.10000","2.55098","2.67505"
"5.20000","2.60096","2.70300"
"5.30000","2.65095","2.74864"
"5.40000","2.70093","2.81270"
"5.50000","2.75110","2.86864"
"5.60000","2.80102","2.91276"
"5.70000","2.85100","2.97739"
"5.80000","2.90093","3.01430"
"5.90000","2.95091","3.06180"
"6.00000","3.00102","3.11662"
"6.10000","3.05094","3.17168"
"6.20000","3.10098","3.24211"
"6.30000","3.15097","3.28147"
"6.40000","3.20089","3.29866"
"6.50000","3.25100","3.34452"
"6.60000","3.30104","3.40145"
"6.70000","3.35090","3.45566"
"6.80000","3.40101","3.50589"
"6.90000","3.45099","3.54739"
"7.00000","3.50092","3.59663"
"7.10000","3.55102","3.65082"
"7.20000","3.60100","3.70326"
"7.30000","3.65093","3.75524"
"7.40000","3.70097","3.81265"
"7.50000","3.75096","3.85791"
"7.60000","3.80100","3.89973"
"7.70000","3.85104","3.93829"
"7.80000","3.90097","3.99615"
"7.90000","3.95089","4.05805"
"8.00000","4.00094","4.11172"
"8.10000","4.05104","4.14417"
"8.20000","4.10102","4.19991"
"8.30000","4.15101","4.25339"
"8.40000","4.20099","4.30554"
"8.50000","4.25098","4.34872"
"8.60000","4.30096","4.40169"
"8.70000","4.35094","4.45248"
"8.80000","4.40099","4.50679"
"8.90000","4.45097","4.54415"
"9.00000","4.50102","4.60134"
"9.10000","4.55088","4.66067"
"9.20000","4.60098","4.71122"
"9.30000","4.65097","4.74546"
"9.40000","4.70101","4.80023"
"9.50000","4.75100","4.85443"
"9.60000","4.80092","4.91231"
"9.70000","4.85084","4.94748"
"9.80000","4.90113","4.99950"
"9.90000","4.95105","5.05638"
"10.00000","5.00098","5.11624"
"10.10000","5.05096","5.15372"
"10.20000","5.10088","5.20318"
"10.30000","5.15087","5.25493"
"10.40000","5.20091","5.31127"
"10.50000","5.25102","5.35836"
"10.60000","5.30094","5.40737"
"10.70000","5.35110","5.46594"
"10.80000","5.40091","5.51275"
"10.90000","5.45101","5.54915"
"11.00000","5.50106","5.59912"
"11.10000","5.55098","5.66281"
"11.20000","5.60096","5.72095"
"11.30000","5.65101","5.76680"
"11.40000","5.70093","5.80456"
"11.50000","5.75092","5.85525"
"11.60000","5.80102","5.92057"
"11.70000","5.85094","5.96886"
"11.80000","5.90093","6.01716"
"11.90000","5.95097","6.06713"
"12.00000","6.00102","6.11302"
"12.10000","6.05100","6.16097"
"12.20000","6.10092","6.21351"
"12.30000","6.15097","6.26594"
"12.40000","6.20101","6.32380"
"12.50000","6.25088","6.36570"
"12.60000","6.30098","6.39190"
"12.70000","6.35102","6.45398"
"12.80000","6.40101","6.52035"
"12.90000","6.45111","6.57698"
"13.00000","6.50086","6.61555"
"13.10000","6.55102","6.66080"
"13.20000","6.60094","6.71383"
"13.30000","6.65105","6.76882"
"13.40000","6.70103","6.81535"
"13.50000","6.75102","6.87134"
"13.60000","6.80094","6.92643"
"13.70000","6.85098","6.96799"
"13.80000","6.90103","7.01090"
"13.90000","6.95101","7.06549"
"14.00000","7.00100","7.12972"
"14.10000","7.05104","7.19150"
"14.20000","7.10096","7.22176"
"14.30000","7.15101","7.26168"
"14.40000","7.20099","7.32010"
"14.50000","7.25098","7.38207"
"14.60000","7.30090","7.42784"
"14.70000","7.35094","7.47660"
"14.80000","7.40093","7.52529"
"14.90000","7.45103","7.57621"
"15.00000","7.50096","7.62304"
"15.10000","7.55100","7.67257"
"15.20000","7.60098","7.73636"
"15.30000","7.65097","7.78602"
"15.40000","7.70089","7.82587"
"15.50000","7.75106","7.87295"
"15.60000","7.80092","7.93096"
"15.70000","7.85096","7.98812"
"15.80000","7.90101","8.03585"
"15.90000","7.95099","8.07539"
"16.00000","8.00103","8.12711"
"16.10000","8.05102","8.18396"
"16.20000","8.10094","8.23027"
"16.30000","8.15117","8.28083"
"16.40000","8.20103","8.33274"
"16.50000","8.25096","8.38694"
"16.60000","8.30094","8.43176"
"16.70000","8.35098","8.47521"
"16.80000","8.40109","8.52875"
"16.90000","8.45095","8.58991"
"17.00000","8.50099","8.64446"
"17.10000","8.55110","8.69573"
"17.20000","8.60096","8.74296"
"17.30000","8.65095","8.79123"
"17.40000","8.70099","8.84322"
"17.50000","8.75097","8.88018"
"17.60000","8.80102","8.92971"
"17.70000","8.85100","8.99232"
"17.80000","8.90093","9.04987"
"17.90000","8.95091","9.08411"
"18.00000","9.00096","9.13761"
"18.10000","9.05100","9.18623"
"18.20000","9.10092","9.23986"
"18.30000","9.15097","9.28441"
"18.40000","9.20107","9.33230"
"18.50000","9.25106","9.38640"
"18.60000","9.30092","9.44249"
"18.70000","9.35102","9.47447"
"18.80000","9.40089","9.52181"
"18.90000","9.45093","9.59011"
"19.00000","9.50092","9.64441"
"19.10000","9.55090","9.68914"
"19.20000","9.60106","9.72555"
"19.30000","9.65105","9.77303"
"19.40000","9.70097","9.83371"
"19.50000","9.75096","9.88478"
"19.60000","9.80094","9.93000"
"19.70000","9.85098","9.98752"
"19.80000","9.90103","10.03120"
"19.90000","9.95101","10.07516"
"20.00000","10.00099","10.11462"
"20.10000","10.05098","10.17700"
"20.20000","10.10108","10.23583"
"20.30000","10.15101","10.28329"
"20.40000","10.20099","10.31090"
"20.50000","10.25091","10.36156"
"20.60000","10.30096","10.42535"
"20.70000","10.35094","10.48656"
"20.80000","10.40099","10.52994"
"20.90000","10.45097","10.57320"
"21.00000","10.50096","10.61523"
"21.10000","10.55106","10.67455"
"21.20000","10.60092","10.71717"
"21.30000","10.65091","10.76629"
"21.40000","10.70095","10.83194"
"21.50000","10.75099","10.87972"
"21.60000","10.80092","10.90812"
"21.70000","10.85102","10.94609"
"21.80000","10.90095","11.01932"
"21.90000","10.95093","11.09074"
"22.00000","11.00103","11.13165"
"22.10000","11.05096","11.16621"
"22.20000","11.10100","11.21790"
"22.30000","11.15105","11.27701"
"22.40000","11.20097","11.32581"
"22.50000","11.25095","11.37442"
"22.60000","11.30100","11.42748"
"22.70000","11.35104","11.47003"
"22.80000","11.40103","11.51997"
"22.90000","11.45095","11.55546"
"23.00000","11.50100","11.61516"
"23.10000","11.55104","11.67311"
"23.20000","11.60102","11.72507"
"23.30000","11.65095","11.75555"
"23.40000","11.70093","11.80805"
"23.50000","11.75092","11.86286"
"23.60000","11.80096","11.92239"
"23.70000","11.85100","11.96549"
"23.80000","11.90099","12.00051"
"23.90000","11.95091","12.05624"
"24.00000","12.00096","12.11440"
"24.10000","12.05094","12.15241"
"24.20000","12.10098","12.20235"
"24.30000","12.15097","12.26212"
"24.40000","12.20101","12.30987"
"24.50000","12.25105","12.35792"
"24.60000","12.30098","12.40584"
"24.70000","12.35102","12.45729"
"24.80000","12.40095","12.51675"
"24.90000","12.45093","12.56307"
"25.00000","12.50103","12.59465"
"25.10000","12.55090","12.65675"
"25.20000","12.60100","12.70750"
"25.30000","12.65099","12.75859"
"25.40000","12.70109","12.79621"
"25.50000","12.75101","12.84285"
"25.60000","12.80100","12.89689"
"25.70000","12.85092","12.95806"
"25.80000","12.90097","12.99147"
"25.90000","12.95101","13.03873"
"26.00000","13.00099","13.09395"
"26.10000","13.05098","13.14296"
"26.20000","13.10108","13.18992"
"26.30000","13.15107","13.24410"
"26.40000","13.20099","13.29560"
"26.50000","13.25091","13.35565"
"26.60000","13.30102","13.39056"
"26.70000","13.35094","13.42320"
"26.80000","13.40099","13.48885"
"26.90000","13.45097","13.54327"
"27.00000","13.50102","13.59200"
"27.10000","13.55100","13.62686"
"27.20000","13.60098","13.67392"
"27.30000","13.65091","13.71712"
"27.40000","13.70095","13.78372"
"27.50000","13.75105","13.81852"
"27.60000","13.80098","13.87567"
"27.70000","13.85096","13.92714"
"27.80000","13.90101","13.97590"
"27.90000","13.95099","14.01109"
"28.00000","14.00103","14.06109"
"28.10000","14.05102","14.12995"
"28.20000","14.10094","14.18060"
"28.30000","14.15099","14.22697"
"28.40000","14.20115","14.25362"
"28.50000","14.25095","14.30619"
"28.60000","14.30106","14.36520"
"28.70000","14.35104","14.42202"
"28.80000","14.40097","14.46514"
"28.90000","14.45095","14.51635"
"29.00000","14.50100","14.55774"
"29.10000","14.55092","14.60596"
"29.20000","14.60108","14.64978"
"29.30000","14.65101","14.70941"
"29.40000","14.70099","14.77070"
"29.50000","14.75098","14.81909"
"29.60000","14.80102","14.84030"
"29.70000","14.85106","14.89828"
"29.80000","14.90099","14.95488"
"29.90000","14.95097","15.00996"
"30.00000","15.00090","15.05458"
"30.10000","15.05100","15.08962"
"30.20000","15.10104","15.12844"
"30.30000","15.15103","15.19111"
"30.40000","15.20107","15.23700"
"30.50000","15.25105","15.28194"
"30.60000","15.30104","15.34368"
"30.70000","15.35090","15.38654"
"30.80000","15.40101","15.43379"
"30.90000","15.45099","15.46710"
"31.00000","15.50104","15.52099"
"31.10000","15.55102","15.58060"
"31.20000","15.60094","15.64499"
"31.30000","15.65099","15.67066"
"31.40000","15.70103","15.72004"
"31.50000","15.75095","15.77623"
"31.60000","15.80094","15.83357"
"31.70000","15.85092","15.88074"
"31.80000","15.90103","15.92432"
"31.90000","15.95101","15.96680"
"32.00000","16.00099","16.02287"
"32.10000","16.05098","16.07001"
"32.20000","16.10096","16.10735"
"32.30000","16.15100","16.17464"
"32.40000","16.20093","16.22813"
"32.50000","16.25103","16.26740"
"32.60000","16.30102","16.30142"
"32.70000","16.35094","16.35433"
"32.80000","16.40099","16.40608"
"32.90000","16.45097","16.46973"
"33.00000","16.50095","16.49878"
"33.10000","16.55106","16.54678"
"33.20000","16.60098","16.60660"
"33.30000","16.65091","16.65916"
"33.40000","16.70095","16.69946"
"33.50000","16.75105","16.71366"
"33.60000","16.80098","16.73232"
"33.70000","16.85102","16.77525"
"33.80000","16.90095","16.82271"
"33.90000","16.95105","16.88120"
"34.00000","17.00097","16.91595"
"34.10000","17.05096","16.96504"
"34.20000","17.10100","17.01951"
"34.30000","17.15099","17.06571"
"34.40000","17.20109","17.10207"
"34.50000","17.25096","17.14395"
"34.60000","17.30088","17.20162"
"34.70000","17.35104","17.24753"
"34.80000","17.40097","17.30838"
"34.90000","17.45101","17.33043"
"35.00000","17.50100","17.39185"
"35.10000","17.55092","17.44097"
"35.20000","17.60102","17.50410"
"35.30000","17.65101","17.53929"
"35.40000","17.70099","17.58460"
"35.50000","17.75097","17.62946"
"35.60000","17.80096","17.67575"
"35.70000","17.85100","17.72470"
"35.80000","17.90099","17.69079"
"35.90000","17.95097","17.73746"
"36.00000","18.00096","17.78000"
"36.10000","18.05112","17.84079"
"36.20000","18.10086","17.88860"
"36.30000","18.15103","17.91891"
"36.40000","18.20095","17.95208"
"36.50000","18.25099","17.94404"
"36.60000","18.30098","17.98587"
"36.70000","18.35090","18.03561"
"36.80000","18.40095","18.08334"
"36.90000","18.45099","18.13765"
"37.00000","18.50097","18.16048"
"37.10000","18.55096","18.20490"
"37.20000","18.60100","18.25321"
"37.30000","18.65093","18.31713"
"37.40000","18.70097","18.35187"
"37.50000","18.75101","18.39914"
"37.60000","18.80094","18.44968"
"37.70000","18.85092","18.48907"
"37.80000","18.90085","18.53542"
"37.90000","18.95101","18.57253"
"38.00000","19.00093","18.63229"
"38.10000","19.05104","18.68243"
"38.20000","19.10108","18.73543"
"38.30000","19.15101","18.75515"
"38.40000","19.20087","18.79156"
"38.50000","19.25097","18.85258"
"38.60000","19.30102","18.89972"
"38.70000","19.35106","18.91037"
"38.80000","19.40093","18.90178"
"38.90000","19.45091","18.95095"
"39.00000","19.50089","18.98591"
"39.10000","19.55100","19.02702"
"39.20000","19.60104","19.06721"
"39.30000","19.65091","19.12541"
"39.40000","19.70095","19.16341"
"39.50000","19.75093","19.20386"
"39.60000","19.80098","19.26738"
"39.70000","19.85102","19.31332"
"39.80000","19.90095","19.35003"
"39.90000","19.95099","19.38097"
"40.00000","20.00097","19.43765"
"40.10000","20.05090","19.47300"
"40.20000","20.10094","19.53811"
"40.30000","20.15104","19.58234"
"40.40000","20.20097","19.60207"
"40.50000","20.25101","19.64863"
"40.60000","20.30088","19.70404"
"40.70000","20.35098","19.75844"
"40.80000","20.40096","19.79377"
"40.90000","20.45095","19.84477"
"41.00000","20.50099","19.88839"
"41.10000","20.55098","19.93329"
"41.20000","20.60096","19.98095"
"41.30000","20.65094","20.00599"
"41.40000","20.70099","20.06557"
"41.50000","20.75103","20.11378"
"41.60000","20.80102","20.16771"
"41.70000","20.85088","20.19781"
"41.80000","20.90105","20.23840"
"41.90000","20.95091","20.29754"
"42.00000","21.00095","20.34392"
"42.10000","21.05100","20.39445"
"42.20000","21.10092","20.42287"
"42.30000","21.15097","20.45915"
"42.40000","21.20101","20.50632"
"42.50000","21.25105","20.56283"
"42.60000","21.30104","20.60317"
"42.70000","21.35102","20.63560"
"42.80000","21.40095","20.69173"
"42.90000","21.45093","20.73005"
"43.00000","21.50097","20.78130"
"43.10000","21.55102","20.82215"
"43.20000","21.60094","20.85469"
"43.30000","21.65092","20.90876"
"43.40000","21.70103","20.95740"
"43.50000","21.75101","21.00190"
"43.60000","21.80100","21.02794"
"43.70000","21.85098","21.07831"
"43.80000","21.90109","21.13213"
"43.90000","21.95101","21.17623"
"44.00000","22.00099","21.22732"
"44.10000","22.05098","21.24972"
"44.20000","22.10108","21.28579"
"44.30000","22.15101","21.33285"
"44.40000","22.20093","21.39452"
"44.50000","22.25097","21.43286"
"44.60000","22.30102","21.46545"
"44.70000","22.35106","21.51714"
"44.80000","22.40105","21.55270"
"44.90000","22.45091","21.59548"
"45.00000","22.50095","21.63656"
"45.10000","22.55100","21.67980"
"45.20000","22.60098","21.72670"
"45.30000","22.65097","21.77561"
"45.40000","22.70095","21.82761"
"45.50000","22.75105","21.84608"
"45.60000","22.80104","21.87551"
"45.70000","22.85090","21.94037"
"45.80000","22.90094","21.98904"
"45.90000","22.95093","22.03923"
"46.00000","23.00103","22.07043"
"46.10000","23.05102","22.10365"
"46.20000","23.10100","22.14228"
"46.30000","23.15099","22.18292"
"46.40000","23.20091","22.23993"
"46.50000","23.25095","22.27073"
"46.60000","23.30088","22.31718"
"46.70000","23.35098","22.37196"
"46.80000","23.40103","22.40538"
"46.90000","23.45101","22.44277"
"47.00000","23.50099","22.46948"
"47.10000","23.55103","22.51585"
"47.20000","23.60102","22.56825"
"47.30000","23.65095","22.61820"
"47.40000","23.70111","22.66444"
"47.50000","23.75091","22.68439"
"47.60000","23.80090","22.71377"
"47.70000","23.85100","22.76662"
"47.80000","23.90099","22.81387"
"47.90000","23.95103","22.85917"
"48.00000","24.00101","22.89618"
"48.10000","24.05106","22.93163"
"48.20000","24.10098","22.97280"
"48.30000","24.15091","23.00358"
"48.40000","24.20095","23.05780"
"48.50000","24.25099","23.08962"
"48.60000","24.30092","23.11282"
"48.70000","24.35096","23.17502"
"48.80000","24.40088","23.21733"
"48.90000","24.45099","23.25645"
"49.00000","24.50103","23.28062"
"49.10000","24.55102","23.30573"
"49.20000","24.60094","23.35365"
"49.30000","24.65093","23.39305"
"49.40000","24.70091","23.44275"
"49.50000","24.75089","23.49404"
"49.60000","24.80100","23.51609"
"49.70000","24.85098","23.54227"
"49.80000","24.90109","23.58902"
"49.90000","24.95107","23.63210"
"50.00000","25.00099","23.67693"
"50.10000","25.05098","23.70521"
"50.20000","25.10096","23.74139"
"50.30000","25.15101","23.79216"
"50.40000","25.20099","23.81924"
"50.50000","25.25103","23.86546"
"50.60000","25.30096","23.90065"
"50.70000","25.35100","23.92981"
"50.80000","25.40099","23.96773"
"50.90000","25.45097","24.01895"
"51.00000","25.50095","24.06326"
"51.10000","25.55100","24.10663"
"51.20000","25.60092","24.11835"
"51.30000","25.65103","24.15101"
"51.40000","25.70107","24.20342"
"51.50000","25.75105","24.23858"
"51.60000","25.80092","24.28581"
"51.70000","25.85096","24.32227"
"51.80000","25.90095","24.34115"
"51.90000","25.95099","24.37427"
"52.00000","26.00092","24.41382"
"52.10000","26.05096","24.45247"
"52.20000","26.10094","24.49894"
"52.30000","26.15099","24.52635"
"52.40000","26.20097","24.55092"
"52.50000","26.25107","24.59463"
"52.60000","26.30094","24.63337"
"52.70000","26.35092","24.65720"
"52.80000","26.40091","24.69869"
"52.90000","26.45113","24.72817"
"53.00000","26.50099","24.75356"
"53.10000","26.55098","24.78643"
"53.20000","26.60096","24.82510"
"53.30000","26.65101","24.85910"
"53.40000","26.70099","24.90114"
"53.50000","26.75097","24.92876"
"53.60000","26.80096","24.93928"
"53.70000","26.85106","24.96523"
"53.80000","26.90105","25.00169"
"53.90000","26.95103","25.03703"
"54.00000","27.00101","25.06754"
"54.10000","27.05106","25.09848"
"54.20000","27.10098","25.13134"
"54.30000","27.15097","25.15148"
"54.40000","27.20089","25.16589"
"54.50000","27.25093","25.18053"
"54.60000","27.30092","25.19811"
"54.70000","27.35096","25.20402"
"54.80000","27.40094","25.18882"
"54.87800","27.43987","24.86907"
"54.88000","27.44094","24.31175"
"54.88200","27.44196","23.41162"
"54.88400","27.44298","22.34294"
"54.88600","27.44399","21.17848"
"54.88800","27.44495","19.86387"
"54.89000","27.44597","18.44884"
"54.89200","27.44692","17.03671"
"54.89400","27.44794","15.61261"
"54.89600","27.44890","14.15915"