File: MT-DataAnalysis-JupyterNotebook/TensionPlots/TensionTests/CoilDiameter/Specimen_RawData_15.csv
End date,"8/16/2018"
Specimen label,"D60L40N5d4"
Maximum Load,"11.33875",N
Extension at Maximum Load,"283.00095",mm
Maximum Slope (Automatic Young's),"0.04222",N/mm
Rate 1,"30.00000",mm/min

Time,Extension,Load
(s),(mm),(N)
"0.00000","0.00000","0.00767"
"0.40000","0.20155","0.01699"
"0.80000","0.40101","0.02504"
"1.20000","0.60100","0.03413"
"1.60000","0.80094","0.04376"
"2.00000","1.00106","0.05401"
"2.40000","1.20087","0.06470"
"2.80000","1.40093","0.07608"
"3.20000","1.60098","0.08429"
"3.60000","1.80098","0.09580"
"4.00000","2.00086","0.10572"
"4.40000","2.20097","0.11679"
"4.80000","2.40091","0.12850"
"5.20000","2.60102","0.13743"
"5.60000","2.80096","0.14630"
"6.00000","3.00096","0.15655"
"6.40000","3.20095","0.16103"
"6.80000","3.40107","0.16404"
"7.20000","3.60100","0.17927"
"7.60000","3.80094","0.18478"
"8.00000","4.00106","0.18988"
"8.40000","4.20093","0.19535"
"8.80000","4.40099","0.20041"
"9.20000","4.60092","0.20855"
"9.60000","4.80098","0.21644"
"10.00000","5.00092","0.22025"
"10.40000","5.20097","0.23125"
"10.80000","5.40097","0.23858"
"11.20000","5.60096","0.24747"
"11.60000","5.80090","0.25623"
"12.00000","6.00108","0.26502"
"12.40000","6.20089","0.27364"
"12.80000","6.40089","0.28375"
"13.20000","6.60094","0.29306"
"13.60000","6.80106","0.30301"
"14.00000","7.00094","0.31108"
"14.40000","7.20093","0.32057"
"14.80000","7.40093","0.32999"
"15.20000","7.60092","0.34016"
"15.60000","7.80098","0.34873"
"16.00000","8.00098","0.35831"
"16.40000","8.20097","0.36472"
"16.80000","8.40097","0.37506"
"17.20000","8.60102","0.38280"
"17.60000","8.80090","0.39114"
"18.00000","9.00102","0.39819"
"18.40000","9.20101","0.40634"
"18.80000","9.40107","0.41517"
"19.20000","9.60100","0.42356"
"19.60000","9.80094","0.43207"
"20.00000","10.00088","0.43950"
"20.40000","10.20093","0.44642"
"20.80000","10.40093","0.45346"
"21.20000","10.60098","0.46390"
"21.60000","10.80092","0.46992"
"22.00000","11.00097","0.48010"
"22.40000","11.20103","0.48931"
"22.80000","11.40097","0.49815"
"23.20000","11.60102","0.50584"
"23.60000","11.80096","0.51542"
"24.00000","12.00101","0.52675"
"24.40000","12.20095","0.53668"
"24.80000","12.40107","0.54781"
"25.20000","12.60094","0.55520"
"25.60000","12.80094","0.56311"
"26.00000","13.00088","0.57031"
"26.40000","13.20099","0.58166"
"26.80000","13.40093","0.58444"
"27.20000","13.60098","0.59324"
"27.60000","13.80098","0.60048"
"28.00000","14.00097","0.60647"
"28.40000","14.20091","0.61207"
"28.80000","14.40097","0.62240"
"29.20000","14.60096","0.62545"
"29.60000","14.80102","0.63388"
"30.00000","15.00102","0.64338"
"30.40000","15.20107","0.65456"
"30.80000","15.40095","0.66034"
"31.20000","15.60100","0.66980"
"31.60000","15.80094","0.67834"
"32.00000","16.00087","0.68964"
"32.40000","16.20099","0.69606"
"32.80000","16.40099","0.70783"
"33.20000","16.60086","0.71753"
"33.60000","16.80098","0.72310"
"34.00000","17.00103","0.73219"
"34.40000","17.20085","0.74265"
"34.80000","17.40097","0.75189"
"35.20000","17.60096","0.76129"
"35.60000","17.80096","0.76630"
"36.00000","18.00096","0.78001"
"36.40000","18.20101","0.78370"
"36.80000","18.40095","0.79224"
"37.20000","18.60094","0.79696"
"37.60000","18.80088","0.80703"
"38.00000","19.00093","0.81119"
"38.40000","19.20093","0.81909"
"38.80000","19.40093","0.82758"
"39.20000","19.60092","0.83934"
"39.60000","19.80092","0.84523"
"40.00000","20.00097","0.85434"
"40.40000","20.20085","0.86286"
"40.80000","20.40096","0.87210"
"41.20000","20.60102","0.88057"
"41.60000","20.80096","0.88929"
"42.00000","21.00095","0.89788"
"42.40000","21.20095","0.90666"
"42.80000","21.40095","0.91719"
"43.20000","21.60088","0.92717"
"43.60000","21.80100","0.93590"
"44.00000","22.00093","0.94496"
"44.40000","22.20099","0.95541"
"44.80000","22.40087","0.96349"
"45.20000","22.60092","0.97287"
"45.60000","22.80098","0.97966"
"46.00000","23.00097","0.98361"
"46.40000","23.20091","0.99351"
"46.80000","23.40108","1.00068"
"47.20000","23.60096","1.01143"
"47.60000","23.80096","1.01673"
"48.00000","24.00089","1.02256"
"48.40000","24.20095","1.02458"
"48.80000","24.40095","1.03713"
"49.20000","24.60100","1.04008"
"49.60000","24.80088","1.04899"
"50.00000","25.00099","1.05790"
"50.40000","25.20093","1.06683"
"50.80000","25.40086","1.07641"
"51.20000","25.60086","1.08471"
"51.60000","25.80104","1.09633"
"52.00000","26.00103","1.10436"
"52.40000","26.20103","1.11458"
"52.80000","26.40102","1.12428"
"53.20000","26.60090","1.13588"
"53.60000","26.80090","1.14499"
"54.00000","27.00095","1.15580"
"54.40000","27.20095","1.16461"
"54.80000","27.40094","1.17377"
"55.20000","27.60094","1.18183"
"55.60000","27.80094","1.19066"
"56.00000","28.00099","1.19768"
"56.40000","28.20081","1.20698"
"56.80000","28.40104","1.21264"
"57.20000","28.60104","1.21946"
"57.60000","28.80098","1.22610"
"58.00000","29.00103","1.23246"
"58.40000","29.20097","1.23812"
"58.80000","29.40097","1.24707"
"59.20000","29.60090","1.25053"
"59.60000","29.80090","1.25999"
"60.00000","30.00096","1.26763"
"60.40000","30.20107","1.27704"
"60.80000","30.40100","1.28613"
"61.20000","30.60094","1.29327"
"61.60000","30.80100","1.30085"
"62.00000","31.00099","1.31064"
"62.40000","31.20087","1.31844"
"62.80000","31.40098","1.32954"
"63.20000","31.60104","1.34103"
"63.60000","31.80097","1.34879"
"64.00000","32.00103","1.35484"
"64.40000","32.20103","1.36722"
"64.80000","32.40096","1.37578"
"65.20000","32.60090","1.38840"
"65.60000","32.80096","1.39618"
"66.00000","33.00095","1.40562"
"66.40000","33.20089","1.41246"
"66.80000","33.40100","1.41837"
"67.20000","33.60088","1.42674"
"67.60000","33.80094","1.43399"
"68.00000","34.00093","1.44147"
"68.40000","34.20099","1.44798"
"68.80000","34.40099","1.45526"
"69.20000","34.60104","1.46453"
"69.60000","34.80092","1.47515"
"70.00000","35.00091","1.48168"
"70.40000","35.20103","1.48816"
"70.80000","35.40091","1.49758"
"71.20000","35.60090","1.50672"
"71.60000","35.80096","1.51613"
"72.00000","36.00095","1.52618"
"72.40000","36.20083","1.53542"
"72.80000","36.40094","1.54213"
"73.20000","36.60100","1.55407"
"73.60000","36.80088","1.56021"
"74.00000","37.00081","1.56940"
"74.40000","37.20093","1.57787"
"74.80000","37.40092","1.58560"
"75.20000","37.60092","1.59641"
"75.60000","37.80091","1.59916"
"76.00000","38.00091","1.60927"
"76.40000","38.20091","1.61434"
"76.80000","38.40090","1.62004"
"77.20000","38.60090","1.62617"
"77.60000","38.80090","1.63575"
"78.00000","39.00089","1.64313"
"78.40000","39.20089","1.64666"
"78.80000","39.40094","1.65871"
"79.20000","39.60099","1.66976"
"79.60000","39.80099","1.67721"
"80.00000","40.00093","1.68728"
"80.40000","40.20093","1.69823"
"80.80000","40.40092","1.70831"
"81.20000","40.60098","1.71756"
"81.60000","40.80104","1.72880"
"82.00000","41.00103","1.73942"
"82.40000","41.20097","1.74681"
"82.80000","41.40084","1.75640"
"83.20000","41.60096","1.76766"
"83.60000","41.80090","1.77411"
"84.00000","42.00089","1.78576"
"84.40000","42.20089","1.79551"
"84.80000","42.40100","1.80172"
"85.20000","42.60094","1.81175"
"85.60000","42.80106","1.82048"
"86.00000","43.00099","1.82521"
"86.40000","43.20093","1.83177"
"86.80000","43.40098","1.83872"
"87.20000","43.60098","1.84240"
"87.60000","43.80091","1.84752"
"88.00000","44.00097","1.85581"
"88.40000","44.20091","1.86104"
"88.80000","44.40102","1.86361"
"89.20000","44.60096","1.86648"
"89.60000","44.80096","1.87948"
"90.00000","45.00089","1.88523"
"90.40000","45.20094","1.89547"
"90.80000","45.40100","1.90405"
"91.20000","45.60100","1.91130"
"91.60000","45.80099","1.92108"
"92.00000","46.00105","1.93467"
"92.40000","46.20092","1.94259"
"92.80000","46.40092","1.95241"
"93.20000","46.60092","1.96285"
"93.60000","46.80098","1.97541"
"94.00000","47.00091","1.98561"
"94.40000","47.20090","1.99523"
"94.80000","47.40090","2.00473"
"95.20000","47.60101","2.01343"
"95.60000","47.80095","2.02302"
"96.00000","48.00089","2.02827"
"96.40000","48.20095","2.03806"
"96.80000","48.40095","2.04648"
"97.20000","48.60081","2.05357"
"97.60000","48.80106","2.06183"
"98.00000","49.00093","2.06794"
"98.40000","49.20093","2.07534"
"98.80000","49.40098","2.08557"
"99.20000","49.60092","2.09245"
"99.60000","49.80091","2.09926"
"100.00000","50.00091","2.10772"
"100.40000","50.20097","2.11507"
"100.80000","50.40096","2.12317"
"101.20000","50.60096","2.12984"
"101.60000","50.80089","2.13898"
"102.00000","51.00101","2.14676"
"102.40000","51.20095","2.15219"
"102.80000","51.40106","2.16409"
"103.20000","51.60100","2.17040"
"103.60000","51.80099","2.17969"
"104.00000","52.00099","2.18820"
"104.40000","52.20098","2.19618"
"104.80000","52.40092","2.20997"
"105.20000","52.60092","2.21667"
"105.60000","52.80098","2.22217"
"106.00000","53.00091","2.23171"
"106.40000","53.20096","2.23939"
"106.80000","53.40108","2.24680"
"107.20000","53.60096","2.25470"
"107.60000","53.80083","2.26432"
"108.00000","54.00095","2.27131"
"108.40000","54.20100","2.27767"
"108.80000","54.40094","2.28664"
"109.20000","54.60100","2.29379"
"109.60000","54.80099","2.30263"
"110.00000","55.00087","2.31349"
"110.40000","55.20092","2.32656"
"110.80000","55.40092","2.33469"
"111.20000","55.60092","2.34538"
"111.60000","55.80091","2.35420"
"112.00000","56.00085","2.36587"
"112.40000","56.20090","2.37521"
"112.80000","56.40097","2.38322"
"113.20000","56.60102","2.39302"
"113.60000","56.80095","2.40147"
"114.00000","57.00095","2.40878"
"114.40000","57.20101","2.41803"
"114.80000","57.40088","2.42404"
"115.20000","57.60100","2.42722"
"115.60000","57.80099","2.43732"
"116.00000","58.00099","2.44265"
"116.40000","58.20092","2.44627"
"116.80000","58.40104","2.45080"
"117.20000","58.60092","2.45510"
"117.60000","58.80097","2.45959"
"118.00000","59.00091","2.47026"
"118.40000","59.20103","2.48112"
"118.80000","59.40096","2.47872"
"119.20000","59.60107","2.48943"
"119.60000","59.80101","2.50207"
"120.00000","60.00101","2.51222"
"120.40000","60.20101","2.52217"
"120.80000","60.40094","2.53275"
"121.20000","60.60100","2.54204"
"121.60000","60.80099","2.55097"
"122.00000","61.00093","2.56326"
"122.40000","61.20093","2.57528"
"122.80000","61.40098","2.58501"
"123.20000","61.60092","2.59889"
"123.60000","61.80097","2.60666"
"124.00000","62.00091","2.61579"
"124.40000","62.20102","2.62618"
"124.80000","62.40090","2.63510"
"125.20000","62.60096","2.64498"
"125.60000","62.80095","2.65042"
"126.00000","63.00101","2.66438"
"126.40000","63.20094","2.67217"
"126.80000","63.40100","2.67526"
"127.20000","63.60099","2.68053"
"127.60000","63.80087","2.68644"
"128.00000","64.00098","2.69004"
"128.40000","64.20098","2.69668"
"128.80000","64.40098","2.70229"
"129.20000","64.60091","2.70787"
"129.60000","64.80097","2.71567"
"130.00000","65.00091","2.72243"
"130.40000","65.20097","2.73099"
"130.80000","65.40108","2.73795"
"131.20000","65.60107","2.74574"
"131.60000","65.80101","2.75163"
"132.00000","66.00095","2.76378"
"132.40000","66.20094","2.77200"
"132.80000","66.40094","2.78624"
"133.20000","66.60094","2.79502"
"133.60000","66.80099","2.80666"
"134.00000","67.00092","2.81697"
"134.40000","67.20098","2.82897"
"134.80000","67.40098","2.83703"
"135.20000","67.60091","2.84594"
"135.60000","67.80091","2.85404"
"136.00000","68.00102","2.86097"
"136.40000","68.20096","2.87105"
"136.80000","68.40102","2.87967"
"137.20000","68.60107","2.88371"
"137.60000","68.80095","2.89520"
"138.00000","69.00095","2.89953"
"138.40000","69.20094","2.90672"
"138.80000","69.40099","2.92122"
"139.20000","69.60088","2.92560"
"139.60000","69.80099","2.93778"
"140.00000","70.00092","2.94562"
"140.40000","70.20098","2.95487"
"140.80000","70.40086","2.96740"
"141.20000","70.60098","2.97282"
"141.60000","70.80091","2.98003"
"142.00000","71.00103","2.98892"
"142.40000","71.20096","2.99829"
"142.80000","71.40102","3.00368"
"143.20000","71.60089","3.01219"
"143.60000","71.80102","3.01845"
"144.00000","72.00095","3.02624"
"144.40000","72.20094","3.03325"
"144.80000","72.40106","3.04202"
"145.20000","72.60100","3.04795"
"145.60000","72.80087","3.05488"
"146.00000","73.00099","3.06079"
"146.40000","73.20099","3.06865"
"146.80000","73.40086","3.07523"
"147.20000","73.60104","3.08182"
"147.60000","73.80103","3.09021"
"148.00000","74.00091","3.09946"
"148.40000","74.20103","3.10887"
"148.80000","74.40096","3.11331"
"149.20000","74.60096","3.12451"
"149.60000","74.80090","3.13248"
"150.00000","75.00089","3.14179"
"150.40000","75.20094","3.15314"
"150.80000","75.40094","3.16394"
"151.20000","75.60094","3.17578"
"151.60000","75.80093","3.18533"
"152.00000","76.00099","3.19686"
"152.40000","76.20093","3.20776"
"152.80000","76.40086","3.21724"
"153.20000","76.60104","3.22868"
"153.60000","76.80103","3.23886"
"154.00000","77.00091","3.24871"
"154.40000","77.20090","3.25836"
"154.80000","77.40096","3.26920"
"155.20000","77.60090","3.26937"
"155.60000","77.80090","3.27016"
"156.00000","78.00101","3.28066"
"156.40000","78.20094","3.28649"
"156.80000","78.40094","3.29214"
"157.20000","78.60094","3.29456"
"157.60000","78.80087","3.29899"
"158.00000","79.00098","3.30582"
"158.40000","79.20104","3.31827"
"158.80000","79.40092","3.32728"
"159.20000","79.60104","3.33234"
"159.60000","79.80090","3.34385"
"160.00000","80.00091","3.35127"
"160.40000","80.20097","3.36060"
"160.80000","80.40096","3.37107"
"161.20000","80.60090","3.38224"
"161.60000","80.80095","3.39228"
"162.00000","81.00101","3.40093"
"162.40000","81.20094","3.41085"
"162.80000","81.40088","3.42136"
"163.20000","81.60093","3.42973"
"163.60000","81.80098","3.44046"
"164.00000","82.00098","3.45081"
"164.40000","82.20103","3.46143"
"164.80000","82.40097","3.46737"
"165.20000","82.60103","3.48010"
"165.60000","82.80091","3.48655"
"166.00000","83.00090","3.49503"
"166.40000","83.20096","3.49923"
"166.80000","83.40089","3.50710"
"167.20000","83.60095","3.51499"
"167.60000","83.80089","3.52430"
"168.00000","84.00095","3.52565"
"168.40000","84.20094","3.53447"
"168.80000","84.40088","3.54356"
"169.20000","84.60093","3.55191"
"169.60000","84.80099","3.56006"
"170.00000","85.00092","3.56702"
"170.40000","85.20104","3.57587"
"170.80000","85.40091","3.58373"
"171.20000","85.60091","3.59172"
"171.60000","85.80108","3.59990"
"172.00000","86.00096","3.60584"
"172.40000","86.20095","3.61468"
"172.80000","86.40096","3.62476"
"173.20000","86.60094","3.63585"
"173.60000","86.80095","3.64276"
"174.00000","87.00101","3.65031"
"174.40000","87.20094","3.66550"
"174.80000","87.40094","3.67125"
"175.20000","87.60099","3.67667"
"175.60000","87.80106","3.68320"
"176.00000","88.00093","3.68998"
"176.40000","88.20099","3.69665"
"176.80000","88.40103","3.70736"
"177.20000","88.60097","3.71493"
"177.60000","88.80103","3.72056"
"178.00000","89.00091","3.73324"
"178.40000","89.20097","3.74087"
"178.80000","89.40090","3.75075"
"179.20000","89.60102","3.75962"
"179.60000","89.80089","3.77218"
"180.00000","90.00095","3.78465"
"180.40000","90.20094","3.79507"
"180.80000","90.40099","3.80439"
"181.20000","90.60093","3.81074"
"181.60000","90.80106","3.82164"
"182.00000","91.00093","3.82913"
"182.40000","91.20086","3.83883"
"182.80000","91.40097","3.84144"
"183.20000","91.60091","3.85494"
"183.60000","91.80097","3.86177"
"184.00000","92.00097","3.86887"
"184.40000","92.20084","3.87925"
"184.80000","92.40090","3.88308"
"185.20000","92.60096","3.88895"
"185.60000","92.80094","3.89699"
"186.00000","93.00089","3.90218"
"186.40000","93.20088","3.91016"
"186.80000","93.40088","3.91595"
"187.20000","93.60094","3.92501"
"187.60000","93.80093","3.93049"
"188.00000","94.00098","3.94030"
"188.40000","94.20081","3.94887"
"188.80000","94.40098","3.95661"
"189.20000","94.60091","3.96409"
"189.60000","94.80096","3.97505"
"190.00000","95.00090","3.98571"
"190.40000","95.20090","3.99239"
"190.80000","95.40089","4.00595"
"191.20000","95.60094","4.01599"
"191.60000","95.80094","4.02544"
"192.00000","96.00095","4.03549"
"192.40000","96.20094","4.04620"
"192.80000","96.40094","4.05576"
"193.20000","96.60105","4.06611"
"193.60000","96.80093","4.07731"
"194.00000","97.00105","4.08338"
"194.40000","97.20098","4.09216"
"194.80000","97.40092","4.10694"
"195.20000","97.60091","4.10729"
"195.60000","97.80097","4.11369"
"196.00000","98.00096","4.11809"
"196.40000","98.20090","4.12122"
"196.80000","98.40095","4.12527"
"197.20000","98.60101","4.14070"
"197.60000","98.80088","4.14097"
"198.00000","99.00101","4.15245"
"198.40000","99.20105","4.15931"
"198.80000","99.40099","4.16978"
"199.20000","99.60093","4.17785"
"199.60000","99.80098","4.18739"
"200.00000","100.00098","4.19834"
"200.40000","100.20098","4.20575"
"200.80000","100.40091","4.21933"
"201.20000","100.60098","4.22837"
"201.60000","100.80103","4.23422"
"202.00000","101.00102","4.24517"
"202.40000","101.20090","4.25046"
"202.80000","101.40095","4.26066"
"203.20000","101.60095","4.27057"
"203.60000","101.80101","4.28068"
"204.00000","102.00088","4.28672"
"204.40000","102.20107","4.29593"
"204.80000","102.40100","4.30366"
"205.20000","102.60105","4.31016"
"205.60000","102.80099","4.31692"
"206.00000","103.00092","4.32478"
"206.40000","103.20079","4.33272"
"206.80000","103.40092","4.34101"
"207.20000","103.60098","4.34703"
"207.60000","103.80096","4.35212"
"208.00000","104.00097","4.36268"
"208.40000","104.20090","4.37417"
"208.80000","104.40096","4.38239"
"209.20000","104.60083","4.39084"
"209.60000","104.80090","4.40247"
"210.00000","105.00095","4.40904"
"210.40000","105.20100","4.41794"
"210.80000","105.40094","4.42492"
"211.20000","105.60106","4.43504"
"211.60000","105.80099","4.44471"
"212.00000","106.00086","4.45360"
"212.40000","106.20087","4.46134"
"212.80000","106.40092","4.47550"
"213.20000","106.60097","4.48552"
"213.60000","106.80097","4.49636"
"214.00000","107.00091","4.50349"
"214.40000","107.20103","4.50728"
"214.80000","107.40096","4.51747"
"215.20000","107.60090","4.52279"
"215.60000","107.80096","4.52795"
"216.00000","108.00094","4.53542"
"216.40000","108.20094","4.54374"
"216.80000","108.40106","4.54650"
"217.20000","108.60093","4.55356"
"217.60000","108.80099","4.56011"
"218.00000","109.00092","4.57255"
"218.40000","109.20093","4.58177"
"218.80000","109.40091","4.59271"
"219.20000","109.60103","4.60384"
"219.60000","109.80091","4.61291"
"220.00000","110.00090","4.62552"
"220.40000","110.20090","4.63645"
"220.80000","110.40102","4.64469"
"221.20000","110.60095","4.65198"
"221.60000","110.80101","4.65973"
"222.00000","111.00095","4.67102"
"222.40000","111.20088","4.67726"
"222.80000","111.40100","4.68753"
"223.20000","111.60094","4.69386"
"223.60000","111.80093","4.70336"
"224.00000","112.00086","4.71234"
"224.40000","112.20097","4.71854"
"224.80000","112.40091","4.72277"
"225.20000","112.60091","4.72765"
"225.60000","112.80097","4.73501"
"226.00000","113.00096","4.73732"
"226.40000","113.20096","4.74953"
"226.80000","113.40101","4.76130"
"227.20000","113.60094","4.76666"
"227.60000","113.80095","4.77514"
"228.00000","114.00107","4.78492"
"228.40000","114.20094","4.79494"
"228.80000","114.40094","4.80207"
"229.20000","114.60099","4.81218"
"229.60000","114.80093","4.82166"
"230.00000","115.00098","4.83045"
"230.40000","115.20091","4.83810"
"230.80000","115.40097","4.84925"
"231.20000","115.60091","4.85941"
"231.60000","115.80102","4.86886"
"232.00000","116.00102","4.87952"
"232.40000","116.20096","4.88695"
"232.80000","116.40102","4.90069"
"233.20000","116.60101","4.90661"
"233.60000","116.80095","4.91356"
"234.00000","117.00101","4.92328"
"234.40000","117.20094","4.93055"
"234.80000","117.40099","4.93583"
"235.20000","117.60105","4.93870"
"235.60000","117.80099","4.94608"
"236.00000","118.00092","4.94958"
"236.40000","118.20099","4.95635"
"236.80000","118.40092","4.95981"
"237.20000","118.60086","4.96869"
"237.60000","118.80096","4.98251"
"238.00000","119.00103","4.99335"
"238.40000","119.20109","5.00465"
"238.80000","119.40102","5.01191"
"239.20000","119.60108","5.02071"
"239.60000","119.80090","5.03370"
"240.00000","120.00089","5.04111"
"240.40000","120.20095","5.05249"
"240.80000","120.40100","5.06366"
"241.20000","120.60094","5.07431"
"241.60000","120.80099","5.08435"
"242.00000","121.00105","5.09481"
"242.40000","121.20092","5.10263"
"242.80000","121.40099","5.11299"
"243.20000","121.60104","5.12239"
"243.60000","121.80103","5.13088"
"244.00000","122.00096","5.13464"
"244.40000","122.20103","5.14035"
"244.80000","122.40089","5.14589"
"245.20000","122.60107","5.15400"
"245.60000","122.80096","5.16025"
"246.00000","123.00100","5.17001"
"246.40000","123.20088","5.17501"
"246.80000","123.40099","5.18033"
"247.20000","123.60088","5.19145"
"247.60000","123.80093","5.19850"
"248.00000","124.00092","5.20814"
"248.40000","124.20103","5.21689"
"248.80000","124.40086","5.22721"
"249.20000","124.60098","5.23238"
"249.60000","124.80103","5.24273"
"250.00000","125.00083","5.24808"
"250.40000","125.20102","5.26069"
"250.80000","125.40101","5.27043"
"251.20000","125.60101","5.27517"
"251.60000","125.80093","5.28572"
"252.00000","126.00100","5.29671"
"252.40000","126.20099","5.30656"
"252.80000","126.40087","5.31902"
"253.20000","126.60086","5.32719"
"253.60000","126.80099","5.33210"
"254.00000","127.00097","5.34066"
"254.40000","127.20092","5.34897"
"254.80000","127.40096","5.35542"
"255.20000","127.60097","5.36255"
"255.60000","127.80096","5.36895"
"256.00000","128.00096","5.37725"
"256.40000","128.20094","5.38755"
"256.80000","128.40102","5.39835"
"257.20000","128.60094","5.40451"
"257.60000","128.80095","5.41354"
"258.00000","129.00087","5.42278"
"258.40000","129.20105","5.43360"
"258.80000","129.40092","5.44354"
"259.20000","129.60086","5.45219"
"259.60000","129.80104","5.46143"
"260.00000","130.00098","5.47090"
"260.40000","130.20085","5.48013"
"260.80000","130.40103","5.48898"
"261.20000","130.60095","5.49642"
"261.60000","130.80084","5.50506"
"262.00000","131.00101","5.51329"
"262.40000","131.20096","5.51897"
"262.80000","131.40094","5.52844"
"263.20000","131.60089","5.53374"
"263.60000","131.80093","5.54033"
"264.00000","132.00089","5.54415"
"264.40000","132.20093","5.54867"
"264.80000","132.40086","5.55758"
"265.20000","132.60074","5.56805"
"265.60000","132.80098","5.57304"
"266.00000","133.00098","5.57541"
"266.40000","133.20097","5.58732"
"266.80000","133.40097","5.59872"
"267.20000","133.60091","5.61223"
"267.60000","133.80083","5.62262"
"268.00000","134.00090","5.63187"
"268.40000","134.20096","5.64270"
"268.80000","134.40089","5.65414"
"269.20000","134.60089","5.66388"
"269.60000","134.80093","5.67254"
"270.00000","135.00095","5.68750"
"270.40000","135.20093","5.69586"
"270.80000","135.40100","5.70078"
"271.20000","135.60098","5.71121"
"271.60000","135.80099","5.72163"
"272.00000","136.00098","5.73371"
"272.40000","136.20097","5.74188"
"272.80000","136.40097","5.75074"
"273.20000","136.60097","5.75721"
"273.60000","136.80096","5.76032"
"274.00000","137.00102","5.76603"
"274.40000","137.20090","5.77089"
"274.80000","137.40089","5.77619"
"275.20000","137.60094","5.78039"
"275.60000","137.80095","5.78549"
"276.00000","138.00093","5.79196"
"276.40000","138.20094","5.79834"
"276.80000","138.40092","5.81171"
"277.20000","138.60104","5.82204"
"277.60000","138.80092","5.82964"
"278.00000","139.00098","5.83827"
"278.40000","139.20091","5.85015"
"278.80000","139.40103","5.85572"
"279.20000","139.60097","5.87099"
"279.60000","139.80090","5.87816"
"280.00000","140.00096","5.89117"
"280.40000","140.20084","5.89691"
"280.80000","140.40094","5.91087"
"281.20000","140.60089","5.92324"
"281.60000","140.80093","5.92861"
"282.00000","141.00095","5.93510"
"282.40000","141.20087","5.94759"
"282.80000","141.40088","5.95586"
"283.20000","141.60092","5.96249"
"283.60000","141.80092","5.97112"
"284.00000","142.00104","5.97773"
"284.40000","142.20097","5.98396"
"284.80000","142.40091","5.99234"
"285.20000","142.60097","6.00186"
"285.60000","142.80096","6.00471"
"286.00000","143.00102","6.01650"
"286.40000","143.20094","6.02323"
"286.80000","143.40089","6.03528"
"287.20000","143.60100","6.04460"
"287.60000","143.80101","6.05314"
"288.00000","144.00099","6.06044"
"288.40000","144.20088","6.06907"
"288.80000","144.40086","6.07473"
"289.20000","144.60098","6.08412"
"289.60000","144.80104","6.09283"
"290.00000","145.00098","6.09818"
"290.40000","145.20103","6.10698"
"290.80000","145.40091","6.11425"
"291.20000","145.60095","6.12480"
"291.60000","145.80103","6.13349"
"292.00000","146.00095","6.13948"
"292.40000","146.20084","6.14901"
"292.80000","146.40094","6.15762"
"293.20000","146.60106","6.16543"
"293.60000","146.80093","6.17216"
"294.00000","147.00099","6.18168"
"294.40000","147.20093","6.18310"
"294.80000","147.40099","6.19265"
"295.20000","147.60098","6.20192"
"295.60000","147.80092","6.21321"
"296.00000","148.00092","6.22392"
"296.40000","148.20103","6.23502"
"296.80000","148.40091","6.24549"
"297.20000","148.60091","6.25582"
"297.60000","148.80095","6.26394"
"298.00000","149.00090","6.27739"
"298.40000","149.20096","6.28690"
"298.80000","149.40089","6.30077"
"299.20000","149.60101","6.30752"
"299.60000","149.80089","6.31663"
"300.00000","150.00101","6.32804"
"300.40000","150.20099","6.33658"
"300.80000","150.40094","6.34075"
"301.20000","150.60080","6.35161"
"301.60000","150.80099","6.35775"
"302.00000","151.00098","6.36499"
"302.40000","151.20093","6.36764"
"302.80000","151.40085","6.37430"
"303.20000","151.60091","6.37694"
"303.60000","151.80096","6.38165"
"304.00000","152.00090","6.38346"
"304.40000","152.20096","6.39129"
"304.80000","152.40096","6.39711"
"305.20000","152.60094","6.41236"
"305.60000","152.80101","6.41658"
"306.00000","153.00093","6.42477"
"306.40000","153.20100","6.43713"
"306.80000","153.40092","6.44850"
"307.20000","153.60100","6.45728"
"307.60000","153.80098","6.46752"
"308.00000","154.00098","6.48313"
"308.40000","154.20091","6.48978"
"308.80000","154.40097","6.50042"
"309.20000","154.60097","6.51023"
"309.60000","154.80096","6.52240"
"310.00000","155.00090","6.53212"
"310.40000","155.20096","6.54479"
"310.80000","155.40112","6.55037"
"311.20000","155.60101","6.56077"
"311.60000","155.80106","6.57106"
"312.00000","156.00101","6.58110"
"312.40000","156.20093","6.59150"
"312.80000","156.40099","6.59810"
"313.20000","156.60098","6.60432"
"313.60000","156.80098","6.60588"
"314.00000","157.00090","6.61020"
"314.40000","157.20102","6.61702"
"314.80000","157.40097","6.62612"
"315.20000","157.60103","6.63332"
"315.60000","157.80090","6.64139"
"316.00000","158.00096","6.65175"
"316.40000","158.20094","6.65436"
"316.80000","158.40100","6.65964"
"317.20000","158.60098","6.66896"
"317.60000","158.80095","6.67873"
"318.00000","159.00099","6.68530"
"318.40000","159.20099","6.69574"
"318.80000","159.40086","6.70683"
"319.20000","159.60091","6.71844"
"319.60000","159.80080","6.72184"
"320.00000","160.00092","6.73659"
"320.40000","160.20091","6.74979"
"320.80000","160.40089","6.75643"
"321.20000","160.60091","6.76551"
"321.60000","160.80096","6.77108"
"322.00000","161.00095","6.77811"
"322.40000","161.20094","6.78531"
"322.80000","161.40082","6.79388"
"323.20000","161.60095","6.80154"
"323.60000","161.80099","6.81255"
"324.00000","162.00095","6.81420"
"324.40000","162.20087","6.82676"
"324.80000","162.40088","6.83844"
"325.20000","162.60104","6.84462"
"325.60000","162.80086","6.85406"
"326.00000","163.00092","6.86728"
"326.40000","163.20091","6.87680"
"326.80000","163.40091","6.88945"
"327.20000","163.60091","6.89498"
"327.60000","163.80087","6.91055"
"328.00000","164.00090","6.91324"
"328.40000","164.20102","6.92152"
"328.80000","164.40088","6.92669"
"329.20000","164.60088","6.93662"
"329.60000","164.80095","6.94466"
"330.00000","165.00095","6.95095"
"330.40000","165.20099","6.95782"
"330.80000","165.40094","6.96428"
"331.20000","165.60092","6.96935"
"331.60000","165.80092","6.97766"
"332.00000","166.00090","6.98251"
"332.40000","166.20093","6.98833"
"332.80000","166.40097","6.99833"
"333.20000","166.60091","7.00017"
"333.60000","166.80095","7.01086"
"334.00000","167.00102","7.01937"
"334.40000","167.20102","7.02771"
"334.80000","167.40096","7.03979"
"335.20000","167.60089","7.04763"
"335.60000","167.80107","7.05674"
"336.00000","168.00087","7.06695"
"336.40000","168.20094","7.07810"
"336.80000","168.40092","7.08768"
"337.20000","168.60100","7.09574"
"337.60000","168.80086","7.10864"
"338.00000","169.00093","7.11906"
"338.40000","169.20097","7.12950"
"338.80000","169.40096","7.14410"
"339.20000","169.60101","7.15251"
"339.60000","169.80096","7.16130"
"340.00000","170.00102","7.17025"
"340.40000","170.20108","7.18271"
"340.80000","170.40094","7.18944"
"341.20000","170.60095","7.19755"
"341.60000","170.80099","7.20297"
"342.00000","171.00082","7.20581"
"342.40000","171.20099","7.21330"
"342.80000","171.40100","7.21682"
"343.20000","171.60097","7.22009"
"343.60000","171.80093","7.22247"
"344.00000","172.00104","7.23159"
"344.40000","172.20096","7.23577"
"344.80000","172.40102","7.24935"
"345.20000","172.60097","7.26068"
"345.60000","172.80103","7.25558"
"346.00000","173.00096","7.26813"
"346.40000","173.20105","7.27767"
"346.80000","173.40108","7.28939"
"347.20000","173.60092","7.29963"
"347.60000","173.80095","7.30791"
"348.00000","174.00093","7.31931"
"348.40000","174.20093","7.33152"
"348.80000","174.40097","7.34141"
"349.20000","174.60098","7.35276"
"349.60000","174.80092","7.36556"
"350.00000","175.00110","7.37735"
"350.40000","175.20091","7.38514"
"350.80000","175.40103","7.39188"
"351.20000","175.60101","7.39997"
"351.60000","175.80101","7.40475"
"352.00000","176.00090","7.40920"
"352.40000","176.20096","7.41757"
"352.80000","176.40092","7.42622"
"353.20000","176.60095","7.43369"
"353.60000","176.80087","7.44122"
"354.00000","177.00101","7.45235"
"354.40000","177.20091","7.46056"
"354.80000","177.40092","7.46934"
"355.20000","177.60098","7.47859"
"355.60000","177.80104","7.48747"
"356.00000","178.00102","7.49775"
"356.40000","178.20097","7.50556"
"356.80000","178.40102","7.51268"
"357.20000","178.60097","7.51902"
"357.60000","178.80099","7.52644"
"358.00000","179.00108","7.53601"
"358.40000","179.20108","7.54742"
"358.80000","179.40096","7.55639"
"359.20000","179.60088","7.55327"
"359.60000","179.80087","7.56586"
"360.00000","180.00099","7.57557"
"360.40000","180.20093","7.58422"
"360.80000","180.40100","7.59309"
"361.20000","180.60091","7.60053"
"361.60000","180.80099","7.60730"
"362.00000","181.00098","7.61259"
"362.40000","181.20093","7.61904"
"362.80000","181.40085","7.63057"
"363.20000","181.60103","7.64401"
"363.60000","181.80103","7.64637"
"364.00000","182.00101","7.65550"
"364.40000","182.20107","7.66233"
"364.80000","182.40096","7.67245"
"365.20000","182.60083","7.68376"
"365.60000","182.80089","7.69578"
"366.00000","183.00093","7.70769"
"366.40000","183.20093","7.70461"
"366.80000","183.40097","7.71843"
"367.20000","183.60106","7.73386"
"367.60000","183.80098","7.74548"
"368.00000","184.00087","7.75341"
"368.40000","184.20102","7.76251"
"368.80000","184.40091","7.76245"
"369.20000","184.60103","7.77224"
"369.60000","184.80090","7.78424"
"370.00000","185.00096","7.79465"
"370.40000","185.20102","7.79922"
"370.80000","185.40094","7.79996"
"371.20000","185.60095","7.80928"
"371.60000","185.80087","7.81530"
"372.00000","186.00101","7.82206"
"372.40000","186.20097","7.82669"
"372.80000","186.40080","7.84185"
"373.20000","186.60104","7.83642"
"373.60000","186.80096","7.85087"
"374.00000","187.00085","7.85811"
"374.40000","187.20103","7.86898"
"374.80000","187.40097","7.87973"
"375.20000","187.60091","7.88527"
"375.60000","187.80090","7.89647"
"376.00000","188.00095","7.90728"
"376.40000","188.20094","7.91828"
"376.80000","188.40089","7.92643"
"377.20000","188.60081","7.93801"
"377.60000","188.80093","7.93374"
"378.00000","189.00093","7.94243"
"378.40000","189.20100","7.95597"
"378.80000","189.40091","7.96079"
"379.20000","189.60097","7.97144"
"379.60000","189.80086","7.98299"
"380.00000","190.00090","7.99229"
"380.40000","190.20096","8.00245"
"380.80000","190.40096","8.01206"
"381.20000","190.60091","8.01876"
"381.60000","190.80089","8.02817"
"382.00000","191.00095","8.03196"
"382.40000","191.20090","8.03963"
"382.80000","191.40086","8.04693"
"383.20000","191.60100","8.05182"
"383.60000","191.80098","8.05925"
"384.00000","192.00095","8.05644"
"384.40000","192.20091","8.06936"
"384.80000","192.40097","8.07648"
"385.20000","192.60097","8.08538"
"385.60000","192.80109","8.09629"
"386.00000","193.00096","8.10786"
"386.40000","193.20108","8.12035"
"386.80000","193.40097","8.13016"
"387.20000","193.60089","8.12231"
"387.60000","193.80093","8.13492"
"388.00000","194.00102","8.14660"
"388.40000","194.20094","8.15852"
"388.80000","194.40094","8.16784"
"389.20000","194.60094","8.18055"
"389.60000","194.80101","8.19186"
"390.00000","195.00085","8.20011"
"390.40000","195.20093","8.20994"
"390.80000","195.40105","8.21750"
"391.20000","195.60104","8.22581"
"391.60000","195.80104","8.22026"
"392.00000","196.00102","8.22793"
"392.40000","196.20099","8.23497"
"392.80000","196.40085","8.24700"
"393.20000","196.60097","8.24756"
"393.60000","196.80096","8.25823"
"394.00000","197.00095","8.26678"
"394.40000","197.20094","8.27755"
"394.80000","197.40102","8.28929"
"395.20000","197.60088","8.28979"
"395.60000","197.80087","8.30298"
"396.00000","198.00089","8.31712"
"396.40000","198.20094","8.33009"
"396.80000","198.40105","8.33985"
"397.20000","198.60092","8.34748"
"397.60000","198.80098","8.35694"
"398.00000","199.00104","8.36311"
"398.40000","199.20096","8.37531"
"398.80000","199.40096","8.36368"
"399.20000","199.60091","8.37933"
"399.60000","199.80095","8.38942"
"400.00000","200.00095","8.39948"
"400.40000","200.20100","8.40906"
"400.80000","200.40096","8.42194"
"401.20000","200.60100","8.42938"
"401.60000","200.80092","8.42681"
"402.00000","201.00101","8.43471"
"402.40000","201.20099","8.44082"
"402.80000","201.40094","8.44924"
"403.20000","201.60103","8.45759"
"403.60000","201.80092","8.46306"
"404.00000","202.00104","8.47099"
"404.40000","202.20087","8.48322"
"404.80000","202.40091","8.49334"
"405.20000","202.60095","8.47961"
"405.60000","202.80101","8.49545"
"406.00000","203.00090","8.50650"
"406.40000","203.20100","8.51545"
"406.80000","203.40094","8.52853"
"407.20000","203.60094","8.54042"
"407.60000","203.80101","8.55273"
"408.00000","204.00099","8.56251"
"408.40000","204.20099","8.57556"
"408.80000","204.40109","8.56946"
"409.20000","204.60092","8.57924"
"409.60000","204.80090","8.58921"
"410.00000","205.00092","8.60202"
"410.40000","205.20091","8.61096"
"410.80000","205.40089","8.62366"
"411.20000","205.60095","8.63284"
"411.60000","205.80090","8.62874"
"412.00000","206.00082","8.63762"
"412.40000","206.20100","8.64397"
"412.80000","206.40092","8.65083"
"413.20000","206.60095","8.65819"
"413.60000","206.80086","8.66108"
"414.00000","207.00095","8.66075"
"414.40000","207.20087","8.67174"
"414.80000","207.40086","8.68083"
"415.20000","207.60086","8.69806"
"415.60000","207.80092","8.70780"
"416.00000","208.00092","8.70629"
"416.40000","208.20096","8.71865"
"416.80000","208.40091","8.73275"
"417.20000","208.60097","8.74154"
"417.60000","208.80083","8.75317"
"418.00000","209.00089","8.75681"
"418.40000","209.20094","8.76232"
"418.80000","209.40096","8.77343"
"419.20000","209.60110","8.78571"
"419.60000","209.80093","8.79531"
"420.00000","210.00093","8.80637"
"420.40000","210.20093","8.81768"
"420.80000","210.40091","8.82074"
"421.20000","210.60097","8.82459"
"421.60000","210.80099","8.83651"
"422.00000","211.00096","8.84076"
"422.40000","211.20090","8.85071"
"422.80000","211.40097","8.85790"
"423.20000","211.60095","8.86421"
"423.60000","211.80095","8.86780"
"424.00000","212.00096","8.86836"
"424.40000","212.20102","8.87446"
"424.80000","212.40094","8.88084"
"425.20000","212.60104","8.88777"
"425.60000","212.80101","8.89966"
"426.00000","213.00105","8.91020"
"426.40000","213.20093","8.92162"
"426.80000","213.40103","8.93382"
"427.20000","213.60092","8.94079"
"427.60000","213.80090","8.95014"
"428.00000","214.00098","8.96036"
"428.40000","214.20091","8.96964"
"428.80000","214.40096","8.96206"
"429.20000","214.60095","8.97526"
"429.60000","214.80096","8.98692"
"430.00000","215.00089","9.00092"
"430.40000","215.20100","9.01196"
"430.80000","215.40105","9.02739"
"431.20000","215.60095","9.03726"
"431.60000","215.80106","9.04550"
"432.00000","216.00095","9.05324"
"432.40000","216.20087","9.05624"
"432.80000","216.40092","9.06186"
"433.20000","216.60097","9.06601"
"433.60000","216.80087","9.07649"
"434.00000","217.00092","9.08241"
"434.40000","217.20096","9.08578"
"434.80000","217.40096","9.09326"
"435.20000","217.60083","9.07920"
"435.60000","217.80096","9.09054"
"436.00000","218.00095","9.10230"
"436.40000","218.20090","9.11489"
"436.80000","218.40088","9.11930"
"437.20000","218.60100","9.13082"
"437.60000","218.80093","9.14174"
"438.00000","219.00087","9.14420"
"438.40000","219.20100","9.15501"
"438.80000","219.40091","9.16416"
"439.20000","219.60094","9.17039"
"439.60000","219.80084","9.17985"
"440.00000","220.00096","9.18774"
"440.40000","220.20090","9.19810"
"440.80000","220.40102","9.19535"
"441.20000","220.60097","9.20462"
"441.60000","220.80090","9.21707"
"442.00000","221.00095","9.22844"
"442.40000","221.20088","9.23699"
"442.80000","221.40100","9.24763"
"443.20000","221.60100","9.25572"
"443.60000","221.80098","9.26431"
"444.00000","222.00093","9.27243"
"444.40000","222.20091","9.26629"
"444.80000","222.40094","9.27406"
"445.20000","222.60092","9.28162"
"445.60000","222.80090","9.29350"
"446.00000","223.00092","9.30148"
"446.40000","223.20103","9.31387"
"446.80000","223.40103","9.32407"
"447.20000","223.60095","9.33472"
"447.60000","223.80090","9.32911"
"448.00000","224.00096","9.34178"
"448.40000","224.20100","9.35273"
"448.80000","224.40100","9.36201"
"449.20000","224.60100","9.37320"
"449.60000","224.80087","9.36701"
"450.00000","225.00092","9.37827"
"450.40000","225.20103","9.39071"
"450.80000","225.40092","9.40377"
"451.20000","225.60091","9.41469"
"451.60000","225.80096","9.42507"
"452.00000","226.00102","9.43635"
"452.40000","226.20090","9.44582"
"452.80000","226.40096","9.43926"
"453.20000","226.60097","9.44858"
"453.60000","226.80089","9.45569"
"454.00000","227.00101","9.46297"
"454.40000","227.20090","9.46700"
"454.80000","227.40096","9.47213"
"455.20000","227.60101","9.47613"
"455.60000","227.80093","9.48149"
"456.00000","228.00095","9.48351"
"456.40000","228.20100","9.50295"
"456.80000","228.40091","9.49477"
"457.20000","228.60098","9.49964"
"457.60000","228.80098","9.51685"
"458.00000","229.00104","9.53283"
"458.40000","229.20096","9.54260"
"458.80000","229.40108","9.55644"
"459.20000","229.60097","9.55759"
"459.60000","229.80095","9.56760"
"460.00000","230.00095","9.57873"
"460.40000","230.20088","9.58969"
"460.80000","230.40094","9.59884"
"461.20000","230.60095","9.60898"
"461.60000","230.80095","9.61830"
"462.00000","231.00101","9.62892"
"462.40000","231.20097","9.63906"
"462.80000","231.40094","9.64566"
"463.20000","231.60098","9.64269"
"463.60000","231.80098","9.65362"
"464.00000","232.00096","9.66370"
"464.40000","232.20097","9.66841"
"464.80000","232.40103","9.67805"
"465.20000","232.60095","9.68725"
"465.60000","232.80101","9.69199"
"466.00000","233.00089","9.69636"
"466.40000","233.20094","9.70258"
"466.80000","233.40083","9.70817"
"467.20000","233.60089","9.71647"
"467.60000","233.80093","9.70954"
"468.00000","234.00098","9.71783"
"468.40000","234.20094","9.72666"
"468.80000","234.40099","9.73577"
"469.20000","234.60092","9.74556"
"469.60000","234.80086","9.75327"
"470.00000","235.00093","9.76244"
"470.40000","235.20103","9.76990"
"470.80000","235.40102","9.76541"
"471.20000","235.60101","9.77721"
"471.60000","235.80096","9.78921"
"472.00000","236.00089","9.80221"
"472.40000","236.20100","9.81386"
"472.80000","236.40089","9.81514"
"473.20000","236.60094","9.82562"
"473.60000","236.80087","9.84025"
"474.00000","237.00101","9.84659"
"474.40000","237.20085","9.84227"
"474.80000","237.40105","9.85364"
"475.20000","237.60092","9.86099"
"475.60000","237.80104","9.87283"
"476.00000","238.00090","9.88368"
"476.40000","238.20090","9.89092"
"476.80000","238.40097","9.89716"
"477.20000","238.60089","9.90612"
"477.60000","238.80089","9.91494"
"478.00000","239.00095","9.90513"
"478.40000","239.20100","9.91325"
"478.80000","239.40083","9.92586"
"479.20000","239.60092","9.93798"
"479.60000","239.80106","9.94806"
"480.00000","240.00093","9.95869"
"480.40000","240.20088","9.95298"
"480.80000","240.40097","9.96669"
"481.20000","240.60098","9.97814"
"481.60000","240.80098","9.98796"
"482.00000","241.00102","9.99698"
"482.40000","241.20091","10.00542"
"482.80000","241.40097","9.99686"
"483.20000","241.60095","10.00864"
"483.60000","241.80096","10.01721"
"484.00000","242.00096","10.02484"
"484.40000","242.20088","10.03502"
"484.80000","242.40094","10.04471"
"485.20000","242.60095","10.05356"
"485.60000","242.80101","10.04858"
"486.00000","243.00098","10.05875"
"486.40000","243.20088","10.06560"
"486.80000","243.40109","10.07378"
"487.20000","243.60106","10.08071"
"487.60000","243.80090","10.08925"
"488.00000","244.00104","10.08588"
"488.40000","244.20097","10.08966"
"488.80000","244.40086","10.09646"
"489.20000","244.60095","10.10905"
"489.60000","244.80096","10.11988"
"490.00000","245.00102","10.12609"
"490.40000","245.20090","10.13809"
"490.80000","245.40096","10.13649"
"491.20000","245.60094","10.14861"
"491.60000","245.80098","10.15954"
"492.00000","246.00101","10.17291"
"492.40000","246.20093","10.16256"
"492.80000","246.40099","10.17769"
"493.20000","246.60097","10.19033"
"493.60000","246.80093","10.20104"
"494.00000","247.00104","10.21085"
"494.40000","247.20091","10.22411"
"494.80000","247.40085","10.23534"
"495.20000","247.60097","10.23868"
"495.60000","247.80103","10.23927"
"496.00000","248.00095","10.25127"
"496.40000","248.20090","10.26690"
"496.80000","248.40102","10.27473"
"497.20000","248.60098","10.28423"
"497.60000","248.80089","10.28789"
"498.00000","249.00105","10.28635"
"498.40000","249.20099","10.27631"
"498.80000","249.40097","10.28683"
"499.20000","249.60104","10.29699"
"499.60000","249.80090","10.30079"
"500.00000","250.00095","10.30439"
"500.40000","250.20096","10.31264"
"500.80000","250.40089","10.31413"
"501.20000","250.60094","10.33076"
"501.60000","250.80093","10.33838"
"502.00000","251.00095","10.33492"
"502.40000","251.20094","10.34399"
"502.80000","251.40097","10.35348"
"503.20000","251.60092","10.36276"
"503.60000","251.80098","10.35887"
"504.00000","252.00099","10.36725"
"504.40000","252.20102","10.37982"
"504.80000","252.40097","10.39088"
"505.20000","252.60097","10.40314"
"505.60000","252.80086","10.41547"
"506.00000","253.00101","10.42577"
"506.40000","253.20088","10.42002"
"506.80000","253.40102","10.43055"
"507.20000","253.60089","10.44317"
"507.60000","253.80087","10.45560"
"508.00000","254.00087","10.46803"
"508.40000","254.20088","10.46567"
"508.80000","254.40094","10.46776"
"509.20000","254.60085","10.48206"
"509.60000","254.80098","10.49214"
"510.00000","255.00085","10.50029"
"510.40000","255.20099","10.50794"
"510.80000","255.40083","10.51398"
"511.20000","255.60095","10.51929"
"511.60000","255.80096","10.52784"
"512.00000","256.00092","10.53538"
"512.40000","256.20087","10.54404"
"512.80000","256.40088","10.52022"
"513.20000","256.60101","10.53152"
"513.60000","256.80096","10.54138"
"514.00000","257.00092","10.54888"
"514.40000","257.20093","10.55819"
"514.80000","257.40106","10.56652"
"515.20000","257.60098","10.57825"
"515.60000","257.80099","10.58181"
"516.00000","258.00098","10.59127"
"516.40000","258.20096","10.59767"
"516.80000","258.40091","10.57410"
"517.20000","258.60098","10.58507"
"517.60000","258.80096","10.59325"
"518.00000","259.00089","10.60285"
"518.40000","259.20084","10.60799"
"518.80000","259.40103","10.61722"
"519.20000","259.60098","10.63093"
"519.60000","259.80093","10.63960"
"520.00000","260.00101","10.64767"
"520.40000","260.20102","10.66007"
"520.80000","260.40097","10.64083"
"521.20000","260.60110","10.65613"
"521.60000","260.80093","10.66825"
"522.00000","261.00095","10.68032"
"522.40000","261.20090","10.69351"
"522.80000","261.40091","10.69719"
"523.20000","261.60092","10.70440"
"523.60000","261.80103","10.71032"
"524.00000","262.00089","10.72121"
"524.40000","262.20090","10.72836"
"524.80000","262.40100","10.73417"
"525.20000","262.60095","10.74274"
"525.60000","262.80099","10.75441"
"526.00000","263.00089","10.76530"
"526.40000","263.20087","10.73976"
"526.80000","263.40088","10.75287"
"527.20000","263.60092","10.76124"
"527.60000","263.80096","10.77587"
"528.00000","264.00085","10.78686"
"528.40000","264.20087","10.79955"
"528.80000","264.40097","10.80927"
"529.20000","264.60089","10.81926"
"529.60000","264.80096","10.83130"
"530.00000","265.00092","10.83877"
"530.40000","265.20090","10.84718"
"530.80000","265.40094","10.82742"
"531.20000","265.60095","10.83453"
"531.60000","265.80090","10.84363"
"532.00000","266.00098","10.85449"
"532.40000","266.20087","10.86275"
"532.80000","266.40094","10.87104"
"533.20000","266.60098","10.87987"
"533.60000","266.80096","10.88290"
"534.00000","267.00092","10.87197"
"534.40000","267.20099","10.87758"
"534.80000","267.40085","10.88778"
"535.20000","267.60089","10.89364"
"535.60000","267.80096","10.89208"
"536.00000","268.00092","10.89855"
"536.40000","268.20102","10.90393"
"536.80000","268.40094","10.90873"
"537.20000","268.60095","10.90856"
"537.60000","268.80099","10.91328"
"538.00000","269.00107","10.92190"
"538.40000","269.20099","10.92754"
"538.80000","269.40097","10.92298"
"539.20000","269.60104","10.93216"
"539.60000","269.80087","10.93867"
"540.00000","270.00092","10.94191"
"540.40000","270.20096","10.95338"
"540.80000","270.40103","10.96623"
"541.20000","270.60092","10.96440"
"541.60000","270.80106","10.97793"
"542.00000","271.00089","10.98713"
"542.40000","271.20096","10.99160"
"542.80000","271.40091","11.00100"
"543.20000","271.60092","11.00902"
"543.60000","271.80087","11.01770"
"544.00000","272.00101","11.02621"
"544.40000","272.20099","11.03652"
"544.80000","272.40085","11.04967"
"545.20000","272.60092","11.03743"
"545.60000","272.80093","11.05519"
"546.00000","273.00085","11.06672"
"546.40000","273.20093","11.07159"
"546.80000","273.40091","11.08436"
"547.20000","273.60089","11.09781"
"547.60000","273.80090","11.10724"
"548.00000","274.00098","11.09645"
"548.40000","274.20084","11.10189"
"548.80000","274.40082","11.11371"
"549.20000","274.60095","11.12302"
"549.60000","274.80103","11.12647"
"550.00000","275.00089","11.13431"
"550.40000","275.20087","11.13910"
"550.80000","275.40100","11.13216"
"551.20000","275.60095","11.13816"
"551.60000","275.80084","11.14318"
"552.00000","276.00092","11.14858"
"552.40000","276.20087","11.15309"
"552.80000","276.40097","11.15859"
"553.20000","276.60089","11.16930"
"553.60000","276.80096","11.15953"
"554.00000","277.00092","11.17127"
"554.40000","277.20090","11.17802"
"554.80000","277.40100","11.18513"
"555.20000","277.60095","11.19350"
"555.60000","277.80099","11.20344"
"556.00000","278.00089","11.21170"
"556.40000","278.20099","11.22095"
"556.80000","278.40100","11.20646"
"557.20000","278.60086","11.22093"
"557.60000","278.80099","11.23079"
"558.00000","279.00092","11.24108"
"558.40000","279.20096","11.25049"
"558.80000","279.40097","11.25910"
"559.20000","279.60104","11.24999"
"559.60000","279.80096","11.25764"
"560.00000","280.00095","11.26646"
"560.40000","280.20096","11.27118"
"560.80000","280.40091","11.27938"
"561.20000","280.60098","11.28355"
"561.60000","280.80099","11.29483"
"562.00000","281.00089","11.29687"
"562.40000","281.20102","11.29866"
"562.80000","281.40091","11.30541"
"563.20000","281.60092","11.31030"
"563.60000","281.80093","11.31492"
"564.00000","282.00098","11.32128"
"564.40000","282.20090","11.32520"
"564.80000","282.40091","11.33122"
"565.20000","282.60107","11.33247"
"565.60000","282.80103","11.33231"
"566.00000","283.00095","11.33875"
"566.40000","283.20108","11.31137"
"566.80000","283.40094","11.31782"
"567.20000","283.60089","11.31651"
"567.60000","283.80093","11.31334"
"568.00000","284.00089","11.26180"
"568.04200","284.02185","9.10258"
"568.05000","284.02588","6.67075"