File: MT-DataAnalysis-JupyterNotebook/TensionPlots/TensionTests/CoilDiameter/Specimen_RawData_14.csv
End date,"8/16/2018"
Specimen label,"D50L40N5d4"
Maximum Load,"14.33048",N
Extension at Maximum Load,"219.70100",mm
Maximum Slope (Automatic Young's),"0.07474",N/mm
Rate 1,"30.00000",mm/min

Time,Extension,Load
(s),(mm),(N)
"0.00000","0.00000","0.00860"
"0.30000","0.14953","0.05195"
"0.60000","0.30116","0.07571"
"0.90000","0.45099","0.09907"
"1.20000","0.60088","0.12212"
"1.50000","0.75102","0.14218"
"1.80000","0.90091","0.15344"
"2.10000","1.05098","0.17366"
"2.40000","1.20093","0.18250"
"2.70000","1.35100","0.19021"
"3.00000","1.50096","0.20459"
"3.30000","1.65109","0.21770"
"3.60000","1.80098","0.23320"
"3.90000","1.95099","0.24761"
"4.20000","2.10106","0.26590"
"4.50000","2.25108","0.27841"
"4.80000","2.40097","0.29364"
"5.10000","2.55104","0.30803"
"5.40000","2.70105","0.32533"
"5.70000","2.85094","0.34084"
"6.00000","3.00096","0.36802"
"6.30000","3.15097","0.36958"
"6.60000","3.30104","0.40083"
"6.90000","3.45105","0.41684"
"7.20000","3.60088","0.43177"
"7.50000","3.75108","0.45130"
"7.80000","3.90091","0.45324"
"8.10000","4.05098","0.47118"
"8.40000","4.20093","0.48283"
"8.70000","4.35094","0.51006"
"9.00000","4.50096","0.52208"
"9.30000","4.65103","0.52992"
"9.60000","4.80092","0.54881"
"9.90000","4.95099","0.56193"
"10.20000","5.10100","0.57674"
"10.50000","5.25108","0.58838"
"10.80000","5.40103","0.59201"
"11.10000","5.55098","0.60073"
"11.40000","5.70105","0.60916"
"11.70000","5.85094","0.61901"
"12.00000","6.00096","0.62231"
"12.30000","6.15091","0.63202"
"12.60000","6.30098","0.64498"
"12.90000","6.45093","0.65155"
"13.20000","6.60094","0.66380"
"13.50000","6.75102","0.66993"
"13.80000","6.90097","0.68785"
"14.10000","7.05098","0.70400"
"14.40000","7.20099","0.71597"
"14.70000","7.35094","0.72615"
"15.00000","7.50090","0.74598"
"15.30000","7.65109","0.75798"
"15.60000","7.80086","0.76580"
"15.90000","7.95099","0.77890"
"16.20000","8.10094","0.78859"
"16.50000","8.25101","0.79415"
"16.80000","8.40097","0.80090"
"17.10000","8.55098","0.81289"
"17.40000","8.70093","0.81927"
"17.70000","8.85094","0.82276"
"18.00000","9.00102","0.83284"
"18.30000","9.15103","0.84342"
"18.60000","9.30104","0.85974"
"18.90000","9.45087","0.86759"
"19.20000","9.60106","0.87380"
"19.50000","9.75102","0.89086"
"19.80000","9.90103","0.91193"
"20.10000","10.05098","0.93049"
"20.40000","10.20099","0.94575"
"20.70000","10.35094","0.95293"
"21.00000","10.50096","0.97584"
"21.30000","10.65097","0.98057"
"21.60000","10.80098","0.99620"
"21.90000","10.95099","1.00179"
"22.20000","11.10112","1.01362"
"22.50000","11.25089","1.02244"
"22.80000","11.40097","1.03186"
"23.10000","11.55098","1.03980"
"23.40000","11.70099","1.05358"
"23.70000","11.85100","1.05350"
"24.00000","12.00101","1.07342"
"24.30000","12.15103","1.08775"
"24.60000","12.30104","1.10522"
"24.90000","12.45093","1.12241"
"25.20000","12.60106","1.13023"
"25.50000","12.75090","1.13908"
"25.80000","12.90103","1.14393"
"26.10000","13.05104","1.17459"
"26.40000","13.20099","1.18681"
"26.70000","13.35100","1.20239"
"27.00000","13.50107","1.20355"
"27.30000","13.65103","1.21392"
"27.60000","13.80098","1.21979"
"27.90000","13.95105","1.23068"
"28.20000","14.10112","1.23769"
"28.50000","14.25101","1.24438"
"28.80000","14.40097","1.24822"
"29.10000","14.55104","1.25761"
"29.40000","14.70105","1.26751"
"29.70000","14.85100","1.27142"
"30.00000","15.00095","1.28122"
"30.30000","15.15109","1.29668"
"30.60000","15.30098","1.31126"
"30.90000","15.45099","1.31897"
"31.20000","15.60100","1.33417"
"31.50000","15.75095","1.34630"
"31.80000","15.90103","1.36340"
"32.10000","16.05110","1.37996"
"32.40000","16.20105","1.38974"
"32.70000","16.35100","1.39411"
"33.00000","16.50095","1.41119"
"33.30000","16.65096","1.41811"
"33.60000","16.80098","1.42556"
"33.90000","16.95105","1.43351"
"34.20000","17.10094","1.44880"
"34.50000","17.25101","1.45391"
"34.80000","17.40097","1.46819"
"35.10000","17.55116","1.48098"
"35.40000","17.70105","1.49825"
"35.70000","17.85100","1.51366"
"36.00000","18.00107","1.52552"
"36.30000","18.15108","1.53493"
"36.60000","18.30092","1.54294"
"36.90000","18.45099","1.55050"
"37.20000","18.60100","1.56667"
"37.50000","18.75095","1.58014"
"37.80000","18.90103","1.59006"
"38.10000","19.05098","1.59887"
"38.40000","19.20099","1.61000"
"38.70000","19.35106","1.61644"
"39.00000","19.50101","1.62809"
"39.30000","19.65108","1.63128"
"39.60000","19.80104","1.63541"
"39.90000","19.95093","1.65015"
"40.20000","20.10094","1.66400"
"40.50000","20.25095","1.67544"
"40.80000","20.40096","1.68848"
"41.10000","20.55104","1.70109"
"41.40000","20.70105","1.71566"
"41.70000","20.85100","1.73023"
"42.00000","21.00107","1.74346"
"42.30000","21.15103","1.75658"
"42.60000","21.30086","1.76759"
"42.90000","21.45099","1.77743"
"43.20000","21.60100","1.79277"
"43.50000","21.75096","1.80949"
"43.80000","21.90103","1.82113"
"44.10000","22.05110","1.82690"
"44.40000","22.20105","1.83595"
"44.70000","22.35094","1.84112"
"45.00000","22.50101","1.84774"
"45.30000","22.65102","1.85339"
"45.60000","22.80098","1.85921"
"45.90000","22.95093","1.86802"
"46.20000","23.10100","1.88201"
"46.50000","23.25095","1.89580"
"46.80000","23.40091","1.90667"
"47.10000","23.55098","1.91620"
"47.40000","23.70099","1.93266"
"47.70000","23.85100","1.94334"
"48.00000","24.00101","1.96002"
"48.30000","24.15102","1.97798"
"48.60000","24.30104","1.98546"
"48.90000","24.45099","1.99896"
"49.20000","24.60094","2.01250"
"49.50000","24.75101","2.02464"
"49.80000","24.90097","2.04274"
"50.10000","25.05104","2.05052"
"50.40000","25.20099","2.05712"
"50.70000","25.35106","2.06561"
"51.00000","25.50101","2.07515"
"51.30000","25.65097","2.08681"
"51.60000","25.80098","2.09285"
"51.90000","25.95093","2.10939"
"52.20000","26.10100","2.12049"
"52.50000","26.25096","2.12504"
"52.80000","26.40102","2.13727"
"53.10000","26.55110","2.14588"
"53.40000","26.70099","2.15785"
"53.70000","26.85094","2.17445"
"54.00000","27.00095","2.18264"
"54.30000","27.15097","2.19124"
"54.60000","27.30098","2.20885"
"54.90000","27.45099","2.21661"
"55.20000","27.60094","2.22795"
"55.50000","27.75095","2.24154"
"55.80000","27.90108","2.24957"
"56.10000","28.05103","2.26018"
"56.40000","28.20105","2.26866"
"56.70000","28.35100","2.28411"
"57.00000","28.50095","2.29974"
"57.30000","28.65103","2.30765"
"57.60000","28.80098","2.32669"
"57.90000","28.95093","2.33877"
"58.20000","29.10094","2.35781"
"58.50000","29.25095","2.37690"
"58.80000","29.40109","2.38757"
"59.10000","29.55098","2.39837"
"59.40000","29.70099","2.40866"
"59.70000","29.85106","2.41787"
"60.00000","30.00113","2.43023"
"60.30000","30.15096","2.44212"
"60.60000","30.30104","2.44531"
"60.90000","30.45105","2.45100"
"61.20000","30.60094","2.45492"
"61.50000","30.75101","2.46511"
"61.80000","30.90108","2.46952"
"62.10000","31.05104","2.48271"
"62.40000","31.20099","2.49098"
"62.70000","31.35100","2.50663"
"63.00000","31.50113","2.51600"
"63.30000","31.65108","2.52933"
"63.60000","31.80097","2.55334"
"63.90000","31.95099","2.56548"
"64.20000","32.10094","2.57146"
"64.50000","32.25095","2.58921"
"64.80000","32.40108","2.59951"
"65.10000","32.55098","2.60876"
"65.40000","32.70105","2.62309"
"65.70000","32.85112","2.63858"
"66.00000","33.00107","2.65521"
"66.30000","33.15091","2.66240"
"66.60000","33.30104","2.67207"
"66.90000","33.45105","2.68234"
"67.20000","33.60094","2.68942"
"67.50000","33.75095","2.69658"
"67.80000","33.90102","2.70274"
"68.10000","34.05103","2.71105"
"68.40000","34.20099","2.72395"
"68.70000","34.35100","2.73554"
"69.00000","34.50107","2.74799"
"69.30000","34.65102","2.76519"
"69.60000","34.80092","2.77837"
"69.90000","34.95105","2.78991"
"70.20000","35.10088","2.80745"
"70.50000","35.25095","2.82559"
"70.80000","35.40096","2.83364"
"71.10000","35.55091","2.85131"
"71.40000","35.70099","2.85712"
"71.70000","35.85100","2.86183"
"72.00000","36.00101","2.87306"
"72.30000","36.15096","2.88161"
"72.60000","36.30098","2.89348"
"72.90000","36.45099","2.90297"
"73.20000","36.60094","2.92091"
"73.50000","36.75089","2.93008"
"73.80000","36.90102","2.95368"
"74.10000","37.05092","2.95910"
"74.40000","37.20099","2.97448"
"74.70000","37.35100","2.98095"
"75.00000","37.50101","2.99364"
"75.30000","37.65102","3.00533"
"75.60000","37.80103","3.01512"
"75.90000","37.95105","3.02297"
"76.20000","38.10100","3.02762"
"76.50000","38.25095","3.03984"
"76.80000","38.40096","3.05214"
"77.10000","38.55098","3.06352"
"77.40000","38.70087","3.07615"
"77.70000","38.85112","3.07768"
"78.00000","39.00101","3.08993"
"78.30000","39.15102","3.09697"
"78.60000","39.30103","3.10808"
"78.90000","39.45099","3.11804"
"79.20000","39.60099","3.13059"
"79.50000","39.75089","3.14903"
"79.80000","39.90102","3.15738"
"80.10000","40.05104","3.17935"
"80.40000","40.20099","3.18906"
"80.70000","40.35106","3.20508"
"81.00000","40.50095","3.22169"
"81.30000","40.65096","3.23523"
"81.60000","40.80098","3.24493"
"81.90000","40.95093","3.25847"
"82.20000","41.10094","3.26539"
"82.50000","41.25107","3.27638"
"82.80000","41.40096","3.28233"
"83.10000","41.55109","3.28699"
"83.40000","41.70093","3.29534"
"83.70000","41.85106","3.30062"
"84.00000","42.00101","3.30988"
"84.30000","42.15096","3.32111"
"84.60000","42.30104","3.33286"
"84.90000","42.45093","3.34256"
"85.20000","42.60100","3.35864"
"85.50000","42.75113","3.37191"
"85.80000","42.90096","3.38679"
"86.10000","43.05103","3.40789"
"86.40000","43.20098","3.41590"
"86.70000","43.35100","3.42912"
"87.00000","43.50095","3.44263"
"87.30000","43.65090","3.45517"
"87.60000","43.80104","3.46385"
"87.90000","43.95092","3.47983"
"88.20000","44.10100","3.49283"
"88.50000","44.25107","3.50617"
"88.80000","44.40102","3.51411"
"89.10000","44.55098","3.51864"
"89.40000","44.70110","3.52751"
"89.70000","44.85100","3.53434"
"90.00000","45.00095","3.54581"
"90.30000","45.15108","3.55882"
"90.60000","45.30109","3.57104"
"90.90000","45.45098","3.58245"
"91.20000","45.60100","3.59148"
"91.50000","45.75101","3.60296"
"91.80000","45.90096","3.61407"
"92.10000","46.05092","3.62750"
"92.40000","46.20105","3.63929"
"92.70000","46.35106","3.65754"
"93.00000","46.50107","3.66002"
"93.30000","46.65090","3.67349"
"93.60000","46.80109","3.68170"
"93.90000","46.95093","3.69292"
"94.20000","47.10100","3.70113"
"94.50000","47.25095","3.71197"
"94.80000","47.40096","3.72251"
"95.10000","47.55098","3.73610"
"95.40000","47.70111","3.74187"
"95.70000","47.85094","3.75740"
"96.00000","48.00101","3.77757"
"96.30000","48.15102","3.79136"
"96.60000","48.30109","3.80463"
"96.90000","48.45098","3.81621"
"97.20000","48.60100","3.82762"
"97.50000","48.75107","3.83567"
"97.80000","48.90096","3.84909"
"98.10000","49.05097","3.85844"
"98.40000","49.20093","3.87166"
"98.70000","49.35094","3.88119"
"99.00000","49.50101","3.88874"
"99.30000","49.65096","3.89883"
"99.60000","49.80110","3.90380"
"99.90000","49.95093","3.91421"
"100.20000","50.10100","3.92149"
"100.50000","50.25095","3.93208"
"100.80000","50.40096","3.94558"
"101.10000","50.55085","3.95108"
"101.40000","50.70098","3.96731"
"101.70000","50.85088","3.98178"
"102.00000","51.00095","3.99275"
"102.30000","51.15096","4.00565"
"102.60000","51.30097","4.01990"
"102.90000","51.45098","4.03410"
"103.20000","51.60100","4.05017"
"103.50000","51.75095","4.06524"
"103.80000","51.90090","4.07784"
"104.10000","52.05098","4.09280"
"104.40000","52.20098","4.09878"
"104.70000","52.35106","4.11228"
"105.00000","52.50089","4.11524"
"105.30000","52.65102","4.11941"
"105.60000","52.80104","4.12611"
"105.90000","52.95105","4.13779"
"106.20000","53.10094","4.14538"
"106.50000","53.25101","4.15974"
"106.80000","53.40096","4.17037"
"107.10000","53.55092","4.18744"
"107.40000","53.70092","4.19729"
"107.70000","53.85094","4.21358"
"108.00000","54.00095","4.22689"
"108.30000","54.15108","4.23816"
"108.60000","54.30091","4.24926"
"108.90000","54.45105","4.26340"
"109.20000","54.60094","4.27816"
"109.50000","54.75101","4.28601"
"109.80000","54.90096","4.29225"
"110.10000","55.05098","4.30111"
"110.40000","55.20092","4.31316"
"110.70000","55.35106","4.32288"
"111.00000","55.50095","4.33243"
"111.30000","55.65108","4.34187"
"111.60000","55.80098","4.35359"
"111.90000","55.95099","4.37022"
"112.20000","56.10100","4.37998"
"112.50000","56.25095","4.39358"
"112.80000","56.40097","4.40341"
"113.10000","56.55103","4.41523"
"113.40000","56.70098","4.38638"
"113.70000","56.85100","4.39010"
"114.00000","57.00101","4.40664"
"114.30000","57.15108","4.41994"
"114.60000","57.30104","4.43085"
"114.90000","57.45098","4.44726"
"115.20000","57.60106","4.46519"
"115.50000","57.75101","4.48357"
"115.80000","57.90096","4.49223"
"116.10000","58.05103","4.50467"
"116.40000","58.20105","4.51568"
"116.70000","58.35106","4.52394"
"117.00000","58.50095","4.53088"
"117.30000","58.65096","4.54153"
"117.60000","58.80097","4.55056"
"117.90000","58.95104","4.56615"
"118.20000","59.10100","4.57743"
"118.50000","59.25101","4.59238"
"118.80000","59.40102","4.60190"
"119.10000","59.55104","4.61592"
"119.40000","59.70098","4.62936"
"119.70000","59.85100","4.64657"
"120.00000","60.00113","4.65608"
"120.30000","60.15102","4.66689"
"120.60000","60.30103","4.68067"
"120.90000","60.45099","4.69622"
"121.20000","60.60106","4.70416"
"121.50000","60.75101","4.71144"
"121.80000","60.90096","4.71963"
"122.10000","61.05103","4.72848"
"122.40000","61.20104","4.73692"
"122.70000","61.35100","4.74782"
"123.00000","61.50101","4.76043"
"123.30000","61.65108","4.77173"
"123.60000","61.80097","4.78396"
"123.90000","61.95105","4.79880"
"124.20000","62.10100","4.81031"
"124.50000","62.25101","4.82406"
"124.80000","62.40096","4.83688"
"125.10000","62.55103","4.85008"
"125.40000","62.70098","4.86423"
"125.70000","62.85106","4.87871"
"126.00000","63.00101","4.88599"
"126.30000","63.15096","4.90343"
"126.60000","63.30097","4.91416"
"126.90000","63.45098","4.92236"
"127.20000","63.60106","4.93452"
"127.50000","63.75100","4.94280"
"127.80000","63.90102","4.94784"
"128.10000","64.05109","4.95946"
"128.40000","64.20104","4.96931"
"128.70000","64.35088","4.97305"
"129.00000","64.50101","4.99059"
"129.30000","64.65102","5.00560"
"129.60000","64.80091","5.02043"
"129.90000","64.95104","5.03716"
"130.20000","65.10106","5.05078"
"130.50000","65.25101","5.06548"
"130.80000","65.40096","5.08167"
"131.10000","65.55103","5.09314"
"131.40000","65.70099","5.10383"
"131.70000","65.85100","5.11417"
"132.00000","66.00095","5.12042"
"132.30000","66.15108","5.13458"
"132.60000","66.30097","5.14187"
"132.90000","66.45092","5.15259"
"133.20000","66.60099","5.16047"
"133.50000","66.75095","5.16756"
"133.80000","66.90102","5.17601"
"134.10000","67.05103","5.19009"
"134.40000","67.20104","5.20604"
"134.70000","67.35100","5.21890"
"135.00000","67.50101","5.23170"
"135.30000","67.65096","5.24292"
"135.60000","67.80097","5.24010"
"135.90000","67.95104","5.25465"
"136.20000","68.10100","5.26146"
"136.50000","68.25095","5.28246"
"136.80000","68.40108","5.29598"
"137.10000","68.55103","5.31013"
"137.40000","68.70093","5.31468"
"137.70000","68.85100","5.33090"
"138.00000","69.00095","5.34322"
"138.30000","69.15096","5.35447"
"138.60000","69.30097","5.36612"
"138.90000","69.45098","5.36372"
"139.20000","69.60105","5.37802"
"139.50000","69.75095","5.39368"
"139.80000","69.90096","5.40779"
"140.10000","70.05097","5.41033"
"140.40000","70.20098","5.42985"
"140.70000","70.35094","5.44450"
"141.00000","70.50101","5.45937"
"141.30000","70.65096","5.47448"
"141.60000","70.80091","5.47563"
"141.90000","70.95099","5.48972"
"142.20000","71.10111","5.50538"
"142.50000","71.25101","5.51797"
"142.80000","71.40096","5.52178"
"143.10000","71.55097","5.53096"
"143.40000","71.70092","5.53656"
"143.70000","71.85105","5.54588"
"144.00000","72.00095","5.55333"
"144.30000","72.15096","5.55705"
"144.60000","72.30097","5.57315"
"144.90000","72.45110","5.57990"
"145.20000","72.60094","5.60106"
"145.50000","72.75101","5.61586"
"145.80000","72.90102","5.62013"
"146.10000","73.05103","5.63778"
"146.40000","73.20099","5.65446"
"146.70000","73.35106","5.66947"
"147.00000","73.50107","5.67707"
"147.30000","73.65102","5.69203"
"147.60000","73.80103","5.70576"
"147.90000","73.95110","5.71960"
"148.20000","74.10105","5.73063"
"148.50000","74.25106","5.74493"
"148.80000","74.40102","5.75410"
"149.10000","74.55115","5.75851"
"149.40000","74.70110","5.76664"
"149.70000","74.85099","5.77279"
"150.00000","75.00101","5.78060"
"150.30000","75.15096","5.78884"
"150.60000","75.30097","5.80702"
"150.90000","75.45110","5.81204"
"151.20000","75.60094","5.82615"
"151.50000","75.75101","5.84105"
"151.80000","75.90114","5.84446"
"152.10000","76.05109","5.85929"
"152.40000","76.20093","5.86365"
"152.70000","76.35105","5.88735"
"153.00000","76.50101","5.90509"
"153.30000","76.65096","5.91697"
"153.60000","76.80103","5.92441"
"153.90000","76.95104","5.94380"
"154.20000","77.10105","5.94926"
"154.50000","77.25095","5.96056"
"154.80000","77.40096","5.97154"
"155.10000","77.55103","5.98246"
"155.40000","77.70104","5.99111"
"155.70000","77.85088","6.00419"
"156.00000","78.00101","6.01549"
"156.30000","78.15096","6.02703"
"156.60000","78.30091","6.03982"
"156.90000","78.45104","6.05282"
"157.20000","78.60094","6.05515"
"157.50000","78.75101","6.06844"
"157.80000","78.90095","6.07486"
"158.10000","79.05103","6.08626"
"158.40000","79.20092","6.10089"
"158.70000","79.35099","6.10099"
"159.00000","79.50101","6.12003"
"159.30000","79.65096","6.13607"
"159.60000","79.80090","6.13930"
"159.90000","79.95110","6.15387"
"160.20000","80.10094","6.16458"
"160.50000","80.25101","6.17846"
"160.80000","80.40101","6.17909"
"161.10000","80.55097","6.19537"
"161.40000","80.70098","6.21185"
"161.70000","80.85094","6.22129"
"162.00000","81.00101","6.23877"
"162.30000","81.15102","6.24918"
"162.60000","81.30096","6.26207"
"162.90000","81.45098","6.28119"
"163.20000","81.60093","6.29650"
"163.50000","81.75095","6.30610"
"163.80000","81.90114","6.32097"
"164.10000","82.05103","6.33330"
"164.40000","82.20098","6.34099"
"164.70000","82.35098","6.35050"
"165.00000","82.50095","6.35749"
"165.30000","82.65101","6.36865"
"165.60000","82.80084","6.37378"
"165.90000","82.95098","6.37584"
"166.20000","83.10106","6.38226"
"166.50000","83.25094","6.39321"
"166.80000","83.40102","6.39415"
"167.10000","83.55096","6.40766"
"167.40000","83.70104","6.41902"
"167.70000","83.85100","6.43663"
"168.00000","84.00095","6.45325"
"168.30000","84.15084","6.46115"
"168.60000","84.30103","6.47974"
"168.90000","84.45092","6.49303"
"169.20000","84.60105","6.50524"
"169.50000","84.75089","6.51355"
"169.80000","84.90108","6.53313"
"170.10000","85.05097","6.54768"
"170.40000","85.20097","6.55751"
"170.70000","85.35099","6.57227"
"171.00000","85.50094","6.58393"
"171.30000","85.65095","6.59073"
"171.60000","85.80103","6.60232"
"171.90000","85.95093","6.60669"
"172.20000","86.10106","6.61501"
"172.50000","86.25095","6.62352"
"172.80000","86.40096","6.63369"
"173.10000","86.55097","6.64274"
"173.40000","86.70092","6.65351"
"173.70000","86.85098","6.66254"
"174.00000","87.00101","6.67166"
"174.30000","87.15096","6.68510"
"174.60000","87.30109","6.69439"
"174.90000","87.45097","6.71063"
"175.20000","87.60099","6.72560"
"175.50000","87.75107","6.73601"
"175.80000","87.90096","6.74332"
"176.10000","88.05090","6.76343"
"176.40000","88.20105","6.77303"
"176.70000","88.35106","6.78174"
"177.00000","88.50095","6.79384"
"177.30000","88.65108","6.80449"
"177.60000","88.80103","6.80882"
"177.90000","88.95098","6.82519"
"178.20000","89.10094","6.83484"
"178.50000","89.25106","6.85036"
"178.80000","89.40108","6.86500"
"179.10000","89.55109","6.87929"
"179.40000","89.70086","6.88832"
"179.70000","89.85105","6.90369"
"180.00000","90.00095","6.91456"
"180.30000","90.15096","6.92211"
"180.60000","90.30103","6.93279"
"180.90000","90.45098","6.94366"
"181.20000","90.60100","6.95591"
"181.50000","90.75106","6.96321"
"181.80000","90.90102","6.97390"
"182.10000","91.05103","6.98146"
"182.40000","91.20099","6.98347"
"182.70000","91.35105","6.99296"
"183.00000","91.50095","7.00520"
"183.30000","91.65096","7.01643"
"183.60000","91.80109","7.02486"
"183.90000","91.95097","7.03842"
"184.20000","92.10099","7.05048"
"184.50000","92.25101","7.06276"
"184.80000","92.40090","7.07761"
"185.10000","92.55097","7.09252"
"185.40000","92.70086","7.10970"
"185.70000","92.85112","7.12078"
"186.00000","93.00089","7.13541"
"186.30000","93.15096","7.15171"
"186.60000","93.30097","7.16348"
"186.90000","93.45093","7.17785"
"187.20000","93.60094","7.19011"
"187.50000","93.75107","7.19629"
"187.80000","93.90095","7.20446"
"188.10000","94.05097","7.21215"
"188.40000","94.20093","7.21756"
"188.70000","94.35094","7.22148"
"189.00000","94.50101","7.22840"
"189.30000","94.65096","7.23378"
"189.60000","94.80096","7.24589"
"189.90000","94.95091","7.25806"
"190.20000","95.10093","7.26750"
"190.50000","95.25101","7.27928"
"190.80000","95.40107","7.29479"
"191.10000","95.55090","7.30034"
"191.40000","95.70099","7.31489"
"191.70000","95.85111","7.33011"
"192.00000","96.00100","7.34258"
"192.30000","96.15089","7.35456"
"192.60000","96.30103","7.37136"
"192.90000","96.45093","7.38041"
"193.20000","96.60094","7.39040"
"193.50000","96.75094","7.39864"
"193.80000","96.90090","7.41146"
"194.10000","97.05096","7.42364"
"194.40000","97.20103","7.43328"
"194.70000","97.35099","7.44253"
"195.00000","97.50101","7.45069"
"195.30000","97.65089","7.46198"
"195.60000","97.80097","7.47565"
"195.90000","97.95092","7.48633"
"196.20000","98.10099","7.49658"
"196.50000","98.25095","7.50772"
"196.80000","98.40101","7.51699"
"197.10000","98.55097","7.52754"
"197.40000","98.70104","7.53900"
"197.70000","98.85099","7.55194"
"198.00000","99.00101","7.56129"
"198.30000","99.15108","7.57533"
"198.60000","99.30090","7.58659"
"198.90000","99.45103","7.59954"
"199.20000","99.60104","7.60517"
"199.50000","99.75095","7.61119"
"199.80000","99.90096","7.61919"
"200.10000","100.05103","7.62806"
"200.40000","100.20098","7.63980"
"200.70000","100.35099","7.65078"
"201.00000","100.50107","7.66151"
"201.30000","100.65101","7.67534"
"201.60000","100.80096","7.69174"
"201.90000","100.95093","7.70764"
"202.20000","101.10106","7.72215"
"202.50000","101.25101","7.73569"
"202.80000","101.40107","7.74806"
"203.10000","101.55096","7.75957"
"203.40000","101.70103","7.77039"
"203.70000","101.85099","7.78083"
"204.00000","102.00106","7.79326"
"204.30000","102.15102","7.80179"
"204.60000","102.30097","7.80806"
"204.90000","102.45103","7.81611"
"205.20000","102.60105","7.82384"
"205.50000","102.75100","7.82876"
"205.80000","102.90101","7.83571"
"206.10000","103.05108","7.84821"
"206.40000","103.20105","7.86048"
"206.70000","103.35099","7.87325"
"207.00000","103.50094","7.88620"
"207.30000","103.65107","7.89881"
"207.60000","103.80103","7.90981"
"207.90000","103.95092","7.92113"
"208.20000","104.10104","7.93511"
"208.50000","104.25100","7.94649"
"208.80000","104.40102","7.96078"
"209.10000","104.55097","7.97457"
"209.40000","104.70103","7.99082"
"209.70000","104.85093","8.00022"
"210.00000","105.00107","8.01239"
"210.30000","105.15096","8.02286"
"210.60000","105.30096","8.03250"
"210.90000","105.45097","8.03859"
"211.20000","105.60106","8.04413"
"211.50000","105.75101","8.05187"
"211.80000","105.90107","8.05624"
"212.10000","106.05103","8.06405"
"212.40000","106.20099","8.08001"
"212.70000","106.35100","8.09101"
"213.00000","106.50095","8.10473"
"213.30000","106.65108","8.11537"
"213.60000","106.80097","8.12753"
"213.90000","106.95092","8.13951"
"214.20000","107.10111","8.15190"
"214.50000","107.25101","8.16531"
"214.80000","107.40090","8.17561"
"215.10000","107.55109","8.18934"
"215.40000","107.70104","8.20313"
"215.70000","107.85094","8.21204"
"216.00000","108.00107","8.21997"
"216.30000","108.15096","8.22833"
"216.60000","108.30097","8.23784"
"216.90000","108.45099","8.24597"
"217.20000","108.60100","8.25635"
"217.50000","108.75100","8.26768"
"217.80000","108.90096","8.28162"
"218.10000","109.05103","8.29269"
"218.40000","109.20103","8.30638"
"218.70000","109.35105","8.31837"
"219.00000","109.50089","8.33451"
"219.30000","109.65102","8.34343"
"219.60000","109.80096","8.35279"
"219.90000","109.95104","8.36272"
"220.20000","110.10099","8.37154"
"220.50000","110.25112","8.38298"
"220.80000","110.40096","8.39682"
"221.10000","110.55103","8.41036"
"221.40000","110.70099","8.41957"
"221.70000","110.85093","8.42708"
"222.00000","111.00100","8.43929"
"222.30000","111.15101","8.44503"
"222.60000","111.30097","8.45322"
"222.90000","111.45103","8.46021"
"223.20000","111.60099","8.47133"
"223.50000","111.75095","8.48099"
"223.80000","111.90096","8.49128"
"224.10000","112.05096","8.50247"
"224.40000","112.20097","8.51371"
"224.70000","112.35099","8.52733"
"225.00000","112.50095","8.54240"
"225.30000","112.65102","8.55255"
"225.60000","112.80090","8.56725"
"225.90000","112.95098","8.57931"
"226.20000","113.10100","8.59097"
"226.50000","113.25106","8.60208"
"226.80000","113.40089","8.61348"
"227.10000","113.55103","8.62424"
"227.40000","113.70099","8.63070"
"227.70000","113.85094","8.63888"
"228.00000","114.00095","8.64717"
"228.30000","114.15108","8.65397"
"228.60000","114.30103","8.66135"
"228.90000","114.45092","8.67428"
"229.20000","114.60099","8.68244"
"229.50000","114.75095","8.69485"
"229.80000","114.90102","8.71193"
"230.10000","115.05097","8.72245"
"230.40000","115.20103","8.73600"
"230.70000","115.35093","8.74554"
"231.00000","115.50100","8.75816"
"231.30000","115.65096","8.76872"
"231.60000","115.80102","8.78162"
"231.90000","115.95110","8.79057"
"232.20000","116.10106","8.80443"
"232.50000","116.25100","8.81757"
"232.80000","116.40108","8.82894"
"233.10000","116.55103","8.83792"
"233.40000","116.70092","8.84944"
"233.70000","116.85104","8.85675"
"234.00000","117.00101","8.86348"
"234.30000","117.15102","8.87043"
"234.60000","117.30103","8.87677"
"234.90000","117.45098","8.88360"
"235.20000","117.60105","8.89351"
"235.50000","117.75106","8.90287"
"235.80000","117.90101","8.91863"
"236.10000","118.05103","8.93156"
"236.40000","118.20099","8.94373"
"236.70000","118.35094","8.95570"
"237.00000","118.50107","8.96475"
"237.30000","118.65102","8.97713"
"237.60000","118.80092","8.99369"
"237.90000","118.95110","9.00722"
"238.20000","119.10100","9.02037"
"238.50000","119.25094","9.03496"
"238.80000","119.40108","9.04306"
"239.10000","119.55103","9.05267"
"239.40000","119.70098","9.05952"
"239.70000","119.85104","9.06480"
"240.00000","120.00100","9.07254"
"240.30000","120.15102","9.07872"
"240.60000","120.30103","9.08755"
"240.90000","120.45104","9.10084"
"241.20000","120.60106","9.11350"
"241.50000","120.75100","9.12497"
"241.80000","120.90090","9.13728"
"242.10000","121.05103","9.14849"
"242.40000","121.20098","9.15950"
"242.70000","121.35093","9.17249"
"243.00000","121.50106","9.18012"
"243.30000","121.65089","9.18718"
"243.60000","121.80103","9.19754"
"243.90000","121.95092","9.20829"
"244.20000","122.10104","9.22212"
"244.50000","122.25095","9.23452"
"244.80000","122.40102","9.24506"
"245.10000","122.55103","9.25434"
"245.40000","122.70097","9.26211"
"245.70000","122.85099","9.27114"
"246.00000","123.00119","9.28159"
"246.30000","123.15096","9.28794"
"246.60000","123.30103","9.30036"
"246.90000","123.45098","9.30941"
"247.20000","123.60093","9.32318"
"247.50000","123.75094","9.33567"
"247.80000","123.90101","9.34648"
"248.10000","124.05103","9.35766"
"248.40000","124.20103","9.36726"
"248.70000","124.35094","9.38250"
"249.00000","124.50095","9.39344"
"249.30000","124.65096","9.40663"
"249.60000","124.80096","9.41688"
"249.90000","124.95110","9.42928"
"250.20000","125.10104","9.43826"
"250.50000","125.25094","9.45086"
"250.80000","125.40095","9.45794"
"251.10000","125.55096","9.46534"
"251.40000","125.70098","9.46925"
"251.70000","125.85093","9.47450"
"252.00000","126.00100","9.47971"
"252.30000","126.15107","9.49266"
"252.60000","126.30096","9.49789"
"252.90000","126.45103","9.51377"
"253.20000","126.60092","9.52819"
"253.50000","126.75105","9.54560"
"253.80000","126.90096","9.55323"
"254.10000","127.05090","9.56935"
"254.40000","127.20092","9.58062"
"254.70000","127.35093","9.59356"
"255.00000","127.50094","9.60576"
"255.30000","127.65101","9.61702"
"255.60000","127.80090","9.62962"
"255.90000","127.95109","9.64034"
"256.20000","128.10100","9.65241"
"256.50000","128.25095","9.66054"
"256.80000","128.40102","9.67119"
"257.10000","128.55090","9.67980"
"257.40000","128.70097","9.68579"
"257.70000","128.85098","9.69320"
"258.00000","129.00093","9.70062"
"258.30000","129.15102","9.70632"
"258.60000","129.30096","9.71387"
"258.90000","129.45091","9.72262"
"259.20000","129.60098","9.73170"
"259.50000","129.75099","9.74232"
"259.80000","129.90094","9.75160"
"260.10000","130.05101","9.76142"
"260.40000","130.20091","9.77241"
"260.70000","130.35106","9.78174"
"261.00000","130.50101","9.79292"
"261.30000","130.65102","9.80214"
"261.60000","130.80096","9.81698"
"261.90000","130.95091","9.83709"
"262.20000","131.10098","9.84484"
"262.50000","131.25099","9.86437"
"262.80000","131.40106","9.87415"
"263.10000","131.55096","9.88018"
"263.40000","131.70103","9.88699"
"263.70000","131.85104","9.89421"
"264.00000","132.00099","9.90305"
"264.30000","132.15096","9.90974"
"264.60000","132.30107","9.92243"
"264.90000","132.45108","9.93573"
"265.20000","132.60092","9.94683"
"265.50000","132.75089","9.95900"
"265.80000","132.90108","9.97469"
"266.10000","133.05096","9.98346"
"266.40000","133.20097","9.99306"
"266.70000","133.35098","10.00219"
"267.00000","133.50093","10.01129"
"267.30000","133.65094","10.02042"
"267.60000","133.80103","10.02929"
"267.90000","133.95103","10.03928"
"268.20000","134.10098","10.04994"
"268.50000","134.25099","10.05810"
"268.80000","134.40100","10.06749"
"269.10000","134.55090","10.07517"
"269.40000","134.70103","10.08147"
"269.70000","134.85104","10.08797"
"270.00000","135.00095","10.10005"
"270.30000","135.15102","10.10659"
"270.60000","135.30109","10.11818"
"270.90000","135.45091","10.13078"
"271.20000","135.60098","10.14485"
"271.50000","135.75087","10.15684"
"271.80000","135.90106","10.16911"
"272.10000","136.05089","10.18150"
"272.40000","136.20087","10.19106"
"272.70000","136.35094","10.20527"
"273.00000","136.50095","10.21541"
"273.30000","136.65102","10.22768"
"273.60000","136.80109","10.24082"
"273.90000","136.95097","10.25464"
"274.20000","137.10098","10.25787"
"274.50000","137.25093","10.27446"
"274.80000","137.40089","10.28373"
"275.10000","137.55103","10.28991"
"275.40000","137.70097","10.29729"
"275.70000","137.85104","10.30087"
"276.00000","138.00093","10.30522"
"276.30000","138.15094","10.31165"
"276.60000","138.30095","10.31459"
"276.90000","138.45097","10.32148"
"277.20000","138.60098","10.33755"
"277.50000","138.75101","10.34254"
"277.80000","138.90108","10.35998"
"278.10000","139.05103","10.36911"
"278.40000","139.20091","10.38203"
"278.70000","139.35104","10.39235"
"279.00000","139.50087","10.40456"
"279.30000","139.65096","10.41904"
"279.60000","139.80103","10.43169"
"279.90000","139.95097","10.44315"
"280.20000","140.10092","10.45372"
"280.50000","140.25105","10.46624"
"280.80000","140.40100","10.47957"
"281.10000","140.55101","10.48866"
"281.40000","140.70091","10.49660"
"281.70000","140.85100","10.50482"
"282.00000","141.00095","10.51429"
"282.30000","141.15096","10.52362"
"282.60000","141.30090","10.53229"
"282.90000","141.45103","10.54176"
"283.20000","141.60098","10.54908"
"283.50000","141.75105","10.55938"
"283.80000","141.90102","10.56797"
"284.10000","142.05090","10.57944"
"284.40000","142.20103","10.58472"
"284.70000","142.35092","10.59473"
"285.00000","142.50099","10.60294"
"285.30000","142.65100","10.61033"
"285.60000","142.80101","10.61852"
"285.90000","142.95097","10.63323"
"286.20000","143.10106","10.64025"
"286.50000","143.25101","10.65310"
"286.80000","143.40102","10.66730"
"287.10000","143.55096","10.67982"
"287.40000","143.70097","10.68985"
"287.70000","143.85092","10.69893"
"288.00000","144.00093","10.70615"
"288.30000","144.15100","10.71267"
"288.60000","144.30109","10.72044"
"288.90000","144.45103","10.72760"
"289.20000","144.60098","10.73997"
"289.50000","144.75105","10.75297"
"289.80000","144.90100","10.76281"
"290.10000","145.05101","10.77680"
"290.40000","145.20097","10.78795"
"290.70000","145.35100","10.80076"
"291.00000","145.50107","10.81143"
"291.30000","145.65102","10.82535"
"291.60000","145.80103","10.83509"
"291.90000","145.95103","10.84417"
"292.20000","146.10104","10.85573"
"292.50000","146.25099","10.86351"
"292.80000","146.40100","10.87230"
"293.10000","146.55103","10.88211"
"293.40000","146.70110","10.88781"
"293.70000","146.85098","10.89493"
"294.00000","147.00089","10.89995"
"294.30000","147.15106","10.90527"
"294.60000","147.30103","10.91094"
"294.90000","147.45103","10.91985"
"295.20000","147.60098","10.92229"
"295.50000","147.75107","10.93454"
"295.80000","147.90096","10.94075"
"296.10000","148.05103","10.95232"
"296.40000","148.20103","10.96641"
"296.70000","148.35092","10.97807"
"297.00000","148.50099","10.98548"
"297.30000","148.65106","10.99837"
"297.60000","148.80095","11.00791"
"297.90000","148.95103","11.02051"
"298.20000","149.10104","11.03046"
"298.50000","149.25095","11.04821"
"298.80000","149.40102","11.05782"
"299.10000","149.55096","11.07236"
"299.40000","149.70110","11.08276"
"299.70000","149.85104","11.09971"
"300.00000","150.00095","11.10721"
"300.30000","150.15114","11.11633"
"300.60000","150.30096","11.12444"
"300.90000","150.45091","11.12979"
"301.20000","150.60098","11.13467"
"301.50000","150.75105","11.14059"
"301.80000","150.90094","11.14512"
"302.10000","151.05101","11.14993"
"302.40000","151.20097","11.16179"
"302.70000","151.35098","11.16838"
"303.00000","151.50101","11.17657"
"303.30000","151.65106","11.18600"
"303.60000","151.80103","11.19755"
"303.90000","151.95097","11.20736"
"304.20000","152.10104","11.21707"
"304.50000","152.25107","11.22839"
"304.80000","152.40108","11.23833"
"305.10000","152.55084","11.24990"
"305.40000","152.70097","11.26257"
"305.70000","152.85092","11.27430"
"306.00000","153.00093","11.28498"
"306.30000","153.15100","11.29080"
"306.60000","153.30107","11.30550"
"306.90000","153.45103","11.31178"
"307.20000","153.60104","11.31924"
"307.50000","153.75101","11.32665"
"307.80000","153.90096","11.33547"
"308.10000","154.05096","11.34276"
"308.40000","154.20097","11.35700"
"308.70000","154.35092","11.36562"
"309.00000","154.50099","11.37501"
"309.30000","154.65089","11.38442"
"309.60000","154.80096","11.39450"
"309.90000","154.95097","11.40418"
"310.20000","155.10098","11.41348"
"310.50000","155.25099","11.42102"
"310.80000","155.40100","11.43069"
"311.10000","155.55096","11.43839"
"311.40000","155.70102","11.44627"
"311.70000","155.85088","11.45204"
"312.00000","156.00101","11.46147"
"312.30000","156.15108","11.47215"
"312.60000","156.30103","11.48085"
"312.90000","156.45090","11.49094"
"313.20000","156.60104","11.50067"
"313.50000","156.75099","11.50929"
"313.80000","156.90096","11.51786"
"314.10000","157.05103","11.52255"
"314.40000","157.20108","11.53135"
"314.70000","157.35098","11.53679"
"315.00000","157.50093","11.54448"
"315.30000","157.65094","11.55057"
"315.60000","157.80095","11.56195"
"315.90000","157.95103","11.56875"
"316.20000","158.10100","11.57916"
"316.50000","158.25101","11.59117"
"316.80000","158.40100","11.60261"
"317.10000","158.55096","11.61115"
"317.40000","158.70103","11.62450"
"317.70000","158.85098","11.63707"
"318.00000","159.00111","11.64939"
"318.30000","159.15099","11.66140"
"318.60000","159.30095","11.67045"
"318.90000","159.45103","11.68315"
"319.20000","159.60104","11.69450"
"319.50000","159.75095","11.70499"
"319.80000","159.90100","11.71283"
"320.10000","160.05101","11.71939"
"320.40000","160.20097","11.72604"
"320.70000","160.35098","11.73101"
"321.00000","160.50095","11.73589"
"321.30000","160.65108","11.74016"
"321.60000","160.80103","11.74409"
"321.90000","160.95103","11.74925"
"322.20000","161.10104","11.75606"
"322.50000","161.25099","11.76127"
"322.80000","161.40100","11.77414"
"323.10000","161.55095","11.78260"
"323.40000","161.70097","11.79326"
"323.70000","161.85092","11.80358"
"324.00000","162.00104","11.81569"
"324.30000","162.15096","11.82535"
"324.60000","162.30095","11.83361"
"324.90000","162.45103","11.84194"
"325.20000","162.60104","11.85219"
"325.50000","162.75101","11.86309"
"325.80000","162.90100","11.87090"
"326.10000","163.05090","11.88418"
"326.40000","163.20096","11.89360"
"326.70000","163.35098","11.90477"
"327.00000","163.50087","11.91505"
"327.30000","163.65105","11.92565"
"327.60000","163.80095","11.93114"
"327.90000","163.95097","11.94173"
"328.20000","164.10098","11.94839"
"328.50000","164.25095","11.95605"
"328.80000","164.40096","11.96433"
"329.10000","164.55101","11.96904"
"329.40000","164.70091","11.97520"
"329.70000","164.85104","11.98241"
"330.00000","165.00087","11.98855"
"330.30000","165.15100","11.99692"
"330.60000","165.30096","12.00679"
"330.90000","165.45103","12.01326"
"331.20000","165.60104","12.02228"
"331.50000","165.75099","12.03113"
"331.80000","165.90100","12.04013"
"332.10000","166.05112","12.04956"
"332.40000","166.20097","12.05695"
"332.70000","166.35100","12.06874"
"333.00000","166.50099","12.07520"
"333.30000","166.65096","12.08607"
"333.60000","166.80095","12.09566"
"333.90000","166.95103","12.10779"
"334.20000","167.10097","12.11047"
"334.50000","167.25105","12.12643"
"334.80000","167.40089","12.13214"
"335.10000","167.55103","12.13687"
"335.40000","167.70091","12.14413"
"335.70000","167.85098","12.14929"
"336.00000","168.00105","12.15302"
"336.30000","168.15099","12.15926"
"336.60000","168.30095","12.16878"
"336.90000","168.45099","12.17306"
"337.20000","168.60100","12.18407"
"337.50000","168.75101","12.19359"
"337.80000","168.90096","12.20401"
"338.10000","169.05109","12.21517"
"338.40000","169.20097","12.22488"
"338.70000","169.35097","12.23425"
"339.00000","169.50099","12.24457"
"339.30000","169.65094","12.25316"
"339.60000","169.80103","12.26227"
"339.90000","169.95096","12.27130"
"340.20000","170.10092","12.27896"
"340.50000","170.25092","12.28590"
"340.80000","170.40083","12.29394"
"341.10000","170.55101","12.30454"
"341.40000","170.70091","12.31001"
"341.70000","170.85092","12.31959"
"342.00000","171.00105","12.32758"
"342.30000","171.15102","12.33436"
"342.60000","171.30090","12.34391"
"342.90000","171.45097","12.34983"
"343.20000","171.60097","12.35589"
"343.50000","171.75093","12.36286"
"343.80000","171.90108","12.36877"
"344.10000","172.05096","12.37878"
"344.40000","172.20103","12.38266"
"344.70000","172.35098","12.39475"
"345.00000","172.50093","12.39788"
"345.30000","172.65099","12.40811"
"345.60000","172.80103","12.41654"
"345.90000","172.95091","12.42500"
"346.20000","173.10100","12.43512"
"346.50000","173.25101","12.44397"
"346.80000","173.40102","12.45201"
"347.10000","173.55109","12.46094"
"347.40000","173.70097","12.47232"
"347.70000","173.85097","12.48023"
"348.00000","174.00093","12.48922"
"348.30000","174.15092","12.49908"
"348.60000","174.30096","12.50810"
"348.90000","174.45103","12.51656"
"349.20000","174.60092","12.52470"
"349.50000","174.75105","12.53216"
"349.80000","174.90096","12.54093"
"350.10000","175.05096","12.54816"
"350.40000","175.20097","12.55315"
"350.70000","175.35098","12.55991"
"351.00000","175.50105","12.56478"
"351.30000","175.65096","12.56855"
"351.60000","175.80095","12.57403"
"351.90000","175.95091","12.57910"
"352.20000","176.10097","12.58226"
"352.50000","176.25087","12.58862"
"352.80000","176.40100","12.59485"
"353.10000","176.55096","12.60352"
"353.40000","176.70091","12.61310"
"353.70000","176.85098","12.62478"
"354.00000","177.00101","12.63544"
"354.30000","177.15096","12.64683"
"354.60000","177.30096","12.65484"
"354.90000","177.45102","12.66234"
"355.20000","177.60085","12.67008"
"355.50000","177.75105","12.67706"
"355.80000","177.90102","12.68611"
"356.10000","178.05096","12.69392"
"356.40000","178.20097","12.70076"
"356.70000","178.35104","12.70918"
"357.00000","178.50093","12.71999"
"357.30000","178.65092","12.72638"
"357.60000","178.80095","12.73400"
"357.90000","178.95103","12.74424"
"358.20000","179.10098","12.74858"
"358.50000","179.25087","12.75846"
"358.80000","179.40102","12.76424"
"359.10000","179.55089","12.77042"
"359.40000","179.70097","12.77627"
"359.70000","179.85098","12.78281"
"360.00000","180.00105","12.78837"
"360.30000","180.15102","12.79403"
"360.60000","180.30101","12.80021"
"360.90000","180.45091","12.80664"
"361.20000","180.60097","12.81420"
"361.50000","180.75099","12.81905"
"361.80000","180.90106","12.82489"
"362.10000","181.05095","12.83298"
"362.40000","181.20097","12.84131"
"362.70000","181.35100","12.85011"
"363.00000","181.50101","12.85696"
"363.30000","181.65096","12.86628"
"363.60000","181.80096","12.87235"
"363.90000","181.95110","12.88025"
"364.20000","182.10104","12.88855"
"364.50000","182.25087","12.89779"
"364.80000","182.40102","12.90499"
"365.10000","182.55096","12.91588"
"365.40000","182.70097","12.92489"
"365.70000","182.85110","12.93407"
"366.00000","183.00099","12.94508"
"366.30000","183.15092","12.94608"
"366.60000","183.30106","12.95743"
"366.90000","183.45097","12.96850"
"367.20000","183.60106","12.96937"
"367.50000","183.75101","12.97465"
"367.80000","183.90096","12.98094"
"368.10000","184.05103","12.98466"
"368.40000","184.20091","12.99086"
"368.70000","184.35098","12.99668"
"369.00000","184.50093","13.00053"
"369.30000","184.65102","13.00491"
"369.60000","184.80101","13.01371"
"369.90000","184.95103","13.02249"
"370.20000","185.10091","13.02847"
"370.50000","185.25099","13.03702"
"370.80000","185.40088","13.04504"
"371.10000","185.55101","13.05197"
"371.40000","185.70097","13.06280"
"371.70000","185.85104","13.06959"
"372.00000","186.00101","13.07590"
"372.30000","186.15096","13.08402"
"372.60000","186.30103","13.08942"
"372.90000","186.45102","13.09642"
"373.20000","186.60098","13.10501"
"373.50000","186.75098","13.11028"
"373.80000","186.90088","13.11654"
"374.10000","187.05101","13.12516"
"374.40000","187.20097","13.13105"
"374.70000","187.35104","13.13780"
"375.00000","187.50099","13.14544"
"375.30000","187.65106","13.15148"
"375.60000","187.80101","13.15765"
"375.90000","187.95108","13.16690"
"376.20000","188.10100","13.17073"
"376.50000","188.25099","13.17535"
"376.80000","188.40102","13.18209"
"377.10000","188.55109","13.18808"
"377.40000","188.70102","13.19118"
"377.70000","188.85098","13.19973"
"378.00000","189.00098","13.20231"
"378.30000","189.15100","13.21142"
"378.60000","189.30095","13.21935"
"378.90000","189.45097","13.22427"
"379.20000","189.60103","13.23073"
"379.50000","189.75099","13.24191"
"379.80000","189.90094","13.24778"
"380.10000","190.05090","13.25733"
"380.40000","190.20110","13.26375"
"380.70000","190.35103","13.27247"
"381.00000","190.50099","13.27985"
"381.30000","190.65100","13.28474"
"381.60000","190.80109","13.29319"
"381.90000","190.95096","13.30243"
"382.20000","191.10098","13.30707"
"382.50000","191.25098","13.31426"
"382.80000","191.40100","13.32484"
"383.10000","191.55096","13.33323"
"383.40000","191.70108","13.34038"
"383.70000","191.85098","13.34983"
"384.00000","192.00104","13.35184"
"384.30000","192.15100","13.36369"
"384.60000","192.30096","13.37027"
"384.90000","192.45096","13.37497"
"385.20000","192.60103","13.37876"
"385.50000","192.75107","13.38146"
"385.80000","192.90102","13.38619"
"386.10000","193.05089","13.38843"
"386.40000","193.20102","13.39213"
"386.70000","193.35091","13.39474"
"387.00000","193.50098","13.40113"
"387.30000","193.65100","13.40082"
"387.60000","193.80099","13.40664"
"387.90000","193.95103","13.41118"
"388.20000","194.10103","13.41637"
"388.50000","194.25107","13.42354"
"388.80000","194.40094","13.42905"
"389.10000","194.55103","13.44384"
"389.40000","194.70110","13.44987"
"389.70000","194.85103","13.45810"
"390.00000","195.00099","13.46703"
"390.30000","195.15100","13.47639"
"390.60000","195.30109","13.48298"
"390.90000","195.45102","13.49450"
"391.20000","195.60091","13.50165"
"391.50000","195.75098","13.50875"
"391.80000","195.90094","13.51536"
"392.10000","196.05095","13.52288"
"392.40000","196.20103","13.53016"
"392.70000","196.35104","13.53829"
"393.00000","196.50101","13.54506"
"393.30000","196.65100","13.55349"
"393.60000","196.80096","13.56302"
"393.90000","196.95090","13.56714"
"394.20000","197.10103","13.57279"
"394.50000","197.25099","13.58017"
"394.80000","197.40102","13.58505"
"395.10000","197.55109","13.59050"
"395.40000","197.70097","13.59428"
"395.70000","197.85098","13.60096"
"396.00000","198.00104","13.60502"
"396.30000","198.15105","13.61061"
"396.60000","198.30099","13.61454"
"396.90000","198.45102","13.62049"
"397.20000","198.60098","13.62397"
"397.50000","198.75087","13.63175"
"397.80000","198.90088","13.63522"
"398.10000","199.05096","13.64146"
"398.40000","199.20110","13.64848"
"398.70000","199.35103","13.65310"
"399.00000","199.50092","13.66036"
"399.30000","199.65100","13.66698"
"399.60000","199.80109","13.67410"
"399.90000","199.95091","13.68007"
"400.20000","200.10104","13.68452"
"400.50000","200.25111","13.69002"
"400.80000","200.40096","13.69505"
"401.10000","200.55089","13.70014"
"401.40000","200.70097","13.70725"
"401.70000","200.85094","13.70999"
"402.00000","201.00105","13.71878"
"402.30000","201.15100","13.72186"
"402.60000","201.30107","13.73146"
"402.90000","201.45110","13.74058"
"403.20000","201.60097","13.74697"
"403.50000","201.75092","13.75310"
"403.80000","201.90092","13.76209"
"404.10000","202.05109","13.76528"
"404.40000","202.20108","13.77826"
"404.70000","202.35098","13.78508"
"405.00000","202.50104","13.79239"
"405.30000","202.65105","13.79554"
"405.60000","202.80095","13.80328"
"405.90000","202.95097","13.80608"
"406.20000","203.10104","13.80831"
"406.50000","203.25101","13.81465"
"406.80000","203.40100","13.81711"
"407.10000","203.55096","13.82463"
"407.40000","203.70103","13.82926"
"407.70000","203.85098","13.83471"
"408.00000","204.00092","13.83946"
"408.30000","204.15105","13.84272"
"408.60000","204.30103","13.85162"
"408.90000","204.45102","13.85907"
"409.20000","204.60098","13.86579"
"409.50000","204.75099","13.87108"
"409.80000","204.90088","13.87934"
"410.10000","205.05109","13.88642"
"410.40000","205.20097","13.89135"
"410.70000","205.35091","13.89876"
"411.00000","205.50101","13.90712"
"411.30000","205.65108","13.91289"
"411.60000","205.80090","13.91804"
"411.90000","205.95096","13.92485"
"412.20000","206.10097","13.93059"
"412.50000","206.25099","13.93633"
"412.80000","206.40092","13.94250"
"413.10000","206.55089","13.94763"
"413.40000","206.70108","13.95357"
"413.70000","206.85100","13.95963"
"414.00000","207.00099","13.96318"
"414.30000","207.15096","13.97114"
"414.60000","207.30095","13.97433"
"414.90000","207.45097","13.97782"
"415.20000","207.60104","13.98213"
"415.50000","207.75095","13.98651"
"415.80000","207.90094","13.98934"
"416.10000","208.05096","13.99265"
"416.40000","208.20096","13.99659"
"416.70000","208.35098","14.00016"
"417.00000","208.50099","14.00327"
"417.30000","208.65105","14.00636"
"417.60000","208.80101","14.01391"
"417.90000","208.95102","14.01359"
"418.20000","209.10104","14.01840"
"418.50000","209.25099","14.02671"
"418.80000","209.40096","14.02904"
"419.10000","209.55089","14.03904"
"419.40000","209.70097","14.04196"
"419.70000","209.85104","14.05417"
"420.00000","210.00104","14.05918"
"420.30000","210.15108","14.06781"
"420.60000","210.30101","14.07656"
"420.90000","210.45096","14.08521"
"421.20000","210.60103","14.08776"
"421.50000","210.75087","14.10121"
"421.80000","210.90094","14.10335"
"422.10000","211.05107","14.11017"
"422.40000","211.20099","14.11431"
"422.70000","211.35106","14.12008"
"423.00000","211.50099","14.12606"
"423.30000","211.65106","14.13045"
"423.60000","211.80101","14.13657"
"423.90000","211.95102","14.14634"
"424.20000","212.10110","14.15007"
"424.50000","212.25098","14.15699"
"424.80000","212.40100","14.16325"
"425.10000","212.55103","14.16983"
"425.40000","212.70090","14.17525"
"425.70000","212.85103","14.18611"
"426.00000","213.00099","14.19070"
"426.30000","213.15099","14.19568"
"426.60000","213.30096","14.19858"
"426.90000","213.45085","14.20338"
"427.20000","213.60100","14.20726"
"427.50000","213.75093","14.21189"
"427.80000","213.90088","14.21298"
"428.10000","214.05101","14.21580"
"428.40000","214.20103","14.22227"
"428.70000","214.35085","14.22433"
"429.00000","214.50093","14.22568"
"429.30000","214.65092","14.22718"
"429.60000","214.80090","14.22880"
"429.90000","214.95096","14.22990"
"430.20000","215.10109","14.23220"
"430.50000","215.25105","14.23470"
"430.80000","215.40094","14.23843"
"431.10000","215.55103","14.23863"
"431.40000","215.70090","14.24138"
"431.70000","215.85100","14.24477"
"432.00000","216.00095","14.24601"
"432.30000","216.15102","14.25770"
"432.60000","216.30101","14.25569"
"432.90000","216.45091","14.25553"
"433.20000","216.60104","14.26329"
"433.50000","216.75098","14.26583"
"433.80000","216.90106","14.27176"
"434.10000","217.05096","14.27376"
"434.40000","217.20096","14.27922"
"434.70000","217.35098","14.28209"
"435.00000","217.50101","14.28601"
"435.30000","217.65089","14.29239"
"435.60000","217.80103","14.29420"
"435.90000","217.95096","14.29822"
"436.20000","218.10098","14.30241"
"436.50000","218.25099","14.30717"
"436.80000","218.40102","14.30975"
"437.10000","218.55101","14.31213"
"437.40000","218.70097","14.31530"
"437.70000","218.85097","14.31923"
"438.00000","219.00099","14.32222"
"438.30000","219.15092","14.32166"
"438.60000","219.30090","14.32547"
"438.90000","219.45103","14.32698"
"439.20000","219.60098","14.32787"
"439.50000","219.75087","14.32780"
"439.80000","219.90100","14.32684"
"440.10000","220.05096","14.32061"
"440.40000","220.20096","14.31476"
"440.70000","220.35085","14.30559"
"441.00000","220.50105","14.29155"
"441.30000","220.65088","14.26734"
"441.57800","220.79002","14.08858"
"441.58400","220.79301","12.96179"
"441.59000","220.79601","10.90762"
"441.59600","220.79909","8.53845"