File: MT-DataAnalysis-JupyterNotebook/TensionPlots/TensionTests/CoilDiameter/Specimen_RawData_13.csv
End date,"8/16/2018"
Specimen label,"D30L40N5d4"
Maximum Load,"30.26905",N
Extension at Maximum Load,"83.10106",mm
Maximum Slope (Automatic Young's),"0.48228",N/mm
Rate 1,"30.00000",mm/min

Time,Extension,Load
(s),(mm),(N)
"0.00000","0.00000","0.01076"
"0.20000","0.09106","0.04098"
"0.40000","0.20173","0.10906"
"0.60000","0.30122","0.16369"
"0.80000","0.40095","0.19123"
"1.00000","0.50104","0.23180"
"1.20000","0.60100","0.28617"
"1.40000","0.70097","0.33936"
"1.60000","0.80088","0.39319"
"1.80000","0.90097","0.43552"
"2.00000","1.00100","0.48936"
"2.20000","1.10096","0.54337"
"2.40000","1.20099","0.59149"
"2.60000","1.30096","0.63050"
"2.80000","1.40099","0.68751"
"3.00000","1.50096","0.73316"
"3.20000","1.60086","0.78512"
"3.40000","1.70101","0.82908"
"3.60000","1.80104","0.87878"
"3.80000","1.90089","0.92713"
"4.00000","2.00104","0.98580"
"4.20000","2.10094","1.02545"
"4.40000","2.20085","1.06957"
"4.60000","2.30100","1.12778"
"4.80000","2.40085","1.18490"
"5.00000","2.50088","1.22756"
"5.20000","2.60096","1.27067"
"5.40000","2.70099","1.32772"
"5.60000","2.80096","1.38336"
"5.80000","2.90111","1.43099"
"6.00000","3.00096","1.47456"
"6.20000","3.10104","1.53015"
"6.40000","3.20101","1.58152"
"6.60000","3.30092","1.62323"
"6.80000","3.40101","1.67311"
"7.00000","3.50098","1.73165"
"7.20000","3.60094","1.78667"
"7.40000","3.70097","1.83508"
"7.60000","3.80100","1.86096"
"7.80000","3.90097","1.91103"
"8.00000","4.00094","1.97339"
"8.20000","4.10102","2.03026"
"8.40000","4.20105","2.07275"
"8.60000","4.30096","2.12141"
"8.80000","4.40099","2.16289"
"9.00000","4.50108","2.21795"
"9.20000","4.60110","2.26158"
"9.40000","4.70089","2.31107"
"9.60000","4.80098","2.37232"
"9.80000","4.90095","2.41934"
"10.00000","5.00104","2.46184"
"10.20000","5.10094","2.51658"
"10.40000","5.20097","2.58003"
"10.60000","5.30100","2.64155"
"10.80000","5.40097","2.68403"
"11.00000","5.50100","2.71416"
"11.20000","5.60096","2.76053"
"11.40000","5.70111","2.82301"
"11.60000","5.80102","2.87455"
"11.80000","5.90099","2.91670"
"12.00000","6.00096","2.97154"
"12.20000","6.10104","3.01261"
"12.40000","6.20101","3.05434"
"12.60000","6.30086","3.09455"
"12.80000","6.40095","3.14415"
"13.00000","6.50098","3.20351"
"13.20000","6.60100","3.25723"
"13.40000","6.70097","3.29126"
"13.60000","6.80094","3.32322"
"13.80000","6.90103","3.38138"
"14.00000","7.00111","3.43779"
"14.20000","7.10090","3.49418"
"14.40000","7.20093","3.52417"
"14.60000","7.30102","3.56992"
"14.80000","7.40093","3.61237"
"15.00000","7.50102","3.66846"
"15.20000","7.60104","3.70539"
"15.40000","7.70089","3.75835"
"15.60000","7.80098","3.81562"
"15.80000","7.90089","3.86262"
"16.00000","8.00098","3.89830"
"16.20000","8.10100","3.93712"
"16.40000","8.20097","3.99607"
"16.60000","8.30094","4.05651"
"16.80000","8.40103","4.10491"
"17.00000","8.50099","4.13156"
"17.20000","8.60096","4.18425"
"17.40000","8.70105","4.23612"
"17.60000","8.80096","4.29113"
"17.80000","8.90093","4.33600"
"18.00000","9.00102","4.38241"
"18.20000","9.10092","4.43051"
"18.40000","9.20101","4.49138"
"18.60000","9.30092","4.52734"
"18.80000","9.40101","4.56325"
"19.00000","9.50098","4.61484"
"19.20000","9.60106","4.66366"
"19.40000","9.70097","4.71666"
"19.60000","9.80106","4.75200"
"19.80000","9.90091","4.80736"
"20.00000","10.00099","4.85766"
"20.20000","10.10096","4.91360"
"20.40000","10.20111","4.94608"
"20.60000","10.30102","4.99283"
"20.80000","10.40099","5.04739"
"21.00000","10.50090","5.10364"
"21.20000","10.60098","5.14105"
"21.40000","10.70107","5.17713"
"21.60000","10.80098","5.22945"
"21.80000","10.90101","5.27134"
"22.00000","11.00097","5.32273"
"22.20000","11.10100","5.35900"
"22.40000","11.20103","5.40632"
"22.60000","11.30106","5.45760"
"22.80000","11.40097","5.50841"
"23.00000","11.50100","5.54375"
"23.20000","11.60102","5.58311"
"23.40000","11.70105","5.63901"
"23.60000","11.80096","5.69635"
"23.80000","11.90099","5.74899"
"24.00000","12.00107","5.77610"
"24.20000","12.10092","5.82031"
"24.40000","12.20107","5.86575"
"24.60000","12.30098","5.92886"
"24.80000","12.40107","5.97061"
"25.00000","12.50103","6.01178"
"25.20000","12.60106","6.06360"
"25.40000","12.70103","6.10066"
"25.60000","12.80106","6.15086"
"25.80000","12.90097","6.19816"
"26.00000","13.00099","6.25421"
"26.20000","13.10102","6.31227"
"26.40000","13.20111","6.36043"
"26.60000","13.30108","6.38074"
"26.80000","13.40099","6.41955"
"27.00000","13.50095","6.47672"
"27.20000","13.60098","6.54390"
"27.40000","13.70107","6.58752"
"27.60000","13.80098","6.62516"
"27.80000","13.90107","6.66517"
"28.00000","14.00103","6.72391"
"28.20000","14.10100","6.78038"
"28.40000","14.20103","6.81581"
"28.60000","14.30106","6.87199"
"28.80000","14.40103","6.92527"
"29.00000","14.50111","6.96774"
"29.20000","14.60096","6.99304"
"29.40000","14.70099","7.04593"
"29.60000","14.80096","7.11215"
"29.80000","14.90093","7.17406"
"30.00000","15.00102","7.21105"
"30.20000","15.10098","7.22954"
"30.40000","15.20095","7.28042"
"30.60000","15.30098","7.33115"
"30.80000","15.40119","7.38876"
"31.00000","15.50097","7.43464"
"31.20000","15.60100","7.48042"
"31.40000","15.70097","7.52964"
"31.60000","15.80112","7.57747"
"31.80000","15.90091","7.61543"
"32.00000","16.00087","7.65904"
"32.20000","16.10096","7.72935"
"32.40000","16.20093","7.77944"
"32.60000","16.30108","7.81676"
"32.80000","16.40093","7.85435"
"33.00000","16.50095","7.91230"
"33.20000","16.60098","7.96951"
"33.40000","16.70107","8.01832"
"33.60000","16.80092","8.05018"
"33.80000","16.90107","8.09137"
"34.00000","17.00097","8.14764"
"34.20000","17.10094","8.20308"
"34.40000","17.20103","8.24504"
"34.60000","17.30094","8.29053"
"34.80000","17.40091","8.34666"
"35.00000","17.50105","8.39206"
"35.20000","17.60096","8.43334"
"35.40000","17.70099","8.46252"
"35.60000","17.80102","8.51082"
"35.80000","17.90093","8.56667"
"36.00000","18.00107","8.61851"
"36.20000","18.10098","8.65169"
"36.40000","18.20095","8.69319"
"36.60000","18.30104","8.74968"
"36.80000","18.40107","8.80012"
"37.00000","18.50092","8.85202"
"37.20000","18.60094","8.88235"
"37.40000","18.70103","8.92937"
"37.60000","18.80106","8.98656"
"37.80000","18.90091","9.04690"
"38.00000","19.00099","9.07781"
"38.20000","19.10090","9.12418"
"38.40000","19.20099","9.17486"
"38.60000","19.30090","9.21566"
"38.80000","19.40093","9.26437"
"39.00000","19.50101","9.30630"
"39.20000","19.60104","9.35807"
"39.40000","19.70095","9.41670"
"39.60000","19.80092","9.45907"
"39.80000","19.90095","9.48491"
"40.00000","20.00091","9.55109"
"40.20000","20.10094","9.60158"
"40.40000","20.20097","9.65709"
"40.60000","20.30094","9.69338"
"40.80000","20.40109","9.72563"
"41.00000","20.50099","9.77290"
"41.20000","20.60090","9.83104"
"41.40000","20.70093","9.88374"
"41.60000","20.80096","9.92014"
"41.80000","20.90092","9.98057"
"42.00000","21.00101","10.02113"
"42.20000","21.10098","10.06646"
"42.40000","21.20095","10.10333"
"42.60000","21.30098","10.16048"
"42.80000","21.40095","10.21311"
"43.00000","21.50097","10.26930"
"43.20000","21.60106","10.30108"
"43.40000","21.70097","10.32635"
"43.60000","21.80100","10.38966"
"43.80000","21.90109","10.44395"
"44.00000","22.00093","10.49849"
"44.20000","22.10102","10.53833"
"44.40000","22.20105","10.58133"
"44.60000","22.30096","10.62007"
"44.80000","22.40099","10.68610"
"45.00000","22.50095","10.72331"
"45.20000","22.60086","10.77757"
"45.40000","22.70101","10.83485"
"45.60000","22.80092","10.87966"
"45.80000","22.90107","10.90778"
"46.00000","23.00097","10.94109"
"46.20000","23.10106","11.00103"
"46.40000","23.20097","11.05684"
"46.60000","23.30106","11.11629"
"46.80000","23.40097","11.14531"
"47.00000","23.50099","11.18727"
"47.20000","23.60108","11.24016"
"47.40000","23.70087","11.29756"
"47.60000","23.80102","11.32935"
"47.80000","23.90099","11.37949"
"48.00000","24.00095","11.43252"
"48.20000","24.10098","11.47410"
"48.40000","24.20101","11.52143"
"48.60000","24.30098","11.55394"
"48.80000","24.40095","11.61041"
"49.00000","24.50091","11.67240"
"49.20000","24.60106","11.72036"
"49.40000","24.70103","11.74581"
"49.60000","24.80094","11.78875"
"49.80000","24.90097","11.84360"
"50.00000","25.00099","11.90274"
"50.20000","25.10102","11.95140"
"50.40000","25.20099","11.98497"
"50.60000","25.30102","12.03335"
"50.80000","25.40104","12.08054"
"51.00000","25.50095","12.13402"
"51.20000","25.60098","12.16237"
"51.40000","25.70095","12.22227"
"51.60000","25.80092","12.27225"
"51.80000","25.90100","12.32173"
"52.00000","26.00109","12.36227"
"52.20000","26.10094","12.40058"
"52.40000","26.20103","12.45324"
"52.60000","26.30100","12.51052"
"52.80000","26.40091","12.55467"
"53.00000","26.50099","12.58200"
"53.20000","26.60108","12.63599"
"53.40000","26.70099","12.68802"
"53.60000","26.80102","12.73957"
"53.80000","26.90098","12.78162"
"54.00000","27.00089","12.81832"
"54.20000","27.10098","12.86799"
"54.40000","27.20107","12.92056"
"54.60000","27.30092","12.97442"
"54.80000","27.40100","13.00384"
"55.00000","27.50097","13.05155"
"55.20000","27.60100","13.10696"
"55.40000","27.70097","13.15217"
"55.60000","27.80094","13.19205"
"55.80000","27.90103","13.24338"
"56.00000","28.00099","13.29147"
"56.20000","28.10096","13.34340"
"56.40000","28.20099","13.38413"
"56.60000","28.30096","13.40911"
"56.80000","28.40098","13.46834"
"57.00000","28.50095","13.52835"
"57.20000","28.60092","13.58241"
"57.40000","28.70101","13.61591"
"57.60000","28.80098","13.65652"
"57.80000","28.90095","13.70091"
"58.00000","29.00103","13.75225"
"58.20000","29.10094","13.80421"
"58.40000","29.20109","13.83722"
"58.60000","29.30100","13.89764"
"58.80000","29.40097","13.94290"
"59.00000","29.50093","13.98191"
"59.20000","29.60102","14.00981"
"59.40000","29.70093","14.07175"
"59.60000","29.80096","14.12544"
"59.80000","29.90093","14.18524"
"60.00000","30.00089","14.22224"
"60.20000","30.10098","14.24368"
"60.40000","30.20101","14.29096"
"60.60000","30.30092","14.34585"
"60.80000","30.40100","14.40932"
"61.00000","30.50103","14.44449"
"61.20000","30.60094","14.49203"
"61.40000","30.70103","14.53282"
"61.60000","30.80094","14.57789"
"61.80000","30.90091","14.62438"
"62.00000","31.00099","14.65757"
"62.20000","31.10108","14.72428"
"62.40000","31.20093","14.77219"
"62.60000","31.30101","14.81784"
"62.80000","31.40092","14.84062"
"63.00000","31.50101","14.89132"
"63.20000","31.60104","14.94406"
"63.40000","31.70101","15.00274"
"63.60000","31.80103","15.04865"
"63.80000","31.90094","15.08145"
"64.00000","32.00097","15.11902"
"64.20000","32.10100","15.16822"
"64.40000","32.20103","15.22736"
"64.60000","32.30099","15.25546"
"64.80000","32.40102","15.31481"
"65.00000","32.50099","15.36190"
"65.20000","32.60096","15.40453"
"65.40000","32.70093","15.44240"
"65.60000","32.80107","15.47928"
"65.80000","32.90105","15.53134"
"66.00000","33.00095","15.58975"
"66.20000","33.10098","15.64754"
"66.40000","33.20107","15.66889"
"66.60000","33.30104","15.70466"
"66.80000","33.40094","15.76355"
"67.00000","33.50097","15.81211"
"67.20000","33.60094","15.86263"
"67.40000","33.70115","15.89746"
"67.60000","33.80094","15.93970"
"67.80000","33.90102","15.98393"
"68.00000","34.00099","16.04119"
"68.20000","34.10102","16.07568"
"68.40000","34.20093","16.11816"
"68.60000","34.30102","16.17927"
"68.80000","34.40104","16.22536"
"69.00000","34.50107","16.26244"
"69.20000","34.60098","16.29708"
"69.40000","34.70095","16.34697"
"69.60000","34.80104","16.39296"
"69.80000","34.90094","16.45252"
"70.00000","35.00097","16.48753"
"70.20000","35.10106","16.51958"
"70.40000","35.20109","16.57187"
"70.60000","35.30094","16.61996"
"70.80000","35.40102","16.66874"
"71.00000","35.50099","16.70413"
"71.20000","35.60108","16.75072"
"71.40000","35.70105","16.79513"
"71.60000","35.80107","16.84526"
"71.80000","35.90099","16.89643"
"72.00000","36.00101","16.92306"
"72.20000","36.10092","16.97545"
"72.40000","36.20101","17.02544"
"72.60000","36.30104","17.06913"
"72.80000","36.40088","17.10093"
"73.00000","36.50103","17.14131"
"73.20000","36.60094","17.19513"
"73.40000","36.70103","17.24040"
"73.60000","36.80094","17.29790"
"73.80000","36.90102","17.32344"
"74.00000","37.00093","17.35427"
"74.20000","37.10102","17.41197"
"74.40000","37.20099","17.47050"
"74.60000","37.30101","17.51356"
"74.80000","37.40092","17.54443"
"75.00000","37.50101","17.59250"
"75.20000","37.60092","17.62740"
"75.40000","37.70095","17.67509"
"75.60000","37.80091","17.72487"
"75.80000","37.90094","17.75752"
"76.00000","38.00091","17.82329"
"76.20000","38.10094","17.86707"
"76.40000","38.20097","17.90793"
"76.60000","38.30093","17.92908"
"76.80000","38.40108","17.97118"
"77.00000","38.50093","18.03823"
"77.20000","38.60096","18.08236"
"77.40000","38.70105","18.13271"
"77.60000","38.80101","18.15651"
"77.80000","38.90104","18.19223"
"78.00000","39.00101","18.23953"
"78.20000","39.10098","18.29116"
"78.40000","39.20095","18.33824"
"78.60000","39.30098","18.36837"
"78.80000","39.40100","18.42152"
"79.00000","39.50109","18.45965"
"79.20000","39.60094","18.50311"
"79.40000","39.70090","18.54259"
"79.60000","39.80106","18.58091"
"79.80000","39.90102","18.63903"
"80.00000","40.00099","18.69174"
"80.20000","40.10108","18.73612"
"80.40000","40.20099","18.75414"
"80.60000","40.30101","18.78507"
"80.80000","40.40092","18.84119"
"81.00000","40.50089","18.89043"
"81.20000","40.60098","18.95292"
"81.40000","40.70101","18.98219"
"81.60000","40.80104","19.02196"
"81.80000","40.90095","19.06234"
"82.00000","41.00103","19.11030"
"82.20000","41.10100","19.16053"
"82.40000","41.20103","19.18761"
"82.60000","41.30094","19.25113"
"82.80000","41.40102","19.29299"
"83.00000","41.50099","19.33377"
"83.20000","41.60096","19.36381"
"83.40000","41.70105","19.39848"
"83.60000","41.80096","19.44873"
"83.80000","41.90110","19.48909"
"84.00000","42.00101","19.55723"
"84.20000","42.10104","19.58607"
"84.40000","42.20095","19.60750"
"84.60000","42.30097","19.65430"
"84.80000","42.40094","19.70314"
"85.00000","42.50103","19.75655"
"85.20000","42.60094","19.79296"
"85.40000","42.70097","19.83123"
"85.60000","42.80106","19.87535"
"85.80000","42.90108","19.91726"
"86.00000","43.00099","19.96559"
"86.20000","43.10102","19.99597"
"86.40000","43.20105","20.02640"
"86.60000","43.30095","20.08592"
"86.80000","43.40098","20.13458"
"87.00000","43.50089","20.17894"
"87.20000","43.60098","20.20257"
"87.40000","43.70101","20.24377"
"87.60000","43.80098","20.28996"
"87.80000","43.90094","20.32711"
"88.00000","44.00097","20.38367"
"88.20000","44.10100","20.41322"
"88.40000","44.20097","20.44308"
"88.60000","44.30088","20.48712"
"88.80000","44.40102","20.53510"
"89.00000","44.50105","20.58444"
"89.20000","44.60089","20.61690"
"89.40000","44.70099","20.65273"
"89.60000","44.80090","20.70252"
"89.80000","44.90092","20.73691"
"90.00000","45.00101","20.78703"
"90.20000","45.10098","20.82444"
"90.40000","45.20094","20.85352"
"90.60000","45.30104","20.90609"
"90.80000","45.40094","20.95181"
"91.00000","45.50097","20.99647"
"91.20000","45.60094","21.01840"
"91.40000","45.70097","21.05539"
"91.60000","45.80093","21.11115"
"91.80000","45.90102","21.15057"
"92.00000","46.00087","21.19881"
"92.20000","46.10090","21.23413"
"92.40000","46.20105","21.25595"
"92.60000","46.30101","21.28991"
"92.80000","46.40104","21.33385"
"93.00000","46.50101","21.39553"
"93.20000","46.60098","21.43283"
"93.40000","46.70101","21.46023"
"93.60000","46.80091","21.50790"
"93.80000","46.90094","21.54515"
"94.00000","47.00103","21.58241"
"94.20000","47.10100","21.62042"
"94.40000","47.20090","21.65745"
"94.60000","47.30093","21.70170"
"94.80000","47.40096","21.74529"
"95.00000","47.50111","21.79247"
"95.20000","47.60090","21.83404"
"95.40000","47.70105","21.84841"
"95.60000","47.80095","21.88072"
"95.80000","47.90110","21.93624"
"96.00000","48.00095","21.98628"
"96.20000","48.10104","22.03026"
"96.40000","48.20095","22.06453"
"96.60000","48.30098","22.09517"
"96.80000","48.40100","22.13021"
"97.00000","48.50097","22.16402"
"97.20000","48.60100","22.21213"
"97.40000","48.70097","22.25920"
"97.60000","48.80087","22.28116"
"97.80000","48.90096","22.33452"
"98.00000","49.00099","22.37358"
"98.20000","49.10108","22.40653"
"98.40000","49.20099","22.43887"
"98.60000","49.30096","22.46501"
"98.80000","49.40104","22.50608"
"99.00000","49.50095","22.55205"
"99.20000","49.60104","22.59589"
"99.40000","49.70107","22.64567"
"99.60000","49.80098","22.67584"
"99.80000","49.90100","22.69155"
"100.00000","50.00097","22.73016"
"100.20000","50.10094","22.77427"
"100.40000","50.20097","22.81804"
"100.60000","50.30099","22.86520"
"100.80000","50.40102","22.89858"
"101.00000","50.50099","22.93275"
"101.20000","50.60102","22.97023"
"101.40000","50.70111","22.99590"
"101.60000","50.80096","23.04039"
"101.80000","50.90110","23.08078"
"102.00000","51.00101","23.10303"
"102.20000","51.10104","23.15001"
"102.40000","51.20095","23.19788"
"102.60000","51.30097","23.23204"
"102.80000","51.40100","23.26680"
"103.00000","51.50091","23.28614"
"103.20000","51.60112","23.32080"
"103.40000","51.70109","23.36890"
"103.60000","51.80106","23.39962"
"103.80000","51.90090","23.45311"
"104.00000","52.00111","23.49720"
"104.20000","52.10096","23.51486"
"104.40000","52.20104","23.53670"
"104.60000","52.30095","23.57692"
"104.80000","52.40092","23.60981"
"105.00000","52.50107","23.66061"
"105.20000","52.60110","23.68861"
"105.40000","52.70101","23.71387"
"105.60000","52.80104","23.75368"
"105.80000","52.90100","23.80253"
"106.00000","53.00097","23.82587"
"106.20000","53.10099","23.86733"
"106.40000","53.20091","23.89971"
"106.60000","53.30111","23.92458"
"106.80000","53.40102","23.95405"
"107.00000","53.50105","23.99988"
"107.20000","53.60102","24.03694"
"107.40000","53.70110","24.09016"
"107.60000","53.80101","24.11257"
"107.80000","53.90098","24.13028"
"108.00000","54.00095","24.17326"
"108.20000","54.10104","24.20413"
"108.40000","54.20100","24.23682"
"108.60000","54.30097","24.27752"
"108.80000","54.40100","24.31397"
"109.00000","54.50091","24.33353"
"109.20000","54.60100","24.37034"
"109.40000","54.70103","24.40116"
"109.60000","54.80105","24.42282"
"109.80000","54.90102","24.47028"
"110.00000","55.00093","24.50534"
"110.20000","55.10090","24.52822"
"110.40000","55.20105","24.56814"
"110.60000","55.30095","24.60555"
"110.80000","55.40110","24.63487"
"111.00000","55.50101","24.66796"
"111.20000","55.60098","24.70408"
"111.40000","55.70088","24.73250"
"111.60000","55.80103","24.76125"
"111.80000","55.90100","24.79737"
"112.00000","56.00091","24.84197"
"112.20000","56.10100","24.87560"
"112.40000","56.20090","24.92047"
"112.60000","56.30100","24.93519"
"112.80000","56.40090","24.95489"
"113.00000","56.50105","24.98860"
"113.20000","56.60096","24.99771"
"113.40000","56.70098","25.04877"
"113.60000","56.80090","25.08833"
"113.80000","56.90105","25.12943"
"114.00000","57.00095","25.15168"
"114.20000","57.10098","25.17569"
"114.40000","57.20095","25.20194"
"114.60000","57.30092","25.23230"
"114.80000","57.40100","25.26348"
"115.00000","57.50092","25.31517"
"115.20000","57.60094","25.35103"
"115.40000","57.70097","25.36491"
"115.60000","57.80105","25.39612"
"115.80000","57.90090","25.43702"
"116.00000","58.00099","25.46733"
"116.20000","58.10102","25.49221"
"116.40000","58.20092","25.51919"
"116.60000","58.30096","25.54388"
"116.80000","58.40092","25.56868"
"117.00000","58.50095","25.60865"
"117.20000","58.60098","25.64814"
"117.40000","58.70089","25.67864"
"117.60000","58.80103","25.72141"
"117.80000","58.90094","25.75920"
"118.00000","59.00085","25.77091"
"118.20000","59.10106","25.78518"
"118.40000","59.20097","25.81021"
"118.60000","59.30094","25.84804"
"118.80000","59.40091","25.88099"
"119.00000","59.50093","25.92732"
"119.20000","59.60096","25.95650"
"119.40000","59.70098","25.98305"
"119.60000","59.80095","26.00047"
"119.80000","59.90099","26.03284"
"120.00000","60.00095","26.06672"
"120.20000","60.10092","26.07956"
"120.40000","60.20095","26.11513"
"120.60000","60.30103","26.14890"
"120.80000","60.40100","26.17749"
"121.00000","60.50103","26.19757"
"121.20000","60.60094","26.22912"
"121.40000","60.70097","26.26891"
"121.60000","60.80093","26.29772"
"121.80000","60.90090","26.32738"
"122.00000","61.00099","26.35570"
"122.20000","61.10096","26.37164"
"122.40000","61.20099","26.38779"
"122.60000","61.30107","26.41457"
"122.80000","61.40104","26.45701"
"123.00000","61.50101","26.48938"
"123.20000","61.60098","26.52192"
"123.40000","61.70101","26.56043"
"123.60000","61.80097","26.59016"
"123.80000","61.90106","26.60272"
"124.00000","62.00103","26.61303"
"124.20000","62.10094","26.63577"
"124.40000","62.20091","26.66671"
"124.60000","62.30099","26.69450"
"124.80000","62.40096","26.73145"
"125.00000","62.50098","26.76434"
"125.20000","62.60096","26.78941"
"125.40000","62.70092","26.81494"
"125.60000","62.80095","26.84294"
"125.80000","62.90097","26.87313"
"126.00000","63.00101","26.90335"
"126.20000","63.10104","26.91908"
"126.40000","63.20106","26.94798"
"126.60000","63.30097","26.97613"
"126.80000","63.40100","26.99749"
"127.00000","63.50103","27.01822"
"127.20000","63.60099","27.03507"
"127.40000","63.70090","27.06349"
"127.60000","63.80099","27.10490"
"127.80000","63.90089","27.13785"
"128.00000","64.00105","27.16743"
"128.20000","64.10096","27.19458"
"128.40000","64.20098","27.20448"
"128.60000","64.30101","27.21215"
"128.80000","64.40098","27.23525"
"129.00000","64.50107","27.26786"
"129.20000","64.60104","27.30358"
"129.40000","64.70100","27.32280"
"129.60000","64.80097","27.34954"
"129.80000","64.90106","27.39010"
"130.00000","65.00091","27.41970"
"130.20000","65.10094","27.43845"
"130.40000","65.20097","27.44909"
"130.60000","65.30093","27.45469"
"130.80000","65.40102","27.47863"
"131.00000","65.50093","27.50183"
"131.20000","65.60101","27.52085"
"131.40000","65.70093","27.55219"
"131.60000","65.80101","27.58846"
"131.80000","65.90092","27.61326"
"132.00000","66.00101","27.62389"
"132.20000","66.10091","27.64462"
"132.40000","66.20106","27.66871"
"132.60000","66.30097","27.70074"
"132.80000","66.40105","27.73352"
"133.00000","66.50097","27.74744"
"133.20000","66.60099","27.76827"
"133.40000","66.70097","27.79424"
"133.60000","66.80093","27.81456"
"133.80000","66.90102","27.82729"
"134.00000","67.00098","27.84210"
"134.20000","67.10101","27.86725"
"134.40000","67.20092","27.88791"
"134.60000","67.30096","27.91508"
"134.80000","67.40104","27.94121"
"135.00000","67.50107","27.96964"
"135.20000","67.60109","28.00119"
"135.40000","67.70100","28.02520"
"135.60000","67.80097","28.03781"
"135.80000","67.90094","28.04308"
"136.00000","68.00096","28.05414"
"136.20000","68.10100","28.07807"
"136.40000","68.20102","28.11001"
"136.60000","68.30099","28.13946"
"136.80000","68.40096","28.16315"
"137.00000","68.50099","28.18475"
"137.20000","68.60101","28.21053"
"137.40000","68.70104","28.23568"
"137.60000","68.80107","28.24794"
"137.80000","68.90104","28.26128"
"138.00000","69.00106","28.28302"
"138.20000","69.10098","28.30815"
"138.40000","69.20106","28.33581"
"138.60000","69.30103","28.34402"
"138.80000","69.40112","28.35881"
"139.00000","69.50097","28.39529"
"139.20000","69.60105","28.41917"
"139.40000","69.70097","28.44031"
"139.60000","69.80099","28.45167"
"139.80000","69.90102","28.45338"
"140.00000","70.00092","28.46952"
"140.20000","70.10107","28.49857"
"140.40000","70.20098","28.52691"
"140.60000","70.30101","28.55033"
"140.80000","70.40098","28.56404"
"141.00000","70.50113","28.58698"
"141.20000","70.60098","28.60619"
"141.40000","70.70107","28.62581"
"141.60000","70.80096","28.63756"
"141.80000","70.90100","28.64917"
"142.00000","71.00103","28.65752"
"142.20000","71.10105","28.66589"
"142.40000","71.20109","28.69122"
"142.60000","71.30093","28.71066"
"142.80000","71.40096","28.72779"
"143.00000","71.50105","28.74172"
"143.20000","71.60102","28.75869"
"143.40000","71.70098","28.77635"
"143.60000","71.80107","28.79878"
"143.80000","71.90110","28.82146"
"144.00000","72.00107","28.84355"
"144.20000","72.10091","28.85705"
"144.40000","72.20100","28.86180"
"144.60000","72.30097","28.86632"
"144.80000","72.40106","28.87865"
"145.00000","72.50097","28.89747"
"145.20000","72.60100","28.92674"
"145.40000","72.70097","28.94951"
"145.60000","72.80099","28.96387"
"145.80000","72.90096","28.97883"
"146.00000","73.00093","29.00524"
"146.20000","73.10114","29.02299"
"146.40000","73.20104","29.03560"
"146.60000","73.30095","29.05215"
"146.80000","73.40092","29.06599"
"147.00000","73.50095","29.07847"
"147.20000","73.60092","29.09001"
"147.40000","73.70107","29.10668"
"147.60000","73.80097","29.12596"
"147.80000","73.90094","29.14365"
"148.00000","74.00103","29.15494"
"148.20000","74.10105","29.16418"
"148.40000","74.20097","29.17761"
"148.60000","74.30099","29.20341"
"148.80000","74.40102","29.22991"
"149.00000","74.50098","29.25137"
"149.20000","74.60101","29.26901"
"149.40000","74.70086","29.27804"
"149.60000","74.80090","29.28397"
"149.80000","74.90098","29.29410"
"150.00000","75.00101","29.31064"
"150.20000","75.10098","29.32896"
"150.40000","75.20107","29.35417"
"150.60000","75.30097","29.37411"
"150.80000","75.40106","29.38981"
"151.00000","75.50091","29.40707"
"151.20000","75.60100","29.42354"
"151.40000","75.70096","29.43974"
"151.60000","75.80099","29.45231"
"151.80000","75.90089","29.45887"
"152.00000","76.00093","29.46670"
"152.20000","76.10095","29.46955"
"152.40000","76.20104","29.48329"
"152.60000","76.30095","29.49711"
"152.80000","76.40098","29.51446"
"153.00000","76.50082","29.53620"
"153.20000","76.60098","29.55849"
"153.40000","76.70100","29.57221"
"153.60000","76.80091","29.58388"
"153.80000","76.90099","29.59258"
"154.00000","77.00103","29.61911"
"154.20000","77.10093","29.64317"
"154.40000","77.20097","29.65540"
"154.60000","77.30093","29.67518"
"154.80000","77.40096","29.68576"
"155.00000","77.50092","29.69138"
"155.20000","77.60095","29.69703"
"155.40000","77.70086","29.70483"
"155.60000","77.80107","29.71167"
"155.80000","77.90098","29.72312"
"156.00000","78.00101","29.73768"
"156.20000","78.10103","29.75482"
"156.40000","78.20100","29.76905"
"156.60000","78.30096","29.78255"
"156.80000","78.40105","29.80048"
"157.00000","78.50096","29.82338"
"157.20000","78.60094","29.83636"
"157.40000","78.70096","29.85978"
"157.60000","78.80087","29.87320"
"157.80000","78.90102","29.88080"
"158.00000","79.00098","29.88774"
"158.20000","79.10102","29.89785"
"158.40000","79.20098","29.90570"
"158.60000","79.30107","29.91830"
"158.80000","79.40092","29.93134"
"159.00000","79.50101","29.94257"
"159.20000","79.60097","29.95792"
"159.40000","79.70100","29.97447"
"159.60000","79.80109","29.98303"
"159.80000","79.90093","29.99204"
"160.00000","80.00097","29.99793"
"160.20000","80.10094","30.00511"
"160.40000","80.20090","30.01573"
"160.60000","80.30099","30.03284"
"160.80000","80.40108","30.04719"
"161.00000","80.50092","30.05825"
"161.20000","80.60094","30.06890"
"161.40000","80.70098","30.07540"
"161.60000","80.80101","30.08500"
"161.80000","80.90099","30.09694"
"162.00000","81.00094","30.10608"
"162.20000","81.10098","30.11609"
"162.40000","81.20100","30.12702"
"162.60000","81.30103","30.13724"
"162.80000","81.40099","30.14600"
"163.00000","81.50102","30.14890"
"163.20000","81.60099","30.16034"
"163.40000","81.70097","30.17820"
"163.60000","81.80098","30.18878"
"163.80000","81.90096","30.19841"
"164.00000","82.00092","30.20645"
"164.20000","82.10107","30.21693"
"164.40000","82.20103","30.22832"
"164.60000","82.30106","30.22923"
"164.80000","82.40104","30.24023"
"165.00000","82.50101","30.24498"
"165.20000","82.60085","30.25182"
"165.40000","82.70094","30.25782"
"165.60000","82.80109","30.26349"
"165.80000","82.90100","30.26814"
"166.00000","83.00102","30.26834"
"166.20000","83.10106","30.26905"
"166.40000","83.20090","30.26753"
"166.60000","83.30099","30.26475"
"166.80000","83.40107","30.25677"
"167.00000","83.50093","30.24563"
"167.20000","83.60107","30.22636"
"167.40000","83.70098","30.18914"
"167.60000","83.80094","30.13021"
"167.79400","83.89799","29.91640"
"167.79800","83.90002","28.67621"
"167.80200","83.90199","25.36553"
"167.80600","83.90397","22.65726"
"167.81000","83.90594","18.90587"
"167.81200","83.90696","17.07897"