File: MT-DataAnalysis-JupyterNotebook/TensionPlots/TensionTests/SpringLength/Specimen_RawData_9.csv
End date,"8/16/2018"
Specimen label,"D32L45N5d4"
Maximum Load,"27.30709",N
Extension at Maximum Load,"125.00095",mm
Maximum Slope (Automatic Young's),"0.35343",N/mm
Rate 1,"30.00000",mm/min

Time,Extension,Load
(s),(mm),(N)
"0.00000","0.00000","0.00403"
"0.20000","0.09046","0.03157"
"0.40000","0.20173","0.07872"
"0.60000","0.30134","0.12520"
"0.80000","0.40107","0.16840"
"1.00000","0.50104","0.19004"
"1.20000","0.60100","0.21701"
"1.40000","0.70109","0.25491"
"1.60000","0.80106","0.29482"
"1.80000","0.90103","0.33403"
"2.00000","1.00100","0.37465"
"2.20000","1.10102","0.40610"
"2.40000","1.20093","0.43626"
"2.60000","1.30102","0.47442"
"2.80000","1.40117","0.51265"
"3.00000","1.50108","0.55440"
"3.20000","1.60104","0.59004"
"3.40000","1.70101","0.61558"
"3.60000","1.80110","0.64447"
"3.80000","1.90107","0.68638"
"4.00000","2.00104","0.72667"
"4.20000","2.10112","0.76292"
"4.40000","2.20097","0.79804"
"4.60000","2.30106","0.82901"
"4.80000","2.40103","0.86496"
"5.00000","2.50106","0.90287"
"5.20000","2.60102","0.94141"
"5.40000","2.70093","0.97924"
"5.60000","2.80108","1.01353"
"5.80000","2.90117","1.03691"
"6.00000","3.00102","1.07396"
"6.20000","3.10098","1.11712"
"6.40000","3.20113","1.16061"
"6.60000","3.30110","1.19650"
"6.80000","3.40107","1.22527"
"7.00000","3.50110","1.25304"
"7.20000","3.60106","1.28878"
"7.40000","3.70103","1.32298"
"7.60000","3.80106","1.36587"
"7.80000","3.90103","1.40451"
"8.00000","4.00117","1.43644"
"8.20000","4.10108","1.46884"
"8.40000","4.20105","1.50647"
"8.60000","4.30102","1.54372"
"8.80000","4.40111","1.58008"
"9.00000","4.50108","1.61378"
"9.20000","4.60110","1.64401"
"9.40000","4.70107","1.67834"
"9.60000","4.80104","1.72210"
"9.80000","4.90107","1.76277"
"10.00000","5.00104","1.80368"
"10.20000","5.10100","1.83383"
"10.40000","5.20103","1.85225"
"10.60000","5.30112","1.87988"
"10.80000","5.40109","1.92085"
"11.00000","5.50112","1.96307"
"11.20000","5.60102","2.00735"
"11.40000","5.70111","2.04192"
"11.60000","5.80114","2.07558"
"11.80000","5.90111","2.10868"
"12.00000","6.00102","2.14053"
"12.20000","6.10122","2.17264"
"12.40000","6.20107","2.21213"
"12.60000","6.30104","2.24812"
"12.80000","6.40107","2.28140"
"13.00000","6.50116","2.31947"
"13.20000","6.60106","2.36423"
"13.40000","6.70103","2.40188"
"13.60000","6.80106","2.42869"
"13.80000","6.90097","2.45325"
"14.00000","7.00111","2.47738"
"14.20000","7.10108","2.52070"
"14.40000","7.20105","2.56539"
"14.60000","7.30108","2.60820"
"14.80000","7.40105","2.65135"
"15.00000","7.50102","2.68058"
"15.20000","7.60116","2.70406"
"15.40000","7.70101","2.73100"
"15.60000","7.80098","2.76832"
"15.80000","7.90107","2.81219"
"16.00000","8.00098","2.85498"
"16.20000","8.10094","2.88804"
"16.40000","8.20097","2.91958"
"16.60000","8.30106","2.96316"
"16.80000","8.40103","2.99824"
"17.00000","8.50105","3.02676"
"17.20000","8.60096","3.05700"
"17.40000","8.70105","3.08499"
"17.60000","8.80102","3.11861"
"17.80000","8.90111","3.16505"
"18.00000","9.00108","3.20848"
"18.20000","9.10116","3.25089"
"18.40000","9.20101","3.28070"
"18.60000","9.30104","3.29912"
"18.80000","9.40095","3.33042"
"19.00000","9.50104","3.37227"
"19.20000","9.60100","3.41609"
"19.40000","9.70091","3.45731"
"19.60000","9.80112","3.49129"
"19.80000","9.90103","3.52112"
"20.00000","10.00099","3.55237"
"20.20000","10.10096","3.58714"
"20.40000","10.20105","3.62276"
"20.60000","10.30102","3.66349"
"20.80000","10.40105","3.69092"
"21.00000","10.50101","3.72445"
"21.20000","10.60104","3.76622"
"21.40000","10.70101","3.81280"
"21.60000","10.80092","3.84556"
"21.80000","10.90107","3.87920"
"22.00000","11.00097","3.90518"
"22.20000","11.10088","3.93649"
"22.40000","11.20103","3.97467"
"22.60000","11.30106","4.01429"
"22.80000","11.40097","4.05746"
"23.00000","11.50111","4.09584"
"23.20000","11.60102","4.11984"
"23.40000","11.70105","4.14745"
"23.60000","11.80108","4.18667"
"23.80000","11.90105","4.22748"
"24.00000","12.00101","4.26534"
"24.20000","12.10104","4.30061"
"24.40000","12.20101","4.32946"
"24.60000","12.30104","4.36363"
"24.80000","12.40107","4.40430"
"25.00000","12.50098","4.43648"
"25.20000","12.60100","4.47833"
"25.40000","12.70109","4.51684"
"25.60000","12.80112","4.53915"
"25.80000","12.90103","4.57328"
"26.00000","13.00099","4.61973"
"26.20000","13.10108","4.65814"
"26.40000","13.20111","4.69730"
"26.60000","13.30096","4.72336"
"26.80000","13.40111","4.75009"
"27.00000","13.50102","4.78872"
"27.20000","13.60104","4.82638"
"27.40000","13.70101","4.86385"
"27.60000","13.80098","4.90857"
"27.80000","13.90101","4.93763"
"28.00000","14.00103","4.95500"
"28.20000","14.10106","4.99916"
"28.40000","14.20103","5.03640"
"28.60000","14.30112","5.08484"
"28.80000","14.40103","5.12332"
"29.00000","14.50105","5.14416"
"29.20000","14.60102","5.17561"
"29.40000","14.70105","5.21261"
"29.60000","14.80102","5.24772"
"29.80000","14.90099","5.28664"
"30.00000","15.00107","5.32604"
"30.20000","15.10104","5.35720"
"30.40000","15.20107","5.38868"
"30.60000","15.30104","5.42883"
"30.80000","15.40101","5.46784"
"31.00000","15.50104","5.50464"
"31.20000","15.60112","5.53498"
"31.40000","15.70097","5.55348"
"31.60000","15.80106","5.59423"
"31.80000","15.90108","5.63774"
"32.00000","16.00099","5.68019"
"32.20000","16.10102","5.72179"
"32.40000","16.20105","5.75737"
"32.60000","16.30096","5.77491"
"32.80000","16.40104","5.80449"
"33.00000","16.50095","5.84229"
"33.20000","16.60098","5.88539"
"33.40000","16.70113","5.93362"
"33.60000","16.80104","5.96392"
"33.80000","16.90107","5.99511"
"34.00000","17.00109","6.02848"
"34.20000","17.10106","6.06368"
"34.40000","17.20103","6.09342"
"34.60000","17.30106","6.12884"
"34.80000","17.40097","6.16353"
"35.00000","17.50105","6.19727"
"35.20000","17.60108","6.23807"
"35.40000","17.70099","6.28174"
"35.60000","17.80108","6.32269"
"35.80000","17.90105","6.35815"
"36.00000","18.00101","6.37626"
"36.20000","18.10104","6.39360"
"36.40000","18.20107","6.43921"
"36.60000","18.30104","6.48161"
"36.80000","18.40107","6.52715"
"37.00000","18.50097","6.56737"
"37.20000","18.60106","6.60164"
"37.40000","18.70103","6.62460"
"37.60000","18.80118","6.65714"
"37.80000","18.90108","6.68847"
"38.00000","19.00105","6.73046"
"38.20000","19.10090","6.77258"
"38.40000","19.20105","6.79750"
"38.60000","19.30114","6.83500"
"38.80000","19.40104","6.87811"
"39.00000","19.50107","6.91637"
"39.20000","19.60098","6.94818"
"39.40000","19.70101","6.97537"
"39.60000","19.80110","7.00069"
"39.80000","19.90113","7.03729"
"40.00000","20.00109","7.08045"
"40.20000","20.10106","7.12566"
"40.40000","20.20109","7.17270"
"40.60000","20.30112","7.20646"
"40.80000","20.40109","7.21897"
"41.00000","20.50099","7.24648"
"41.20000","20.60114","7.28642"
"41.40000","20.70099","7.32565"
"41.60000","20.80108","7.37348"
"41.80000","20.90105","7.40429"
"42.00000","21.00113","7.43799"
"42.20000","21.10116","7.47332"
"42.40000","21.20113","7.50755"
"42.60000","21.30110","7.53992"
"42.80000","21.40112","7.58002"
"43.00000","21.50103","7.60927"
"43.20000","21.60106","7.63714"
"43.40000","21.70109","7.67550"
"43.60000","21.80112","7.72477"
"43.80000","21.90109","7.76308"
"44.00000","22.00099","7.79956"
"44.20000","22.10102","7.82099"
"44.40000","22.20105","7.84775"
"44.60000","22.30114","7.88750"
"44.80000","22.40105","7.92570"
"45.00000","22.50113","7.97048"
"45.20000","22.60104","8.01173"
"45.40000","22.70107","8.04025"
"45.60000","22.80104","8.06023"
"45.80000","22.90118","8.10010"
"46.00000","23.00109","8.13746"
"46.20000","23.10112","8.17692"
"46.40000","23.20103","8.21447"
"46.60000","23.30106","8.23921"
"46.80000","23.40103","8.27653"
"47.00000","23.50099","8.32061"
"47.20000","23.60114","8.35284"
"47.40000","23.70099","8.38969"
"47.60000","23.80096","8.42531"
"47.80000","23.90104","8.45209"
"48.00000","24.00119","8.48284"
"48.20000","24.10098","8.52171"
"48.40000","24.20107","8.56517"
"48.60000","24.30110","8.60369"
"48.80000","24.40113","8.63589"
"49.00000","24.50097","8.65784"
"49.20000","24.60100","8.69218"
"49.40000","24.70103","8.73894"
"49.60000","24.80100","8.77467"
"49.80000","24.90103","8.81431"
"50.00000","25.00099","8.84957"
"50.20000","25.10102","8.87273"
"50.40000","25.20099","8.90335"
"50.60000","25.30108","8.94316"
"50.80000","25.40104","8.98155"
"51.00000","25.50113","9.02572"
"51.20000","25.60104","9.05800"
"51.40000","25.70101","9.08023"
"51.60000","25.80104","9.12129"
"51.80000","25.90100","9.15915"
"52.00000","26.00092","9.19071"
"52.20000","26.10112","9.22823"
"52.40000","26.20103","9.26134"
"52.60000","26.30106","9.29164"
"52.80000","26.40108","9.32970"
"53.00000","26.50093","9.36773"
"53.20000","26.60108","9.40851"
"53.40000","26.70105","9.44545"
"53.60000","26.80102","9.47006"
"53.80000","26.90105","9.48773"
"54.00000","27.00113","9.53661"
"54.20000","27.10098","9.58162"
"54.40000","27.20101","9.62058"
"54.60000","27.30103","9.65831"
"54.80000","27.40107","9.68713"
"55.00000","27.50103","9.70850"
"55.20000","27.60106","9.73860"
"55.40000","27.70097","9.77335"
"55.60000","27.80106","9.81101"
"55.80000","27.90096","9.86569"
"56.00000","28.00099","9.88912"
"56.20000","28.10108","9.92071"
"56.40000","28.20105","9.96829"
"56.60000","28.30102","10.00046"
"56.80000","28.40092","10.03145"
"57.00000","28.50107","10.06329"
"57.20000","28.60104","10.08840"
"57.40000","28.70101","10.12641"
"57.60000","28.80104","10.16941"
"57.80000","28.90095","10.20798"
"58.00000","29.00109","10.25324"
"58.20000","29.10106","10.28757"
"58.40000","29.20103","10.30403"
"58.60000","29.30100","10.32206"
"58.80000","29.40102","10.36738"
"59.00000","29.50099","10.40806"
"59.20000","29.60108","10.45204"
"59.40000","29.70099","10.49073"
"59.60000","29.80102","10.52120"
"59.80000","29.90099","10.55352"
"60.00000","30.00101","10.58428"
"60.20000","30.10098","10.61120"
"60.40000","30.20113","10.65104"
"60.60000","30.30104","10.69503"
"60.80000","30.40095","10.71761"
"61.00000","30.50109","10.75553"
"61.20000","30.60100","10.80325"
"61.40000","30.70109","10.84095"
"61.60000","30.80106","10.87456"
"61.80000","30.90097","10.90049"
"62.00000","31.00105","10.92073"
"62.20000","31.10102","10.95492"
"62.40000","31.20093","10.99709"
"62.60000","31.30101","11.03962"
"62.80000","31.40098","11.08522"
"63.00000","31.50107","11.12154"
"63.20000","31.60110","11.14157"
"63.40000","31.70113","11.16409"
"63.60000","31.80103","11.20305"
"63.80000","31.90106","11.23982"
"64.00000","32.00103","11.28371"
"64.20000","32.10106","11.31529"
"64.40000","32.20115","11.34499"
"64.60000","32.30093","11.38332"
"64.80000","32.40108","11.42215"
"65.00000","32.50105","11.44944"
"65.20000","32.60102","11.48611"
"65.40000","32.70099","11.51955"
"65.60000","32.80114","11.54284"
"65.80000","32.90099","11.57789"
"66.00000","33.00101","11.62090"
"66.20000","33.10098","11.66674"
"66.40000","33.20113","11.70735"
"66.60000","33.30110","11.73380"
"66.80000","33.40107","11.75285"
"67.00000","33.50109","11.78509"
"67.20000","33.60112","11.82619"
"67.40000","33.70109","11.86246"
"67.60000","33.80100","11.90629"
"67.80000","33.90102","11.94104"
"68.00000","34.00105","11.96891"
"68.20000","34.10102","11.99387"
"68.40000","34.20099","12.03154"
"68.60000","34.30102","12.06616"
"68.80000","34.40099","12.11023"
"69.00000","34.50107","12.14011"
"69.20000","34.60116","12.15928"
"69.40000","34.70107","12.19924"
"69.60000","34.80116","12.23754"
"69.80000","34.90106","12.27558"
"70.00000","35.00097","12.30970"
"70.20000","35.10106","12.34497"
"70.40000","35.20115","12.36977"
"70.60000","35.30112","12.40273"
"70.80000","35.40108","12.44026"
"71.00000","35.50099","12.48050"
"71.20000","35.60090","12.51982"
"71.40000","35.70111","12.55289"
"71.60000","35.80114","12.57443"
"71.80000","35.90099","12.60062"
"72.00000","36.00107","12.64498"
"72.20000","36.10104","12.68178"
"72.40000","36.20101","12.71881"
"72.60000","36.30104","12.75405"
"72.80000","36.40100","12.78240"
"73.00000","36.50109","12.80625"
"73.20000","36.60112","12.83967"
"73.40000","36.70103","12.87780"
"73.60000","36.80099","12.91741"
"73.80000","36.90102","12.96257"
"74.00000","37.00099","12.98477"
"74.20000","37.10108","13.00835"
"74.40000","37.20099","13.04972"
"74.60000","37.30101","13.08768"
"74.80000","37.40104","13.11979"
"75.00000","37.50101","13.15418"
"75.20000","37.60104","13.18418"
"75.40000","37.70107","13.21067"
"75.60000","37.80121","13.25196"
"75.80000","37.90100","13.29168"
"76.00000","38.00103","13.32970"
"76.20000","38.10106","13.36797"
"76.40000","38.20109","13.38872"
"76.60000","38.30093","13.40769"
"76.80000","38.40090","13.43913"
"77.00000","38.50105","13.48930"
"77.20000","38.60102","13.53026"
"77.40000","38.70105","13.57032"
"77.60000","38.80107","13.59589"
"77.80000","38.90098","13.62120"
"78.00000","39.00107","13.65296"
"78.20000","39.10104","13.68659"
"78.40000","39.20101","13.71528"
"78.60000","39.30103","13.75758"
"78.80000","39.40100","13.79869"
"79.00000","39.50091","13.81877"
"79.20000","39.60106","13.85181"
"79.40000","39.70109","13.89321"
"79.60000","39.80099","13.92988"
"79.80000","39.90102","13.96186"
"80.00000","40.00099","13.98758"
"80.20000","40.10102","14.00971"
"80.40000","40.20111","14.04163"
"80.60000","40.30101","14.09554"
"80.80000","40.40104","14.13033"
"81.00000","40.50101","14.16977"
"81.20000","40.60098","14.20993"
"81.40000","40.70107","14.22760"
"81.60000","40.80104","14.24274"
"81.80000","40.90107","14.27466"
"82.00000","41.00109","14.31512"
"82.20000","41.10100","14.35777"
"82.40000","41.20103","14.40229"
"82.60000","41.30106","14.42320"
"82.80000","41.40120","14.45181"
"83.00000","41.50105","14.48816"
"83.20000","41.60102","14.52154"
"83.40000","41.70099","14.54549"
"83.60000","41.80113","14.58172"
"83.80000","41.90110","14.61636"
"84.00000","42.00101","14.64091"
"84.20000","42.10104","14.67782"
"84.40000","42.20100","14.72024"
"84.60000","42.30116","14.75701"
"84.80000","42.40100","14.79659"
"85.00000","42.50109","14.82167"
"85.20000","42.60106","14.83663"
"85.40000","42.70109","14.86034"
"85.60000","42.80099","14.90570"
"85.80000","42.90114","14.94550"
"86.00000","43.00105","14.98345"
"86.20000","43.10108","15.03133"
"86.40000","43.20105","15.05426"
"86.60000","43.30095","15.07474"
"86.80000","43.40104","15.10176"
"87.00000","43.50095","15.13356"
"87.20000","43.60098","15.16944"
"87.40000","43.70107","15.20567"
"87.60000","43.80104","15.23859"
"87.80000","43.90094","15.26197"
"88.00000","44.00103","15.30313"
"88.20000","44.10106","15.34407"
"88.40000","44.20115","15.37255"
"88.60000","44.30111","15.40295"
"88.80000","44.40108","15.43091"
"89.00000","44.50105","15.45413"
"89.20000","44.60108","15.48159"
"89.40000","44.70093","15.51839"
"89.60000","44.80101","15.55874"
"89.80000","44.90104","15.60321"
"90.00000","45.00095","15.64250"
"90.20000","45.10104","15.65987"
"90.40000","45.20100","15.67757"
"90.60000","45.30104","15.70845"
"90.80000","45.40100","15.75160"
"91.00000","45.50109","15.78247"
"91.20000","45.60100","15.82013"
"91.40000","45.70108","15.85687"
"91.60000","45.80105","15.87852"
"91.80000","45.90096","15.91115"
"92.00000","46.00099","15.94093"
"92.20000","46.10102","15.97050"
"92.40000","46.20098","16.00607"
"92.60000","46.30107","16.04509"
"92.80000","46.40092","16.07113"
"93.00000","46.50101","16.09031"
"93.20000","46.60098","16.13093"
"93.40000","46.70101","16.17183"
"93.60000","46.80098","16.20254"
"93.80000","46.90100","16.23679"
"94.00000","47.00109","16.26147"
"94.20000","47.10106","16.28441"
"94.40000","47.20103","16.31353"
"94.60000","47.30106","16.34869"
"94.80000","47.40108","16.38197"
"95.00000","47.50117","16.41262"
"95.20000","47.60108","16.45407"
"95.40000","47.70098","16.48117"
"95.60000","47.80095","16.49922"
"95.80000","47.90105","16.52391"
"96.00000","48.00101","16.56564"
"96.20000","48.10116","16.60142"
"96.40000","48.20101","16.63876"
"96.60000","48.30098","16.66879"
"96.80000","48.40112","16.69356"
"97.00000","48.50109","16.71954"
"97.20000","48.60100","16.75114"
"97.40000","48.70109","16.78215"
"97.60000","48.80106","16.81393"
"97.80000","48.90102","16.85240"
"98.00000","49.00105","16.88688"
"98.20000","49.10096","16.91060"
"98.40000","49.20105","16.93201"
"98.60000","49.30107","16.97282"
"98.80000","49.40104","17.00657"
"99.00000","49.50101","17.03861"
"99.20000","49.60104","17.06773"
"99.40000","49.70107","17.09020"
"99.60000","49.80110","17.11387"
"99.80000","49.90107","17.14238"
"100.00000","50.00109","17.18444"
"100.20000","50.10106","17.21286"
"100.40000","50.20102","17.24898"
"100.60000","50.30105","17.29045"
"100.80000","50.40102","17.31239"
"101.00000","50.50111","17.32706"
"101.20000","50.60108","17.35001"
"101.40000","50.70111","17.38636"
"101.60000","50.80096","17.42583"
"101.80000","50.90104","17.46585"
"102.00000","51.00101","17.49860"
"102.20000","51.10110","17.52076"
"102.40000","51.20107","17.54297"
"102.60000","51.30103","17.57312"
"102.80000","51.40106","17.60417"
"103.00000","51.50109","17.62925"
"103.20000","51.60106","17.65849"
"103.40000","51.70109","17.69295"
"103.60000","51.80117","17.72098"
"103.80000","51.90096","17.74562"
"104.00000","52.00111","17.77657"
"104.20000","52.10096","17.81577"
"104.40000","52.20098","17.84783"
"104.60000","52.30107","17.88148"
"104.80000","52.40110","17.90623"
"105.00000","52.50101","17.92045"
"105.20000","52.60104","17.93648"
"105.40000","52.70107","17.97303"
"105.60000","52.80104","18.01670"
"105.80000","52.90100","18.04636"
"106.00000","53.00109","18.08123"
"106.20000","53.10118","18.12149"
"106.40000","53.20102","18.14373"
"106.60000","53.30099","18.15686"
"106.80000","53.40102","18.17793"
"107.00000","53.50099","18.20337"
"107.20000","53.60108","18.22964"
"107.40000","53.70110","18.26540"
"107.60000","53.80101","18.30026"
"107.80000","53.90110","18.33585"
"108.00000","54.00095","18.35156"
"108.20000","54.10104","18.38255"
"108.40000","54.20107","18.41605"
"108.60000","54.30109","18.44624"
"108.80000","54.40094","18.46889"
"109.00000","54.50103","18.49418"
"109.20000","54.60094","18.52231"
"109.40000","54.70097","18.54527"
"109.60000","54.80111","18.56928"
"109.80000","54.90102","18.60314"
"110.00000","55.00105","18.64275"
"110.20000","55.10108","18.67323"
"110.40000","55.20105","18.70635"
"110.60000","55.30108","18.73719"
"110.80000","55.40098","18.74968"
"111.00000","55.50101","18.76125"
"111.20000","55.60104","18.78291"
"111.40000","55.70107","18.81737"
"111.60000","55.80098","18.85342"
"111.80000","55.90100","18.88067"
"112.00000","56.00103","18.91683"
"112.20000","56.10106","18.95213"
"112.40000","56.20097","18.97471"
"112.60000","56.30117","18.99590"
"112.80000","56.40097","19.02119"
"113.00000","56.50117","19.04604"
"113.20000","56.60102","19.07003"
"113.40000","56.70105","19.10183"
"113.60000","56.80107","19.13229"
"113.80000","56.90105","19.16051"
"114.00000","57.00107","19.17160"
"114.20000","57.10098","19.20139"
"114.40000","57.20107","19.23930"
"114.60000","57.30104","19.27198"
"114.80000","57.40100","19.29525"
"115.00000","57.50097","19.32340"
"115.20000","57.60100","19.34425"
"115.40000","57.70115","19.36430"
"115.60000","57.80105","19.38324"
"115.80000","57.90096","19.41093"
"116.00000","58.00111","19.44573"
"116.20000","58.10108","19.47138"
"116.40000","58.20110","19.50158"
"116.60000","58.30107","19.54446"
"116.80000","58.40104","19.56962"
"117.00000","58.50107","19.58501"
"117.20000","58.60098","19.59808"
"117.40000","58.70100","19.62375"
"117.60000","58.80103","19.65008"
"117.80000","58.90112","19.68071"
"118.00000","59.00103","19.70980"
"118.20000","59.10100","19.74096"
"118.40000","59.20108","19.76928"
"118.60000","59.30111","19.78838"
"118.80000","59.40108","19.80802"
"119.00000","59.50117","19.84007"
"119.20000","59.60102","19.87026"
"119.40000","59.70105","19.89045"
"119.60000","59.80101","19.91677"
"119.80000","59.90104","19.94145"
"120.00000","60.00107","19.96814"
"120.20000","60.10098","19.98997"
"120.40000","60.20107","20.00348"
"120.60000","60.30109","20.02240"
"120.80000","60.40112","20.05955"
"121.00000","60.50097","20.09060"
"121.20000","60.60112","20.11832"
"121.40000","60.70103","20.14802"
"121.60000","60.80111","20.17196"
"121.80000","60.90102","20.18801"
"122.00000","61.00099","20.20526"
"122.20000","61.10107","20.22486"
"122.40000","61.20116","20.25735"
"122.60000","61.30096","20.28532"
"122.80000","61.40110","20.30416"
"123.00000","61.50107","20.33518"
"123.20000","61.60098","20.37043"
"123.40000","61.70101","20.39608"
"123.60000","61.80097","20.40923"
"123.80000","61.90112","20.42554"
"124.00000","62.00103","20.44526"
"124.20000","62.10112","20.47034"
"124.40000","62.20108","20.49609"
"124.60000","62.30111","20.52557"
"124.80000","62.40102","20.55344"
"125.00000","62.50098","20.58197"
"125.20000","62.60107","20.59890"
"125.40000","62.70116","20.61475"
"125.60000","62.80107","20.63331"
"125.80000","62.90104","20.66186"
"126.00000","63.00107","20.69097"
"126.20000","63.10097","20.71124"
"126.40000","63.20106","20.73590"
"126.60000","63.30109","20.75890"
"126.80000","63.40112","20.78594"
"127.00000","63.50109","20.80333"
"127.20000","63.60099","20.81436"
"127.40000","63.70097","20.83387"
"127.60000","63.80111","20.84906"
"127.80000","63.90102","20.87498"
"128.00000","64.00111","20.90711"
"128.20000","64.10102","20.93038"
"128.40000","64.20104","20.95662"
"128.60000","64.30090","20.98201"
"128.80000","64.40110","20.99811"
"129.00000","64.50107","21.01407"
"129.20000","64.60098","21.03071"
"129.40000","64.70107","21.04926"
"129.60000","64.80103","21.07472"
"129.80000","64.90100","21.10717"
"130.00000","65.00102","21.13101"
"130.20000","65.10112","21.15268"
"130.40000","65.20102","21.17476"
"130.60000","65.30106","21.20273"
"130.80000","65.40096","21.22738"
"131.00000","65.50105","21.23814"
"131.20000","65.60101","21.25173"
"131.40000","65.70104","21.26752"
"131.60000","65.80101","21.28709"
"131.80000","65.90092","21.30899"
"132.00000","66.00101","21.33482"
"132.20000","66.10104","21.36472"
"132.40000","66.20100","21.39639"
"132.60000","66.30097","21.42050"
"132.80000","66.40112","21.43362"
"133.00000","66.50097","21.44431"
"133.20000","66.60099","21.46830"
"133.40000","66.70103","21.48849"
"133.60000","66.80093","21.51326"
"133.80000","66.90108","21.53423"
"134.00000","67.00098","21.55396"
"134.20000","67.10096","21.56972"
"134.40000","67.20104","21.59125"
"134.60000","67.30096","21.61019"
"134.80000","67.40104","21.62982"
"135.00000","67.50107","21.64812"
"135.20000","67.60091","21.66781"
"135.40000","67.70113","21.68907"
"135.60000","67.80103","21.71073"
"135.80000","67.90100","21.73532"
"136.00000","68.00096","21.75872"
"136.20000","68.10100","21.78314"
"136.40000","68.20090","21.80795"
"136.60000","68.30105","21.82553"
"136.80000","68.40096","21.83923"
"137.00000","68.50099","21.84672"
"137.20000","68.60101","21.85335"
"137.40000","68.70098","21.87265"
"137.60000","68.80101","21.89543"
"137.80000","68.90104","21.92376"
"138.00000","69.00101","21.95139"
"138.20000","69.10104","21.97262"
"138.40000","69.20106","21.99672"
"138.60000","69.30103","22.01694"
"138.80000","69.40099","22.03701"
"139.00000","69.50097","22.05268"
"139.20000","69.60105","22.06790"
"139.40000","69.70097","22.08030"
"139.60000","69.80099","22.09729"
"139.80000","69.90108","22.11429"
"140.00000","70.00105","22.13313"
"140.20000","70.10114","22.14760"
"140.40000","70.20110","22.16705"
"140.60000","70.30101","22.18883"
"140.80000","70.40103","22.21298"
"141.00000","70.50113","22.23264"
"141.20000","70.60110","22.25510"
"141.40000","70.70107","22.26841"
"141.60000","70.80103","22.27962"
"141.80000","70.90106","22.29992"
"142.00000","71.00109","22.32444"
"142.20000","71.10105","22.35216"
"142.40000","71.20096","22.36978"
"142.60000","71.30105","22.38630"
"142.80000","71.40102","22.40110"
"143.00000","71.50098","22.41816"
"143.20000","71.60107","22.43285"
"143.40000","71.70104","22.44549"
"143.60000","71.80113","22.45708"
"143.80000","71.90110","22.47037"
"144.00000","72.00113","22.49014"
"144.20000","72.10110","22.50931"
"144.40000","72.20113","22.52987"
"144.60000","72.30097","22.55181"
"144.80000","72.40106","22.57309"
"145.00000","72.50097","22.59515"
"145.20000","72.60106","22.61635"
"145.40000","72.70102","22.63984"
"145.60000","72.80106","22.65773"
"145.80000","72.90108","22.67269"
"146.00000","73.00111","22.67868"
"146.20000","73.10114","22.68515"
"146.40000","73.20110","22.69463"
"146.60000","73.30107","22.70888"
"146.80000","73.40104","22.73116"
"147.00000","73.50112","22.75022"
"147.20000","73.60104","22.77008"
"147.40000","73.70100","22.79132"
"147.60000","73.80109","22.80902"
"147.80000","73.90100","22.83013"
"148.00000","74.00109","22.84770"
"148.20000","74.10105","22.86837"
"148.40000","74.20109","22.88493"
"148.60000","74.30099","22.89701"
"148.80000","74.40114","22.90892"
"149.00000","74.50105","22.92591"
"149.20000","74.60107","22.94238"
"149.40000","74.70098","22.95811"
"149.60000","74.80107","22.96913"
"149.80000","74.90104","22.98310"
"150.00000","75.00113","22.99705"
"150.20000","75.10104","23.01352"
"150.40000","75.20107","23.03486"
"150.60000","75.30097","23.05313"
"150.80000","75.40100","23.07092"
"151.00000","75.50102","23.08287"
"151.20000","75.60100","23.09179"
"151.40000","75.70108","23.09872"
"151.60000","75.80099","23.11311"
"151.80000","75.90102","23.14022"
"152.00000","76.00111","23.16176"
"152.20000","76.10114","23.18705"
"152.40000","76.20104","23.20096"
"152.60000","76.30107","23.21603"
"152.80000","76.40104","23.23186"
"153.00000","76.50101","23.24817"
"153.20000","76.60110","23.25966"
"153.40000","76.70112","23.27069"
"153.60000","76.80115","23.27908"
"153.80000","76.90105","23.28594"
"154.00000","77.00103","23.29815"
"154.20000","77.10105","23.30998"
"154.40000","77.20114","23.32381"
"154.60000","77.30105","23.34536"
"154.80000","77.40108","23.36558"
"155.00000","77.50111","23.37976"
"155.20000","77.60114","23.39116"
"155.40000","77.70104","23.40893"
"155.60000","77.80113","23.42518"
"155.80000","77.90104","23.44732"
"156.00000","78.00113","23.47046"
"156.20000","78.10103","23.48503"
"156.40000","78.20112","23.50056"
"156.60000","78.30103","23.51029"
"156.80000","78.40105","23.51592"
"157.00000","78.50109","23.52022"
"157.20000","78.60105","23.53143"
"157.40000","78.70115","23.54552"
"157.60000","78.80105","23.56052"
"157.80000","78.90102","23.57498"
"158.00000","79.00098","23.59316"
"158.20000","79.10107","23.60686"
"158.40000","79.20098","23.62358"
"158.60000","79.30113","23.64328"
"158.80000","79.40103","23.65729"
"159.00000","79.50101","23.67024"
"159.20000","79.60110","23.68360"
"159.40000","79.70113","23.69389"
"159.60000","79.80109","23.70379"
"159.80000","79.90100","23.71399"
"160.00000","80.00103","23.72816"
"160.20000","80.10105","23.74188"
"160.40000","80.20107","23.75860"
"160.60000","80.30099","23.77527"
"160.80000","80.40114","23.79604"
"161.00000","80.50111","23.80400"
"161.20000","80.60107","23.81437"
"161.40000","80.70098","23.82365"
"161.60000","80.80101","23.83800"
"161.80000","80.90104","23.85274"
"162.00000","81.00112","23.86941"
"162.20000","81.10103","23.88244"
"162.40000","81.20100","23.89453"
"162.60000","81.30103","23.90388"
"162.80000","81.40105","23.91293"
"163.00000","81.50102","23.92233"
"163.20000","81.60099","23.93292"
"163.40000","81.70113","23.94488"
"163.60000","81.80105","23.95657"
"163.80000","81.90102","23.97383"
"164.00000","82.00092","23.98899"
"164.20000","82.10096","24.00941"
"164.40000","82.20098","24.02133"
"164.60000","82.30106","24.03372"
"164.80000","82.40097","24.05009"
"165.00000","82.50107","24.06680"
"165.20000","82.60109","24.08424"
"165.40000","82.70107","24.09351"
"165.60000","82.80109","24.09970"
"165.80000","82.90105","24.11218"
"166.00000","83.00102","24.11599"
"166.20000","83.10099","24.12020"
"166.40000","83.20108","24.12889"
"166.60000","83.30093","24.13713"
"166.80000","83.40102","24.14973"
"167.00000","83.50105","24.16751"
"167.20000","83.60101","24.17954"
"167.40000","83.70110","24.19737"
"167.60000","83.80107","24.20693"
"167.80000","83.90098","24.22249"
"168.00000","84.00106","24.22987"
"168.20000","84.10097","24.24478"
"168.40000","84.20100","24.25974"
"168.60000","84.30103","24.27225"
"168.80000","84.40099","24.28869"
"169.00000","84.50097","24.30087"
"169.20000","84.60098","24.31206"
"169.40000","84.70103","24.32166"
"169.60000","84.80110","24.32697"
"169.80000","84.90102","24.33431"
"170.00000","85.00104","24.33916"
"170.20000","85.10090","24.35148"
"170.40000","85.20104","24.36007"
"170.60000","85.30101","24.37202"
"170.80000","85.40103","24.38409"
"171.00000","85.50101","24.39775"
"171.20000","85.60109","24.40538"
"171.40000","85.70106","24.41836"
"171.60000","85.80103","24.42783"
"171.80000","85.90099","24.44026"
"172.00000","86.00108","24.45004"
"172.20000","86.10100","24.46458"
"172.40000","86.20102","24.47890"
"172.60000","86.30093","24.49212"
"172.80000","86.40115","24.50447"
"173.00000","86.50105","24.51558"
"173.20000","86.60101","24.52109"
"173.40000","86.70110","24.52549"
"173.60000","86.80106","24.53067"
"173.80000","86.90104","24.53918"
"174.00000","87.00107","24.54948"
"174.20000","87.10103","24.55876"
"174.40000","87.20100","24.57088"
"174.60000","87.30103","24.58468"
"174.80000","87.40094","24.59554"
"175.00000","87.50108","24.61213"
"175.20000","87.60106","24.62038"
"175.40000","87.70101","24.63089"
"175.60000","87.80106","24.63971"
"175.80000","87.90107","24.64522"
"176.00000","88.00098","24.65970"
"176.20000","88.10107","24.67191"
"176.40000","88.20105","24.68492"
"176.60000","88.30101","24.69297"
"176.80000","88.40110","24.70504"
"177.00000","88.50106","24.71561"
"177.20000","88.60104","24.72368"
"177.40000","88.70107","24.73121"
"177.60000","88.80097","24.74020"
"177.80000","88.90105","24.74708"
"178.00000","89.00114","24.75687"
"178.20000","89.10099","24.76709"
"178.40000","89.20103","24.77658"
"178.60000","89.30099","24.78701"
"178.80000","89.40114","24.79818"
"179.00000","89.50111","24.81035"
"179.20000","89.60102","24.82101"
"179.40000","89.70097","24.83176"
"179.60000","89.80107","24.84545"
"179.80000","89.90110","24.85645"
"180.00000","90.00107","24.86504"
"180.20000","90.10109","24.87805"
"180.40000","90.20106","24.89005"
"180.60000","90.30108","24.90393"
"180.80000","90.40099","24.91376"
"181.00000","90.50097","24.92269"
"181.20000","90.60100","24.92335"
"181.40000","90.70107","24.93080"
"181.60000","90.80106","24.93405"
"181.80000","90.90114","24.93873"
"182.00000","91.00110","24.94587"
"182.20000","91.10107","24.94642"
"182.40000","91.20093","24.95816"
"182.60000","91.30101","24.96792"
"182.80000","91.40110","24.97989"
"183.00000","91.50107","24.99279"
"183.20000","91.60110","25.00445"
"183.40000","91.70112","25.01673"
"183.60000","91.80097","25.02881"
"183.80000","91.90105","25.03757"
"184.00000","92.00114","25.04846"
"184.20000","92.10099","25.05874"
"184.40000","92.20114","25.06791"
"184.60000","92.30104","25.07801"
"184.80000","92.40102","25.08913"
"185.00000","92.50105","25.09904"
"185.20000","92.60107","25.11061"
"185.40000","92.70110","25.11929"
"185.60000","92.80107","25.13029"
"185.80000","92.90098","25.13873"
"186.00000","93.00095","25.14902"
"186.20000","93.10108","25.15294"
"186.40000","93.20107","25.15998"
"186.60000","93.30102","25.16507"
"186.80000","93.40100","25.17192"
"187.00000","93.50108","25.18146"
"187.20000","93.60106","25.18969"
"187.40000","93.70108","25.19728"
"187.60000","93.80099","25.20560"
"187.80000","93.90108","25.21535"
"188.00000","94.00104","25.22286"
"188.20000","94.10089","25.22915"
"188.40000","94.20104","25.23955"
"188.60000","94.30102","25.24461"
"188.80000","94.40109","25.25602"
"189.00000","94.50107","25.26985"
"189.20000","94.60110","25.27935"
"189.40000","94.70106","25.29453"
"189.60000","94.80096","25.30729"
"189.80000","94.90106","25.31685"
"190.00000","95.00108","25.32914"
"190.20000","95.10106","25.34096"
"190.40000","95.20107","25.34729"
"190.60000","95.30105","25.35106"
"190.80000","95.40102","25.35771"
"191.00000","95.50093","25.36055"
"191.20000","95.60107","25.36695"
"191.40000","95.70099","25.37279"
"191.60000","95.80101","25.37779"
"191.80000","95.90104","25.38432"
"192.00000","96.00100","25.39695"
"192.20000","96.10109","25.40728"
"192.40000","96.20100","25.41757"
"192.60000","96.30103","25.42900"
"192.80000","96.40105","25.43861"
"193.00000","96.50115","25.45256"
"193.20000","96.60099","25.45869"
"193.40000","96.70109","25.46315"
"193.60000","96.80099","25.47271"
"193.80000","96.90096","25.47694"
"194.00000","97.00098","25.48404"
"194.20000","97.10096","25.49499"
"194.40000","97.20098","25.50218"
"194.60000","97.30101","25.51067"
"194.80000","97.40103","25.51873"
"195.00000","97.50106","25.52515"
"195.20000","97.60120","25.53261"
"195.40000","97.70112","25.53645"
"195.60000","97.80109","25.54319"
"195.80000","97.90106","25.54981"
"196.00000","98.00108","25.55522"
"196.20000","98.10105","25.56385"
"196.40000","98.20102","25.56821"
"196.60000","98.30106","25.57803"
"196.80000","98.40101","25.58094"
"197.00000","98.50105","25.59284"
"197.20000","98.60107","25.60383"
"197.40000","98.70110","25.61818"
"197.60000","98.80107","25.62519"
"197.80000","98.90103","25.63475"
"198.00000","99.00101","25.64337"
"198.20000","99.10103","25.65180"
"198.40000","99.20105","25.66137"
"198.60000","99.30120","25.66621"
"198.80000","99.40099","25.67803"
"199.00000","99.50109","25.68483"
"199.20000","99.60099","25.69697"
"199.40000","99.70108","25.70569"
"199.60000","99.80098","25.71774"
"199.80000","99.90102","25.72827"
"200.00000","100.00098","25.73854"
"200.20000","100.10101","25.74218"
"200.40000","100.20103","25.75690"
"200.60000","100.30106","25.75341"
"200.80000","100.40115","25.76300"
"201.00000","100.50112","25.76867"
"201.20000","100.60103","25.76924"
"201.40000","100.70100","25.77391"
"201.60000","100.80108","25.77513"
"201.80000","100.90099","25.77831"
"202.00000","101.00096","25.78308"
"202.20000","101.10106","25.78990"
"202.40000","101.20101","25.79845"
"202.60000","101.30104","25.80405"
"202.80000","101.40102","25.81532"
"203.00000","101.50098","25.82002"
"203.20000","101.60107","25.83119"
"203.40000","101.70110","25.83901"
"203.60000","101.80094","25.84823"
"203.80000","101.90103","25.86091"
"204.00000","102.00106","25.87015"
"204.20000","102.10097","25.88302"
"204.40000","102.20112","25.89553"
"204.60000","102.30109","25.90849"
"204.80000","102.40093","25.91444"
"205.00000","102.50108","25.92326"
"205.20000","102.60094","25.93112"
"205.40000","102.70107","25.94022"
"205.60000","102.80099","25.94794"
"205.80000","102.90096","25.95468"
"206.00000","103.00105","25.96153"
"206.20000","103.10101","25.97061"
"206.40000","103.20105","25.97535"
"206.60000","103.30100","25.97876"
"206.80000","103.40109","25.98625"
"207.00000","103.50101","25.98972"
"207.20000","103.60103","25.99872"
"207.40000","103.70100","26.00411"
"207.60000","103.80103","26.01033"
"207.80000","103.90106","26.01966"
"208.00000","104.00090","26.02891"
"208.20000","104.10104","26.03827"
"208.40000","104.20103","26.04786"
"208.60000","104.30111","26.05668"
"208.80000","104.40096","26.06058"
"209.00000","104.50104","26.06991"
"209.20000","104.60095","26.07059"
"209.40000","104.70098","26.07737"
"209.60000","104.80102","26.08358"
"209.80000","104.90115","26.08959"
"210.00000","105.00107","26.09943"
"210.20000","105.10103","26.10976"
"210.40000","105.20107","26.12190"
"210.60000","105.30103","26.13035"
"210.80000","105.40105","26.13966"
"211.00000","105.50108","26.14126"
"211.20000","105.60099","26.14855"
"211.40000","105.70101","26.15909"
"211.60000","105.80105","26.16867"
"211.80000","105.90107","26.17570"
"212.00000","106.00111","26.18395"
"212.20000","106.10101","26.18870"
"212.40000","106.20103","26.19681"
"212.60000","106.30107","26.20129"
"212.80000","106.40110","26.20754"
"213.00000","106.50095","26.21123"
"213.20000","106.60104","26.22308"
"213.40000","106.70111","26.23216"
"213.60000","106.80103","26.24452"
"213.80000","106.90112","26.25714"
"214.00000","107.00103","26.26926"
"214.20000","107.10111","26.28144"
"214.40000","107.20103","26.28725"
"214.60000","107.30104","26.28530"
"214.80000","107.40108","26.29625"
"215.00000","107.50111","26.30552"
"215.20000","107.60101","26.31479"
"215.40000","107.70104","26.32300"
"215.60000","107.80100","26.33317"
"215.80000","107.90109","26.34017"
"216.00000","108.00112","26.34941"
"216.20000","108.10104","26.35819"
"216.40000","108.20100","26.36264"
"216.60000","108.30103","26.36077"
"216.80000","108.40112","26.36718"
"217.00000","108.50108","26.36929"
"217.20000","108.60105","26.37443"
"217.40000","108.70107","26.37926"
"217.60000","108.80105","26.38554"
"217.80000","108.90101","26.38603"
"218.00000","109.00099","26.39815"
"218.20000","109.10101","26.39947"
"218.40000","109.20116","26.40639"
"218.60000","109.30106","26.41806"
"218.80000","109.40104","26.42929"
"219.00000","109.50095","26.43678"
"219.20000","109.60103","26.44994"
"219.40000","109.70107","26.46291"
"219.60000","109.80103","26.46853"
"219.80000","109.90105","26.46701"
"220.00000","110.00103","26.47833"
"220.20000","110.10111","26.49001"
"220.40000","110.20108","26.49998"
"220.60000","110.30105","26.50408"
"220.80000","110.40102","26.51841"
"221.00000","110.50111","26.52772"
"221.20000","110.60095","26.54051"
"221.40000","110.70104","26.54972"
"221.60000","110.80094","26.56017"
"221.80000","110.90099","26.56495"
"222.00000","111.00117","26.57622"
"222.20000","111.10104","26.58320"
"222.40000","111.20100","26.58289"
"222.60000","111.30103","26.59506"
"222.80000","111.40117","26.59236"
"223.00000","111.50103","26.59788"
"223.20000","111.60105","26.60275"
"223.40000","111.70103","26.60643"
"223.60000","111.80099","26.60776"
"223.80000","111.90113","26.61349"
"224.00000","112.00098","26.62011"
"224.20000","112.10102","26.62030"
"224.40000","112.20110","26.63274"
"224.60000","112.30107","26.63527"
"224.80000","112.40103","26.62826"
"225.00000","112.50112","26.63889"
"225.20000","112.60104","26.64523"
"225.40000","112.70113","26.65120"
"225.60000","112.80103","26.66093"
"225.80000","112.90106","26.66926"
"226.00000","113.00108","26.67620"
"226.20000","113.10112","26.68573"
"226.40000","113.20102","26.68639"
"226.60000","113.30099","26.69367"
"226.80000","113.40101","26.70718"
"227.00000","113.50117","26.71049"
"227.20000","113.60094","26.71856"
"227.40000","113.70103","26.72817"
"227.60000","113.80088","26.72983"
"227.80000","113.90109","26.74387"
"228.00000","114.00100","26.74935"
"228.20000","114.10098","26.75653"
"228.40000","114.20106","26.76849"
"228.60000","114.30109","26.77176"
"228.80000","114.40105","26.77988"
"229.00000","114.50097","26.77304"
"229.20000","114.60110","26.78247"
"229.40000","114.70102","26.78963"
"229.60000","114.80099","26.79605"
"229.80000","114.90107","26.80305"
"230.00000","115.00105","26.80877"
"230.20000","115.10113","26.81635"
"230.40000","115.20103","26.82343"
"230.60000","115.30101","26.82951"
"230.80000","115.40104","26.82899"
"231.00000","115.50106","26.83798"
"231.20000","115.60098","26.84449"
"231.40000","115.70112","26.85299"
"231.60000","115.80102","26.86175"
"231.80000","115.90100","26.86840"
"232.00000","116.00108","26.87794"
"232.20000","116.10106","26.88268"
"232.40000","116.20108","26.88751"
"232.60000","116.30105","26.90141"
"232.80000","116.40102","26.90218"
"233.00000","116.50104","26.90741"
"233.20000","116.60114","26.91356"
"233.40000","116.70097","26.90640"
"233.60000","116.80107","26.91102"
"233.80000","116.90103","26.91740"
"234.00000","117.00105","26.92543"
"234.20000","117.10104","26.92767"
"234.40000","117.20106","26.93764"
"234.60000","117.30097","26.94389"
"234.80000","117.40106","26.95216"
"235.00000","117.50096","26.95858"
"235.20000","117.60117","26.96719"
"235.40000","117.70107","26.97075"
"235.60000","117.80112","26.98164"
"235.80000","117.90101","26.98629"
"236.00000","118.00105","26.99174"
"236.20000","118.10107","26.99756"
"236.40000","118.20110","26.99655"
"236.60000","118.30106","27.00146"
"236.80000","118.40098","27.00702"
"237.00000","118.50107","27.01110"
"237.20000","118.60103","27.01536"
"237.40000","118.70100","27.01833"
"237.60000","118.80103","27.02241"
"237.80000","118.90112","27.02693"
"238.00000","119.00108","27.03119"
"238.20000","119.10104","27.04382"
"238.40000","119.20102","27.04397"
"238.60000","119.30111","27.05250"
"238.80000","119.40114","27.04640"
"239.00000","119.50105","27.05012"
"239.20000","119.60108","27.06100"
"239.40000","119.70103","27.06865"
"239.60000","119.80107","27.07963"
"239.80000","119.90097","27.08691"
"240.00000","120.00100","27.10270"
"240.20000","120.10109","27.10555"
"240.40000","120.20107","27.11334"
"240.60000","120.30103","27.12310"
"240.80000","120.40100","27.13103"
"241.00000","120.50096","27.13543"
"241.20000","120.60106","27.13604"
"241.40000","120.70113","27.14168"
"241.60000","120.80099","27.15081"
"241.80000","120.90108","27.15813"
"242.00000","121.00099","27.16513"
"242.20000","121.10095","27.17307"
"242.40000","121.20104","27.17484"
"242.60000","121.30107","27.17561"
"242.80000","121.40103","27.19040"
"243.00000","121.50106","27.18987"
"243.20000","121.60097","27.19683"
"243.40000","121.70094","27.19918"
"243.60000","121.80103","27.20011"
"243.80000","121.90111","27.20156"
"244.00000","122.00102","27.20294"
"244.20000","122.10104","27.20452"
"244.40000","122.20103","27.20594"
"244.60000","122.30110","27.20766"
"244.80000","122.40102","27.20658"
"245.00000","122.50098","27.21162"
"245.20000","122.60113","27.21170"
"245.40000","122.70104","27.21581"
"245.60000","122.80100","27.21935"
"245.80000","122.90104","27.22029"
"246.00000","123.00100","27.22763"
"246.20000","123.10103","27.23256"
"246.40000","123.20100","27.23644"
"246.60000","123.30096","27.23812"
"246.80000","123.40106","27.24159"
"247.00000","123.50097","27.24555"
"247.20000","123.60100","27.25257"
"247.40000","123.70113","27.25624"
"247.60000","123.80099","27.26315"
"247.80000","123.90101","27.26483"
"248.00000","124.00105","27.27155"
"248.20000","124.10101","27.27458"
"248.40000","124.20098","27.27681"
"248.60000","124.30106","27.28119"
"248.80000","124.40097","27.28627"
"249.00000","124.50100","27.28888"
"249.20000","124.60091","27.29483"
"249.40000","124.70100","27.29800"
"249.60000","124.80109","27.29642"
"249.80000","124.90099","27.29679"
"250.00000","125.00095","27.30709"
"250.20000","125.10104","27.30221"
"250.40000","125.20113","27.29962"
"250.60000","125.30097","27.30329"
"250.80000","125.40106","27.29771"
"251.00000","125.50098","27.28131"
"251.20000","125.60101","27.28114"
"251.40000","125.70110","27.27863"
"251.60000","125.80099","27.27513"
"251.80000","125.90097","27.26737"
"252.00000","126.00106","27.25983"
"252.20000","126.10103","27.24803"
"252.40000","126.20105","27.23640"
"252.60000","126.30108","27.22366"
"252.80000","126.40105","27.20705"
"253.00000","126.50102","27.18912"
"253.20000","126.60104","27.02654"
"253.25400","126.62807","26.74798"
"253.25800","126.63010","25.26957"
"253.26200","126.63214","21.84380"
"253.26600","126.63411","18.51004"
"253.27000","126.63603","15.87159"