File: MT-DataAnalysis-JupyterNotebook/TensionPlots/TensionTests/SpringLength/Specimen_RawData_8.csv
End date,"8/16/2018"
Specimen label,"D32L25N5d4"
Maximum Load,"23.68072",N
Extension at Maximum Load,"85.45108",mm
Maximum Slope (Automatic Young's),"0.40103",N/mm
Rate 1,"30.00000",mm/min

Time,Extension,Load
(s),(mm),(N)
"0.00000","0.00000","0.00406"
"0.20000","0.09004","0.03854"
"0.40000","0.20173","0.09489"
"0.60000","0.30128","0.14447"
"0.80000","0.40107","0.18291"
"1.00000","0.50098","0.20897"
"1.20000","0.60100","0.24964"
"1.40000","0.70097","0.29504"
"1.60000","0.80106","0.34083"
"1.80000","0.90103","0.38460"
"2.00000","1.00100","0.41793"
"2.20000","1.10108","0.45839"
"2.40000","1.20093","0.50005"
"2.60000","1.30096","0.55018"
"2.80000","1.40105","0.58905"
"3.00000","1.50114","0.61943"
"3.20000","1.60104","0.65470"
"3.40000","1.70113","0.70558"
"3.60000","1.80098","0.74845"
"3.80000","1.90101","0.78824"
"4.00000","2.00104","0.82144"
"4.20000","2.10100","0.86158"
"4.40000","2.20103","0.90599"
"4.60000","2.30100","0.94920"
"4.80000","2.40091","0.99745"
"5.00000","2.50106","1.02544"
"5.20000","2.60108","1.05944"
"5.40000","2.70105","1.10726"
"5.60000","2.80108","1.15511"
"5.80000","2.90105","1.19739"
"6.00000","3.00102","1.22952"
"6.20000","3.10104","1.26141"
"6.40000","3.20101","1.30495"
"6.60000","3.30104","1.34727"
"6.80000","3.40101","1.39190"
"7.00000","3.50104","1.43097"
"7.20000","3.60106","1.46642"
"7.40000","3.70103","1.51020"
"7.60000","3.80094","1.55269"
"7.80000","3.90109","1.58954"
"8.00000","4.00106","1.62611"
"8.20000","4.10102","1.66463"
"8.40000","4.20093","1.71139"
"8.60000","4.30102","1.75950"
"8.80000","4.40099","1.80326"
"9.00000","4.50108","1.83943"
"9.20000","4.60098","1.85788"
"9.40000","4.70101","1.89748"
"9.60000","4.80098","1.94388"
"9.80000","4.90101","1.99663"
"10.00000","5.00104","2.03943"
"10.20000","5.10094","2.07420"
"10.40000","5.20109","2.11498"
"10.60000","5.30106","2.14885"
"10.80000","5.40085","2.18956"
"11.00000","5.50088","2.23295"
"11.20000","5.60096","2.26975"
"11.40000","5.70099","2.31202"
"11.60000","5.80108","2.35960"
"11.80000","5.90099","2.40246"
"12.00000","6.00096","2.43889"
"12.20000","6.10104","2.45959"
"12.40000","6.20107","2.49994"
"12.60000","6.30092","2.55167"
"12.80000","6.40101","2.60046"
"13.00000","6.50098","2.64801"
"13.20000","6.60094","2.68187"
"13.40000","6.70097","2.70612"
"13.60000","6.80088","2.74283"
"13.80000","6.90097","2.78839"
"14.00000","7.00106","2.84002"
"14.20000","7.10096","2.88239"
"14.40000","7.20105","2.92024"
"14.60000","7.30108","2.96498"
"14.80000","7.40093","3.00089"
"15.00000","7.50114","3.03449"
"15.20000","7.60092","3.06758"
"15.40000","7.70101","3.10181"
"15.60000","7.80104","3.14856"
"15.80000","7.90101","3.19964"
"16.00000","8.00092","3.24867"
"16.20000","8.10094","3.28411"
"16.40000","8.20103","3.30328"
"16.60000","8.30100","3.34410"
"16.80000","8.40097","3.39257"
"17.00000","8.50099","3.44051"
"17.20000","8.60096","3.48581"
"17.40000","8.70099","3.51614"
"17.60000","8.80096","3.55502"
"17.80000","8.90093","3.59216"
"18.00000","9.00108","3.62897"
"18.20000","9.10104","3.67540"
"18.40000","9.20101","3.70715"
"18.60000","9.30092","3.75366"
"18.80000","9.40101","3.80339"
"19.00000","9.50104","3.84194"
"19.20000","9.60088","3.87703"
"19.40000","9.70097","3.90912"
"19.60000","9.80088","3.94420"
"19.80000","9.90115","3.98682"
"20.00000","10.00105","4.03709"
"20.20000","10.10102","4.08705"
"20.40000","10.20099","4.11684"
"20.60000","10.30102","4.14467"
"20.80000","10.40099","4.18907"
"21.00000","10.50107","4.23348"
"21.20000","10.60098","4.27723"
"21.40000","10.70095","4.31307"
"21.60000","10.80098","4.34675"
"21.80000","10.90089","4.38712"
"22.00000","11.00097","4.42853"
"22.20000","11.10100","4.47598"
"22.40000","11.20103","4.51752"
"22.60000","11.30100","4.54417"
"22.80000","11.40103","4.58752"
"23.00000","11.50088","4.63779"
"23.20000","11.60102","4.67820"
"23.40000","11.70105","4.71476"
"23.60000","11.80096","4.74212"
"23.80000","11.90105","4.78572"
"24.00000","12.00101","4.82812"
"24.20000","12.10098","4.86945"
"24.40000","12.20101","4.91788"
"24.60000","12.30086","4.94412"
"24.80000","12.40101","4.97251"
"25.00000","12.50110","5.02064"
"25.20000","12.60094","5.07393"
"25.40000","12.70103","5.11696"
"25.60000","12.80100","5.14819"
"25.80000","12.90109","5.18091"
"26.00000","13.00099","5.22378"
"26.20000","13.10102","5.26044"
"26.40000","13.20093","5.30976"
"26.60000","13.30102","5.34685"
"26.80000","13.40093","5.37975"
"27.00000","13.50102","5.42446"
"27.20000","13.60098","5.47062"
"27.40000","13.70101","5.51097"
"27.60000","13.80104","5.54033"
"27.80000","13.90095","5.56207"
"28.00000","14.00097","5.61982"
"28.20000","14.10100","5.66515"
"28.40000","14.20109","5.71088"
"28.60000","14.30100","5.75250"
"28.80000","14.40103","5.77601"
"29.00000","14.50100","5.80953"
"29.20000","14.60102","5.85153"
"29.40000","14.70093","5.89976"
"29.60000","14.80096","5.94576"
"29.80000","14.90111","5.98010"
"30.00000","15.00102","6.01722"
"30.20000","15.10104","6.05747"
"30.40000","15.20101","6.09204"
"30.60000","15.30092","6.13124"
"30.80000","15.40107","6.16866"
"31.00000","15.50109","6.20817"
"31.20000","15.60100","6.25798"
"31.40000","15.70109","6.30583"
"31.60000","15.80100","6.35103"
"31.80000","15.90097","6.37393"
"32.00000","16.00099","6.39545"
"32.20000","16.10108","6.44182"
"32.40000","16.20099","6.49279"
"32.60000","16.30102","6.54109"
"32.80000","16.40099","6.58388"
"33.00000","16.50089","6.61172"
"33.20000","16.60104","6.64542"
"33.40000","16.70101","6.68188"
"33.60000","16.80098","6.72529"
"33.80000","16.90095","6.77212"
"34.00000","17.00109","6.80321"
"34.20000","17.10100","6.84389"
"34.40000","17.20103","6.89550"
"34.60000","17.30100","6.93236"
"34.80000","17.40109","6.96681"
"35.00000","17.50100","6.99319"
"35.20000","17.60096","7.03168"
"35.40000","17.70099","7.08003"
"35.60000","17.80096","7.13154"
"35.80000","17.90099","7.18023"
"36.00000","18.00101","7.20752"
"36.20000","18.10104","7.23012"
"36.40000","18.20101","7.26933"
"36.60000","18.30098","7.31372"
"36.80000","18.40101","7.36065"
"37.00000","18.50109","7.40030"
"37.20000","18.60094","7.43963"
"37.40000","18.70109","7.48002"
"37.60000","18.80100","7.51632"
"37.80000","18.90097","7.55237"
"38.00000","19.00093","7.59373"
"38.20000","19.10096","7.62443"
"38.40000","19.20093","7.65945"
"38.60000","19.30096","7.71746"
"38.80000","19.40104","7.76076"
"39.00000","19.50089","7.79580"
"39.20000","19.60104","7.82341"
"39.40000","19.70095","7.85921"
"39.60000","19.80092","7.90346"
"39.80000","19.90106","7.94763"
"40.00000","20.00115","7.99804"
"40.20000","20.10100","8.03448"
"40.40000","20.20103","8.05557"
"40.60000","20.30100","8.09922"
"40.80000","20.40090","8.14038"
"41.00000","20.50099","8.18378"
"41.20000","20.60096","8.22236"
"41.40000","20.70105","8.25393"
"41.60000","20.80102","8.29643"
"41.80000","20.90086","8.34304"
"42.00000","21.00101","8.37605"
"42.20000","21.10110","8.42159"
"42.40000","21.20101","8.45175"
"42.60000","21.30104","8.48355"
"42.80000","21.40101","8.52820"
"43.00000","21.50103","8.57537"
"43.20000","21.60106","8.61806"
"43.40000","21.70109","8.64691"
"43.60000","21.80100","8.67975"
"43.80000","21.90096","8.72534"
"44.00000","22.00099","8.76731"
"44.20000","22.10102","8.81179"
"44.40000","22.20105","8.84834"
"44.60000","22.30102","8.87644"
"44.80000","22.40105","8.91196"
"45.00000","22.50095","8.95593"
"45.20000","22.60098","9.00645"
"45.40000","22.70101","9.04960"
"45.60000","22.80116","9.07467"
"45.80000","22.90101","9.11251"
"46.00000","23.00097","9.15556"
"46.20000","23.10100","9.19030"
"46.40000","23.20109","9.23312"
"46.60000","23.30094","9.26872"
"46.80000","23.40103","9.30021"
"47.00000","23.50099","9.34395"
"47.20000","23.60096","9.38954"
"47.40000","23.70099","9.43137"
"47.60000","23.80096","9.46435"
"47.80000","23.90111","9.48522"
"48.00000","24.00107","9.53173"
"48.20000","24.10092","9.58136"
"48.40000","24.20095","9.62771"
"48.60000","24.30110","9.66717"
"48.80000","24.40100","9.69545"
"49.00000","24.50097","9.72262"
"49.20000","24.60100","9.75918"
"49.40000","24.70097","9.80294"
"49.60000","24.80100","9.85988"
"49.80000","24.90097","9.88622"
"50.00000","25.00093","9.92041"
"50.20000","25.10102","9.96813"
"50.40000","25.20105","10.00541"
"50.60000","25.30090","10.04081"
"50.80000","25.40099","10.07388"
"51.00000","25.50101","10.10311"
"51.20000","25.60098","10.15288"
"51.40000","25.70095","10.19696"
"51.60000","25.80104","10.24379"
"51.80000","25.90095","10.28517"
"52.00000","26.00109","10.30276"
"52.20000","26.10094","10.32553"
"52.40000","26.20103","10.37565"
"52.60000","26.30094","10.42016"
"52.80000","26.40096","10.47297"
"53.00000","26.50099","10.50702"
"53.20000","26.60096","10.53996"
"53.40000","26.70093","10.57483"
"53.60000","26.80096","10.60973"
"53.80000","26.90105","10.64715"
"54.00000","27.00101","10.69654"
"54.20000","27.10092","10.72083"
"54.40000","27.20095","10.76613"
"54.60000","27.30098","10.80668"
"54.80000","27.40100","10.84940"
"55.00000","27.50091","10.88337"
"55.20000","27.60100","10.90703"
"55.40000","27.70097","10.93052"
"55.60000","27.80106","10.97998"
"55.80000","27.90096","11.02087"
"56.00000","28.00099","11.07352"
"56.20000","28.10096","11.11784"
"56.40000","28.20099","11.14121"
"56.60000","28.30096","11.16928"
"56.80000","28.40111","11.20932"
"57.00000","28.50101","11.25440"
"57.20000","28.60098","11.30249"
"57.40000","28.70101","11.33338"
"57.60000","28.80098","11.37032"
"57.80000","28.90101","11.41156"
"58.00000","29.00103","11.44577"
"58.20000","29.10094","11.48158"
"58.40000","29.20091","11.52045"
"58.60000","29.30100","11.54877"
"58.80000","29.40097","11.58626"
"59.00000","29.50105","11.63295"
"59.20000","29.60102","11.68204"
"59.40000","29.70105","11.72072"
"59.60000","29.80102","11.74205"
"59.80000","29.90104","11.76879"
"60.00000","30.00096","11.81614"
"60.20000","30.10098","11.85215"
"60.40000","30.20101","11.90005"
"60.60000","30.30104","11.94227"
"60.80000","30.40100","11.97169"
"61.00000","30.50097","12.00220"
"61.20000","30.60106","12.04231"
"61.40000","30.70103","12.08479"
"61.60000","30.80100","12.12678"
"61.80000","30.90102","12.15069"
"62.00000","31.00099","12.18469"
"62.20000","31.10096","12.23030"
"62.40000","31.20105","12.26982"
"62.60000","31.30090","12.31033"
"62.80000","31.40110","12.34404"
"63.00000","31.50101","12.37508"
"63.20000","31.60104","12.41179"
"63.40000","31.70095","12.45332"
"63.60000","31.80097","12.49992"
"63.80000","31.90094","12.54051"
"64.00000","32.00109","12.56658"
"64.20000","32.10106","12.58688"
"64.40000","32.20097","12.62978"
"64.60000","32.30099","12.67440"
"64.80000","32.40096","12.71407"
"65.00000","32.50105","12.75283"
"65.20000","32.60102","12.78206"
"65.40000","32.70117","12.81398"
"65.60000","32.80102","12.85185"
"65.80000","32.90099","12.89192"
"66.00000","33.00089","12.93821"
"66.20000","33.10098","12.97620"
"66.40000","33.20095","12.99886"
"66.60000","33.30098","13.03715"
"66.80000","33.40107","13.07829"
"67.00000","33.50097","13.11466"
"67.20000","33.60106","13.15113"
"67.40000","33.70103","13.18310"
"67.60000","33.80100","13.21319"
"67.80000","33.90102","13.25689"
"68.00000","34.00105","13.29918"
"68.20000","34.10090","13.33914"
"68.40000","34.20099","13.37541"
"68.60000","34.30090","13.39635"
"68.80000","34.40092","13.41920"
"69.00000","34.50107","13.46702"
"69.20000","34.60104","13.51346"
"69.40000","34.70095","13.55543"
"69.60000","34.80104","13.59419"
"69.80000","34.90100","13.61901"
"70.00000","35.00097","13.65272"
"70.20000","35.10100","13.68728"
"70.40000","35.20103","13.71831"
"70.60000","35.30094","13.76266"
"70.80000","35.40102","13.80479"
"71.00000","35.50093","13.82589"
"71.20000","35.60096","13.86968"
"71.40000","35.70105","13.90967"
"71.60000","35.80096","13.94580"
"71.80000","35.90104","13.97761"
"72.00000","36.00107","14.00181"
"72.20000","36.10098","14.03461"
"72.40000","36.20107","14.08742"
"72.60000","36.30091","14.12303"
"72.80000","36.40100","14.16575"
"73.00000","36.50097","14.20752"
"73.20000","36.60100","14.22745"
"73.40000","36.70103","14.24324"
"73.60000","36.80099","14.28076"
"73.80000","36.90102","14.31920"
"74.00000","37.00105","14.36811"
"74.20000","37.10096","14.40877"
"74.40000","37.20105","14.43793"
"74.60000","37.30101","14.47258"
"74.80000","37.40104","14.51098"
"75.00000","37.50095","14.53723"
"75.20000","37.60092","14.57194"
"75.40000","37.70101","14.60921"
"75.60000","37.80098","14.63708"
"75.80000","37.90100","14.67072"
"76.00000","38.00097","14.71666"
"76.20000","38.10106","14.75726"
"76.40000","38.20103","14.79667"
"76.60000","38.30093","14.81962"
"76.80000","38.40096","14.83747"
"77.00000","38.50105","14.87428"
"77.20000","38.60102","14.91414"
"77.40000","38.70105","14.95583"
"77.60000","38.80090","14.99663"
"77.80000","38.90098","15.04029"
"78.00000","39.00101","15.06328"
"78.20000","39.10098","15.08871"
"78.40000","39.20107","15.11747"
"78.60000","39.30098","15.15600"
"78.80000","39.40094","15.19748"
"79.00000","39.50103","15.22628"
"79.20000","39.60106","15.25657"
"79.40000","39.70096","15.29591"
"79.60000","39.80099","15.34198"
"79.80000","39.90102","15.37011"
"80.00000","40.00105","15.40207"
"80.20000","40.10102","15.43178"
"80.40000","40.20099","15.45532"
"80.60000","40.30101","15.48810"
"80.80000","40.40104","15.52584"
"81.00000","40.50095","15.56403"
"81.20000","40.60098","15.61425"
"81.40000","40.70101","15.64971"
"81.60000","40.80098","15.66636"
"81.80000","40.90107","15.68707"
"82.00000","41.00092","15.72789"
"82.20000","41.10112","15.76719"
"82.40000","41.20103","15.80024"
"82.60000","41.30099","15.84201"
"82.80000","41.40096","15.87024"
"83.00000","41.50111","15.90122"
"83.20000","41.60102","15.93111"
"83.40000","41.70111","15.96216"
"83.60000","41.80102","15.99817"
"83.80000","41.90092","16.03858"
"84.00000","42.00101","16.06503"
"84.20000","42.10092","16.09099"
"84.40000","42.20095","16.12582"
"84.60000","42.30097","16.17056"
"84.80000","42.40107","16.20418"
"85.00000","42.50103","16.23703"
"85.20000","42.60100","16.26384"
"85.40000","42.70103","16.28809"
"85.60000","42.80099","16.31860"
"85.80000","42.90102","16.35477"
"86.00000","43.00105","16.38616"
"86.20000","43.10102","16.42800"
"86.40000","43.20111","16.46771"
"86.60000","43.30102","16.48815"
"86.80000","43.40098","16.50875"
"87.00000","43.50095","16.54175"
"87.20000","43.60104","16.58230"
"87.40000","43.70107","16.61973"
"87.60000","43.80098","16.65408"
"87.80000","43.90094","16.68185"
"88.00000","44.00091","16.70915"
"88.20000","44.10112","16.73664"
"88.40000","44.20102","16.76815"
"88.60000","44.30106","16.79982"
"88.80000","44.40102","16.83678"
"89.00000","44.50099","16.87679"
"89.20000","44.60089","16.90411"
"89.40000","44.70105","16.92430"
"89.60000","44.80101","16.95768"
"89.80000","44.90092","16.99555"
"90.00000","45.00101","17.02807"
"90.20000","45.10092","17.05933"
"90.40000","45.20094","17.08235"
"90.60000","45.30098","17.10616"
"90.80000","45.40106","17.13506"
"91.00000","45.50097","17.17388"
"91.20000","45.60100","17.20625"
"91.40000","45.70091","17.24120"
"91.60000","45.80099","17.28204"
"91.80000","45.90096","17.30810"
"92.00000","46.00093","17.32399"
"92.20000","46.10102","17.34331"
"92.40000","46.20098","17.37885"
"92.60000","46.30096","17.41708"
"92.80000","46.40092","17.45618"
"93.00000","46.50095","17.49338"
"93.20000","46.60098","17.51533"
"93.40000","46.70089","17.53840"
"93.60000","46.80091","17.56560"
"93.80000","46.90100","17.59485"
"94.00000","47.00097","17.62018"
"94.20000","47.10094","17.64832"
"94.40000","47.20103","17.68440"
"94.60000","47.30099","17.71346"
"94.80000","47.40102","17.73945"
"95.00000","47.50099","17.77077"
"95.20000","47.60096","17.80338"
"95.40000","47.70098","17.83863"
"95.60000","47.80102","17.86893"
"95.80000","47.90086","17.89964"
"96.00000","48.00095","17.91659"
"96.20000","48.10098","17.93076"
"96.40000","48.20088","17.95322"
"96.60000","48.30098","17.99668"
"96.80000","48.40095","18.03650"
"97.00000","48.50092","18.06859"
"97.20000","48.60106","18.10221"
"97.40000","48.70097","18.12861"
"97.60000","48.80093","18.14939"
"97.80000","48.90096","18.17061"
"98.00000","49.00093","18.18848"
"98.20000","49.10096","18.21680"
"98.40000","49.20099","18.24894"
"98.60000","49.30096","18.28422"
"98.80000","49.40098","18.31641"
"99.00000","49.50107","18.34164"
"99.20000","49.60092","18.36404"
"99.40000","49.70095","18.39220"
"99.60000","49.80098","18.42518"
"99.80000","49.90107","18.45036"
"100.00000","50.00097","18.47382"
"100.20000","50.10100","18.50124"
"100.40000","50.20108","18.52631"
"100.60000","50.30105","18.54924"
"100.80000","50.40102","18.57137"
"101.00000","50.50099","18.60506"
"101.20000","50.60096","18.64071"
"101.40000","50.70098","18.67196"
"101.60000","50.80102","18.70479"
"101.80000","50.90099","18.73281"
"102.00000","51.00107","18.74712"
"102.20000","51.10098","18.75693"
"102.40000","51.20100","18.77419"
"102.60000","51.30097","18.80623"
"102.80000","51.40112","18.83949"
"103.00000","51.50103","18.86833"
"103.20000","51.60100","18.89974"
"103.40000","51.70103","18.93301"
"103.60000","51.80099","18.96267"
"103.80000","51.90102","18.97888"
"104.00000","52.00093","19.00070"
"104.20000","52.10102","19.02362"
"104.40000","52.20104","19.04873"
"104.60000","52.30095","19.07382"
"104.80000","52.40098","19.09924"
"105.00000","52.50107","19.13129"
"105.20000","52.60104","19.15089"
"105.40000","52.70107","19.17067"
"105.60000","52.80091","19.19441"
"105.80000","52.90106","19.22642"
"106.00000","53.00109","19.25648"
"106.20000","53.10094","19.28285"
"106.40000","53.20096","19.30608"
"106.60000","53.30099","19.33172"
"106.80000","53.40102","19.35003"
"107.00000","53.50105","19.36629"
"107.20000","53.60096","19.38459"
"107.40000","53.70105","19.40787"
"107.60000","53.80107","19.43851"
"107.80000","53.90098","19.46570"
"108.00000","54.00101","19.49131"
"108.20000","54.10098","19.52595"
"108.40000","54.20100","19.55367"
"108.60000","54.30097","19.58029"
"108.80000","54.40106","19.58739"
"109.00000","54.50097","19.60034"
"109.20000","54.60094","19.61882"
"109.40000","54.70108","19.64767"
"109.60000","54.80093","19.67493"
"109.80000","54.90102","19.70377"
"110.00000","55.00093","19.73009"
"110.20000","55.10101","19.75766"
"110.40000","55.20098","19.77645"
"110.60000","55.30113","19.79627"
"110.80000","55.40098","19.81503"
"111.00000","55.50101","19.84452"
"111.20000","55.60098","19.86857"
"111.40000","55.70101","19.88749"
"111.60000","55.80098","19.90777"
"111.80000","55.90094","19.93349"
"112.00000","56.00103","19.95684"
"112.20000","56.10100","19.97989"
"112.40000","56.20085","19.99302"
"112.60000","56.30100","20.00741"
"112.80000","56.40108","20.02839"
"113.00000","56.50105","20.05942"
"113.20000","56.60108","20.08582"
"113.40000","56.70093","20.10999"
"113.60000","56.80101","20.13718"
"113.80000","56.90105","20.15878"
"114.00000","57.00107","20.17682"
"114.20000","57.10104","20.19242"
"114.40000","57.20107","20.21079"
"114.60000","57.30098","20.22585"
"114.80000","57.40106","20.25526"
"115.00000","57.50097","20.28438"
"115.20000","57.60100","20.30181"
"115.40000","57.70109","20.32501"
"115.60000","57.80093","20.34887"
"115.80000","57.90102","20.37815"
"116.00000","58.00099","20.39539"
"116.20000","58.10108","20.41037"
"116.40000","58.20105","20.42225"
"116.60000","58.30107","20.44016"
"116.80000","58.40099","20.46118"
"117.00000","58.50107","20.48209"
"117.20000","58.60098","20.50523"
"117.40000","58.70100","20.52683"
"117.60000","58.80103","20.55277"
"117.80000","58.90100","20.57951"
"118.00000","59.00109","20.59322"
"118.20000","59.10094","20.60953"
"118.40000","59.20097","20.62339"
"118.60000","59.30105","20.64589"
"118.80000","59.40102","20.66797"
"119.00000","59.50099","20.68611"
"119.20000","59.60107","20.70865"
"119.40000","59.70098","20.72828"
"119.60000","59.80101","20.74798"
"119.80000","59.90110","20.77168"
"120.00000","60.00101","20.79500"
"120.20000","60.10104","20.81032"
"120.40000","60.20107","20.82625"
"120.60000","60.30098","20.84100"
"120.80000","60.40100","20.85566"
"121.00000","60.50097","20.88132"
"121.20000","60.60094","20.90482"
"121.40000","60.70109","20.92421"
"121.60000","60.80099","20.94449"
"121.80000","60.90090","20.96745"
"122.00000","61.00099","20.98988"
"122.20000","61.10107","21.00347"
"122.40000","61.20099","21.01389"
"122.60000","61.30101","21.02599"
"122.80000","61.40104","21.04090"
"123.00000","61.50107","21.06336"
"123.20000","61.60092","21.08570"
"123.40000","61.70089","21.11154"
"123.60000","61.80097","21.13243"
"123.80000","61.90094","21.14777"
"124.00000","62.00103","21.16565"
"124.20000","62.10100","21.18907"
"124.40000","62.20108","21.21405"
"124.60000","62.30099","21.22625"
"124.80000","62.40096","21.23685"
"125.00000","62.50092","21.24811"
"125.20000","62.60107","21.26080"
"125.40000","62.70104","21.27729"
"125.60000","62.80095","21.29031"
"125.80000","62.90092","21.30967"
"126.00000","63.00095","21.33223"
"126.20000","63.10091","21.35178"
"126.40000","63.20100","21.37785"
"126.60000","63.30097","21.40265"
"126.80000","63.40100","21.41480"
"127.00000","63.50103","21.43314"
"127.20000","63.60094","21.44453"
"127.40000","63.70103","21.45893"
"127.60000","63.80093","21.47345"
"127.80000","63.90102","21.49347"
"128.00000","64.00098","21.51328"
"128.20000","64.10102","21.52746"
"128.40000","64.20087","21.54424"
"128.60000","64.30096","21.55859"
"128.80000","64.40104","21.57343"
"129.00000","64.50095","21.58991"
"129.20000","64.60104","21.60620"
"129.40000","64.70100","21.62154"
"129.60000","64.80097","21.63597"
"129.80000","64.90100","21.65189"
"130.00000","65.00091","21.66693"
"130.20000","65.10100","21.68415"
"130.40000","65.20102","21.70090"
"130.60000","65.30099","21.71825"
"130.80000","65.40096","21.73833"
"131.00000","65.50093","21.75541"
"131.20000","65.60095","21.77413"
"131.40000","65.70104","21.79412"
"131.60000","65.80089","21.81209"
"131.80000","65.90104","21.83114"
"132.00000","66.00095","21.83487"
"132.20000","66.10110","21.84314"
"132.40000","66.20100","21.85013"
"132.60000","66.30091","21.85711"
"132.80000","66.40094","21.86712"
"133.00000","66.50097","21.88849"
"133.20000","66.60094","21.90886"
"133.40000","66.70097","21.93051"
"133.60000","66.80093","21.94908"
"133.80000","66.90102","21.96724"
"134.00000","67.00098","21.98679"
"134.20000","67.10096","22.00276"
"134.40000","67.20092","22.01792"
"134.60000","67.30101","22.03152"
"134.80000","67.40104","22.05113"
"135.00000","67.50095","22.05928"
"135.20000","67.60104","22.07036"
"135.40000","67.70094","22.07827"
"135.60000","67.80109","22.09254"
"135.80000","67.90100","22.10457"
"136.00000","68.00096","22.11682"
"136.20000","68.10100","22.12854"
"136.40000","68.20096","22.14115"
"136.60000","68.30093","22.15776"
"136.80000","68.40108","22.16812"
"137.00000","68.50093","22.18724"
"137.20000","68.60101","22.20430"
"137.40000","68.70110","22.21867"
"137.60000","68.80101","22.24110"
"137.80000","68.90098","22.25448"
"138.00000","69.00101","22.26192"
"138.20000","69.10104","22.27095"
"138.40000","69.20094","22.28419"
"138.60000","69.30103","22.29526"
"138.80000","69.40094","22.31675"
"139.00000","69.50097","22.33025"
"139.20000","69.60099","22.35325"
"139.40000","69.70090","22.35842"
"139.60000","69.80099","22.37742"
"139.80000","69.90102","22.39025"
"140.00000","70.00098","22.39975"
"140.20000","70.10095","22.41213"
"140.40000","70.20098","22.42410"
"140.60000","70.30107","22.43523"
"140.80000","70.40109","22.44279"
"141.00000","70.50095","22.45232"
"141.20000","70.60098","22.46075"
"141.40000","70.70107","22.47195"
"141.60000","70.80103","22.48092"
"141.80000","70.90100","22.49922"
"142.00000","71.00103","22.51029"
"142.20000","71.10100","22.52644"
"142.40000","71.20109","22.54080"
"142.60000","71.30099","22.55763"
"142.80000","71.40096","22.57036"
"143.00000","71.50098","22.58549"
"143.20000","71.60102","22.60172"
"143.40000","71.70110","22.61670"
"143.60000","71.80096","22.63137"
"143.80000","71.90116","22.64606"
"144.00000","72.00107","22.65759"
"144.20000","72.10104","22.66860"
"144.40000","72.20100","22.66777"
"144.60000","72.30109","22.68030"
"144.80000","72.40100","22.68414"
"145.00000","72.50102","22.69022"
"145.20000","72.60100","22.69915"
"145.40000","72.70090","22.70965"
"145.60000","72.80112","22.71770"
"145.80000","72.90102","22.73408"
"146.00000","73.00105","22.74714"
"146.20000","73.10101","22.75999"
"146.40000","73.20104","22.77472"
"146.60000","73.30095","22.78687"
"146.80000","73.40104","22.80059"
"147.00000","73.50101","22.81445"
"147.20000","73.60104","22.82659"
"147.40000","73.70107","22.83835"
"147.60000","73.80091","22.85212"
"147.80000","73.90100","22.86447"
"148.00000","74.00103","22.87366"
"148.20000","74.10099","22.88870"
"148.40000","74.20097","22.89487"
"148.60000","74.30093","22.90383"
"148.80000","74.40096","22.91148"
"149.00000","74.50098","22.92151"
"149.20000","74.60101","22.93308"
"149.40000","74.70098","22.94293"
"149.60000","74.80101","22.95422"
"149.80000","74.90115","22.96453"
"150.00000","75.00095","22.96990"
"150.20000","75.10098","22.97930"
"150.40000","75.20100","22.98410"
"150.60000","75.30103","22.99820"
"150.80000","75.40094","23.00775"
"151.00000","75.50096","23.02003"
"151.20000","75.60106","23.03133"
"151.40000","75.70090","23.04428"
"151.60000","75.80093","23.05567"
"151.80000","75.90102","23.06708"
"152.00000","76.00099","23.07490"
"152.20000","76.10101","23.08093"
"152.40000","76.20104","23.08945"
"152.60000","76.30101","23.09519"
"152.80000","76.40104","23.10019"
"153.00000","76.50095","23.11057"
"153.20000","76.60086","23.11678"
"153.40000","76.70100","23.13485"
"153.60000","76.80109","23.14927"
"153.80000","76.90088","23.16421"
"154.00000","77.00109","23.17780"
"154.20000","77.10099","23.18640"
"154.40000","77.20097","23.20048"
"154.60000","77.30105","23.20976"
"154.80000","77.40096","23.21746"
"155.00000","77.50098","23.22704"
"155.20000","77.60095","23.23528"
"155.40000","77.70098","23.24577"
"155.60000","77.80101","23.25147"
"155.80000","77.90098","23.26151"
"156.00000","78.00095","23.26890"
"156.20000","78.10098","23.27194"
"156.40000","78.20100","23.27710"
"156.60000","78.30096","23.28177"
"156.80000","78.40100","23.28646"
"157.00000","78.50102","23.29080"
"157.20000","78.60105","23.30079"
"157.40000","78.70096","23.30301"
"157.60000","78.80093","23.31000"
"157.80000","78.90102","23.32389"
"158.00000","79.00111","23.32949"
"158.20000","79.10095","23.33707"
"158.40000","79.20098","23.34825"
"158.60000","79.30096","23.35922"
"158.80000","79.40103","23.36927"
"159.00000","79.50101","23.38056"
"159.20000","79.60110","23.38332"
"159.40000","79.70100","23.39136"
"159.60000","79.80103","23.39607"
"159.80000","79.90093","23.40660"
"160.00000","80.00103","23.41487"
"160.20000","80.10100","23.41838"
"160.40000","80.20097","23.43182"
"160.60000","80.30093","23.44023"
"160.80000","80.40096","23.44997"
"161.00000","80.50105","23.46182"
"161.20000","80.60094","23.47042"
"161.40000","80.70104","23.47284"
"161.60000","80.80101","23.49162"
"161.80000","80.90099","23.49558"
"162.00000","81.00089","23.49653"
"162.20000","81.10103","23.50407"
"162.40000","81.20100","23.50818"
"162.60000","81.30103","23.51073"
"162.80000","81.40105","23.51297"
"163.00000","81.50090","23.51523"
"163.20000","81.60105","23.51722"
"163.40000","81.70103","23.52305"
"163.60000","81.80098","23.52785"
"163.80000","81.90096","23.53168"
"164.00000","82.00098","23.53425"
"164.20000","82.10084","23.54099"
"164.40000","82.20098","23.54686"
"164.60000","82.30095","23.55015"
"164.80000","82.40097","23.55875"
"165.00000","82.50101","23.56321"
"165.20000","82.60103","23.57022"
"165.40000","82.70100","23.57611"
"165.60000","82.80103","23.58095"
"165.80000","82.90100","23.58571"
"166.00000","83.00097","23.59362"
"166.20000","83.10099","23.59899"
"166.40000","83.20090","23.60357"
"166.60000","83.30099","23.60983"
"166.80000","83.40102","23.61210"
"167.00000","83.50093","23.62225"
"167.20000","83.60095","23.62528"
"167.40000","83.70093","23.62948"
"167.60000","83.80101","23.63729"
"167.80000","83.90098","23.64082"
"168.00000","84.00089","23.64708"
"168.20000","84.10097","23.65356"
"168.40000","84.20100","23.65782"
"168.60000","84.30090","23.66002"
"168.80000","84.40093","23.66684"
"169.00000","84.50097","23.66726"
"169.20000","84.60105","23.67123"
"169.40000","84.70103","23.67009"
"169.60000","84.80099","23.67596"
"169.80000","84.90090","23.67636"
"170.00000","85.00092","23.67693"
"170.20000","85.10095","23.67999"
"170.40000","85.20110","23.68050"
"170.60000","85.30095","23.68063"
"170.80000","85.40091","23.67898"
"171.00000","85.50101","23.68000"
"171.20000","85.60109","23.67867"
"171.40000","85.70100","23.67303"
"171.60000","85.80103","23.67223"
"171.80000","85.90099","23.67347"
"172.00000","86.00101","23.66640"
"172.20000","86.10100","23.66410"
"172.40000","86.20090","23.66117"
"172.60000","86.30105","23.65464"
"172.80000","86.40102","23.64449"
"173.00000","86.50098","23.63835"
"173.20000","86.60094","23.62623"
"173.40000","86.70098","23.61834"
"173.60000","86.80102","23.60591"
"173.80000","86.90104","23.59198"
"174.00000","87.00101","23.57853"
"174.20000","87.10098","23.56297"
"174.40000","87.20112","23.54439"
"174.60000","87.30103","23.52584"
"174.80000","87.40100","23.51527"
"175.00000","87.50097","23.49660"
"175.20000","87.60111","23.46360"
"175.40000","87.70108","23.41053"
"175.60000","87.80112","23.37211"
"175.80000","87.90096","23.32286"
"176.00000","88.00098","23.28359"
"176.20000","88.10095","23.25113"
"176.40000","88.20105","23.19100"
"176.60000","88.30101","23.11687"
"176.80000","88.40099","23.05666"
"177.00000","88.50101","22.97233"
"177.20000","88.60104","22.88795"
"177.40000","88.70107","22.77483"
"177.60000","88.80103","22.67693"
"177.80000","88.90112","22.54649"
"178.00000","89.00097","22.43390"
"178.20000","89.10105","22.33482"
"178.40000","89.20097","22.23819"
"178.60000","89.30099","22.15757"
"178.80000","89.40102","22.09297"
"179.00000","89.50104","22.04569"
"179.20000","89.60102","21.99350"
"179.40000","89.70104","21.94286"
"179.60000","89.80101","21.89709"
"179.80000","89.90098","21.87509"
"180.00000","90.00101","21.84687"
"180.20000","90.10104","21.83756"
"180.40000","90.20113","21.82015"
"180.60000","90.30090","21.80018"
"180.80000","90.40099","21.79171"
"181.00000","90.50101","21.77950"
"181.20000","90.60100","21.76648"
"181.40000","90.70095","21.75848"
"181.60000","90.80099","21.75011"
"181.80000","90.90096","21.74511"
"182.00000","91.00105","21.74499"
"182.20000","91.10101","21.74098"
"182.40000","91.20093","21.74000"
"182.60000","91.30106","21.74105"
"182.80000","91.40097","21.74427"
"183.00000","91.50089","21.74759"
"183.20000","91.60098","21.75228"
"183.40000","91.70094","21.75754"
"183.60000","91.80097","21.76194"
"183.80000","91.90105","21.76867"
"184.00000","92.00103","21.77395"
"184.20000","92.10099","21.78150"
"184.40000","92.20108","21.78497"
"184.60000","92.30099","21.79643"
"184.80000","92.40107","21.80148"
"185.00000","92.50098","21.80032"
"185.20000","92.60096","21.82154"
"185.40000","92.70098","21.82965"
"185.60000","92.80107","21.83305"
"185.80000","92.90092","21.83131"
"186.00000","93.00095","21.84317"
"186.20000","93.10103","21.84660"
"186.40000","93.20100","21.85597"
"186.60000","93.30097","21.86213"
"186.80000","93.40112","21.86161"
"187.00000","93.50095","21.88574"
"187.20000","93.60106","21.88427"
"187.40000","93.70089","21.89690"
"187.60000","93.80105","21.90920"
"187.80000","93.90095","21.92453"
"188.00000","94.00098","21.93880"
"188.20000","94.10094","21.95067"
"188.40000","94.20093","21.96613"
"188.60000","94.30102","21.97839"
"188.80000","94.40103","21.99264"
"189.00000","94.50094","22.00437"
"189.20000","94.60103","22.01558"
"189.40000","94.70100","22.02596"
"189.60000","94.80103","22.03931"
"189.80000","94.90099","22.04837"
"190.00000","95.00090","22.05527"
"190.20000","95.10106","22.06433"
"190.40000","95.20107","22.07084"
"190.60000","95.30105","22.07994"
"190.80000","95.40102","22.08857"
"191.00000","95.50093","22.09505"
"191.20000","95.60101","22.10315"
"191.40000","95.70099","22.11286"
"191.60000","95.80094","22.12158"
"191.80000","95.90092","22.13177"
"192.00000","96.00107","22.13850"
"192.20000","96.10109","22.14717"
"192.40000","96.20100","22.15531"
"192.60000","96.30103","22.16481"
"192.80000","96.40099","22.17229"
"193.00000","96.50108","22.18542"
"193.20000","96.60110","22.19585"
"193.40000","96.70097","22.20515"
"193.60000","96.80099","22.21206"
"193.80000","96.90102","22.22269"
"194.00000","97.00098","22.23444"
"194.20000","97.10107","22.24232"
"194.40000","97.20098","22.25000"
"194.60000","97.30101","22.25347"
"194.80000","97.40110","22.25864"
"195.00000","97.50106","22.25809"
"195.20000","97.60091","22.26650"
"195.40000","97.70107","22.26902"
"195.60000","97.80109","22.27437"
"195.80000","97.90106","22.27950"
"196.00000","98.00096","22.27570"
"196.20000","98.10099","22.27960"
"196.40000","98.20102","22.29147"
"196.60000","98.30106","22.28646"
"196.80000","98.40090","22.29117"
"197.00000","98.50105","22.29579"
"197.20000","98.60101","22.30040"
"197.40000","98.70104","22.30579"
"197.60000","98.80100","22.30482"
"197.80000","98.90098","22.31227"
"198.00000","99.00107","22.30997"
"198.20000","99.10098","22.30304"
"198.40000","99.20105","22.30779"
"198.60000","99.30103","22.29995"
"198.80000","99.40111","22.29863"
"199.00000","99.50097","22.30147"
"199.20000","99.60099","22.29368"
"199.40000","99.70103","22.29529"
"199.60000","99.80105","22.29190"
"199.80000","99.90102","22.29218"
"200.00000","100.00092","22.28908"
"200.20000","100.10095","22.28777"
"200.40000","100.20092","22.28472"
"200.60000","100.30106","22.28813"
"200.80000","100.40104","22.28795"
"201.00000","100.50112","22.28107"
"201.20000","100.60103","22.27887"
"201.40000","100.70094","22.27805"
"201.60000","100.80096","22.27421"
"201.80000","100.90105","22.27658"
"202.00000","101.00102","22.27476"
"202.20000","101.10099","22.27669"
"202.40000","101.20101","22.27314"
"202.60000","101.30099","22.27030"
"202.80000","101.40089","22.27073"
"203.00000","101.50098","22.26934"
"203.20000","101.60107","22.26894"
"203.40000","101.70098","22.26766"
"203.60000","101.80101","22.26612"
"203.80000","101.90098","22.26550"
"204.00000","102.00095","22.26141"
"204.20000","102.10097","22.25716"
"204.40000","102.20107","22.24731"
"204.60000","102.30103","22.24338"
"204.80000","102.40100","22.23788"
"205.00000","102.50091","22.21707"
"205.20000","102.60099","22.19778"
"205.40000","102.70097","22.16772"
"205.60000","102.80093","22.12241"
"205.76000","102.88098","21.93387"
"205.76400","102.88302","21.25198"
"205.76800","102.88499","19.57675"
"205.77200","102.88702","17.40039"
"205.77600","102.88900","14.93567"
"205.77800","102.89001","13.67078"