File: MT-DataAnalysis-JupyterNotebook/TensionPlots/TensionTests/SpringLength/Specimen_RawData_10.csv
End date,"8/16/2018"
Specimen label,"D32L65N5d4"
Maximum Load,"28.30387",N
Extension at Maximum Load,"115.45102",mm
Maximum Slope (Automatic Young's),"0.34484",N/mm
Rate 1,"30.00000",mm/min

Time,Extension,Load
(s),(mm),(N)
"0.00000","0.00000","0.01034"
"0.20000","0.09004","0.03974"
"0.40000","0.20161","0.08722"
"0.60000","0.30110","0.13185"
"0.80000","0.40101","0.16780"
"1.00000","0.50110","0.19337"
"1.20000","0.60094","0.21810"
"1.40000","0.70103","0.25535"
"1.60000","0.80100","0.29373"
"1.80000","0.90097","0.33041"
"2.00000","1.00100","0.36968"
"2.20000","1.10096","0.40212"
"2.40000","1.20093","0.43405"
"2.60000","1.30102","0.46803"
"2.80000","1.40099","0.50465"
"3.00000","1.50090","0.54609"
"3.20000","1.60104","0.58224"
"3.40000","1.70101","0.60770"
"3.60000","1.80092","0.63563"
"3.80000","1.90107","0.67431"
"4.00000","2.00104","0.71514"
"4.20000","2.10100","0.75015"
"4.40000","2.20091","0.78644"
"4.60000","2.30100","0.81179"
"4.80000","2.40097","0.84720"
"5.00000","2.50100","0.88375"
"5.20000","2.60090","0.91908"
"5.40000","2.70099","0.95890"
"5.60000","2.80102","0.99791"
"5.80000","2.90099","1.02096"
"6.00000","3.00102","1.04698"
"6.20000","3.10104","1.08465"
"6.40000","3.20107","1.12663"
"6.60000","3.30098","1.16884"
"6.80000","3.40101","1.20437"
"7.00000","3.50110","1.22963"
"7.20000","3.60100","1.25889"
"7.40000","3.70097","1.29411"
"7.60000","3.80106","1.32926"
"7.80000","3.90097","1.36766"
"8.00000","4.00106","1.40591"
"8.20000","4.10096","1.43575"
"8.40000","4.20099","1.46562"
"8.60000","4.30102","1.50170"
"8.80000","4.40105","1.54033"
"9.00000","4.50096","1.57581"
"9.20000","4.60104","1.60504"
"9.40000","4.70101","1.63512"
"9.60000","4.80110","1.66998"
"9.80000","4.90101","1.71058"
"10.00000","5.00098","1.75287"
"10.20000","5.10100","1.79189"
"10.40000","5.20103","1.82412"
"10.60000","5.30094","1.84559"
"10.80000","5.40097","1.87418"
"11.00000","5.50100","1.90198"
"11.20000","5.60090","1.94216"
"11.40000","5.70099","1.98936"
"11.60000","5.80096","2.02888"
"11.80000","5.90105","2.05868"
"12.00000","6.00108","2.08917"
"12.20000","6.10110","2.12249"
"12.40000","6.20095","2.15326"
"12.60000","6.30104","2.18955"
"12.80000","6.40101","2.22629"
"13.00000","6.50104","2.25880"
"13.20000","6.60100","2.29173"
"13.40000","6.70097","2.33120"
"13.60000","6.80106","2.37517"
"13.80000","6.90091","2.40851"
"14.00000","7.00094","2.43872"
"14.20000","7.10102","2.45569"
"14.40000","7.20111","2.48277"
"14.60000","7.30096","2.53084"
"14.80000","7.40099","2.57344"
"15.00000","7.50102","2.61268"
"15.20000","7.60098","2.65365"
"15.40000","7.70095","2.68067"
"15.60000","7.80104","2.70406"
"15.80000","7.90095","2.73070"
"16.00000","8.00103","2.76523"
"16.20000","8.10094","2.81239"
"16.40000","8.20103","2.84807"
"16.60000","8.30088","2.88431"
"16.80000","8.40097","2.91327"
"17.00000","8.50094","2.95944"
"17.20000","8.60090","2.98998"
"17.40000","8.70105","3.01894"
"17.60000","8.80096","3.04976"
"17.80000","8.90099","3.07687"
"18.00000","9.00102","3.10672"
"18.20000","9.10104","3.14833"
"18.40000","9.20095","3.19522"
"18.60000","9.30098","3.23545"
"18.80000","9.40101","3.27233"
"19.00000","9.50098","3.29071"
"19.20000","9.60100","3.31496"
"19.40000","9.70103","3.35260"
"19.60000","9.80106","3.39416"
"19.80000","9.90097","3.43441"
"20.00000","10.00093","3.47603"
"20.20000","10.10096","3.50694"
"20.40000","10.20105","3.53271"
"20.60000","10.30096","3.56482"
"20.80000","10.40111","3.60040"
"21.00000","10.50101","3.63647"
"21.20000","10.60104","3.67192"
"21.40000","10.70101","3.70052"
"21.60000","10.80098","3.73596"
"21.80000","10.90101","3.77782"
"22.00000","11.00103","3.82116"
"22.20000","11.10094","3.85206"
"22.40000","11.20097","3.88250"
"22.60000","11.30106","3.90753"
"22.80000","11.40097","3.93571"
"23.00000","11.50105","3.97430"
"23.20000","11.60102","4.01583"
"23.40000","11.70105","4.05829"
"23.60000","11.80102","4.09891"
"23.80000","11.90105","4.11933"
"24.00000","12.00101","4.14453"
"24.20000","12.10098","4.18321"
"24.40000","12.20101","4.22286"
"24.60000","12.30104","4.26104"
"24.80000","12.40101","4.29441"
"25.00000","12.50091","4.32444"
"25.20000","12.60100","4.35215"
"25.40000","12.70097","4.39305"
"25.60000","12.80106","4.42654"
"25.80000","12.90097","4.46666"
"26.00000","13.00099","4.50570"
"26.20000","13.10102","4.52997"
"26.40000","13.20105","4.55973"
"26.60000","13.30084","4.60025"
"26.80000","13.40111","4.64048"
"27.00000","13.50102","4.67597"
"27.20000","13.60104","4.70938"
"27.40000","13.70101","4.73821"
"27.60000","13.80098","4.76769"
"27.80000","13.90095","4.80487"
"28.00000","14.00103","4.84409"
"28.20000","14.10100","4.88022"
"28.40000","14.20097","4.92123"
"28.60000","14.30100","4.94229"
"28.80000","14.40097","4.97226"
"29.00000","14.50105","5.01008"
"29.20000","14.60096","5.05091"
"29.40000","14.70111","5.09235"
"29.60000","14.80102","5.12839"
"29.80000","14.90093","5.15275"
"30.00000","15.00090","5.18143"
"30.20000","15.10098","5.21720"
"30.40000","15.20095","5.25389"
"30.60000","15.30104","5.29053"
"30.80000","15.40095","5.33037"
"31.00000","15.50092","5.35887"
"31.20000","15.60106","5.39051"
"31.40000","15.70097","5.43094"
"31.60000","15.80094","5.47033"
"31.80000","15.90097","5.50494"
"32.00000","16.00105","5.53547"
"32.20000","16.10096","5.55426"
"32.40000","16.20099","5.59020"
"32.60000","16.30090","5.63465"
"32.80000","16.40093","5.67557"
"33.00000","16.50101","5.71487"
"33.20000","16.60098","5.75004"
"33.40000","16.70101","5.77099"
"33.60000","16.80104","5.79928"
"33.80000","16.90089","5.83419"
"34.00000","17.00103","5.86860"
"34.20000","17.10094","5.92400"
"34.40000","17.20097","5.95286"
"34.60000","17.30100","5.98180"
"34.80000","17.40103","6.01395"
"35.00000","17.50093","6.05167"
"35.20000","17.60090","6.08053"
"35.40000","17.70099","6.11376"
"35.60000","17.80102","6.14905"
"35.80000","17.90099","6.17989"
"36.00000","18.00101","6.21775"
"36.20000","18.10092","6.25863"
"36.40000","18.20101","6.29999"
"36.60000","18.30092","6.33926"
"36.80000","18.40107","6.36893"
"37.00000","18.50097","6.38469"
"37.20000","18.60094","6.40991"
"37.40000","18.70103","6.45346"
"37.60000","18.80100","6.49768"
"37.80000","18.90097","6.53894"
"38.00000","19.00105","6.57206"
"38.20000","19.10090","6.60592"
"38.40000","19.20099","6.63447"
"38.60000","19.30096","6.66552"
"38.80000","19.40111","6.69887"
"39.00000","19.50101","6.74311"
"39.20000","19.60092","6.77549"
"39.40000","19.70101","6.80465"
"39.60000","19.80098","6.83864"
"39.80000","19.90106","6.88490"
"40.00000","20.00103","6.92092"
"40.20000","20.10100","6.94894"
"40.40000","20.20103","6.97589"
"40.60000","20.30094","7.00046"
"40.80000","20.40090","7.03626"
"41.00000","20.50099","7.07937"
"41.20000","20.60102","7.12436"
"41.40000","20.70105","7.16820"
"41.60000","20.80096","7.20289"
"41.80000","20.90105","7.21727"
"42.00000","21.00095","7.24472"
"42.20000","21.10098","7.28101"
"42.40000","21.20107","7.32338"
"42.60000","21.30092","7.36028"
"42.80000","21.40095","7.40076"
"43.00000","21.50097","7.43129"
"43.20000","21.60100","7.46509"
"43.40000","21.70103","7.50036"
"43.60000","21.80094","7.53233"
"43.80000","21.90096","7.56979"
"44.00000","22.00105","7.60308"
"44.20000","22.10096","7.63107"
"44.40000","22.20099","7.66239"
"44.60000","22.30102","7.70494"
"44.80000","22.40105","7.74619"
"45.00000","22.50101","7.78527"
"45.20000","22.60098","7.81093"
"45.40000","22.70095","7.83879"
"45.60000","22.80098","7.86878"
"45.80000","22.90112","7.90759"
"46.00000","23.00097","7.94868"
"46.20000","23.10112","7.98777"
"46.40000","23.20103","8.02500"
"46.60000","23.30100","8.04831"
"46.80000","23.40097","8.07662"
"47.00000","23.50099","8.11294"
"47.20000","23.60102","8.15227"
"47.40000","23.70111","8.19010"
"47.60000","23.80102","8.22318"
"47.80000","23.90099","8.25611"
"48.00000","24.00107","8.28889"
"48.20000","24.10092","8.32552"
"48.40000","24.20095","8.36463"
"48.60000","24.30098","8.39875"
"48.80000","24.40107","8.43141"
"49.00000","24.50109","8.45652"
"49.20000","24.60106","8.48946"
"49.40000","24.70103","8.52919"
"49.60000","24.80094","8.56929"
"49.80000","24.90103","8.60697"
"50.00000","25.00105","8.63846"
"50.20000","25.10096","8.65936"
"50.40000","25.20105","8.69948"
"50.60000","25.30096","8.74045"
"50.80000","25.40093","8.77713"
"51.00000","25.50101","8.81763"
"51.20000","25.60098","8.84919"
"51.40000","25.70101","8.87345"
"51.60000","25.80110","8.90497"
"51.80000","25.90095","8.94329"
"52.00000","26.00092","8.98403"
"52.20000","26.10106","9.02561"
"52.40000","26.20097","9.05602"
"52.60000","26.30100","9.08265"
"52.80000","26.40102","9.11574"
"53.00000","26.50105","9.15214"
"53.20000","26.60096","9.18732"
"53.40000","26.70099","9.22078"
"53.60000","26.80096","9.25250"
"53.80000","26.90098","9.28997"
"54.00000","27.00101","9.32442"
"54.20000","27.10086","9.35982"
"54.40000","27.20101","9.39884"
"54.60000","27.30098","9.43011"
"54.80000","27.40100","9.46232"
"55.00000","27.50097","9.48874"
"55.20000","27.60100","9.52662"
"55.40000","27.70097","9.56963"
"55.60000","27.80100","9.60910"
"55.80000","27.90103","9.64982"
"56.00000","28.00105","9.68140"
"56.20000","28.10102","9.70333"
"56.40000","28.20093","9.72920"
"56.60000","28.30096","9.76311"
"56.80000","28.40092","9.79671"
"57.00000","28.50089","9.84501"
"57.20000","28.60092","9.88317"
"57.40000","28.70095","9.90677"
"57.60000","28.80092","9.94556"
"57.80000","28.90101","9.98740"
"58.00000","29.00097","10.01845"
"58.20000","29.10100","10.05040"
"58.40000","29.20097","10.07814"
"58.60000","29.30094","10.10473"
"58.80000","29.40102","10.14946"
"59.00000","29.50099","10.18961"
"59.20000","29.60090","10.23061"
"59.40000","29.70099","10.27112"
"59.60000","29.80096","10.29542"
"59.80000","29.90087","10.31281"
"60.00000","30.00096","10.34432"
"60.20000","30.10092","10.38739"
"60.40000","30.20095","10.42489"
"60.60000","30.30092","10.46781"
"60.80000","30.40100","10.50453"
"61.00000","30.50097","10.53437"
"61.20000","30.60112","10.56509"
"61.40000","30.70097","10.59535"
"61.60000","30.80106","10.62463"
"61.80000","30.90091","10.66975"
"62.00000","31.00093","10.70380"
"62.20000","31.10096","10.73215"
"62.40000","31.20093","10.77122"
"62.60000","31.30095","10.81624"
"62.80000","31.40098","10.85244"
"63.00000","31.50107","10.88476"
"63.20000","31.60104","10.90559"
"63.40000","31.70101","10.92935"
"63.60000","31.80097","10.96465"
"63.80000","31.90106","11.00475"
"64.00000","32.00091","11.04660"
"64.20000","32.10100","11.09518"
"64.40000","32.20109","11.12554"
"64.60000","32.30106","11.14456"
"64.80000","32.40090","11.17300"
"65.00000","32.50099","11.20961"
"65.20000","32.60096","11.25029"
"65.40000","32.70093","11.29582"
"65.60000","32.80096","11.32478"
"65.80000","32.90099","11.35537"
"66.00000","33.00101","11.39235"
"66.20000","33.10098","11.42640"
"66.40000","33.20095","11.45380"
"66.60000","33.30104","11.49365"
"66.80000","33.40107","11.52589"
"67.00000","33.50103","11.54967"
"67.20000","33.60094","11.58433"
"67.40000","33.70097","11.62582"
"67.60000","33.80100","11.67259"
"67.80000","33.90097","11.70779"
"68.00000","34.00093","11.73310"
"68.20000","34.10102","11.75579"
"68.40000","34.20093","11.78576"
"68.60000","34.30102","11.82846"
"68.80000","34.40099","11.86528"
"69.00000","34.50101","11.90837"
"69.20000","34.60104","11.94385"
"69.40000","34.70107","11.97140"
"69.60000","34.80086","11.99907"
"69.80000","34.90100","12.03537"
"70.00000","35.00103","12.07215"
"70.20000","35.10094","12.10887"
"70.40000","35.20097","12.13894"
"70.60000","35.30099","12.16199"
"70.80000","35.40091","12.20241"
"71.00000","35.50105","12.24359"
"71.20000","35.60090","12.27829"
"71.40000","35.70099","12.31266"
"71.60000","35.80101","12.34719"
"71.80000","35.90092","12.37304"
"72.00000","36.00101","12.40597"
"72.20000","36.10098","12.44380"
"72.40000","36.20095","12.48307"
"72.60000","36.30098","12.52429"
"72.80000","36.40100","12.55453"
"73.00000","36.50103","12.57630"
"73.20000","36.60094","12.60493"
"73.40000","36.70103","12.64617"
"73.60000","36.80094","12.68326"
"73.80000","36.90102","12.72023"
"74.00000","37.00093","12.75559"
"74.20000","37.10102","12.78407"
"74.40000","37.20099","12.81439"
"74.60000","37.30114","12.84692"
"74.80000","37.40092","12.88380"
"75.00000","37.50095","12.92534"
"75.20000","37.60098","12.96628"
"75.40000","37.70101","12.98790"
"75.60000","37.80098","13.01529"
"75.80000","37.90100","13.05363"
"76.00000","38.00109","13.09111"
"76.20000","38.10094","13.12061"
"76.40000","38.20097","13.15364"
"76.60000","38.30099","13.18451"
"76.80000","38.40102","13.21246"
"77.00000","38.50105","13.25250"
"77.20000","38.60108","13.29127"
"77.40000","38.70098","13.33001"
"77.60000","38.80096","13.37009"
"77.80000","38.90104","13.38837"
"78.00000","39.00101","13.40652"
"78.20000","39.10098","13.43994"
"78.40000","39.20101","13.48907"
"78.60000","39.30109","13.52914"
"78.80000","39.40100","13.57104"
"79.00000","39.50097","13.59945"
"79.20000","39.60099","13.62655"
"79.40000","39.70109","13.65765"
"79.60000","39.80099","13.69028"
"79.80000","39.90108","13.71993"
"80.00000","40.00099","13.76302"
"80.20000","40.10108","13.80126"
"80.40000","40.20105","13.82706"
"80.60000","40.30101","13.85943"
"80.80000","40.40098","13.89796"
"81.00000","40.50107","13.93492"
"81.20000","40.60092","13.96591"
"81.40000","40.70101","13.99155"
"81.60000","40.80104","14.01785"
"81.80000","40.90095","14.05508"
"82.00000","41.00103","14.09830"
"82.20000","41.10100","14.13712"
"82.40000","41.20103","14.18231"
"82.60000","41.30099","14.21279"
"82.80000","41.40115","14.23032"
"83.00000","41.50105","14.24857"
"83.20000","41.60108","14.28439"
"83.40000","41.70099","14.32052"
"83.60000","41.80102","14.36657"
"83.80000","41.90110","14.40905"
"84.00000","42.00095","14.43123"
"84.20000","42.10110","14.46437"
"84.40000","42.20107","14.49774"
"84.60000","42.30097","14.52838"
"84.80000","42.40094","14.55874"
"85.00000","42.50103","14.59218"
"85.20000","42.60094","14.62302"
"85.40000","42.70103","14.64899"
"85.60000","42.80106","14.69102"
"85.80000","42.90102","14.73526"
"86.00000","43.00093","14.77016"
"86.20000","43.10108","14.80571"
"86.40000","43.20105","14.82729"
"86.60000","43.30102","14.84225"
"86.80000","43.40098","14.88000"
"87.00000","43.50107","14.92158"
"87.20000","43.60086","14.95625"
"87.40000","43.70095","15.00589"
"87.60000","43.80098","15.03982"
"87.80000","43.90094","15.06270"
"88.00000","44.00103","15.08321"
"88.20000","44.10100","15.11548"
"88.40000","44.20102","15.14762"
"88.60000","44.30099","15.18983"
"88.80000","44.40108","15.22623"
"89.00000","44.50093","15.24849"
"89.20000","44.60102","15.28155"
"89.40000","44.70099","15.32911"
"89.60000","44.80096","15.36059"
"89.80000","44.90098","15.39100"
"90.00000","45.00095","15.42113"
"90.20000","45.10092","15.44657"
"90.40000","45.20100","15.47343"
"90.60000","45.30091","15.50775"
"90.80000","45.40100","15.54567"
"91.00000","45.50115","15.58727"
"91.20000","45.60094","15.63432"
"91.40000","45.70103","15.65762"
"91.60000","45.80093","15.67245"
"91.80000","45.90096","15.70020"
"92.00000","46.00105","15.74097"
"92.20000","46.10108","15.77823"
"92.40000","46.20092","15.81460"
"92.60000","46.30096","15.85148"
"92.80000","46.40098","15.87798"
"93.00000","46.50101","15.90675"
"93.20000","46.60092","15.93750"
"93.40000","46.70095","15.96767"
"93.60000","46.80091","16.00150"
"93.80000","46.90100","16.04580"
"94.00000","47.00091","16.07039"
"94.20000","47.10094","16.09517"
"94.40000","47.20108","16.13285"
"94.60000","47.30099","16.17318"
"94.80000","47.40096","16.20870"
"95.00000","47.50093","16.23984"
"95.20000","47.60101","16.26507"
"95.40000","47.70105","16.29283"
"95.60000","47.80095","16.32189"
"95.80000","47.90098","16.35863"
"96.00000","48.00095","16.38889"
"96.20000","48.10110","16.43450"
"96.40000","48.20101","16.46926"
"96.60000","48.30098","16.49017"
"96.80000","48.40100","16.50942"
"97.00000","48.50097","16.54402"
"97.20000","48.60088","16.58505"
"97.40000","48.70103","16.62308"
"97.60000","48.80093","16.65650"
"97.80000","48.90096","16.68408"
"98.00000","49.00099","16.71038"
"98.20000","49.10102","16.74014"
"98.40000","49.20093","16.77181"
"98.60000","49.30101","16.80565"
"98.80000","49.40098","16.84307"
"99.00000","49.50101","16.88306"
"99.20000","49.60104","16.90749"
"99.40000","49.70089","16.92870"
"99.60000","49.80104","16.96679"
"99.80000","49.90100","17.00404"
"100.00000","50.00097","17.03546"
"100.20000","50.10094","17.06635"
"100.40000","50.20097","17.08979"
"100.60000","50.30094","17.11618"
"100.80000","50.40102","17.15129"
"101.00000","50.50087","17.18841"
"101.20000","50.60108","17.21687"
"101.40000","50.70111","17.26064"
"101.60000","50.80096","17.29875"
"101.80000","50.90099","17.31748"
"102.00000","51.00095","17.33246"
"102.20000","51.10104","17.36478"
"102.40000","51.20107","17.40906"
"102.60000","51.30109","17.44886"
"102.80000","51.40094","17.48135"
"103.00000","51.50097","17.51352"
"103.20000","51.60088","17.53490"
"103.40000","51.70097","17.56357"
"103.60000","51.80099","17.59786"
"103.80000","51.90102","17.62126"
"104.00000","52.00099","17.65139"
"104.20000","52.10096","17.68865"
"104.40000","52.20098","17.72321"
"104.60000","52.30101","17.74596"
"104.80000","52.40104","17.77818"
"105.00000","52.50101","17.82004"
"105.20000","52.60104","17.85348"
"105.40000","52.70107","17.88638"
"105.60000","52.80098","17.90784"
"105.80000","52.90094","17.92619"
"106.00000","53.00097","17.94689"
"106.20000","53.10106","17.99015"
"106.40000","53.20102","18.03315"
"106.60000","53.30093","18.06482"
"106.80000","53.40102","18.10384"
"107.00000","53.50093","18.13567"
"107.20000","53.60102","18.15297"
"107.40000","53.70110","18.17281"
"107.60000","53.80096","18.20092"
"107.80000","53.90110","18.23167"
"108.00000","54.00101","18.26610"
"108.20000","54.10098","18.30890"
"108.40000","54.20100","18.33736"
"108.60000","54.30109","18.36176"
"108.80000","54.40100","18.39160"
"109.00000","54.50103","18.43131"
"109.20000","54.60100","18.45590"
"109.40000","54.70090","18.48292"
"109.60000","54.80099","18.51395"
"109.80000","54.90096","18.53914"
"110.00000","55.00099","18.56432"
"110.20000","55.10096","18.60175"
"110.40000","55.20105","18.64044"
"110.60000","55.30101","18.67523"
"110.80000","55.40098","18.70922"
"111.00000","55.50095","18.73836"
"111.20000","55.60104","18.75242"
"111.40000","55.70101","18.76601"
"111.60000","55.80091","18.79854"
"111.80000","55.90094","18.83914"
"112.00000","56.00097","18.87054"
"112.20000","56.10100","18.90875"
"112.40000","56.20097","18.94761"
"112.60000","56.30094","18.97350"
"112.80000","56.40097","18.99404"
"113.00000","56.50099","19.02248"
"113.20000","56.60102","19.05013"
"113.40000","56.70105","19.07696"
"113.60000","56.80095","19.11491"
"113.80000","56.90105","19.14970"
"114.00000","57.00101","19.16727"
"114.20000","57.10098","19.20067"
"114.40000","57.20095","19.23222"
"114.60000","57.30104","19.27070"
"114.80000","57.40094","19.29891"
"115.00000","57.50097","19.32635"
"115.20000","57.60100","19.35114"
"115.40000","57.70091","19.36981"
"115.60000","57.80105","19.39580"
"115.80000","57.90096","19.42589"
"116.00000","58.00093","19.46103"
"116.20000","58.10102","19.49294"
"116.40000","58.20116","19.53701"
"116.60000","58.30096","19.57267"
"116.80000","58.40104","19.58605"
"117.00000","58.50095","19.60351"
"117.20000","58.60092","19.62828"
"117.40000","58.70100","19.66543"
"117.60000","58.80097","19.70058"
"117.80000","58.90094","19.72911"
"118.00000","59.00097","19.76143"
"118.20000","59.10094","19.78825"
"118.40000","59.20097","19.81612"
"118.60000","59.30111","19.84768"
"118.80000","59.40096","19.87300"
"119.00000","59.50105","19.89789"
"119.20000","59.60096","19.93023"
"119.40000","59.70098","19.96080"
"119.60000","59.80101","19.98336"
"119.80000","59.90104","19.99975"
"120.00000","60.00101","20.02072"
"120.20000","60.10098","20.05934"
"120.40000","60.20101","20.09418"
"120.60000","60.30103","20.12584"
"120.80000","60.40100","20.15680"
"121.00000","60.50097","20.18278"
"121.20000","60.60106","20.19816"
"121.40000","60.70090","20.22302"
"121.60000","60.80099","20.25860"
"121.80000","60.90102","20.29049"
"122.00000","61.00111","20.31829"
"122.20000","61.10096","20.35244"
"122.40000","61.20099","20.38697"
"122.60000","61.30096","20.40763"
"122.80000","61.40110","20.42690"
"123.00000","61.50095","20.44966"
"123.20000","61.60098","20.47876"
"123.40000","61.70101","20.50989"
"123.60000","61.80104","20.54193"
"123.80000","61.90100","20.57154"
"124.00000","62.00103","20.59774"
"124.20000","62.10106","20.61738"
"124.40000","62.20102","20.64554"
"124.60000","62.30099","20.67594"
"124.80000","62.40090","20.70432"
"125.00000","62.50098","20.72774"
"125.20000","62.60096","20.75950"
"125.40000","62.70104","20.79006"
"125.60000","62.80101","20.81580"
"125.80000","62.90097","20.83718"
"126.00000","63.00095","20.86192"
"126.20000","63.10104","20.89245"
"126.40000","63.20100","20.92365"
"126.60000","63.30103","20.95500"
"126.80000","63.40100","20.98745"
"127.00000","63.50090","21.00399"
"127.20000","63.60106","21.02014"
"127.40000","63.70103","21.04258"
"127.60000","63.80093","21.07457"
"127.80000","63.90096","21.11170"
"128.00000","64.00111","21.13771"
"128.20000","64.10090","21.16232"
"128.40000","64.20098","21.19672"
"128.60000","64.30096","21.21866"
"128.80000","64.40104","21.23991"
"129.00000","64.50095","21.25442"
"129.20000","64.60098","21.27657"
"129.40000","64.70094","21.30310"
"129.60000","64.80097","21.33153"
"129.80000","64.90100","21.36953"
"130.00000","65.00097","21.40300"
"130.20000","65.10094","21.42511"
"130.40000","65.20102","21.44222"
"130.60000","65.30093","21.46381"
"130.80000","65.40096","21.49708"
"131.00000","65.50093","21.52335"
"131.20000","65.60095","21.54894"
"131.40000","65.70093","21.57065"
"131.60000","65.80101","21.59612"
"131.80000","65.90104","21.61743"
"132.00000","66.00101","21.64226"
"132.20000","66.10104","21.66714"
"132.40000","66.20094","21.69430"
"132.60000","66.30097","21.72071"
"132.80000","66.40094","21.75089"
"133.00000","66.50091","21.78291"
"133.20000","66.60105","21.81381"
"133.40000","66.70097","21.83666"
"133.60000","66.80099","21.84550"
"133.80000","66.90096","21.85443"
"134.00000","67.00092","21.87627"
"134.20000","67.10096","21.91053"
"134.40000","67.20104","21.94725"
"134.60000","67.30096","21.97714"
"134.80000","67.40092","22.00331"
"135.00000","67.50101","22.02939"
"135.20000","67.60104","22.05236"
"135.40000","67.70100","22.07010"
"135.60000","67.80097","22.08709"
"135.80000","67.90106","22.11051"
"136.00000","68.00102","22.13282"
"136.20000","68.10100","22.15226"
"136.40000","68.20090","22.17966"
"136.60000","68.30105","22.21110"
"136.80000","68.40102","22.24221"
"137.00000","68.50099","22.26614"
"137.20000","68.60095","22.28110"
"137.40000","68.70098","22.30476"
"137.60000","68.80101","22.33575"
"137.80000","68.90110","22.36368"
"138.00000","69.00101","22.38505"
"138.20000","69.10104","22.40791"
"138.40000","69.20100","22.43046"
"138.60000","69.30097","22.44617"
"138.80000","69.40099","22.46303"
"139.00000","69.50097","22.48255"
"139.20000","69.60111","22.50547"
"139.40000","69.70108","22.53531"
"139.60000","69.80105","22.56526"
"139.80000","69.90096","22.59255"
"140.00000","70.00092","22.62152"
"140.20000","70.10095","22.64979"
"140.40000","70.20110","22.67392"
"140.60000","70.30095","22.68109"
"140.80000","70.40092","22.68952"
"141.00000","70.50107","22.71208"
"141.20000","70.60103","22.73667"
"141.40000","70.70094","22.76424"
"141.60000","70.80096","22.79178"
"141.80000","70.90106","22.81775"
"142.00000","71.00109","22.84267"
"142.20000","71.10100","22.86624"
"142.40000","71.20090","22.89261"
"142.60000","71.30093","22.90726"
"142.80000","71.40096","22.92816"
"143.00000","71.50098","22.95296"
"143.20000","71.60102","22.97167"
"143.40000","71.70098","22.98737"
"143.60000","71.80102","23.01468"
"143.80000","71.90104","23.03265"
"144.00000","72.00095","23.06132"
"144.20000","72.10104","23.08366"
"144.40000","72.20107","23.09821"
"144.60000","72.30091","23.11020"
"144.80000","72.40100","23.13646"
"145.00000","72.50097","23.17114"
"145.20000","72.60094","23.19907"
"145.40000","72.70102","23.22024"
"145.60000","72.80099","23.24374"
"145.80000","72.90096","23.26265"
"146.00000","73.00105","23.27500"
"146.20000","73.10101","23.28571"
"146.40000","73.20104","23.29932"
"146.60000","73.30095","23.31979"
"146.80000","73.40092","23.34856"
"147.00000","73.50095","23.37014"
"147.20000","73.60104","23.39251"
"147.40000","73.70088","23.42085"
"147.60000","73.80097","23.44678"
"147.80000","73.90105","23.48066"
"148.00000","74.00103","23.50072"
"148.20000","74.10105","23.51215"
"148.40000","74.20109","23.52279"
"148.60000","74.30093","23.53062"
"148.80000","74.40108","23.55443"
"149.00000","74.50092","23.57713"
"149.20000","74.60101","23.59786"
"149.40000","74.70104","23.62358"
"149.60000","74.80101","23.64710"
"149.80000","74.90098","23.67380"
"150.00000","75.00095","23.68810"
"150.20000","75.10098","23.70338"
"150.40000","75.20107","23.71943"
"150.60000","75.30097","23.73668"
"150.80000","75.40106","23.76532"
"151.00000","75.50096","23.78459"
"151.20000","75.60111","23.80875"
"151.40000","75.70096","23.82535"
"151.60000","75.80106","23.84982"
"151.80000","75.90096","23.86108"
"152.00000","76.00099","23.88570"
"152.20000","76.10095","23.90247"
"152.40000","76.20098","23.91908"
"152.60000","76.30101","23.93985"
"152.80000","76.40098","23.95195"
"153.00000","76.50095","23.97194"
"153.20000","76.60098","23.99886"
"153.40000","76.70112","24.02186"
"153.60000","76.80103","24.04582"
"153.80000","76.90099","24.07459"
"154.00000","77.00091","24.09018"
"154.20000","77.10105","24.10926"
"154.40000","77.20103","24.11501"
"154.60000","77.30099","24.13029"
"154.80000","77.40108","24.14500"
"155.00000","77.50092","24.16336"
"155.20000","77.60101","24.19057"
"155.40000","77.70098","24.20592"
"155.60000","77.80101","24.22753"
"155.80000","77.90092","24.25160"
"156.00000","78.00101","24.26990"
"156.20000","78.10103","24.29154"
"156.40000","78.20107","24.31424"
"156.60000","78.30096","24.32564"
"156.80000","78.40094","24.34067"
"157.00000","78.50109","24.35201"
"157.20000","78.60110","24.37155"
"157.40000","78.70096","24.39039"
"157.60000","78.80099","24.40975"
"157.80000","78.90095","24.42443"
"158.00000","79.00098","24.43430"
"158.20000","79.10102","24.45899"
"158.40000","79.20092","24.48397"
"158.60000","79.30107","24.50922"
"158.80000","79.40098","24.52073"
"159.00000","79.50101","24.53259"
"159.20000","79.60097","24.54794"
"159.40000","79.70107","24.56394"
"159.60000","79.80103","24.57343"
"159.80000","79.90106","24.59772"
"160.00000","80.00103","24.61724"
"160.20000","80.10100","24.63535"
"160.40000","80.20102","24.65576"
"160.60000","80.30099","24.67370"
"160.80000","80.40090","24.69067"
"161.00000","80.50099","24.70451"
"161.20000","80.60101","24.72232"
"161.40000","80.70098","24.73543"
"161.60000","80.80107","24.75152"
"161.80000","80.90099","24.76984"
"162.00000","81.00107","24.78732"
"162.20000","81.10103","24.80932"
"162.40000","81.20106","24.82966"
"162.60000","81.30096","24.84569"
"162.80000","81.40111","24.85783"
"163.00000","81.50097","24.87783"
"163.20000","81.60099","24.89953"
"163.40000","81.70097","24.90845"
"163.60000","81.80105","24.92791"
"163.80000","81.90102","24.93455"
"164.00000","82.00092","24.94964"
"164.20000","82.10096","24.95227"
"164.40000","82.20092","24.97353"
"164.60000","82.30106","24.98666"
"164.80000","82.40104","25.00866"
"165.00000","82.50107","25.03137"
"165.20000","82.60103","25.05097"
"165.40000","82.70100","25.06857"
"165.60000","82.80091","25.08854"
"165.80000","82.90105","25.10723"
"166.00000","83.00097","25.12800"
"166.20000","83.10099","25.14121"
"166.40000","83.20101","25.14786"
"166.60000","83.30093","25.16014"
"166.80000","83.40089","25.17372"
"167.00000","83.50098","25.18713"
"167.20000","83.60101","25.20287"
"167.40000","83.70098","25.21893"
"167.60000","83.80107","25.23344"
"167.80000","83.90092","25.24769"
"168.00000","84.00095","25.26987"
"168.20000","84.10097","25.29207"
"168.40000","84.20106","25.30483"
"168.60000","84.30103","25.31671"
"168.80000","84.40105","25.33896"
"169.00000","84.50091","25.34945"
"169.20000","84.60098","25.36024"
"169.40000","84.70090","25.36638"
"169.60000","84.80099","25.38465"
"169.80000","84.90096","25.40026"
"170.00000","85.00092","25.42131"
"170.20000","85.10101","25.44279"
"170.40000","85.20097","25.45576"
"170.60000","85.30089","25.46246"
"170.80000","85.40098","25.47080"
"171.00000","85.50101","25.48695"
"171.20000","85.60098","25.50220"
"171.40000","85.70100","25.51859"
"171.60000","85.80096","25.53149"
"171.80000","85.90099","25.54172"
"172.00000","86.00096","25.55484"
"172.20000","86.10088","25.56574"
"172.40000","86.20095","25.58694"
"172.60000","86.30093","25.60448"
"172.80000","86.40083","25.61288"
"173.00000","86.50098","25.63249"
"173.20000","86.60101","25.64857"
"173.40000","86.70092","25.66407"
"173.60000","86.80106","25.67694"
"173.80000","86.90097","25.69321"
"174.00000","87.00101","25.71459"
"174.20000","87.10098","25.73163"
"174.40000","87.20094","25.74916"
"174.60000","87.30097","25.76306"
"174.80000","87.40100","25.76544"
"175.00000","87.50090","25.76673"
"175.20000","87.60099","25.77195"
"175.40000","87.70101","25.78038"
"175.60000","87.80093","25.79042"
"175.80000","87.90096","25.80656"
"176.00000","88.00105","25.81976"
"176.20000","88.10101","25.84018"
"176.40000","88.20099","25.85935"
"176.60000","88.30094","25.87631"
"176.80000","88.40103","25.89961"
"177.00000","88.50101","25.91871"
"177.20000","88.60092","25.91805"
"177.40000","88.70107","25.93851"
"177.60000","88.80090","25.95133"
"177.80000","88.90093","25.96427"
"178.00000","89.00097","25.97659"
"178.20000","89.10094","25.98690"
"178.40000","89.20097","25.99547"
"178.60000","89.30099","26.00859"
"178.80000","89.40096","26.02336"
"179.00000","89.50104","26.03972"
"179.20000","89.60114","26.03828"
"179.40000","89.70104","26.05747"
"179.60000","89.80101","26.06467"
"179.80000","89.90098","26.07382"
"180.00000","90.00101","26.08982"
"180.20000","90.10098","26.10312"
"180.40000","90.20094","26.12080"
"180.60000","90.30097","26.13561"
"180.80000","90.40099","26.15199"
"181.00000","90.50101","26.16478"
"181.20000","90.60100","26.17681"
"181.40000","90.70102","26.17655"
"181.60000","90.80106","26.18894"
"181.80000","90.90108","26.19905"
"182.00000","91.00087","26.21666"
"182.20000","91.10101","26.22741"
"182.40000","91.20103","26.24460"
"182.60000","91.30095","26.26159"
"182.80000","91.40097","26.27916"
"183.00000","91.50095","26.29226"
"183.20000","91.60091","26.30461"
"183.40000","91.70100","26.30396"
"183.60000","91.80091","26.31750"
"183.80000","91.90094","26.33122"
"184.00000","92.00103","26.34431"
"184.20000","92.10099","26.35645"
"184.40000","92.20102","26.36304"
"184.60000","92.30104","26.37050"
"184.80000","92.40107","26.37842"
"185.00000","92.50098","26.38429"
"185.20000","92.60101","26.39405"
"185.40000","92.70091","26.40803"
"185.60000","92.80094","26.40764"
"185.80000","92.90104","26.43166"
"186.00000","93.00089","26.44782"
"186.20000","93.10103","26.46512"
"186.40000","93.20094","26.47899"
"186.60000","93.30097","26.49381"
"186.80000","93.40100","26.51009"
"187.00000","93.50108","26.51709"
"187.20000","93.60099","26.53454"
"187.40000","93.70096","26.55256"
"187.60000","93.80093","26.56503"
"187.80000","93.90101","26.57831"
"188.00000","94.00098","26.58233"
"188.20000","94.10107","26.58961"
"188.40000","94.20104","26.60019"
"188.60000","94.30102","26.60500"
"188.80000","94.40086","26.60847"
"189.00000","94.50094","26.61694"
"189.20000","94.60110","26.62866"
"189.40000","94.70094","26.63716"
"189.60000","94.80103","26.63746"
"189.80000","94.90099","26.65195"
"190.00000","95.00102","26.66545"
"190.20000","95.10106","26.67871"
"190.40000","95.20107","26.68979"
"190.60000","95.30105","26.70804"
"190.80000","95.40102","26.71087"
"191.00000","95.50098","26.72652"
"191.20000","95.60101","26.74499"
"191.40000","95.70104","26.75599"
"191.60000","95.80101","26.76820"
"191.80000","95.90104","26.77988"
"192.00000","96.00095","26.79052"
"192.20000","96.10103","26.80153"
"192.40000","96.20100","26.80244"
"192.60000","96.30109","26.81442"
"192.80000","96.40112","26.82657"
"193.00000","96.50108","26.83720"
"193.20000","96.60105","26.84262"
"193.40000","96.70109","26.85900"
"193.60000","96.80099","26.87017"
"193.80000","96.90102","26.88441"
"194.00000","97.00105","26.89305"
"194.20000","97.10114","26.90199"
"194.40000","97.20098","26.90777"
"194.60000","97.30101","26.91232"
"194.80000","97.40092","26.92612"
"195.00000","97.50101","26.93868"
"195.20000","97.60104","26.95085"
"195.40000","97.70100","26.96395"
"195.60000","97.80109","26.96858"
"195.80000","97.90106","26.97873"
"196.00000","98.00102","26.99120"
"196.20000","98.10099","27.00020"
"196.40000","98.20114","27.00954"
"196.60000","98.30106","27.01612"
"196.80000","98.40108","27.02388"
"197.00000","98.50099","27.03110"
"197.20000","98.60101","27.04619"
"197.40000","98.70098","27.05530"
"197.60000","98.80095","27.04519"
"197.80000","98.90103","27.06479"
"198.00000","99.00094","27.08139"
"198.20000","99.10091","27.09579"
"198.40000","99.20100","27.11417"
"198.60000","99.30116","27.12661"
"198.80000","99.40094","27.13917"
"199.00000","99.50102","27.15078"
"199.20000","99.60104","27.16277"
"199.40000","99.70108","27.17321"
"199.60000","99.80093","27.17296"
"199.80000","99.90089","27.18533"
"200.00000","100.00098","27.19291"
"200.20000","100.10095","27.19466"
"200.40000","100.20098","27.20371"
"200.60000","100.30095","27.20733"
"200.80000","100.40097","27.21356"
"201.00000","100.50095","27.21887"
"201.20000","100.60103","27.22612"
"201.40000","100.70094","27.23748"
"201.60000","100.80108","27.25078"
"201.80000","100.90099","27.24487"
"202.00000","101.00096","27.26247"
"202.20000","101.10099","27.27846"
"202.40000","101.20095","27.29133"
"202.60000","101.30087","27.30472"
"202.80000","101.40107","27.31400"
"203.00000","101.50098","27.32328"
"203.20000","101.60095","27.33168"
"203.40000","101.70103","27.34577"
"203.60000","101.80094","27.35529"
"203.80000","101.90103","27.37200"
"204.00000","102.00095","27.38666"
"204.20000","102.10097","27.40192"
"204.40000","102.20100","27.40960"
"204.60000","102.30109","27.40417"
"204.80000","102.40087","27.41776"
"205.00000","102.50096","27.42593"
"205.20000","102.60099","27.43369"
"205.40000","102.70103","27.43838"
"205.60000","102.80099","27.44353"
"205.80000","102.90108","27.44978"
"206.00000","103.00092","27.45580"
"206.20000","103.10101","27.46353"
"206.40000","103.20086","27.47296"
"206.60000","103.30095","27.48268"
"206.80000","103.40099","27.49138"
"207.00000","103.50101","27.49891"
"207.20000","103.60098","27.50723"
"207.40000","103.70087","27.51793"
"207.60000","103.80103","27.53060"
"207.80000","103.90094","27.53562"
"208.00000","104.00097","27.55447"
"208.20000","104.10100","27.56536"
"208.40000","104.20096","27.58023"
"208.60000","104.30105","27.58847"
"208.80000","104.40102","27.59560"
"209.00000","104.50098","27.60933"
"209.20000","104.60095","27.61303"
"209.40000","104.70098","27.61774"
"209.60000","104.80095","27.62263"
"209.80000","104.90104","27.63041"
"210.00000","105.00100","27.62955"
"210.20000","105.10098","27.64260"
"210.40000","105.20094","27.63339"
"210.60000","105.30091","27.64537"
"210.80000","105.40094","27.65500"
"211.00000","105.50108","27.66928"
"211.20000","105.60094","27.68284"
"211.40000","105.70090","27.69559"
"211.60000","105.80105","27.70635"
"211.80000","105.90095","27.72201"
"212.00000","106.00098","27.72442"
"212.20000","106.10101","27.73628"
"212.40000","106.20099","27.74359"
"212.60000","106.30094","27.75103"
"212.80000","106.40098","27.75668"
"213.00000","106.50082","27.76701"
"213.20000","106.60097","27.77509"
"213.40000","106.70094","27.78351"
"213.60000","106.80103","27.79272"
"213.80000","106.90105","27.80099"
"214.00000","107.00103","27.80578"
"214.20000","107.10098","27.81387"
"214.40000","107.20103","27.81725"
"214.60000","107.30099","27.82335"
"214.80000","107.40102","27.83153"
"215.00000","107.50104","27.83242"
"215.20000","107.60090","27.84344"
"215.40000","107.70104","27.85069"
"215.60000","107.80100","27.85568"
"215.80000","107.90098","27.86387"
"216.00000","108.00094","27.87331"
"216.20000","108.10104","27.88250"
"216.40000","108.20094","27.87058"
"216.60000","108.30097","27.88159"
"216.80000","108.40099","27.89358"
"217.00000","108.50101","27.90285"
"217.20000","108.60105","27.91307"
"217.40000","108.70095","27.92139"
"217.60000","108.80099","27.93288"
"217.80000","108.90108","27.94065"
"218.00000","109.00104","27.94919"
"218.20000","109.10094","27.96472"
"218.40000","109.20098","27.97425"
"218.60000","109.30100","27.98530"
"218.80000","109.40097","27.99851"
"219.00000","109.50095","28.00458"
"219.20000","109.60098","28.01593"
"219.40000","109.70094","28.02700"
"219.60000","109.80103","28.02266"
"219.80000","109.90112","28.03165"
"220.00000","110.00097","28.03727"
"220.20000","110.10106","28.03842"
"220.40000","110.20096","28.04197"
"220.60000","110.30093","28.04607"
"220.80000","110.40096","28.04727"
"221.00000","110.50111","28.05686"
"221.20000","110.60101","28.06584"
"221.40000","110.70099","28.06265"
"221.60000","110.80094","28.07728"
"221.80000","110.90086","28.08371"
"222.00000","111.00100","28.07806"
"222.20000","111.10109","28.08144"
"222.40000","111.20094","28.09405"
"222.60000","111.30103","28.10358"
"222.80000","111.40100","28.11708"
"223.00000","111.50096","28.12881"
"223.20000","111.60099","28.13523"
"223.40000","111.70090","28.14492"
"223.60000","111.80099","28.15487"
"223.80000","111.90108","28.16341"
"224.00000","112.00098","28.17057"
"224.20000","112.10095","28.17901"
"224.40000","112.20104","28.18671"
"224.60000","112.30096","28.19389"
"224.80000","112.40098","28.20480"
"225.00000","112.50089","28.21128"
"225.20000","112.60097","28.21900"
"225.40000","112.70100","28.22398"
"225.60000","112.80090","28.23321"
"225.80000","112.90099","28.23615"
"226.00000","113.00096","28.22030"
"226.20000","113.10112","28.22854"
"226.40000","113.20096","28.23044"
"226.60000","113.30099","28.24238"
"226.80000","113.40096","28.24359"
"227.00000","113.50105","28.24822"
"227.20000","113.60089","28.25082"
"227.40000","113.70093","28.25866"
"227.60000","113.80100","28.25760"
"227.80000","113.90098","28.26409"
"228.00000","114.00100","28.26612"
"228.20000","114.10103","28.26984"
"228.40000","114.20094","28.26641"
"228.60000","114.30096","28.27275"
"228.80000","114.40099","28.27728"
"229.00000","114.50097","28.27850"
"229.20000","114.60104","28.28713"
"229.40000","114.70096","28.28638"
"229.60000","114.80087","28.29100"
"229.80000","114.90102","28.29348"
"230.00000","115.00105","28.29587"
"230.20000","115.10089","28.29814"
"230.40000","115.20098","28.30129"
"230.60000","115.30095","28.30257"
"230.80000","115.40092","28.30272"
"231.00000","115.50106","28.30281"
"231.20000","115.60098","28.30329"
"231.40000","115.70100","28.30256"
"231.60000","115.80096","28.30060"
"231.80000","115.90087","28.29970"
"232.00000","116.00096","28.29833"
"232.20000","116.10099","28.29673"
"232.40000","116.20096","28.29161"
"232.60000","116.30099","28.28897"
"232.80000","116.40102","28.28371"
"233.00000","116.50099","28.27963"
"233.20000","116.60101","28.25557"
"233.40000","116.70116","28.25452"
"233.60000","116.80100","28.25118"
"233.80000","116.90098","28.24875"
"234.00000","117.00094","28.24475"
"234.20000","117.10104","28.23883"
"234.40000","117.20106","28.22772"
"234.60000","117.30090","28.21815"
"234.80000","117.40099","28.20074"
"235.00000","117.50096","28.18799"
"235.20000","117.60112","28.17255"
"235.40000","117.70096","28.15284"
"235.60000","117.80106","28.13591"
"235.80000","117.90096","28.11392"
"236.00000","118.00105","28.08746"
"236.20000","118.10095","28.06104"
"236.40000","118.20104","28.05079"
"236.60000","118.30100","28.04132"
"236.80000","118.40105","28.03452"
"237.00000","118.50095","27.98098"
"237.20000","118.60098","27.94745"
"237.40000","118.70100","27.91006"
"237.60000","118.80092","27.84538"
"237.80000","118.90094","27.78953"
"238.00000","119.00103","27.70568"
"238.20000","119.10100","27.61145"
"238.40000","119.20096","27.50706"
"238.60000","119.30099","27.43589"
"238.80000","119.40102","27.33760"
"239.00000","119.50110","27.24588"
"239.20000","119.60108","27.19727"
"239.40000","119.70103","27.12051"
"239.60000","119.80102","27.03373"
"239.80000","119.90104","26.98306"
"240.00000","120.00095","26.91249"
"240.20000","120.10104","26.85049"
"240.40000","120.20100","26.77306"
"240.60000","120.30091","26.60294"
"240.68600","120.34396","26.33331"
"240.69200","120.34700","25.82429"
"240.69600","120.34904","24.11482"
"240.70000","120.35101","21.68432"
"240.70400","120.35304","18.81466"
"240.70800","120.35508","15.82595"