File: MT-DataAnalysis-JupyterNotebook/TensionPlots/TensionTests/SpringLength/Specimen_RawData_11.csv
End date,"8/16/2018"
Specimen label,"D32L85N5d4"
Maximum Load,"23.09019",N
Extension at Maximum Load,"77.35085",mm
Maximum Slope (Automatic Young's),"0.34165",N/mm
Rate 1,"30.00000",mm/min

Time,Extension,Load
(s),(mm),(N)
"0.00000","0.00000","0.00491"
"0.20000","0.09094","0.03528"
"0.40000","0.20149","0.07961"
"0.60000","0.30110","0.12049"
"0.80000","0.40095","0.16281"
"1.00000","0.50092","0.18698"
"1.20000","0.60094","0.21672"
"1.40000","0.70091","0.24484"
"1.60000","0.80094","0.28162"
"1.80000","0.90091","0.31856"
"2.00000","1.00088","0.35688"
"2.20000","1.10102","0.39319"
"2.40000","1.20093","0.42361"
"2.60000","1.30084","0.45400"
"2.80000","1.40099","0.49006"
"3.00000","1.50084","0.52770"
"3.20000","1.60092","0.57215"
"3.40000","1.70101","0.59687"
"3.60000","1.80092","0.62558"
"3.80000","1.90089","0.65717"
"4.00000","2.00104","0.69361"
"4.20000","2.10094","0.72790"
"4.40000","2.20097","0.76250"
"4.60000","2.30088","0.79510"
"4.80000","2.40091","0.82586"
"5.00000","2.50100","0.85750"
"5.20000","2.60102","0.89834"
"5.40000","2.70087","0.93498"
"5.60000","2.80096","0.97292"
"5.80000","2.90099","1.00547"
"6.00000","3.00102","1.03102"
"6.20000","3.10092","1.06022"
"6.40000","3.20107","1.09893"
"6.60000","3.30098","1.13919"
"6.80000","3.40101","1.18091"
"7.00000","3.50092","1.21128"
"7.20000","3.60100","1.23720"
"7.40000","3.70091","1.26718"
"7.60000","3.80094","1.29941"
"7.80000","3.90085","1.33432"
"8.00000","4.00088","1.37406"
"8.20000","4.10096","1.41101"
"8.40000","4.20093","1.44152"
"8.60000","4.30084","1.47533"
"8.80000","4.40099","1.50885"
"9.00000","4.50090","1.54327"
"9.20000","4.60098","1.57866"
"9.40000","4.70095","1.60737"
"9.60000","4.80086","1.63860"
"9.80000","4.90101","1.67149"
"10.00000","5.00098","1.71150"
"10.20000","5.10094","1.75494"
"10.40000","5.20097","1.79301"
"10.60000","5.30088","1.82026"
"10.80000","5.40097","1.84695"
"11.00000","5.50088","1.86622"
"11.20000","5.60096","1.90052"
"11.40000","5.70081","1.94404"
"11.60000","5.80102","1.98661"
"11.80000","5.90099","2.02454"
"12.00000","6.00096","2.05695"
"12.20000","6.10098","2.08621"
"12.40000","6.20095","2.11948"
"12.60000","6.30098","2.14965"
"12.80000","6.40107","2.18301"
"13.00000","6.50092","2.22170"
"13.20000","6.60088","2.25278"
"13.40000","6.70097","2.28491"
"13.60000","6.80088","2.32375"
"13.80000","6.90097","2.36622"
"14.00000","7.00088","2.40173"
"14.20000","7.10090","2.43169"
"14.40000","7.20099","2.45228"
"14.60000","7.30102","2.47611"
"14.80000","7.40087","2.52017"
"15.00000","7.50096","2.55793"
"15.20000","7.60098","2.60025"
"15.40000","7.70101","2.64010"
"15.60000","7.80092","2.67322"
"15.80000","7.90089","2.69427"
"16.00000","8.00092","2.71926"
"16.20000","8.10094","2.75327"
"16.40000","8.20085","2.79419"
"16.60000","8.30094","2.83551"
"16.80000","8.40097","2.86933"
"17.00000","8.50094","2.90047"
"17.20000","8.60090","2.93928"
"17.40000","8.70087","2.97615"
"17.60000","8.80102","3.00415"
"17.80000","8.90099","3.03679"
"18.00000","9.00096","3.06341"
"18.20000","9.10092","3.09078"
"18.40000","9.20101","3.12626"
"18.60000","9.30092","3.16640"
"18.80000","9.40101","3.21207"
"19.00000","9.50092","3.25448"
"19.20000","9.60094","3.28019"
"19.40000","9.70097","3.29827"
"19.60000","9.80088","3.32956"
"19.80000","9.90091","3.36780"
"20.00000","10.00088","3.40924"
"20.20000","10.10096","3.44945"
"20.40000","10.20093","3.48483"
"20.60000","10.30102","3.51299"
"20.80000","10.40093","3.54353"
"21.00000","10.50096","3.57565"
"21.20000","10.60092","3.61007"
"21.40000","10.70095","3.64651"
"21.60000","10.80098","3.67852"
"21.80000","10.90095","3.70699"
"22.00000","11.00097","3.74636"
"22.20000","11.10088","3.78807"
"22.40000","11.20079","3.82495"
"22.60000","11.30094","3.85779"
"22.80000","11.40103","3.88721"
"23.00000","11.50094","3.91322"
"23.20000","11.60096","3.94367"
"23.40000","11.70093","3.97998"
"23.60000","11.80090","4.02278"
"23.80000","11.90087","4.06431"
"24.00000","12.00101","4.09766"
"24.20000","12.10098","4.12494"
"24.40000","12.20095","4.15101"
"24.60000","12.30086","4.18696"
"24.80000","12.40095","4.22371"
"25.00000","12.50091","4.26220"
"25.20000","12.60088","4.29606"
"25.40000","12.70091","4.32591"
"25.60000","12.80088","4.35433"
"25.80000","12.90097","4.39113"
"26.00000","13.00094","4.42716"
"26.20000","13.10090","4.46657"
"26.40000","13.20093","4.50071"
"26.60000","13.30102","4.53184"
"26.80000","13.40087","4.56415"
"27.00000","13.50089","4.59916"
"27.20000","13.60086","4.63849"
"27.40000","13.70089","4.67432"
"27.60000","13.80104","4.70529"
"27.80000","13.90089","4.73578"
"28.00000","14.00092","4.76633"
"28.20000","14.10094","4.80104"
"28.40000","14.20085","4.83820"
"28.60000","14.30094","4.87649"
"28.80000","14.40103","4.91320"
"29.00000","14.50082","4.93953"
"29.20000","14.60102","4.96504"
"29.40000","14.70093","5.00028"
"29.60000","14.80090","5.04302"
"29.80000","14.90093","5.08627"
"30.00000","15.00095","5.12093"
"30.20000","15.10086","5.14822"
"30.40000","15.20089","5.17535"
"30.60000","15.30086","5.21035"
"30.80000","15.40083","5.24450"
"31.00000","15.50097","5.28212"
"31.20000","15.60088","5.31655"
"31.40000","15.70091","5.35172"
"31.60000","15.80100","5.38346"
"31.80000","15.90103","5.41957"
"32.00000","16.00093","5.45711"
"32.20000","16.10090","5.49395"
"32.40000","16.20087","5.52516"
"32.60000","16.30096","5.54816"
"32.80000","16.40093","5.58182"
"33.00000","16.50095","5.61756"
"33.20000","16.60092","5.65982"
"33.40000","16.70089","5.70015"
"33.60000","16.80092","5.73797"
"33.80000","16.90089","5.76406"
"34.00000","17.00097","5.78402"
"34.20000","17.10100","5.81951"
"34.40000","17.20097","5.85846"
"34.60000","17.30094","5.89899"
"34.80000","17.40103","5.93851"
"35.00000","17.50093","5.96955"
"35.20000","17.60090","5.99720"
"35.40000","17.70099","6.03359"
"35.60000","17.80090","6.06633"
"35.80000","17.90099","6.09602"
"36.00000","18.00089","6.13105"
"36.20000","18.10098","6.16433"
"36.40000","18.20095","6.19835"
"36.60000","18.30098","6.23920"
"36.80000","18.40095","6.27730"
"37.00000","18.50097","6.31974"
"37.20000","18.60100","6.35387"
"37.40000","18.70103","6.37427"
"37.60000","18.80088","6.39331"
"37.80000","18.90103","6.43354"
"38.00000","19.00093","6.47218"
"38.20000","19.10096","6.51366"
"38.40000","19.20087","6.55601"
"38.60000","19.30096","6.58906"
"38.80000","19.40093","6.61743"
"39.00000","19.50089","6.64407"
"39.20000","19.60092","6.67639"
"39.40000","19.70089","6.71407"
"39.60000","19.80098","6.75099"
"39.80000","19.90100","6.78598"
"40.00000","20.00103","6.81819"
"40.20000","20.10094","6.85556"
"40.40000","20.20103","6.89075"
"40.60000","20.30094","6.92712"
"40.80000","20.40096","6.95858"
"41.00000","20.50093","6.98488"
"41.20000","20.60090","7.01386"
"41.40000","20.70099","7.04983"
"41.60000","20.80090","7.09341"
"41.80000","20.90092","7.13442"
"42.00000","21.00095","7.17695"
"42.20000","21.10104","7.20123"
"42.40000","21.20095","7.22926"
"42.60000","21.30098","7.25609"
"42.80000","21.40095","7.29191"
"43.00000","21.50092","7.33144"
"43.20000","21.60094","7.36884"
"43.40000","21.70097","7.40596"
"43.60000","21.80094","7.43731"
"43.80000","21.90103","7.47191"
"44.00000","22.00088","7.50500"
"44.20000","22.10096","7.53748"
"44.40000","22.20081","7.57111"
"44.60000","22.30090","7.60350"
"44.80000","22.40087","7.63342"
"45.00000","22.50084","7.67285"
"45.20000","22.60098","7.71042"
"45.40000","22.70089","7.75056"
"45.60000","22.80092","7.78397"
"45.80000","22.90094","7.81245"
"46.00000","23.00097","7.84087"
"46.20000","23.10088","7.87526"
"46.40000","23.20097","7.91187"
"46.60000","23.30094","7.95203"
"46.80000","23.40097","7.98968"
"47.00000","23.50099","8.02387"
"47.20000","23.60096","8.05183"
"47.40000","23.70105","8.08119"
"47.60000","23.80090","8.11440"
"47.80000","23.90087","8.15212"
"48.00000","24.00095","8.19112"
"48.20000","24.10104","8.22309"
"48.40000","24.20095","8.25156"
"48.60000","24.30104","8.28784"
"48.80000","24.40095","8.32514"
"49.00000","24.50097","8.36353"
"49.20000","24.60094","8.39702"
"49.40000","24.70097","8.42522"
"49.60000","24.80100","8.45930"
"49.80000","24.90103","8.48920"
"50.00000","25.00093","8.52616"
"50.20000","25.10096","8.56569"
"50.40000","25.20093","8.60409"
"50.60000","25.30096","8.63215"
"50.80000","25.40099","8.65602"
"51.00000","25.50101","8.69322"
"51.20000","25.60098","8.73620"
"51.40000","25.70095","8.77064"
"51.60000","25.80098","8.80817"
"51.80000","25.90095","8.84143"
"52.00000","26.00092","8.86830"
"52.20000","26.10088","8.89822"
"52.40000","26.20103","8.93298"
"52.60000","26.30094","8.96180"
"52.80000","26.40084","9.00200"
"53.00000","26.50093","9.04327"
"53.20000","26.60096","9.06743"
"53.40000","26.70099","9.09851"
"53.60000","26.80096","9.13295"
"53.80000","26.90093","9.16790"
"54.00000","27.00101","9.20174"
"54.20000","27.10098","9.23717"
"54.40000","27.20083","9.26851"
"54.60000","27.30103","9.29809"
"54.80000","27.40094","9.33825"
"55.00000","27.50097","9.37265"
"55.20000","27.60094","9.41349"
"55.40000","27.70091","9.45051"
"55.60000","27.80094","9.47068"
"55.80000","27.90096","9.49651"
"56.00000","28.00093","9.53684"
"56.20000","28.10090","9.58165"
"56.40000","28.20093","9.62134"
"56.60000","28.30090","9.65854"
"56.80000","28.40098","9.68680"
"57.00000","28.50089","9.70863"
"57.20000","28.60104","9.73734"
"57.40000","28.70095","9.77100"
"57.60000","28.80086","9.81332"
"57.80000","28.90082","9.85361"
"58.00000","29.00097","9.88632"
"58.20000","29.10088","9.91267"
"58.40000","29.20097","9.95432"
"58.60000","29.30094","9.99337"
"58.80000","29.40085","10.02229"
"59.00000","29.50099","10.05553"
"59.20000","29.60090","10.08180"
"59.40000","29.70093","10.10979"
"59.60000","29.80096","10.15472"
"59.80000","29.90099","10.19248"
"60.00000","30.00089","10.23503"
"60.20000","30.10092","10.27404"
"60.40000","30.20083","10.29600"
"60.60000","30.30092","10.31684"
"60.80000","30.40095","10.34570"
"61.00000","30.50092","10.38824"
"61.20000","30.60100","10.42828"
"61.40000","30.70097","10.47374"
"61.60000","30.80088","10.50446"
"61.80000","30.90097","10.53417"
"62.00000","31.00088","10.56456"
"62.20000","31.10090","10.59441"
"62.40000","31.20093","10.62435"
"62.60000","31.30095","10.66882"
"62.80000","31.40086","10.70171"
"63.00000","31.50089","10.72946"
"63.20000","31.60092","10.76687"
"63.40000","31.70095","10.81281"
"63.60000","31.80091","10.84845"
"63.80000","31.90094","10.88108"
"64.00000","32.00091","10.90302"
"64.20000","32.10094","10.92429"
"64.40000","32.20090","10.95876"
"64.60000","32.30099","10.98769"
"64.80000","32.40090","11.02433"
"65.00000","32.50093","11.07387"
"65.20000","32.60096","11.11383"
"65.40000","32.70093","11.13718"
"65.60000","32.80090","11.15545"
"65.80000","32.90099","11.19201"
"66.00000","33.00089","11.22984"
"66.20000","33.10092","11.27087"
"66.40000","33.20089","11.30897"
"66.60000","33.30104","11.33722"
"66.80000","33.40094","11.37162"
"67.00000","33.50085","11.40813"
"67.20000","33.60094","11.43856"
"67.40000","33.70091","11.46849"
"67.60000","33.80100","11.50651"
"67.80000","33.90097","11.53240"
"68.00000","34.00093","11.55978"
"68.20000","34.10102","11.59755"
"68.40000","34.20087","11.64085"
"68.60000","34.30090","11.68687"
"68.80000","34.40092","11.71361"
"69.00000","34.50089","11.73999"
"69.20000","34.60098","11.76126"
"69.40000","34.70095","11.79945"
"69.60000","34.80098","11.83613"
"69.80000","34.90089","11.87352"
"70.00000","35.00097","11.91731"
"70.20000","35.10100","11.94693"
"70.40000","35.20091","11.97642"
"70.60000","35.30094","12.00450"
"70.80000","35.40091","12.04021"
"71.00000","35.50093","12.07435"
"71.20000","35.60096","12.11800"
"71.40000","35.70093","12.14327"
"71.60000","35.80096","12.16381"
"71.80000","35.90104","12.20420"
"72.00000","36.00089","12.24404"
"72.20000","36.10092","12.27964"
"72.40000","36.20101","12.31198"
"72.60000","36.30098","12.34774"
"72.80000","36.40100","12.37303"
"73.00000","36.50097","12.40205"
"73.20000","36.60094","12.44272"
"73.40000","36.70097","12.48181"
"73.60000","36.80106","12.52137"
"73.80000","36.90091","12.55081"
"74.00000","37.00105","12.57344"
"74.20000","37.10096","12.59667"
"74.40000","37.20099","12.64067"
"74.60000","37.30096","12.67797"
"74.80000","37.40092","12.71297"
"75.00000","37.50101","12.74973"
"75.20000","37.60104","12.77823"
"75.40000","37.70095","12.80442"
"75.60000","37.80091","12.83558"
"75.80000","37.90100","12.87352"
"76.00000","38.00091","12.91338"
"76.20000","38.10088","12.95710"
"76.40000","38.20097","12.98099"
"76.60000","38.30106","13.00731"
"76.80000","38.40102","13.03952"
"77.00000","38.50099","13.07781"
"77.20000","38.60102","13.10961"
"77.40000","38.70087","13.13860"
"77.60000","38.80101","13.16940"
"77.80000","38.90104","13.19470"
"78.00000","39.00089","13.22833"
"78.20000","39.10098","13.26630"
"78.40000","39.20095","13.29931"
"78.60000","39.30085","13.34372"
"78.80000","39.40094","13.37648"
"79.00000","39.50091","13.39320"
"79.20000","39.60094","13.41444"
"79.40000","39.70096","13.45354"
"79.60000","39.80099","13.49947"
"79.80000","39.90084","13.53594"
"80.00000","40.00105","13.57372"
"80.20000","40.10089","13.60221"
"80.40000","40.20099","13.62851"
"80.60000","40.30095","13.66283"
"80.80000","40.40098","13.69171"
"81.00000","40.50095","13.72415"
"81.20000","40.60092","13.76533"
"81.40000","40.70095","13.80257"
"81.60000","40.80098","13.82327"
"81.80000","40.90095","13.85746"
"82.00000","41.00085","13.89880"
"82.20000","41.10094","13.93155"
"82.40000","41.20091","13.96250"
"82.60000","41.30099","13.98907"
"82.80000","41.40091","14.00913"
"83.00000","41.50099","14.04438"
"83.20000","41.60096","14.09076"
"83.40000","41.70093","14.12718"
"83.60000","41.80096","14.16706"
"83.80000","41.90099","14.20590"
"84.00000","42.00089","14.22669"
"84.20000","42.10092","14.24208"
"84.40000","42.20095","14.27200"
"84.60000","42.30092","14.30562"
"84.80000","42.40089","14.34383"
"85.00000","42.50091","14.38864"
"85.20000","42.60088","14.41981"
"85.40000","42.70091","14.44755"
"85.60000","42.80094","14.48277"
"85.80000","42.90091","14.51599"
"86.00000","43.00093","14.54260"
"86.20000","43.10090","14.57589"
"86.40000","43.20087","14.61056"
"86.60000","43.30102","14.63650"
"86.80000","43.40098","14.66640"
"87.00000","43.50089","14.70982"
"87.20000","43.60092","14.74819"
"87.40000","43.70089","14.78396"
"87.60000","43.80085","14.81636"
"87.80000","43.90089","14.83116"
"88.00000","44.00091","14.85332"
"88.20000","44.10094","14.88615"
"88.40000","44.20091","14.92821"
"88.60000","44.30093","14.95802"
"88.80000","44.40096","15.01067"
"89.00000","44.50111","15.04452"
"89.20000","44.60089","15.06437"
"89.40000","44.70099","15.08681"
"89.60000","44.80090","15.11693"
"89.80000","44.90086","15.14784"
"90.00000","45.00095","15.18995"
"90.20000","45.10086","15.22553"
"90.40000","45.20094","15.24757"
"90.60000","45.30091","15.28088"
"90.80000","45.40100","15.32400"
"91.00000","45.50097","15.35722"
"91.20000","45.60100","15.38419"
"91.40000","45.70091","15.41596"
"91.60000","45.80099","15.44058"
"91.80000","45.90090","15.46357"
"92.00000","46.00093","15.49476"
"92.20000","46.10102","15.53235"
"92.40000","46.20098","15.57005"
"92.60000","46.30089","15.61934"
"92.80000","46.40092","15.64861"
"93.00000","46.50089","15.66533"
"93.20000","46.60092","15.68266"
"93.40000","46.70089","15.72095"
"93.60000","46.80091","15.76044"
"93.80000","46.90094","15.79096"
"94.00000","47.00085","15.83134"
"94.20000","47.10094","15.86347"
"94.40000","47.20096","15.89169"
"94.60000","47.30106","15.92246"
"94.80000","47.40102","15.94221"
"95.00000","47.50093","15.97292"
"95.20000","47.60090","16.00916"
"95.40000","47.70093","16.04774"
"95.60000","47.80095","16.07193"
"95.80000","47.90086","16.09378"
"96.00000","48.00095","16.13653"
"96.20000","48.10086","16.17534"
"96.40000","48.20101","16.20668"
"96.60000","48.30091","16.23703"
"96.80000","48.40095","16.26498"
"97.00000","48.50092","16.28895"
"97.20000","48.60100","16.31970"
"97.40000","48.70085","16.34907"
"97.60000","48.80100","16.38095"
"97.80000","48.90096","16.41597"
"98.00000","49.00093","16.45727"
"98.20000","49.10096","16.48114"
"98.40000","49.20093","16.49948"
"98.60000","49.30083","16.52617"
"98.80000","49.40098","16.56569"
"99.00000","49.50089","16.60262"
"99.20000","49.60098","16.63746"
"99.40000","49.70095","16.66996"
"99.60000","49.80085","16.69470"
"99.80000","49.90094","16.72224"
"100.00000","50.00091","16.75230"
"100.20000","50.10094","16.78398"
"100.40000","50.20091","16.81695"
"100.60000","50.30094","16.85541"
"100.80000","50.40096","16.89137"
"101.00000","50.50087","16.90585"
"101.20000","50.60102","16.92706"
"101.40000","50.70092","16.96803"
"101.60000","50.80096","17.00223"
"101.80000","50.90092","17.03580"
"102.00000","51.00101","17.06655"
"102.20000","51.10098","17.08937"
"102.40000","51.20100","17.11478"
"102.60000","51.30086","17.14702"
"102.80000","51.40094","17.17470"
"103.00000","51.50091","17.20741"
"103.20000","51.60094","17.24540"
"103.40000","51.70090","17.28293"
"103.60000","51.80099","17.31151"
"103.80000","51.90096","17.32471"
"104.00000","52.00093","17.34283"
"104.20000","52.10090","17.37993"
"104.40000","52.20093","17.42186"
"104.60000","52.30095","17.46200"
"104.80000","52.40104","17.49315"
"105.00000","52.50095","17.51694"
"105.20000","52.60092","17.54343"
"105.40000","52.70089","17.57071"
"105.60000","52.80098","17.60237"
"105.80000","52.90094","17.62620"
"106.00000","53.00097","17.65751"
"106.20000","53.10099","17.69452"
"106.40000","53.20102","17.72443"
"106.60000","53.30099","17.74736"
"106.80000","53.40090","17.77529"
"107.00000","53.50093","17.81578"
"107.20000","53.60102","17.84690"
"107.40000","53.70092","17.87940"
"107.60000","53.80101","17.90331"
"107.80000","53.90092","17.92184"
"108.00000","54.00101","17.93745"
"108.20000","54.10098","17.97531"
"108.40000","54.20100","18.01628"
"108.60000","54.30097","18.04979"
"108.80000","54.40100","18.08619"
"109.00000","54.50085","18.11777"
"109.20000","54.60094","18.14384"
"109.40000","54.70097","18.15932"
"109.60000","54.80099","18.18036"
"109.80000","54.90102","18.19581"
"110.00000","55.00087","18.22785"
"110.20000","55.10096","18.26175"
"110.40000","55.20098","18.30153"
"110.60000","55.30108","18.33222"
"110.80000","55.40098","18.35299"
"111.00000","55.50101","18.37271"
"111.20000","55.60092","18.41013"
"111.40000","55.70101","18.44062"
"111.60000","55.80103","18.46580"
"111.80000","55.90094","18.49412"
"112.00000","56.00103","18.52217"
"112.20000","56.10100","18.54647"
"112.40000","56.20097","18.57196"
"112.60000","56.30094","18.60761"
"112.80000","56.40097","18.62877"
"113.00000","56.50093","18.66513"
"113.20000","56.60096","18.70142"
"113.40000","56.70098","18.73019"
"113.60000","56.80095","18.74841"
"113.80000","56.90087","18.76012"
"114.00000","57.00101","18.78646"
"114.20000","57.10098","18.82135"
"114.40000","57.20095","18.85437"
"114.60000","57.30098","18.88607"
"114.80000","57.40100","18.90778"
"115.00000","57.50085","18.94946"
"115.20000","57.60088","18.97188"
"115.40000","57.70091","18.99203"
"115.60000","57.80088","19.01908"
"115.80000","57.90102","19.04612"
"116.00000","58.00093","19.07137"
"116.20000","58.10096","19.10667"
"116.40000","58.20099","19.12947"
"116.60000","58.30107","19.15956"
"116.80000","58.40092","19.17795"
"117.00000","58.50095","19.20392"
"117.20000","58.60092","19.24403"
"117.40000","58.70089","19.27380"
"117.60000","58.80097","19.29979"
"117.80000","58.90088","19.32982"
"118.00000","59.00091","19.35134"
"118.20000","59.10094","19.37211"
"118.40000","59.20097","19.38503"
"118.60000","59.30094","19.41068"
"118.80000","59.40102","19.44168"
"119.00000","59.50087","19.47216"
"119.20000","59.60102","19.50525"
"119.40000","59.70092","19.54611"
"119.60000","59.80095","19.57596"
"119.80000","59.90099","19.58713"
"120.00000","60.00101","19.60431"
"120.20000","60.10092","19.62946"
"120.40000","60.20095","19.66162"
"120.60000","60.30091","19.69212"
"120.80000","60.40094","19.72473"
"121.00000","60.50091","19.73500"
"121.20000","60.60094","19.76310"
"121.40000","60.70085","19.78669"
"121.60000","60.80093","19.81207"
"121.80000","60.90090","19.84175"
"122.00000","61.00093","19.87262"
"122.20000","61.10102","19.89383"
"122.40000","61.20099","19.91920"
"122.60000","61.30090","19.94989"
"122.80000","61.40092","19.97562"
"123.00000","61.50101","19.99479"
"123.20000","61.60092","20.00895"
"123.40000","61.70083","20.01662"
"123.60000","61.80091","20.05599"
"123.80000","61.90088","20.08767"
"124.00000","62.00103","20.11946"
"124.20000","62.10094","20.15249"
"124.40000","62.20091","20.17646"
"124.60000","62.30099","20.19095"
"124.80000","62.40096","20.20942"
"125.00000","62.50087","20.23466"
"125.20000","62.60096","20.26810"
"125.40000","62.70092","20.28398"
"125.60000","62.80095","20.31117"
"125.80000","62.90092","20.34181"
"126.00000","63.00095","20.37653"
"126.20000","63.10091","20.39965"
"126.40000","63.20094","20.41391"
"126.60000","63.30091","20.43454"
"126.80000","63.40094","20.45605"
"127.00000","63.50096","20.48362"
"127.20000","63.60088","20.50879"
"127.40000","63.70103","20.52320"
"127.60000","63.80093","20.55519"
"127.80000","63.90089","20.58640"
"128.00000","64.00087","20.60304"
"128.20000","64.10096","20.62206"
"128.40000","64.20092","20.64376"
"128.60000","64.30096","20.67612"
"128.80000","64.40086","20.70039"
"129.00000","64.50107","20.72551"
"129.20000","64.60098","20.74847"
"129.40000","64.70089","20.77874"
"129.60000","64.80091","20.80115"
"129.80000","64.90094","20.81936"
"130.00000","65.00097","20.83137"
"130.20000","65.10094","20.84841"
"130.40000","65.20102","20.87465"
"130.60000","65.30087","20.90525"
"130.80000","65.40096","20.92411"
"131.00000","65.50093","20.95141"
"131.20000","65.60089","20.98119"
"131.40000","65.70093","20.99873"
"131.60000","65.80095","21.01239"
"131.80000","65.90098","21.02924"
"132.00000","66.00095","21.05059"
"132.20000","66.10091","21.07977"
"132.40000","66.20094","21.10678"
"132.60000","66.30097","21.12872"
"132.80000","66.40094","21.15227"
"133.00000","66.50097","21.18031"
"133.20000","66.60099","21.20758"
"133.40000","66.70097","21.22994"
"133.60000","66.80087","21.24135"
"133.80000","66.90090","21.25470"
"134.00000","67.00098","21.26999"
"134.20000","67.10096","21.29043"
"134.40000","67.20092","21.31642"
"134.60000","67.30096","21.34520"
"134.80000","67.40086","21.37593"
"135.00000","67.50095","21.40569"
"135.20000","67.60104","21.42559"
"135.40000","67.70088","21.43775"
"135.60000","67.80103","21.45264"
"135.80000","67.90094","21.47199"
"136.00000","68.00091","21.49850"
"136.20000","68.10094","21.52599"
"136.40000","68.20102","21.54441"
"136.60000","68.30087","21.56245"
"136.80000","68.40096","21.58128"
"137.00000","68.50093","21.60218"
"137.20000","68.60083","21.62248"
"137.40000","68.70098","21.64066"
"137.60000","68.80095","21.65936"
"137.80000","68.90092","21.67968"
"138.00000","69.00095","21.70235"
"138.20000","69.10098","21.72223"
"138.40000","69.20094","21.74670"
"138.60000","69.30091","21.73491"
"138.80000","69.40094","21.76086"
"139.00000","69.50103","21.78184"
"139.20000","69.60093","21.81225"
"139.40000","69.70090","21.82828"
"139.60000","69.80093","21.83902"
"139.80000","69.90096","21.84623"
"140.00000","70.00092","21.85939"
"140.20000","70.10090","21.87405"
"140.40000","70.20092","21.89617"
"140.60000","70.30095","21.92817"
"140.80000","70.40086","21.95404"
"141.00000","70.50089","21.98049"
"141.20000","70.60103","21.99889"
"141.40000","70.70088","22.02079"
"141.60000","70.80096","22.04111"
"141.80000","70.90100","22.05844"
"142.00000","71.00090","22.07139"
"142.20000","71.10094","22.08565"
"142.40000","71.20096","22.10171"
"142.60000","71.30087","22.11908"
"142.80000","71.40096","22.13620"
"143.00000","71.50093","22.15295"
"143.20000","71.60089","22.17353"
"143.40000","71.70098","22.18657"
"143.60000","71.80090","22.21219"
"143.80000","71.90086","22.23667"
"144.00000","72.00101","22.26180"
"144.20000","72.10104","22.27092"
"144.40000","72.20100","22.28150"
"144.60000","72.30103","22.30892"
"144.80000","72.40100","22.33156"
"145.00000","72.50091","22.34171"
"145.20000","72.60094","22.36423"
"145.40000","72.70090","22.38209"
"145.60000","72.80093","22.40013"
"145.80000","72.90096","22.41688"
"146.00000","73.00093","22.43270"
"146.20000","73.10089","22.44537"
"146.40000","73.20110","22.45754"
"146.60000","73.30095","22.47796"
"146.80000","73.40098","22.48407"
"147.00000","73.50089","22.50296"
"147.20000","73.60098","22.52404"
"147.40000","73.70094","22.54720"
"147.60000","73.80097","22.56897"
"147.80000","73.90094","22.59005"
"148.00000","74.00097","22.61232"
"148.20000","74.10099","22.63701"
"148.40000","74.20097","22.65853"
"148.60000","74.30093","22.66574"
"148.80000","74.40096","22.67617"
"149.00000","74.50098","22.68107"
"149.20000","74.60090","22.68826"
"149.40000","74.70092","22.70566"
"149.60000","74.80096","22.71907"
"149.80000","74.90104","22.74010"
"150.00000","75.00101","22.76071"
"150.20000","75.10098","22.78093"
"150.40000","75.20094","22.78661"
"150.60000","75.30103","22.80729"
"150.80000","75.40088","22.82717"
"151.00000","75.50096","22.84583"
"151.20000","75.60100","22.86642"
"151.40000","75.70096","22.87834"
"151.60000","75.80093","22.89583"
"151.80000","75.90096","22.90811"
"152.00000","76.00099","22.91985"
"152.20000","76.10095","22.93113"
"152.40000","76.20093","22.94939"
"152.60000","76.30089","22.96352"
"152.80000","76.40098","22.97466"
"153.00000","76.50095","22.98758"
"153.20000","76.60098","22.99979"
"153.40000","76.70094","23.01905"
"153.60000","76.80097","23.03967"
"153.80000","76.90094","23.05594"
"154.00000","77.00091","23.06761"
"154.20000","77.10093","23.08115"
"154.40000","77.20103","23.07656"
"154.60000","77.30099","23.08993"
"154.80000","77.40090","23.08089"
"154.81600","77.40891","22.41328"
"154.82000","77.41100","20.56404"
"154.82400","77.41292","18.31015"
"154.82800","77.41489","15.73404"
"154.83200","77.41692","13.08222"