File: MT-DataAnalysis-JupyterNotebook/TensionPlots/TensionTests/TurnNumber/Specimen_RawData_4.csv
End date,"8/16/2018"
Specimen label,"D32L50N6d4"
Maximum Load,"19.30017",N
Extension at Maximum Load,"96.10103",mm
Maximum Slope (Automatic Young's),"0.22871",N/mm
Rate 1,"30.00000",mm/min

Time,Extension,Load
(s),(mm),(N)
"0.00000","0.00006","0.00716"
"0.20000","0.08962","0.06186"
"0.40000","0.20179","0.09468"
"0.60000","0.30134","0.12353"
"0.80000","0.40107","0.14842"
"1.00000","0.50098","0.17261"
"1.20000","0.60106","0.18724"
"1.40000","0.70103","0.20091"
"1.60000","0.80106","0.22081"
"1.80000","0.90109","0.24326"
"2.00000","1.00106","0.27588"
"2.20000","1.10102","0.29948"
"2.40000","1.20099","0.32556"
"2.60000","1.30096","0.35181"
"2.80000","1.40111","0.37458"
"3.00000","1.50108","0.39777"
"3.20000","1.60098","0.41610"
"3.40000","1.70113","0.43878"
"3.60000","1.80104","0.46500"
"3.80000","1.90101","0.48579"
"4.00000","2.00116","0.50967"
"4.20000","2.10106","0.53500"
"4.40000","2.20103","0.56494"
"4.60000","2.30106","0.58626"
"4.80000","2.40097","0.60399"
"5.00000","2.50106","0.62050"
"5.20000","2.60108","0.64000"
"5.40000","2.70099","0.66777"
"5.60000","2.80108","0.69285"
"5.80000","2.90111","0.71567"
"6.00000","3.00108","0.74109"
"6.20000","3.10110","0.77084"
"6.40000","3.20107","0.78853"
"6.60000","3.30116","0.80978"
"6.80000","3.40107","0.82883"
"7.00000","3.50110","0.85089"
"7.20000","3.60106","0.87595"
"7.40000","3.70103","0.90167"
"7.60000","3.80106","0.92696"
"7.80000","3.90109","0.95463"
"8.00000","4.00100","0.98305"
"8.20000","4.10114","1.00629"
"8.40000","4.20105","1.01848"
"8.60000","4.30114","1.03616"
"8.80000","4.40111","1.05774"
"9.00000","4.50114","1.08329"
"9.20000","4.60104","1.11246"
"9.40000","4.70107","1.13805"
"9.60000","4.80116","1.16488"
"9.80000","4.90107","1.19336"
"10.00000","5.00104","1.21152"
"10.20000","5.10106","1.22777"
"10.40000","5.20109","1.24526"
"10.60000","5.30106","1.26657"
"10.80000","5.40109","1.29319"
"11.00000","5.50112","1.31215"
"11.20000","5.60108","1.33605"
"11.40000","5.70099","1.36441"
"11.60000","5.80108","1.39265"
"11.80000","5.90111","1.41616"
"12.00000","6.00114","1.43457"
"12.20000","6.10116","1.45445"
"12.40000","6.20107","1.47535"
"12.60000","6.30110","1.50183"
"12.80000","6.40113","1.52634"
"13.00000","6.50109","1.55261"
"13.20000","6.60106","1.56835"
"13.40000","6.70109","1.59315"
"13.60000","6.80094","1.61125"
"13.80000","6.90103","1.62634"
"14.00000","7.00100","1.64803"
"14.20000","7.10108","1.67451"
"14.40000","7.20111","1.70055"
"14.60000","7.30114","1.73308"
"14.80000","7.40111","1.75877"
"15.00000","7.50108","1.78235"
"15.20000","7.60110","1.81253"
"15.40000","7.70101","1.83179"
"15.60000","7.80110","1.84421"
"15.80000","7.90101","1.85443"
"16.00000","8.00109","1.87227"
"16.20000","8.10112","1.89801"
"16.40000","8.20103","1.92053"
"16.60000","8.30106","1.95407"
"16.80000","8.40103","1.98475"
"17.00000","8.50105","2.00760"
"17.20000","8.60108","2.03614"
"17.40000","8.70111","2.05713"
"17.60000","8.80102","2.07507"
"17.80000","8.90111","2.09403"
"18.00000","9.00108","2.11784"
"18.20000","9.10110","2.13648"
"18.40000","9.20107","2.15670"
"18.60000","9.30116","2.17793"
"18.80000","9.40107","2.20550"
"19.00000","9.50109","2.22959"
"19.20000","9.60100","2.25075"
"19.40000","9.70103","2.27304"
"19.60000","9.80112","2.29759"
"19.80000","9.90121","2.32608"
"20.00000","10.00105","2.35176"
"20.20000","10.10102","2.37645"
"20.40000","10.20105","2.40164"
"20.60000","10.30108","2.42508"
"20.80000","10.40111","2.44048"
"21.00000","10.50107","2.45230"
"21.20000","10.60116","2.46641"
"21.40000","10.70113","2.48745"
"21.60000","10.80110","2.51706"
"21.80000","10.90107","2.54770"
"22.00000","11.00115","2.57334"
"22.20000","11.10112","2.60783"
"22.40000","11.20109","2.63677"
"22.60000","11.30106","2.65665"
"22.80000","11.40109","2.67716"
"23.00000","11.50111","2.69082"
"23.20000","11.60114","2.70776"
"23.40000","11.70117","2.72439"
"23.60000","11.80102","2.74479"
"23.80000","11.90117","2.76779"
"24.00000","12.00107","2.79454"
"24.20000","12.10110","2.82799"
"24.40000","12.20113","2.85025"
"24.60000","12.30128","2.87146"
"24.80000","12.40107","2.89459"
"25.00000","12.50115","2.91753"
"25.20000","12.60106","2.94417"
"25.40000","12.70109","2.97012"
"25.60000","12.80112","2.99089"
"25.80000","12.90109","3.00872"
"26.00000","13.00117","3.03071"
"26.20000","13.10108","3.05001"
"26.40000","13.20105","3.06663"
"26.60000","13.30108","3.08602"
"26.80000","13.40123","3.10631"
"27.00000","13.50107","3.13355"
"27.20000","13.60116","3.16245"
"27.40000","13.70113","3.19153"
"27.60000","13.80110","3.21905"
"27.80000","13.90107","3.24570"
"28.00000","14.00115","3.26560"
"28.20000","14.10118","3.28305"
"28.40000","14.20115","3.29440"
"28.60000","14.30100","3.30908"
"28.80000","14.40109","3.33659"
"29.00000","14.50111","3.36366"
"29.20000","14.60108","3.39175"
"29.40000","14.70117","3.41933"
"29.60000","14.80114","3.44806"
"29.80000","14.90117","3.47527"
"30.00000","15.00095","3.49340"
"30.20000","15.10110","3.51323"
"30.40000","15.20113","3.53011"
"30.60000","15.30116","3.55512"
"30.80000","15.40107","3.57331"
"31.00000","15.50109","3.59706"
"31.20000","15.60106","3.61711"
"31.40000","15.70115","3.64855"
"31.60000","15.80112","3.67023"
"31.80000","15.90103","3.68684"
"32.00000","16.00117","3.70750"
"32.20000","16.10108","3.72987"
"32.40000","16.20099","3.75976"
"32.60000","16.30108","3.79050"
"32.80000","16.40104","3.81494"
"33.00000","16.50101","3.83577"
"33.20000","16.60116","3.85763"
"33.40000","16.70107","3.88034"
"33.60000","16.80110","3.89475"
"33.80000","16.90113","3.91361"
"34.00000","17.00115","3.93324"
"34.20000","17.10106","3.95769"
"34.40000","17.20109","3.98506"
"34.60000","17.30112","4.01027"
"34.80000","17.40109","4.03776"
"35.00000","17.50105","4.06693"
"35.20000","17.60096","4.08679"
"35.40000","17.70099","4.10887"
"35.60000","17.80114","4.12467"
"35.80000","17.90111","4.14053"
"36.00000","18.00107","4.16589"
"36.20000","18.10122","4.19157"
"36.40000","18.20107","4.21534"
"36.60000","18.30116","4.24174"
"36.80000","18.40101","4.26554"
"37.00000","18.50109","4.29004"
"37.20000","18.60112","4.30873"
"37.40000","18.70109","4.32773"
"37.60000","18.80100","4.34823"
"37.80000","18.90103","4.37354"
"38.00000","19.00105","4.39801"
"38.20000","19.10108","4.41977"
"38.40000","19.20105","4.44302"
"38.60000","19.30108","4.47304"
"38.80000","19.40104","4.50234"
"39.00000","19.50107","4.51837"
"39.20000","19.60104","4.53393"
"39.40000","19.70101","4.55092"
"39.60000","19.80116","4.57778"
"39.80000","19.90113","4.60511"
"40.00000","20.00109","4.63199"
"40.20000","20.10106","4.65690"
"40.40000","20.20109","4.68229"
"40.60000","20.30112","4.70492"
"40.80000","20.40102","4.72146"
"41.00000","20.50105","4.73424"
"41.20000","20.60096","4.75767"
"41.40000","20.70117","4.78325"
"41.60000","20.80114","4.80845"
"41.80000","20.90111","4.83203"
"42.00000","21.00113","4.85628"
"42.20000","21.10110","4.88330"
"42.40000","21.20107","4.90782"
"42.60000","21.30116","4.93124"
"42.80000","21.40101","4.94420"
"43.00000","21.50103","4.95698"
"43.20000","21.60106","4.98341"
"43.40000","21.70103","5.01006"
"43.60000","21.80106","5.03677"
"43.80000","21.90103","5.06672"
"44.00000","22.00105","5.09389"
"44.20000","22.10114","5.11814"
"44.40000","22.20117","5.13336"
"44.60000","22.30096","5.15262"
"44.80000","22.40110","5.17039"
"45.00000","22.50113","5.19517"
"45.20000","22.60110","5.21742"
"45.40000","22.70113","5.23987"
"45.60000","22.80104","5.26120"
"45.80000","22.90107","5.28872"
"46.00000","23.00115","5.31519"
"46.20000","23.10100","5.33751"
"46.40000","23.20115","5.35751"
"46.60000","23.30118","5.37838"
"46.80000","23.40103","5.40068"
"47.00000","23.50111","5.42643"
"47.20000","23.60102","5.45217"
"47.40000","23.70117","5.47746"
"47.60000","23.80107","5.49971"
"47.80000","23.90111","5.52151"
"48.00000","24.00107","5.53706"
"48.20000","24.10110","5.55078"
"48.40000","24.20101","5.57084"
"48.60000","24.30110","5.59745"
"48.80000","24.40107","5.62603"
"49.00000","24.50103","5.65395"
"49.20000","24.60112","5.68050"
"49.40000","24.70103","5.70845"
"49.60000","24.80112","5.73518"
"49.80000","24.90103","5.75698"
"50.00000","25.00111","5.76820"
"50.20000","25.10108","5.78321"
"50.40000","25.20105","5.79732"
"50.60000","25.30114","5.82443"
"50.80000","25.40116","5.84881"
"51.00000","25.50107","5.87340"
"51.20000","25.60104","5.90765"
"51.40000","25.70119","5.93648"
"51.60000","25.80110","5.95623"
"51.80000","25.90112","5.97635"
"52.00000","26.00109","5.99282"
"52.20000","26.10100","6.01675"
"52.40000","26.20109","6.04050"
"52.60000","26.30118","6.06266"
"52.80000","26.40108","6.08138"
"53.00000","26.50117","6.10090"
"53.20000","26.60102","6.12682"
"53.40000","26.70099","6.14948"
"53.60000","26.80108","6.16908"
"53.80000","26.90110","6.19020"
"54.00000","27.00107","6.21602"
"54.20000","27.10110","6.24563"
"54.40000","27.20101","6.26955"
"54.60000","27.30098","6.29838"
"54.80000","27.40107","6.32717"
"55.00000","27.50103","6.35066"
"55.20000","27.60106","6.36580"
"55.40000","27.70103","6.37683"
"55.60000","27.80112","6.39102"
"55.80000","27.90108","6.40950"
"56.00000","28.00105","6.43630"
"56.20000","28.10102","6.45820"
"56.40000","28.20117","6.48570"
"56.60000","28.30108","6.51727"
"56.80000","28.40104","6.54384"
"57.00000","28.50107","6.56953"
"57.20000","28.60098","6.59131"
"57.40000","28.70107","6.60816"
"57.60000","28.80104","6.62559"
"57.80000","28.90106","6.64484"
"58.00000","29.00109","6.66329"
"58.20000","29.10106","6.68488"
"58.40000","29.20103","6.71282"
"58.60000","29.30118","6.74190"
"58.80000","29.40097","6.76626"
"59.00000","29.50111","6.78323"
"59.20000","29.60108","6.80307"
"59.40000","29.70111","6.82798"
"59.60000","29.80108","6.85441"
"59.80000","29.90104","6.88262"
"60.00000","30.00101","6.90655"
"60.20000","30.10104","6.92674"
"60.40000","30.20107","6.94705"
"60.60000","30.30092","6.96673"
"60.80000","30.40107","6.98218"
"61.00000","30.50103","6.99971"
"61.20000","30.60106","7.02103"
"61.40000","30.70115","7.04701"
"61.60000","30.80118","7.07421"
"61.80000","30.90102","7.10232"
"62.00000","31.00111","7.13259"
"62.20000","31.10108","7.16106"
"62.40000","31.20111","7.18587"
"62.60000","31.30107","7.20458"
"62.80000","31.40104","7.21579"
"63.00000","31.50113","7.22641"
"63.20000","31.60110","7.24749"
"63.40000","31.70101","7.27127"
"63.60000","31.80110","7.29877"
"63.80000","31.90118","7.32145"
"64.00000","32.00115","7.35231"
"64.20000","32.10118","7.37977"
"64.40000","32.20109","7.40119"
"64.60000","32.30118","7.42121"
"64.80000","32.40115","7.44119"
"65.00000","32.50111","7.46346"
"65.20000","32.60114","7.48707"
"65.40000","32.70105","7.50948"
"65.60000","32.80107","7.52885"
"65.80000","32.90105","7.55111"
"66.00000","33.00107","7.57814"
"66.20000","33.10110","7.60155"
"66.40000","33.20113","7.61503"
"66.60000","33.30104","7.63416"
"66.80000","33.40112","7.65561"
"67.00000","33.50109","7.68360"
"67.20000","33.60124","7.71117"
"67.40000","33.70103","7.74022"
"67.60000","33.80112","7.76421"
"67.80000","33.90108","7.78933"
"68.00000","34.00117","7.80686"
"68.20000","34.10096","7.82091"
"68.40000","34.20111","7.83724"
"68.60000","34.30107","7.85747"
"68.80000","34.40104","7.88640"
"69.00000","34.50107","7.90975"
"69.20000","34.60104","7.93617"
"69.40000","34.70113","7.96172"
"69.60000","34.80116","7.99375"
"69.80000","34.90112","8.01442"
"70.00000","35.00103","8.03122"
"70.20000","35.10118","8.04641"
"70.40000","35.20109","8.05897"
"70.60000","35.30112","8.08350"
"70.80000","35.40108","8.11048"
"71.00000","35.50111","8.13361"
"71.20000","35.60108","8.16037"
"71.40000","35.70105","8.18462"
"71.60000","35.80096","8.20844"
"71.80000","35.90110","8.22755"
"72.00000","36.00119","8.24563"
"72.20000","36.10104","8.26874"
"72.40000","36.20113","8.29479"
"72.60000","36.30109","8.31952"
"72.80000","36.40106","8.34362"
"73.00000","36.50103","8.36246"
"73.20000","36.60112","8.38840"
"73.40000","36.70103","8.41428"
"73.60000","36.80111","8.43613"
"73.80000","36.90102","8.44942"
"74.00000","37.00111","8.46786"
"74.20000","37.10102","8.48714"
"74.40000","37.20105","8.51352"
"74.60000","37.30107","8.54111"
"74.80000","37.40104","8.56514"
"75.00000","37.50107","8.59206"
"75.20000","37.60104","8.61551"
"75.40000","37.70113","8.63389"
"75.60000","37.80109","8.64914"
"75.80000","37.90100","8.66243"
"76.00000","38.00103","8.69139"
"76.20000","38.10112","8.71592"
"76.40000","38.20109","8.74320"
"76.60000","38.30106","8.76673"
"76.80000","38.40108","8.79126"
"77.00000","38.50111","8.81557"
"77.20000","38.60114","8.84148"
"77.40000","38.70105","8.85932"
"77.60000","38.80101","8.87266"
"77.80000","38.90104","8.88702"
"78.00000","39.00107","8.91197"
"78.20000","39.10104","8.93789"
"78.40000","39.20119","8.96489"
"78.60000","39.30103","8.99016"
"78.80000","39.40106","9.02143"
"79.00000","39.50109","9.04556"
"79.20000","39.60112","9.06032"
"79.40000","39.70109","9.07165"
"79.60000","39.80112","9.09678"
"79.80000","39.90102","9.12050"
"80.00000","40.00105","9.14426"
"80.20000","40.10108","9.16742"
"80.40000","40.20105","9.18769"
"80.60000","40.30114","9.20975"
"80.80000","40.40110","9.23835"
"81.00000","40.50113","9.25756"
"81.20000","40.60110","9.27458"
"81.40000","40.70113","9.29548"
"81.60000","40.80110","9.31912"
"81.80000","40.90107","9.34266"
"82.00000","41.00109","9.36737"
"82.20000","41.10112","9.39158"
"82.40000","41.20108","9.41919"
"82.60000","41.30106","9.43782"
"82.80000","41.40115","9.46035"
"83.00000","41.50111","9.47237"
"83.20000","41.60114","9.48416"
"83.40000","41.70111","9.50886"
"83.60000","41.80107","9.54266"
"83.80000","41.90110","9.57076"
"84.00000","42.00113","9.59383"
"84.20000","42.10098","9.62091"
"84.40000","42.20119","9.64538"
"84.60000","42.30116","9.66815"
"84.80000","42.40112","9.68688"
"85.00000","42.50109","9.69926"
"85.20000","42.60106","9.71645"
"85.40000","42.70109","9.73552"
"85.60000","42.80117","9.75519"
"85.80000","42.90114","9.77734"
"86.00000","43.00099","9.79835"
"86.20000","43.10114","9.83223"
"86.40000","43.20105","9.86394"
"86.60000","43.30114","9.88174"
"86.80000","43.40110","9.89638"
"87.00000","43.50125","9.91431"
"87.20000","43.60110","9.94164"
"87.40000","43.70101","9.97033"
"87.60000","43.80098","9.99359"
"87.80000","43.90112","10.01196"
"88.00000","44.00109","10.03260"
"88.20000","44.10106","10.05203"
"88.40000","44.20109","10.07225"
"88.60000","44.30099","10.08640"
"88.80000","44.40114","10.10991"
"89.00000","44.50111","10.13381"
"89.20000","44.60108","10.16408"
"89.40000","44.70110","10.18579"
"89.60000","44.80119","10.21400"
"89.80000","44.90104","10.24122"
"90.00000","45.00101","10.26730"
"90.20000","45.10098","10.28478"
"90.40000","45.20100","10.29842"
"90.60000","45.30116","10.30578"
"90.80000","45.40106","10.31990"
"91.00000","45.50109","10.34463"
"91.20000","45.60112","10.37238"
"91.40000","45.70108","10.39797"
"91.60000","45.80111","10.42624"
"91.80000","45.90102","10.45745"
"92.00000","46.00105","10.48011"
"92.20000","46.10108","10.49967"
"92.40000","46.20105","10.51854"
"92.60000","46.30101","10.53847"
"92.80000","46.40098","10.55835"
"93.00000","46.50113","10.57627"
"93.20000","46.60109","10.59572"
"93.40000","46.70113","10.61326"
"93.60000","46.80109","10.63754"
"93.80000","46.90100","10.66704"
"94.00000","47.00115","10.69473"
"94.20000","47.10106","10.70873"
"94.40000","47.20115","10.72942"
"94.60000","47.30106","10.74953"
"94.80000","47.40108","10.77660"
"95.00000","47.50111","10.80103"
"95.20000","47.60108","10.82848"
"95.40000","47.70105","10.84968"
"95.60000","47.80114","10.87069"
"95.80000","47.90098","10.88847"
"96.00000","48.00113","10.90257"
"96.20000","48.10104","10.91350"
"96.40000","48.20119","10.92851"
"96.60000","48.30103","10.95265"
"96.80000","48.40100","10.98219"
"97.00000","48.50109","11.00611"
"97.20000","48.60106","11.03227"
"97.40000","48.70109","11.06088"
"97.60000","48.80106","11.09482"
"97.80000","48.90108","11.11503"
"98.00000","49.00111","11.12896"
"98.20000","49.10102","11.14198"
"98.40000","49.20105","11.15448"
"98.60000","49.30107","11.17535"
"98.80000","49.40110","11.20002"
"99.00000","49.50113","11.22344"
"99.20000","49.60104","11.25003"
"99.40000","49.70113","11.27596"
"99.60000","49.80110","11.30322"
"99.80000","49.90107","11.31900"
"100.00000","50.00115","11.33992"
"100.20000","50.10106","11.35949"
"100.40000","50.20102","11.38413"
"100.60000","50.30105","11.40853"
"100.80000","50.40114","11.42981"
"101.00000","50.50105","11.44675"
"101.20000","50.60108","11.46473"
"101.40000","50.70111","11.48870"
"101.60000","50.80119","11.51104"
"101.80000","50.90104","11.52995"
"102.00000","51.00107","11.54453"
"102.20000","51.10110","11.56512"
"102.40000","51.20107","11.58700"
"102.60000","51.30109","11.61466"
"102.80000","51.40112","11.64318"
"103.00000","51.50109","11.67145"
"103.20000","51.60112","11.69741"
"103.40000","51.70120","11.71790"
"103.60000","51.80099","11.73115"
"103.80000","51.90120","11.74293"
"104.00000","52.00111","11.75444"
"104.20000","52.10114","11.77674"
"104.40000","52.20104","11.80317"
"104.60000","52.30114","11.82537"
"104.80000","52.40116","11.85058"
"105.00000","52.50119","11.87339"
"105.20000","52.60110","11.90267"
"105.40000","52.70107","11.92718"
"105.60000","52.80115","11.94846"
"105.80000","52.90106","11.96458"
"106.00000","53.00103","11.98029"
"106.20000","53.10106","12.00265"
"106.40000","53.20121","12.02055"
"106.60000","53.30111","12.04361"
"106.80000","53.40114","12.06452"
"107.00000","53.50111","12.09106"
"107.20000","53.60108","12.11621"
"107.40000","53.70110","12.13497"
"107.60000","53.80119","12.14827"
"107.80000","53.90104","12.16239"
"108.00000","54.00113","12.18589"
"108.20000","54.10109","12.21194"
"108.40000","54.20107","12.23715"
"108.60000","54.30103","12.26115"
"108.80000","54.40106","12.28217"
"109.00000","54.50109","12.30557"
"109.20000","54.60111","12.32541"
"109.40000","54.70103","12.34718"
"109.60000","54.80099","12.36314"
"109.80000","54.90115","12.38049"
"110.00000","55.00111","12.39869"
"110.20000","55.10114","12.42356"
"110.40000","55.20111","12.44763"
"110.60000","55.30113","12.47241"
"110.80000","55.40098","12.49835"
"111.00000","55.50107","12.52600"
"111.20000","55.60110","12.54424"
"111.40000","55.70113","12.56114"
"111.60000","55.80103","12.57326"
"111.80000","55.90100","12.59034"
"112.00000","56.00103","12.60832"
"112.20000","56.10106","12.63374"
"112.40000","56.20115","12.65723"
"112.60000","56.30106","12.68228"
"112.80000","56.40114","12.70403"
"113.00000","56.50105","12.73043"
"113.20000","56.60108","12.75090"
"113.40000","56.70105","12.76838"
"113.60000","56.80107","12.78403"
"113.80000","56.90110","12.80195"
"114.00000","57.00107","12.82071"
"114.20000","57.10104","12.84200"
"114.40000","57.20101","12.86573"
"114.60000","57.30104","12.88854"
"114.80000","57.40106","12.91307"
"115.00000","57.50103","12.94324"
"115.20000","57.60106","12.96815"
"115.40000","57.70109","12.98037"
"115.60000","57.80105","12.99246"
"115.80000","57.90102","13.00825"
"116.00000","58.00105","13.03271"
"116.20000","58.10108","13.05798"
"116.40000","58.20110","13.08140"
"116.60000","58.30113","13.10161"
"116.80000","58.40104","13.12178"
"117.00000","58.50113","13.14170"
"117.20000","58.60104","13.16300"
"117.40000","58.70095","13.18043"
"117.60000","58.80103","13.19901"
"117.80000","58.90107","13.21511"
"118.00000","59.00097","13.24334"
"118.20000","59.10106","13.26743"
"118.40000","59.20108","13.28866"
"118.60000","59.30105","13.31112"
"118.80000","59.40120","13.33605"
"119.00000","59.50105","13.35971"
"119.20000","59.60107","13.37599"
"119.40000","59.70105","13.38906"
"119.60000","59.80107","13.39843"
"119.80000","59.90104","13.41188"
"120.00000","60.00101","13.43482"
"120.20000","60.10104","13.46274"
"120.40000","60.20107","13.48937"
"120.60000","60.30116","13.51559"
"120.80000","60.40106","13.54032"
"121.00000","60.50109","13.56690"
"121.20000","60.60106","13.58480"
"121.40000","60.70115","13.60158"
"121.60000","60.80106","13.61801"
"121.80000","60.90108","13.63603"
"122.00000","61.00122","13.65495"
"122.20000","61.10114","13.67616"
"122.40000","61.20110","13.69417"
"122.60000","61.30107","13.71062"
"122.80000","61.40104","13.73330"
"123.00000","61.50107","13.76153"
"123.20000","61.60110","13.78802"
"123.40000","61.70107","13.80566"
"123.60000","61.80115","13.81736"
"123.80000","61.90106","13.83679"
"124.00000","62.00109","13.85578"
"124.20000","62.10112","13.88276"
"124.40000","62.20114","13.90440"
"124.60000","62.30111","13.92777"
"124.80000","62.40102","13.94778"
"125.00000","62.50104","13.96879"
"125.20000","62.60107","13.98213"
"125.40000","62.70104","13.99630"
"125.60000","62.80101","14.00743"
"125.80000","62.90110","14.02681"
"126.00000","63.00107","14.05282"
"126.20000","63.10110","14.08400"
"126.40000","63.20106","14.10695"
"126.60000","63.30109","14.13088"
"126.80000","63.40112","14.15270"
"127.00000","63.50115","14.17968"
"127.20000","63.60094","14.20237"
"127.40000","63.70108","14.21519"
"127.60000","63.80111","14.22712"
"127.80000","63.90102","14.23466"
"128.00000","64.00105","14.24737"
"128.20000","64.10114","14.26850"
"128.40000","64.20104","14.29289"
"128.60000","64.30113","14.31288"
"128.80000","64.40098","14.34094"
"129.00000","64.50113","14.36482"
"129.20000","64.60115","14.39513"
"129.40000","64.70107","14.40860"
"129.60000","64.80103","14.42935"
"129.80000","64.90106","14.44437"
"130.00000","65.00108","14.46384"
"130.20000","65.10112","14.48473"
"130.40000","65.20108","14.50867"
"130.60000","65.30106","14.52396"
"130.80000","65.40102","14.54096"
"131.00000","65.50117","14.55836"
"131.20000","65.60107","14.57860"
"131.40000","65.70110","14.60170"
"131.60000","65.80101","14.61803"
"131.80000","65.90110","14.63565"
"132.00000","66.00112","14.65033"
"132.20000","66.10116","14.67237"
"132.40000","66.20106","14.69830"
"132.60000","66.30103","14.72472"
"132.80000","66.40100","14.74511"
"133.00000","66.50109","14.76821"
"133.20000","66.60105","14.79096"
"133.40000","66.70109","14.81187"
"133.60000","66.80117","14.82046"
"133.80000","66.90108","14.83160"
"134.00000","67.00098","14.84285"
"134.20000","67.10107","14.85697"
"134.40000","67.20116","14.88315"
"134.60000","67.30119","14.91116"
"134.80000","67.40109","14.93288"
"135.00000","67.50107","14.94973"
"135.20000","67.60109","14.97124"
"135.40000","67.70107","15.00369"
"135.60000","67.80115","15.02849"
"135.80000","67.90112","15.04310"
"136.00000","68.00108","15.05775"
"136.20000","68.10111","15.07006"
"136.40000","68.20114","15.08453"
"136.60000","68.30105","15.09207"
"136.80000","68.40108","15.08836"
"137.00000","68.50111","15.11078"
"137.20000","68.60107","15.13003"
"137.40000","68.70116","15.14869"
"137.60000","68.80107","15.17386"
"137.80000","68.90110","15.19716"
"138.00000","69.00118","15.21710"
"138.20000","69.10110","15.23630"
"138.40000","69.20106","15.24858"
"138.60000","69.30115","15.27085"
"138.80000","69.40105","15.29264"
"139.00000","69.50108","15.31943"
"139.20000","69.60105","15.33795"
"139.40000","69.70108","15.35838"
"139.60000","69.80117","15.37568"
"139.80000","69.90102","15.39236"
"140.00000","70.00111","15.41110"
"140.20000","70.10114","15.42747"
"140.40000","70.20116","15.44172"
"140.60000","70.30113","15.45488"
"140.80000","70.40116","15.47517"
"141.00000","70.50113","15.49262"
"141.20000","70.60110","15.51295"
"141.40000","70.70113","15.53362"
"141.60000","70.80109","15.55760"
"141.80000","70.90118","15.57916"
"142.00000","71.00115","15.60670"
"142.20000","71.10105","15.63454"
"142.40000","71.20109","15.64991"
"142.60000","71.30111","15.65954"
"142.80000","71.40108","15.66836"
"143.00000","71.50117","15.67647"
"143.20000","71.60107","15.69338"
"143.40000","71.70110","15.71744"
"143.60000","71.80107","15.74128"
"143.80000","71.90116","15.76408"
"144.00000","72.00107","15.78228"
"144.20000","72.10115","15.80247"
"144.40000","72.20107","15.82418"
"144.60000","72.30115","15.84453"
"144.80000","72.40100","15.86022"
"145.00000","72.50097","15.87758"
"145.20000","72.60106","15.89303"
"145.40000","72.70102","15.91028"
"145.60000","72.80106","15.92744"
"145.80000","72.90102","15.94388"
"146.00000","73.00111","15.96147"
"146.20000","73.10107","15.98032"
"146.40000","73.20116","16.00043"
"146.60000","73.30101","16.02291"
"146.80000","73.40116","16.04015"
"147.00000","73.50107","16.05168"
"147.20000","73.60110","16.06901"
"147.40000","73.70107","16.08069"
"147.60000","73.80103","16.09627"
"147.80000","73.90100","16.11666"
"148.00000","74.00115","16.14060"
"148.20000","74.10105","16.16466"
"148.40000","74.20114","16.18418"
"148.60000","74.30117","16.20439"
"148.80000","74.40102","16.22513"
"149.00000","74.50117","16.23977"
"149.20000","74.60107","16.25283"
"149.40000","74.70110","16.26927"
"149.60000","74.80113","16.28220"
"149.80000","74.90115","16.29783"
"150.00000","75.00101","16.31407"
"150.20000","75.10109","16.33365"
"150.40000","75.20113","16.35362"
"150.60000","75.30109","16.37316"
"150.80000","75.40106","16.39085"
"151.00000","75.50108","16.41088"
"151.20000","75.60100","16.43672"
"151.40000","75.70114","16.45650"
"151.60000","75.80106","16.47413"
"151.80000","75.90102","16.48501"
"152.00000","76.00117","16.49705"
"152.20000","76.10114","16.50680"
"152.40000","76.20104","16.52619"
"152.60000","76.30101","16.54362"
"152.80000","76.40110","16.56534"
"153.00000","76.50112","16.58775"
"153.20000","76.60104","16.60728"
"153.40000","76.70112","16.62704"
"153.60000","76.80103","16.64839"
"153.80000","76.90118","16.66467"
"154.00000","77.00109","16.67884"
"154.20000","77.10099","16.69348"
"154.40000","77.20114","16.70724"
"154.60000","77.30105","16.72261"
"154.80000","77.40102","16.73968"
"155.00000","77.50111","16.75705"
"155.20000","77.60101","16.77465"
"155.40000","77.70110","16.79208"
"155.60000","77.80107","16.81169"
"155.80000","77.90109","16.83099"
"156.00000","78.00107","16.85256"
"156.20000","78.10116","16.87279"
"156.40000","78.20107","16.89287"
"156.60000","78.30103","16.90515"
"156.80000","78.40112","16.91324"
"157.00000","78.50096","16.92887"
"157.20000","78.60110","16.94450"
"157.40000","78.70109","16.96630"
"157.60000","78.80105","16.98666"
"157.80000","78.90108","17.00569"
"158.00000","79.00105","17.02344"
"158.20000","79.10107","17.03951"
"158.40000","79.20110","17.05590"
"158.60000","79.30101","17.07068"
"158.80000","79.40110","17.08224"
"159.00000","79.50119","17.09553"
"159.20000","79.60110","17.10915"
"159.40000","79.70113","17.12357"
"159.60000","79.80109","17.14174"
"159.80000","79.90112","17.16214"
"160.00000","80.00108","17.17967"
"160.20000","80.10117","17.19896"
"160.40000","80.20102","17.21707"
"160.60000","80.30106","17.23822"
"160.80000","80.40101","17.25648"
"161.00000","80.50105","17.28047"
"161.20000","80.60107","17.29791"
"161.40000","80.70110","17.30899"
"161.60000","80.80107","17.31811"
"161.80000","80.90104","17.32544"
"162.00000","81.00101","17.33877"
"162.20000","81.10115","17.35100"
"162.40000","81.20118","17.36676"
"162.60000","81.30103","17.38959"
"162.80000","81.40111","17.41172"
"163.00000","81.50115","17.43170"
"163.20000","81.60105","17.45366"
"163.40000","81.70103","17.47386"
"163.60000","81.80111","17.49403"
"163.80000","81.90114","17.50628"
"164.00000","82.00110","17.51751"
"164.20000","82.10107","17.52770"
"164.40000","82.20110","17.54006"
"164.60000","82.30101","17.55750"
"164.80000","82.40104","17.57242"
"165.00000","82.50118","17.59045"
"165.20000","82.60103","17.60204"
"165.40000","82.70119","17.61724"
"165.60000","82.80114","17.62932"
"165.80000","82.90105","17.64734"
"166.00000","83.00108","17.66491"
"166.20000","83.10117","17.68139"
"166.40000","83.20101","17.69963"
"166.60000","83.30111","17.71610"
"166.80000","83.40102","17.72178"
"167.00000","83.50098","17.73155"
"167.20000","83.60114","17.74554"
"167.40000","83.70110","17.75610"
"167.60000","83.80107","17.77522"
"167.80000","83.90103","17.79698"
"168.00000","84.00112","17.81858"
"168.20000","84.10104","17.83522"
"168.40000","84.20106","17.85287"
"168.60000","84.30109","17.86966"
"168.80000","84.40112","17.88296"
"169.00000","84.50103","17.89745"
"169.20000","84.60098","17.90970"
"169.40000","84.70107","17.91838"
"169.60000","84.80105","17.92464"
"169.80000","84.90108","17.93615"
"170.00000","85.00104","17.94584"
"170.20000","85.10101","17.96451"
"170.40000","85.20104","17.98633"
"170.60000","85.30101","18.01059"
"170.80000","85.40109","18.03254"
"171.00000","85.50112","18.04491"
"171.20000","85.60103","18.06165"
"171.40000","85.70118","18.08113"
"171.60000","85.80108","18.09781"
"171.80000","85.90111","18.11541"
"172.00000","86.00101","18.13212"
"172.20000","86.10111","18.14080"
"172.40000","86.20102","18.14932"
"172.60000","86.30105","18.15742"
"172.80000","86.40115","18.16516"
"173.00000","86.50098","18.17721"
"173.20000","86.60101","18.19173"
"173.40000","86.70103","18.20749"
"173.60000","86.80102","18.22231"
"173.80000","86.90110","18.23706"
"174.00000","87.00118","18.25462"
"174.20000","87.10110","18.27270"
"174.40000","87.20112","18.29205"
"174.60000","87.30103","18.31160"
"174.80000","87.40100","18.32802"
"175.00000","87.50108","18.33555"
"175.20000","87.60111","18.34798"
"175.40000","87.70101","18.35679"
"175.60000","87.80112","18.36763"
"175.80000","87.90102","18.38951"
"176.00000","88.00111","18.40577"
"176.20000","88.10119","18.42317"
"176.40000","88.20105","18.44110"
"176.60000","88.30112","18.44881"
"176.80000","88.40110","18.46250"
"177.00000","88.50106","18.47496"
"177.20000","88.60116","18.48748"
"177.40000","88.70111","18.49999"
"177.60000","88.80109","18.51618"
"177.80000","88.90112","18.52867"
"178.00000","89.00114","18.53968"
"178.20000","89.10111","18.54984"
"178.40000","89.20108","18.56225"
"178.60000","89.30110","18.57348"
"178.80000","89.40114","18.59402"
"179.00000","89.50104","18.60910"
"179.20000","89.60107","18.62643"
"179.40000","89.70110","18.64218"
"179.60000","89.80125","18.65930"
"179.80000","89.90110","18.67350"
"180.00000","90.00107","18.69083"
"180.20000","90.10104","18.70734"
"180.40000","90.20113","18.72505"
"180.60000","90.30103","18.73732"
"180.80000","90.40112","18.74392"
"181.00000","90.50108","18.74930"
"181.20000","90.60112","18.75407"
"181.40000","90.70107","18.75838"
"181.60000","90.80111","18.76998"
"181.80000","90.90108","18.77718"
"182.00000","91.00110","18.79236"
"182.20000","91.10107","18.81002"
"182.40000","91.20103","18.82594"
"182.60000","91.30112","18.84197"
"182.80000","91.40104","18.85660"
"183.00000","91.50118","18.87019"
"183.20000","91.60116","18.88226"
"183.40000","91.70112","18.89645"
"183.60000","91.80103","18.91620"
"183.80000","91.90112","18.93347"
"184.00000","92.00103","18.95155"
"184.20000","92.10117","18.95992"
"184.40000","92.20114","18.96833"
"184.60000","92.30104","18.97897"
"184.80000","92.40114","18.98637"
"185.00000","92.50111","18.99748"
"185.20000","92.60101","19.00829"
"185.40000","92.70103","19.02010"
"185.60000","92.80119","19.03132"
"185.80000","92.90098","19.04361"
"186.00000","93.00106","19.05282"
"186.20000","93.10103","19.06098"
"186.40000","93.20112","19.07298"
"186.60000","93.30109","19.08575"
"186.80000","93.40106","19.09721"
"187.00000","93.50108","19.09218"
"187.20000","93.60106","19.11035"
"187.40000","93.70102","19.12306"
"187.60000","93.80105","19.13638"
"187.80000","93.90108","19.14343"
"188.00000","94.00104","19.15439"
"188.20000","94.10107","19.16456"
"188.40000","94.20110","19.16727"
"188.60000","94.30102","19.17231"
"188.80000","94.40103","19.17770"
"189.00000","94.50101","19.19467"
"189.20000","94.60110","19.20486"
"189.40000","94.70106","19.21637"
"189.60000","94.80109","19.23012"
"189.80000","94.90112","19.24123"
"190.00000","95.00108","19.24635"
"190.20000","95.10106","19.26246"
"190.40000","95.20102","19.26862"
"190.60000","95.30105","19.27369"
"190.80000","95.40114","19.27016"
"191.00000","95.50111","19.27825"
"191.20000","95.60113","19.28411"
"191.40000","95.70104","19.28883"
"191.60000","95.80101","19.29057"
"191.80000","95.90104","19.29386"
"192.00000","96.00117","19.29782"
"192.20000","96.10103","19.30017"
"192.40000","96.20100","19.29986"
"192.60000","96.30115","19.29625"
"192.80000","96.40112","19.29183"
"193.00000","96.50108","19.28256"
"193.20000","96.60110","19.26425"
"193.40000","96.70114","19.20107"
"193.51200","96.75710","18.80000"
"193.51600","96.75908","16.79622"
"193.52000","96.76105","14.14184"
"193.52400","96.76308","12.11947"
"193.52600","96.76410","11.22402"