File: MT-DataAnalysis-JupyterNotebook/TensionPlots/TensionTests/TurnNumber/Specimen_RawData_6.csv
End date,"8/16/2018"
Specimen label,"D32L50N8d4"
Maximum Load,"19.82815",N
Extension at Maximum Load,"144.65109",mm
Maximum Slope (Automatic Young's),"0.17154",N/mm
Rate 1,"30.00000",mm/min

Time,Extension,Load
(s),(mm),(N)
"0.00000","0.00006","0.00359"
"0.20000","0.09076","0.01721"
"0.40000","0.20167","0.03926"
"0.60000","0.30128","0.06084"
"0.80000","0.40107","0.08311"
"1.00000","0.50098","0.10211"
"1.20000","0.60100","0.12554"
"1.40000","0.70091","0.14228"
"1.60000","0.80100","0.15967"
"1.80000","0.90097","0.17635"
"2.00000","1.00094","0.18867"
"2.20000","1.10102","0.19993"
"2.40000","1.20099","0.21356"
"2.60000","1.30102","0.22735"
"2.80000","1.40099","0.24821"
"3.00000","1.50102","0.26633"
"3.20000","1.60104","0.28582"
"3.40000","1.70101","0.30471"
"3.60000","1.80098","0.32550"
"3.80000","1.90101","0.34456"
"4.00000","2.00104","0.36502"
"4.20000","2.10094","0.38271"
"4.40000","2.20103","0.39686"
"4.60000","2.30100","0.41152"
"4.80000","2.40103","0.42344"
"5.00000","2.50100","0.44505"
"5.20000","2.60102","0.46505"
"5.40000","2.70099","0.47886"
"5.60000","2.80096","0.49904"
"5.80000","2.90099","0.51652"
"6.00000","3.00120","0.53539"
"6.20000","3.10098","0.55946"
"6.40000","3.20101","0.57733"
"6.60000","3.30104","0.58998"
"6.80000","3.40101","0.60254"
"7.00000","3.50104","0.61581"
"7.20000","3.60106","0.62840"
"7.40000","3.70097","0.64226"
"7.60000","3.80100","0.66529"
"7.80000","3.90109","0.68659"
"8.00000","4.00106","0.70526"
"8.20000","4.10108","0.72221"
"8.40000","4.20099","0.74258"
"8.60000","4.30102","0.76128"
"8.80000","4.40105","0.77971"
"9.00000","4.50108","0.79299"
"9.20000","4.60098","0.80573"
"9.40000","4.70101","0.82203"
"9.60000","4.80104","0.83830"
"9.80000","4.90101","0.85718"
"10.00000","5.00110","0.87467"
"10.20000","5.10100","0.89368"
"10.40000","5.20103","0.91241"
"10.60000","5.30106","0.93039"
"10.80000","5.40103","0.95100"
"11.00000","5.50106","0.97188"
"11.20000","5.60108","0.99140"
"11.40000","5.70099","1.00621"
"11.60000","5.80102","1.01701"
"11.80000","5.90099","1.02627"
"12.00000","6.00108","1.04038"
"12.20000","6.10110","1.05791"
"12.40000","6.20101","1.07629"
"12.60000","6.30098","1.09820"
"12.80000","6.40101","1.12059"
"13.00000","6.50109","1.13938"
"13.20000","6.60106","1.16040"
"13.40000","6.70097","1.17909"
"13.60000","6.80106","1.19901"
"13.80000","6.90103","1.21090"
"14.00000","7.00100","1.22428"
"14.20000","7.10102","1.23713"
"14.40000","7.20105","1.25030"
"14.60000","7.30114","1.26781"
"14.80000","7.40105","1.28619"
"15.00000","7.50096","1.30318"
"15.20000","7.60092","1.32150"
"15.40000","7.70101","1.34014"
"15.60000","7.80098","1.36053"
"15.80000","7.90101","1.38076"
"16.00000","8.00109","1.40118"
"16.20000","8.10100","1.41721"
"16.40000","8.20109","1.43106"
"16.60000","8.30106","1.44478"
"16.80000","8.40109","1.45965"
"17.00000","8.50099","1.47535"
"17.20000","8.60108","1.49501"
"17.40000","8.70093","1.51506"
"17.60000","8.80102","1.53380"
"17.80000","8.90099","1.55204"
"18.00000","9.00096","1.57062"
"18.20000","9.10110","1.58758"
"18.40000","9.20101","1.60057"
"18.60000","9.30098","1.61626"
"18.80000","9.40107","1.62834"
"19.00000","9.50115","1.64164"
"19.20000","9.60100","1.66312"
"19.40000","9.70103","1.68127"
"19.60000","9.80106","1.70325"
"19.80000","9.90103","1.72329"
"20.00000","10.00105","1.74588"
"20.20000","10.10096","1.76532"
"20.40000","10.20099","1.78069"
"20.60000","10.30102","1.80505"
"20.80000","10.40099","1.81987"
"21.00000","10.50107","1.83330"
"21.20000","10.60110","1.84359"
"21.40000","10.70101","1.85202"
"21.60000","10.80110","1.86210"
"21.80000","10.90095","1.87695"
"22.00000","11.00103","1.89625"
"22.20000","11.10106","1.91354"
"22.40000","11.20109","1.93434"
"22.60000","11.30100","1.96103"
"22.80000","11.40097","1.98092"
"23.00000","11.50105","2.00121"
"23.20000","11.60114","2.02064"
"23.40000","11.70093","2.03646"
"23.60000","11.80102","2.05119"
"23.80000","11.90093","2.06591"
"24.00000","12.00107","2.08234"
"24.20000","12.10098","2.09942"
"24.40000","12.20095","2.11601"
"24.60000","12.30104","2.13104"
"24.80000","12.40107","2.14632"
"25.00000","12.50103","2.16262"
"25.20000","12.60094","2.18112"
"25.40000","12.70103","2.19840"
"25.60000","12.80100","2.21861"
"25.80000","12.90097","2.23564"
"26.00000","13.00099","2.25165"
"26.20000","13.10102","2.26659"
"26.40000","13.20111","2.28365"
"26.60000","13.30102","2.30016"
"26.80000","13.40093","2.32186"
"27.00000","13.50107","2.34213"
"27.20000","13.60104","2.36343"
"27.40000","13.70095","2.38363"
"27.60000","13.80110","2.40040"
"27.80000","13.90101","2.41721"
"28.00000","14.00097","2.43343"
"28.20000","14.10100","2.44356"
"28.40000","14.20097","2.45206"
"28.60000","14.30100","2.45979"
"28.80000","14.40097","2.47350"
"29.00000","14.50100","2.49482"
"29.20000","14.60108","2.51468"
"29.40000","14.70111","2.53727"
"29.60000","14.80096","2.55983"
"29.80000","14.90105","2.58041"
"30.00000","15.00102","2.60338"
"30.20000","15.10098","2.62236"
"30.40000","15.20101","2.64366"
"30.60000","15.30098","2.66071"
"30.80000","15.40101","2.67262"
"31.00000","15.50104","2.68537"
"31.20000","15.60094","2.69540"
"31.40000","15.70115","2.70634"
"31.60000","15.80100","2.72221"
"31.80000","15.90108","2.73784"
"32.00000","16.00099","2.75629"
"32.20000","16.10102","2.77346"
"32.40000","16.20099","2.79738"
"32.60000","16.30108","2.81993"
"32.80000","16.40104","2.83777"
"33.00000","16.50095","2.85504"
"33.20000","16.60104","2.87161"
"33.40000","16.70095","2.88787"
"33.60000","16.80104","2.90579"
"33.80000","16.90101","2.92123"
"34.00000","17.00103","2.94588"
"34.20000","17.10106","2.96341"
"34.40000","17.20103","2.97920"
"34.60000","17.30094","2.99417"
"34.80000","17.40109","3.00719"
"35.00000","17.50105","3.02394"
"35.20000","17.60102","3.03889"
"35.40000","17.70105","3.05359"
"35.60000","17.80102","3.06675"
"35.80000","17.90111","3.08074"
"36.00000","18.00096","3.09722"
"36.20000","18.10098","3.11337"
"36.40000","18.20107","3.13401"
"36.60000","18.30104","3.15380"
"36.80000","18.40101","3.17793"
"37.00000","18.50097","3.19701"
"37.20000","18.60094","3.21973"
"37.40000","18.70109","3.23901"
"37.60000","18.80112","3.25645"
"37.80000","18.90097","3.27483"
"38.00000","19.00111","3.28493"
"38.20000","19.10096","3.29219"
"38.40000","19.20093","3.30170"
"38.60000","19.30102","3.31826"
"38.80000","19.40104","3.33508"
"39.00000","19.50101","3.35538"
"39.20000","19.60098","3.37652"
"39.40000","19.70095","3.39571"
"39.60000","19.80092","3.41651"
"39.80000","19.90100","3.43621"
"40.00000","20.00109","3.45752"
"40.20000","20.10100","3.47664"
"40.40000","20.20103","3.49136"
"40.60000","20.30100","3.50653"
"40.80000","20.40109","3.51859"
"41.00000","20.50099","3.53278"
"41.20000","20.60096","3.54960"
"41.40000","20.70111","3.56731"
"41.60000","20.80102","3.58349"
"41.80000","20.90099","3.59894"
"42.00000","21.00095","3.61527"
"42.20000","21.10098","3.63339"
"42.40000","21.20101","3.65337"
"42.60000","21.30098","3.66747"
"42.80000","21.40095","3.68490"
"43.00000","21.50103","3.69960"
"43.20000","21.60094","3.71470"
"43.40000","21.70097","3.72835"
"43.60000","21.80106","3.75065"
"43.80000","21.90096","3.77263"
"44.00000","22.00105","3.79447"
"44.20000","22.10102","3.81366"
"44.40000","22.20099","3.83146"
"44.60000","22.30096","3.84624"
"44.80000","22.40105","3.86273"
"45.00000","22.50095","3.88002"
"45.20000","22.60098","3.89219"
"45.40000","22.70095","3.90488"
"45.60000","22.80098","3.91794"
"45.80000","22.90107","3.93245"
"46.00000","23.00097","3.95186"
"46.20000","23.10094","3.96911"
"46.40000","23.20103","3.98824"
"46.60000","23.30112","4.00983"
"46.80000","23.40097","4.02996"
"47.00000","23.50099","4.05116"
"47.20000","23.60096","4.07164"
"47.40000","23.70099","4.09193"
"47.60000","23.80107","4.10641"
"47.80000","23.90099","4.11690"
"48.00000","24.00101","4.12363"
"48.20000","24.10104","4.13756"
"48.40000","24.20101","4.15649"
"48.60000","24.30104","4.17595"
"48.80000","24.40107","4.19475"
"49.00000","24.50103","4.21228"
"49.20000","24.60100","4.23344"
"49.40000","24.70103","4.24890"
"49.60000","24.80106","4.26744"
"49.80000","24.90103","4.28899"
"50.00000","25.00099","4.30206"
"50.20000","25.10108","4.31751"
"50.40000","25.20105","4.33105"
"50.60000","25.30102","4.34889"
"50.80000","25.40104","4.36596"
"51.00000","25.50101","4.37939"
"51.20000","25.60104","4.39752"
"51.40000","25.70095","4.41465"
"51.60000","25.80098","4.43307"
"51.80000","25.90107","4.45418"
"52.00000","26.00109","4.47309"
"52.20000","26.10112","4.49181"
"52.40000","26.20097","4.50571"
"52.60000","26.30106","4.52241"
"52.80000","26.40102","4.53362"
"53.00000","26.50111","4.54823"
"53.20000","26.60096","4.56344"
"53.40000","26.70099","4.58443"
"53.60000","26.80096","4.60458"
"53.80000","26.90098","4.62806"
"54.00000","27.00101","4.64423"
"54.20000","27.10104","4.66221"
"54.40000","27.20107","4.68008"
"54.60000","27.30110","4.69927"
"54.80000","27.40107","4.71406"
"55.00000","27.50097","4.72457"
"55.20000","27.60106","4.73853"
"55.40000","27.70097","4.75049"
"55.60000","27.80100","4.76915"
"55.80000","27.90103","4.78797"
"56.00000","28.00105","4.80660"
"56.20000","28.10102","4.82425"
"56.40000","28.20099","4.84293"
"56.60000","28.30102","4.85992"
"56.80000","28.40104","4.88034"
"57.00000","28.50107","4.90307"
"57.20000","28.60104","4.92050"
"57.40000","28.70101","4.93207"
"57.60000","28.80098","4.94330"
"57.80000","28.90095","4.95472"
"58.00000","29.00103","4.97215"
"58.20000","29.10106","4.98878"
"58.40000","29.20091","5.00517"
"58.60000","29.30100","5.02644"
"58.80000","29.40102","5.04698"
"59.00000","29.50111","5.06906"
"59.20000","29.60096","5.08807"
"59.40000","29.70105","5.10718"
"59.60000","29.80096","5.12355"
"59.80000","29.90116","5.13773"
"60.00000","30.00101","5.14609"
"60.20000","30.10104","5.16182"
"60.40000","30.20095","5.17747"
"60.60000","30.30104","5.19555"
"60.80000","30.40100","5.21233"
"61.00000","30.50097","5.23083"
"61.20000","30.60106","5.24607"
"61.40000","30.70103","5.26489"
"61.60000","30.80094","5.28306"
"61.80000","30.90102","5.30086"
"62.00000","31.00111","5.31677"
"62.20000","31.10102","5.33742"
"62.40000","31.20105","5.35169"
"62.60000","31.30101","5.36593"
"62.80000","31.40098","5.38232"
"63.00000","31.50101","5.40065"
"63.20000","31.60104","5.41742"
"63.40000","31.70113","5.43846"
"63.60000","31.80103","5.45692"
"63.80000","31.90100","5.47724"
"64.00000","32.00103","5.49345"
"64.20000","32.10106","5.50935"
"64.40000","32.20103","5.52532"
"64.60000","32.30106","5.53616"
"64.80000","32.40102","5.54626"
"65.00000","32.50105","5.55538"
"65.20000","32.60102","5.57384"
"65.40000","32.70105","5.59563"
"65.60000","32.80114","5.61462"
"65.80000","32.90105","5.63635"
"66.00000","33.00101","5.65415"
"66.20000","33.10104","5.67990"
"66.40000","33.20095","5.69790"
"66.60000","33.30098","5.71789"
"66.80000","33.40100","5.73820"
"67.00000","33.50103","5.75210"
"67.20000","33.60106","5.76323"
"67.40000","33.70097","5.77298"
"67.60000","33.80112","5.78506"
"67.80000","33.90108","5.79421"
"68.00000","34.00105","5.81419"
"68.20000","34.10102","5.83089"
"68.40000","34.20111","5.85115"
"68.60000","34.30102","5.87198"
"68.80000","34.40099","5.89260"
"69.00000","34.50107","5.91545"
"69.20000","34.60098","5.93270"
"69.40000","34.70107","5.95060"
"69.60000","34.80104","5.96671"
"69.80000","34.90106","5.98043"
"70.00000","35.00097","5.99192"
"70.20000","35.10100","6.00791"
"70.40000","35.20091","6.02962"
"70.60000","35.30112","6.04725"
"70.80000","35.40102","6.06176"
"71.00000","35.50093","6.07588"
"71.20000","35.60108","6.09027"
"71.40000","35.70111","6.10391"
"71.60000","35.80101","6.12367"
"71.80000","35.90099","6.14017"
"72.00000","36.00107","6.15746"
"72.20000","36.10104","6.17134"
"72.40000","36.20095","6.18771"
"72.60000","36.30091","6.20587"
"72.80000","36.40100","6.22758"
"73.00000","36.50103","6.24730"
"73.20000","36.60100","6.26543"
"73.40000","36.70097","6.28914"
"73.60000","36.80106","6.31032"
"73.80000","36.90108","6.32864"
"74.00000","37.00099","6.34514"
"74.20000","37.10096","6.35933"
"74.40000","37.20111","6.36874"
"74.60000","37.30101","6.37733"
"74.80000","37.40092","6.38665"
"75.00000","37.50101","6.40117"
"75.20000","37.60092","6.41554"
"75.40000","37.70095","6.43717"
"75.60000","37.80103","6.45698"
"75.80000","37.90100","6.47422"
"76.00000","38.00097","6.49821"
"76.20000","38.10106","6.51962"
"76.40000","38.20097","6.54116"
"76.60000","38.30106","6.56106"
"76.80000","38.40096","6.57845"
"77.00000","38.50099","6.59357"
"77.20000","38.60108","6.60675"
"77.40000","38.70105","6.61660"
"77.60000","38.80090","6.63071"
"77.80000","38.90098","6.64699"
"78.00000","39.00107","6.66147"
"78.20000","39.10104","6.67802"
"78.40000","39.20107","6.69842"
"78.60000","39.30103","6.71495"
"78.80000","39.40100","6.73338"
"79.00000","39.50097","6.75759"
"79.20000","39.60094","6.77035"
"79.40000","39.70096","6.78365"
"79.60000","39.80106","6.79899"
"79.80000","39.90102","6.81564"
"80.00000","40.00099","6.83398"
"80.20000","40.10096","6.85225"
"80.40000","40.20105","6.87303"
"80.60000","40.30114","6.88813"
"80.80000","40.40092","6.90958"
"81.00000","40.50107","6.92726"
"81.20000","40.60098","6.94199"
"81.40000","40.70113","6.95664"
"81.60000","40.80104","6.97036"
"81.80000","40.90100","6.98227"
"82.00000","41.00097","6.99227"
"82.20000","41.10100","7.00802"
"82.40000","41.20097","7.02509"
"82.60000","41.30099","7.04490"
"82.80000","41.40102","7.06350"
"83.00000","41.50099","7.08204"
"83.20000","41.60096","7.10681"
"83.40000","41.70099","7.12692"
"83.60000","41.80107","7.14724"
"83.80000","41.90110","7.17018"
"84.00000","42.00101","7.18731"
"84.20000","42.10098","7.20012"
"84.40000","42.20107","7.21139"
"84.60000","42.30097","7.21947"
"84.80000","42.40107","7.22834"
"85.00000","42.50103","7.24078"
"85.20000","42.60100","7.25907"
"85.40000","42.70103","7.27904"
"85.60000","42.80099","7.29829"
"85.80000","42.90096","7.31921"
"86.00000","43.00105","7.33767"
"86.20000","43.10090","7.35807"
"86.40000","43.20098","7.37468"
"86.60000","43.30107","7.39490"
"86.80000","43.40098","7.41146"
"87.00000","43.50101","7.42561"
"87.20000","43.60104","7.44285"
"87.40000","43.70112","7.45814"
"87.60000","43.80104","7.47539"
"87.80000","43.90100","7.49295"
"88.00000","44.00097","7.50756"
"88.20000","44.10100","7.52314"
"88.40000","44.20102","7.53965"
"88.60000","44.30093","7.55637"
"88.80000","44.40108","7.57571"
"89.00000","44.50111","7.59426"
"89.20000","44.60108","7.60631"
"89.40000","44.70099","7.61884"
"89.60000","44.80107","7.63403"
"89.80000","44.90104","7.65514"
"90.00000","45.00107","7.66742"
"90.20000","45.10098","7.68738"
"90.40000","45.20100","7.71222"
"90.60000","45.30104","7.73440"
"90.80000","45.40106","7.75247"
"91.00000","45.50103","7.76863"
"91.20000","45.60106","7.78568"
"91.40000","45.70103","7.80179"
"91.60000","45.80099","7.81290"
"91.80000","45.90108","7.82218"
"92.00000","46.00099","7.83243"
"92.20000","46.10102","7.84697"
"92.40000","46.20105","7.86749"
"92.60000","46.30113","7.88580"
"92.80000","46.40098","7.90565"
"93.00000","46.50113","7.92411"
"93.20000","46.60104","7.94374"
"93.40000","46.70095","7.96417"
"93.60000","46.80098","7.98370"
"93.80000","46.90112","8.00290"
"94.00000","47.00097","8.02065"
"94.20000","47.10100","8.03150"
"94.40000","47.20103","8.04388"
"94.60000","47.30093","8.05264"
"94.80000","47.40108","8.06465"
"95.00000","47.50099","8.08306"
"95.20000","47.60101","8.10312"
"95.40000","47.70105","8.11876"
"95.60000","47.80108","8.13855"
"95.80000","47.90092","8.15732"
"96.00000","48.00107","8.17592"
"96.20000","48.10104","8.19392"
"96.40000","48.20107","8.21336"
"96.60000","48.30103","8.22564"
"96.80000","48.40095","8.23597"
"97.00000","48.50097","8.25320"
"97.20000","48.60100","8.27051"
"97.40000","48.70103","8.29028"
"97.60000","48.80100","8.30918"
"97.80000","48.90108","8.33020"
"98.00000","49.00099","8.34438"
"98.20000","49.10102","8.36153"
"98.40000","49.20099","8.37871"
"98.60000","49.30107","8.39472"
"98.80000","49.40098","8.41374"
"99.00000","49.50113","8.43097"
"99.20000","49.60098","8.44091"
"99.40000","49.70107","8.45399"
"99.60000","49.80098","8.46787"
"99.80000","49.90107","8.47940"
"100.00000","50.00097","8.50079"
"100.20000","50.10094","8.51852"
"100.40000","50.20108","8.53869"
"100.60000","50.30094","8.55626"
"100.80000","50.40096","8.57711"
"101.00000","50.50099","8.59441"
"101.20000","50.60102","8.61310"
"101.40000","50.70105","8.62892"
"101.60000","50.80107","8.64332"
"101.80000","50.90099","8.65274"
"102.00000","51.00101","8.66904"
"102.20000","51.10098","8.68467"
"102.40000","51.20095","8.69965"
"102.60000","51.30097","8.72557"
"102.80000","51.40094","8.73965"
"103.00000","51.50091","8.75588"
"103.20000","51.60106","8.77304"
"103.40000","51.70090","8.79232"
"103.60000","51.80094","8.81259"
"103.80000","51.90102","8.83004"
"104.00000","52.00099","8.84658"
"104.20000","52.10096","8.85696"
"104.40000","52.20098","8.86877"
"104.60000","52.30101","8.87935"
"104.80000","52.40098","8.89736"
"105.00000","52.50107","8.91455"
"105.20000","52.60098","8.92984"
"105.40000","52.70101","8.94851"
"105.60000","52.80098","8.97082"
"105.80000","52.90106","8.99034"
"106.00000","53.00103","9.01021"
"106.20000","53.10099","9.03325"
"106.40000","53.20109","9.04393"
"106.60000","53.30099","9.05729"
"106.80000","53.40102","9.06791"
"107.00000","53.50105","9.07715"
"107.20000","53.60108","9.09533"
"107.40000","53.70092","9.11557"
"107.60000","53.80101","9.13447"
"107.80000","53.90098","9.15045"
"108.00000","54.00107","9.16773"
"108.20000","54.10104","9.18354"
"108.40000","54.20100","9.19677"
"108.60000","54.30109","9.21541"
"108.80000","54.40100","9.23507"
"109.00000","54.50097","9.25196"
"109.20000","54.60100","9.26465"
"109.40000","54.70108","9.27793"
"109.60000","54.80105","9.29399"
"109.80000","54.90096","9.31170"
"110.00000","55.00093","9.32829"
"110.20000","55.10108","9.34644"
"110.40000","55.20105","9.36460"
"110.60000","55.30101","9.38295"
"110.80000","55.40098","9.40248"
"111.00000","55.50101","9.42109"
"111.20000","55.60098","9.43776"
"111.40000","55.70101","9.45413"
"111.60000","55.80098","9.46290"
"111.80000","55.90100","9.47289"
"112.00000","56.00109","9.48221"
"112.20000","56.10094","9.49491"
"112.40000","56.20103","9.51847"
"112.60000","56.30106","9.53949"
"112.80000","56.40102","9.55870"
"113.00000","56.50105","9.58257"
"113.20000","56.60102","9.59939"
"113.40000","56.70093","9.61958"
"113.60000","56.80107","9.63778"
"113.80000","56.90098","9.65624"
"114.00000","57.00095","9.67176"
"114.20000","57.10104","9.68465"
"114.40000","57.20101","9.69382"
"114.60000","57.30104","9.70487"
"114.80000","57.40100","9.71741"
"115.00000","57.50097","9.73160"
"115.20000","57.60100","9.74529"
"115.40000","57.70115","9.76254"
"115.60000","57.80093","9.77860"
"115.80000","57.90096","9.79990"
"116.00000","58.00099","9.81928"
"116.20000","58.10096","9.84524"
"116.40000","58.20105","9.86287"
"116.60000","58.30096","9.87552"
"116.80000","58.40099","9.88957"
"117.00000","58.50095","9.89950"
"117.20000","58.60110","9.91457"
"117.40000","58.70100","9.93098"
"117.60000","58.80103","9.95391"
"117.80000","58.90094","9.97561"
"118.00000","59.00109","9.99122"
"118.20000","59.10100","10.00637"
"118.40000","59.20115","10.02008"
"118.60000","59.30099","10.03572"
"118.80000","59.40102","10.05024"
"119.00000","59.50099","10.06485"
"119.20000","59.60096","10.07725"
"119.40000","59.70105","10.08736"
"119.60000","59.80107","10.09989"
"119.80000","59.90099","10.11973"
"120.00000","60.00095","10.14137"
"120.20000","60.10098","10.16316"
"120.40000","60.20101","10.17989"
"120.60000","60.30103","10.19951"
"120.80000","60.40112","10.21825"
"121.00000","60.50103","10.23845"
"121.20000","60.60106","10.25987"
"121.40000","60.70103","10.27683"
"121.60000","60.80099","10.28731"
"121.80000","60.90108","10.29558"
"122.00000","61.00105","10.30302"
"122.20000","61.10102","10.31052"
"122.40000","61.20110","10.32174"
"122.60000","61.30101","10.33949"
"122.80000","61.40098","10.35915"
"123.00000","61.50107","10.38060"
"123.20000","61.60104","10.40002"
"123.40000","61.70101","10.41887"
"123.60000","61.80109","10.43978"
"123.80000","61.90100","10.45867"
"124.00000","62.00103","10.48034"
"124.20000","62.10100","10.49394"
"124.40000","62.20114","10.50756"
"124.60000","62.30105","10.52225"
"124.80000","62.40108","10.53650"
"125.00000","62.50092","10.55117"
"125.20000","62.60101","10.56452"
"125.40000","62.70104","10.57962"
"125.60000","62.80101","10.59317"
"125.80000","62.90110","10.60477"
"126.00000","63.00101","10.62111"
"126.20000","63.10104","10.63866"
"126.40000","63.20106","10.65916"
"126.60000","63.30116","10.67889"
"126.80000","63.40106","10.69314"
"127.00000","63.50109","10.70754"
"127.20000","63.60099","10.72260"
"127.40000","63.70103","10.73592"
"127.60000","63.80099","10.75426"
"127.80000","63.90108","10.77501"
"128.00000","64.00105","10.79788"
"128.20000","64.10102","10.81143"
"128.40000","64.20098","10.83336"
"128.60000","64.30101","10.84643"
"128.80000","64.40110","10.86364"
"129.00000","64.50101","10.87817"
"129.20000","64.60110","10.89085"
"129.40000","64.70113","10.90059"
"129.60000","64.80109","10.90919"
"129.80000","64.90094","10.92006"
"130.00000","65.00097","10.93344"
"130.20000","65.10100","10.94629"
"130.40000","65.20102","10.96632"
"130.60000","65.30106","10.98710"
"130.80000","65.40102","11.00603"
"131.00000","65.50099","11.02413"
"131.20000","65.60107","11.04257"
"131.40000","65.70099","11.06556"
"131.60000","65.80095","11.08731"
"131.80000","65.90110","11.10637"
"132.00000","66.00101","11.12164"
"132.20000","66.10104","11.13126"
"132.40000","66.20100","11.14008"
"132.60000","66.30097","11.14839"
"132.80000","66.40088","11.15988"
"133.00000","66.50109","11.17634"
"133.20000","66.60099","11.19307"
"133.40000","66.70103","11.21037"
"133.60000","66.80105","11.23008"
"133.80000","66.90096","11.24729"
"134.00000","67.00111","11.26730"
"134.20000","67.10096","11.28739"
"134.40000","67.20098","11.30458"
"134.60000","67.30107","11.31721"
"134.80000","67.40109","11.33233"
"135.00000","67.50095","11.34405"
"135.20000","67.60098","11.36201"
"135.40000","67.70100","11.37843"
"135.60000","67.80103","11.39610"
"135.80000","67.90100","11.41335"
"136.00000","68.00114","11.42891"
"136.20000","68.10094","11.44135"
"136.40000","68.20108","11.45655"
"136.60000","68.30093","11.47213"
"136.80000","68.40102","11.48678"
"137.00000","68.50099","11.50172"
"137.20000","68.60095","11.51882"
"137.40000","68.70093","11.52947"
"137.60000","68.80101","11.54118"
"137.80000","68.90104","11.55037"
"138.00000","69.00106","11.56703"
"138.20000","69.10098","11.58751"
"138.40000","69.20100","11.60760"
"138.60000","69.30097","11.62732"
"138.80000","69.40099","11.64844"
"139.00000","69.50108","11.67068"
"139.20000","69.60093","11.68884"
"139.40000","69.70103","11.70075"
"139.60000","69.80105","11.71486"
"139.80000","69.90102","11.73037"
"140.00000","70.00105","11.73779"
"140.20000","70.10095","11.74762"
"140.40000","70.20092","11.75628"
"140.60000","70.30101","11.77593"
"140.80000","70.40098","11.79074"
"141.00000","70.50095","11.81049"
"141.20000","70.60110","11.82853"
"141.40000","70.70100","11.84268"
"141.60000","70.80103","11.85946"
"141.80000","70.90106","11.87832"
"142.00000","71.00103","11.89898"
"142.20000","71.10105","11.91927"
"142.40000","71.20109","11.93574"
"142.60000","71.30099","11.94811"
"142.80000","71.40108","11.96043"
"143.00000","71.50098","11.97318"
"143.20000","71.60096","11.98473"
"143.40000","71.70104","12.00084"
"143.60000","71.80096","12.01362"
"143.80000","71.90110","12.03051"
"144.00000","72.00101","12.04636"
"144.20000","72.10110","12.06184"
"144.40000","72.20100","12.08077"
"144.60000","72.30115","12.09931"
"144.80000","72.40100","12.11672"
"145.00000","72.50102","12.13176"
"145.20000","72.60106","12.14389"
"145.40000","72.70090","12.15483"
"145.60000","72.80099","12.16992"
"145.80000","72.90096","12.17762"
"146.00000","73.00093","12.19769"
"146.20000","73.10101","12.21525"
"146.40000","73.20110","12.23389"
"146.60000","73.30101","12.25058"
"146.80000","73.40092","12.26758"
"147.00000","73.50095","12.28440"
"147.20000","73.60110","12.30002"
"147.40000","73.70107","12.31523"
"147.60000","73.80103","12.33238"
"147.80000","73.90100","12.34527"
"148.00000","74.00103","12.35864"
"148.20000","74.10099","12.36915"
"148.40000","74.20103","12.38311"
"148.60000","74.30105","12.39592"
"148.80000","74.40108","12.41485"
"149.00000","74.50098","12.43158"
"149.20000","74.60101","12.44962"
"149.40000","74.70098","12.46549"
"149.60000","74.80096","12.48520"
"149.80000","74.90110","12.50398"
"150.00000","75.00107","12.52084"
"150.20000","75.10109","12.53781"
"150.40000","75.20107","12.54578"
"150.60000","75.30103","12.56028"
"150.80000","75.40088","12.57143"
"151.00000","75.50102","12.58018"
"151.20000","75.60111","12.58976"
"151.40000","75.70102","12.60744"
"151.60000","75.80106","12.62648"
"151.80000","75.90102","12.64686"
"152.00000","76.00093","12.66287"
"152.20000","76.10101","12.67979"
"152.40000","76.20110","12.69612"
"152.60000","76.30095","12.71358"
"152.80000","76.40104","12.72814"
"153.00000","76.50101","12.74495"
"153.20000","76.60104","12.75999"
"153.40000","76.70100","12.77231"
"153.60000","76.80097","12.78468"
"153.80000","76.90105","12.79695"
"154.00000","77.00103","12.81019"
"154.20000","77.10099","12.82189"
"154.40000","77.20103","12.83912"
"154.60000","77.30099","12.85661"
"154.80000","77.40102","12.87276"
"155.00000","77.50098","12.88820"
"155.20000","77.60090","12.90746"
"155.40000","77.70098","12.92700"
"155.60000","77.80101","12.94442"
"155.80000","77.90098","12.96179"
"156.00000","78.00107","12.96965"
"156.20000","78.10109","12.98379"
"156.40000","78.20107","12.99528"
"156.60000","78.30103","13.00758"
"156.80000","78.40100","13.02228"
"157.00000","78.50096","13.03817"
"157.20000","78.60105","13.05740"
"157.40000","78.70096","13.07423"
"157.60000","78.80093","13.08898"
"157.80000","78.90102","13.10312"
"158.00000","79.00093","13.11681"
"158.20000","79.10102","13.13176"
"158.40000","79.20104","13.14762"
"158.60000","79.30089","13.16372"
"158.80000","79.40103","13.17339"
"159.00000","79.50106","13.18746"
"159.20000","79.60097","13.19786"
"159.40000","79.70107","13.21512"
"159.60000","79.80097","13.23184"
"159.80000","79.90093","13.24982"
"160.00000","80.00097","13.26731"
"160.20000","80.10100","13.28196"
"160.40000","80.20097","13.29660"
"160.60000","80.30106","13.31381"
"160.80000","80.40096","13.33301"
"161.00000","80.50099","13.35236"
"161.20000","80.60107","13.36771"
"161.40000","80.70110","13.37592"
"161.60000","80.80107","13.38598"
"161.80000","80.90099","13.39323"
"162.00000","81.00101","13.40319"
"162.20000","81.10098","13.41276"
"162.40000","81.20106","13.42871"
"162.60000","81.30096","13.44702"
"162.80000","81.40099","13.46498"
"163.00000","81.50097","13.48489"
"163.20000","81.60105","13.50403"
"163.40000","81.70103","13.51918"
"163.60000","81.80111","13.53700"
"163.80000","81.90102","13.55809"
"164.00000","82.00105","13.57271"
"164.20000","82.10107","13.58604"
"164.40000","82.20110","13.59838"
"164.60000","82.30106","13.60993"
"164.80000","82.40097","13.62010"
"165.00000","82.50101","13.63271"
"165.20000","82.60091","13.64545"
"165.40000","82.70107","13.66125"
"165.60000","82.80103","13.67543"
"165.80000","82.90100","13.69027"
"166.00000","83.00108","13.70266"
"166.20000","83.10111","13.71504"
"166.40000","83.20101","13.73015"
"166.60000","83.30106","13.75114"
"166.80000","83.40107","13.77202"
"167.00000","83.50111","13.79096"
"167.20000","83.60095","13.80326"
"167.40000","83.70104","13.81142"
"167.60000","83.80107","13.82365"
"167.80000","83.90103","13.83516"
"168.00000","84.00095","13.84890"
"168.20000","84.10104","13.86727"
"168.40000","84.20106","13.88465"
"168.60000","84.30097","13.90356"
"168.80000","84.40105","13.91793"
"169.00000","84.50103","13.93169"
"169.20000","84.60111","13.94721"
"169.40000","84.70103","13.96177"
"169.60000","84.80110","13.97230"
"169.80000","84.90102","13.98491"
"170.00000","85.00104","13.99470"
"170.20000","85.10095","14.00260"
"170.40000","85.20104","14.01145"
"170.60000","85.30101","14.02428"
"170.80000","85.40091","14.04541"
"171.00000","85.50107","14.06486"
"171.20000","85.60098","14.09053"
"171.40000","85.70100","14.10517"
"171.60000","85.80096","14.11800"
"171.80000","85.90111","14.13528"
"172.00000","86.00101","14.14980"
"172.20000","86.10106","14.17037"
"172.40000","86.20102","14.18669"
"172.60000","86.30105","14.20504"
"172.80000","86.40102","14.21302"
"173.00000","86.50105","14.22206"
"173.20000","86.60094","14.22946"
"173.40000","86.70103","14.23451"
"173.60000","86.80095","14.24355"
"173.80000","86.90097","14.25477"
"174.00000","87.00089","14.27143"
"174.20000","87.10098","14.28909"
"174.40000","87.20100","14.30457"
"174.60000","87.30103","14.31906"
"174.80000","87.40112","14.33716"
"175.00000","87.50097","14.35850"
"175.20000","87.60099","14.37296"
"175.40000","87.70108","14.39314"
"175.60000","87.80112","14.40482"
"175.80000","87.90096","14.41949"
"176.00000","88.00111","14.43029"
"176.20000","88.10107","14.44459"
"176.40000","88.20105","14.45693"
"176.60000","88.30094","14.47123"
"176.80000","88.40099","14.48744"
"177.00000","88.50106","14.50316"
"177.20000","88.60097","14.51570"
"177.40000","88.70094","14.52787"
"177.60000","88.80109","14.53859"
"177.80000","88.90105","14.55279"
"178.00000","89.00109","14.56590"
"178.20000","89.10111","14.58139"
"178.40000","89.20103","14.59570"
"178.60000","89.30110","14.60993"
"178.80000","89.40102","14.62100"
"179.00000","89.50098","14.63301"
"179.20000","89.60107","14.64739"
"179.40000","89.70104","14.65480"
"179.60000","89.80101","14.67367"
"179.80000","89.90103","14.69100"
"180.00000","90.00107","14.71021"
"180.20000","90.10104","14.72665"
"180.40000","90.20106","14.74223"
"180.60000","90.30103","14.75920"
"180.80000","90.40106","14.77455"
"181.00000","90.50101","14.78981"
"181.20000","90.60112","14.80233"
"181.40000","90.70102","14.81425"
"181.60000","90.80106","14.82278"
"181.80000","90.90108","14.82894"
"182.00000","91.00105","14.83691"
"182.20000","91.10101","14.84343"
"182.40000","91.20093","14.85808"
"182.60000","91.30101","14.87458"
"182.80000","91.40097","14.88924"
"183.00000","91.50107","14.91118"
"183.20000","91.60110","14.92563"
"183.40000","91.70100","14.93974"
"183.60000","91.80103","14.95279"
"183.80000","91.90105","14.96985"
"184.00000","92.00097","14.98997"
"184.20000","92.10105","15.01134"
"184.40000","92.20108","15.02916"
"184.60000","92.30099","15.04121"
"184.80000","92.40102","15.05017"
"185.00000","92.50098","15.05945"
"185.20000","92.60101","15.06777"
"185.40000","92.70103","15.07553"
"185.60000","92.80101","15.08754"
"185.80000","92.90098","15.09881"
"186.00000","93.00106","15.10800"
"186.20000","93.10091","15.12236"
"186.40000","93.20107","15.13410"
"186.60000","93.30097","15.14784"
"186.80000","93.40112","15.16289"
"187.00000","93.50102","15.18020"
"187.20000","93.60094","15.20140"
"187.40000","93.70096","15.21733"
"187.60000","93.80099","15.22904"
"187.80000","93.90095","15.23848"
"188.00000","94.00104","15.24692"
"188.20000","94.10101","15.26279"
"188.40000","94.20093","15.27792"
"188.60000","94.30113","15.28958"
"188.80000","94.40098","15.30765"
"189.00000","94.50101","15.32642"
"189.20000","94.60098","15.33702"
"189.40000","94.70100","15.35291"
"189.60000","94.80103","15.36475"
"189.80000","94.90099","15.37658"
"190.00000","95.00090","15.38875"
"190.20000","95.10100","15.40168"
"190.40000","95.20107","15.41478"
"190.60000","95.30099","15.42684"
"190.80000","95.40102","15.43750"
"191.00000","95.50105","15.44591"
"191.20000","95.60101","15.45610"
"191.40000","95.70104","15.46498"
"191.60000","95.80089","15.47870"
"191.80000","95.90098","15.49279"
"192.00000","96.00100","15.50782"
"192.20000","96.10103","15.52205"
"192.40000","96.20094","15.53732"
"192.60000","96.30097","15.55506"
"192.80000","96.40099","15.57098"
"193.00000","96.50108","15.59003"
"193.20000","96.60094","15.60486"
"193.40000","96.70109","15.62461"
"193.60000","96.80099","15.63954"
"193.80000","96.90113","15.65023"
"194.00000","97.00098","15.65769"
"194.20000","97.10102","15.66352"
"194.40000","97.20103","15.67039"
"194.60000","97.30101","15.67722"
"194.80000","97.40098","15.68430"
"195.00000","97.50095","15.69867"
"195.20000","97.60097","15.71617"
"195.40000","97.70107","15.73334"
"195.60000","97.80090","15.74878"
"195.80000","97.90100","15.76460"
"196.00000","98.00096","15.77726"
"196.20000","98.10105","15.79087"
"196.40000","98.20107","15.80638"
"196.60000","98.30099","15.82064"
"196.80000","98.40108","15.83662"
"197.00000","98.50105","15.84973"
"197.20000","98.60114","15.86027"
"197.40000","98.70104","15.86986"
"197.60000","98.80100","15.88000"
"197.80000","98.90098","15.89386"
"198.00000","99.00101","15.90535"
"198.20000","99.10098","15.91711"
"198.40000","99.20100","15.92969"
"198.60000","99.30096","15.94075"
"198.80000","99.40099","15.95237"
"199.00000","99.50102","15.96356"
"199.20000","99.60099","15.97627"
"199.40000","99.70108","15.99110"
"199.60000","99.80105","16.00709"
"199.80000","99.90114","16.02332"
"200.00000","100.00098","16.03808"
"200.20000","100.10101","16.05327"
"200.40000","100.20098","16.06235"
"200.60000","100.30101","16.07065"
"200.80000","100.40108","16.07732"
"201.00000","100.50095","16.08501"
"201.20000","100.60103","16.09472"
"201.40000","100.70107","16.11252"
"201.60000","100.80103","16.12896"
"201.80000","100.90105","16.14489"
"202.00000","101.00108","16.16179"
"202.20000","101.10099","16.17501"
"202.40000","101.20115","16.18934"
"202.60000","101.30104","16.20230"
"202.80000","101.40102","16.21536"
"203.00000","101.50105","16.22901"
"203.20000","101.60114","16.24031"
"203.40000","101.70098","16.25099"
"203.60000","101.80108","16.26153"
"203.80000","101.90098","16.27129"
"204.00000","102.00106","16.27985"
"204.20000","102.10097","16.28784"
"204.40000","102.20100","16.29727"
"204.60000","102.30103","16.31148"
"204.80000","102.40106","16.32510"
"205.00000","102.50108","16.33822"
"205.20000","102.60099","16.35101"
"205.40000","102.70114","16.36383"
"205.60000","102.80099","16.37697"
"205.80000","102.90096","16.38790"
"206.00000","103.00105","16.40278"
"206.20000","103.10114","16.41919"
"206.40000","103.20098","16.43545"
"206.60000","103.30112","16.45110"
"206.80000","103.40099","16.45999"
"207.00000","103.50094","16.47538"
"207.20000","103.60103","16.48150"
"207.40000","103.70112","16.48879"
"207.60000","103.80103","16.49562"
"207.80000","103.90099","16.50316"
"208.00000","104.00102","16.51431"
"208.20000","104.10100","16.52720"
"208.40000","104.20108","16.53787"
"208.60000","104.30098","16.55233"
"208.80000","104.40108","16.56748"
"209.00000","104.50110","16.58247"
"209.20000","104.60101","16.59558"
"209.40000","104.70092","16.60962"
"209.60000","104.80113","16.62370"
"209.80000","104.90104","16.63801"
"210.00000","105.00095","16.64977"
"210.20000","105.10103","16.66234"
"210.40000","105.20100","16.67346"
"210.60000","105.30096","16.68319"
"210.80000","105.40099","16.69145"
"211.00000","105.50102","16.70116"
"211.20000","105.60106","16.71060"
"211.40000","105.70101","16.72346"
"211.60000","105.80093","16.73331"
"211.80000","105.90095","16.74275"
"212.00000","106.00098","16.75562"
"212.20000","106.10107","16.76857"
"212.40000","106.20103","16.77877"
"212.60000","106.30107","16.79225"
"212.80000","106.40098","16.80493"
"213.00000","106.50100","16.81651"
"213.20000","106.60091","16.82741"
"213.40000","106.70106","16.84399"
"213.60000","106.80103","16.85937"
"213.80000","106.90100","16.87389"
"214.00000","107.00103","16.88431"
"214.20000","107.10098","16.89163"
"214.40000","107.20097","16.90380"
"214.60000","107.30099","16.91164"
"214.80000","107.40096","16.92166"
"215.00000","107.50098","16.92609"
"215.20000","107.60101","16.93774"
"215.40000","107.70091","16.95382"
"215.60000","107.80100","16.96892"
"215.80000","107.90098","16.98309"
"216.00000","108.00089","16.99543"
"216.20000","108.10108","17.00774"
"216.40000","108.20100","17.01867"
"216.60000","108.30097","17.03069"
"216.80000","108.40099","17.04294"
"217.00000","108.50096","17.05424"
"217.20000","108.60093","17.06431"
"217.40000","108.70090","17.07217"
"217.60000","108.80093","17.08029"
"217.80000","108.90101","17.08973"
"218.00000","109.00104","17.09791"
"218.20000","109.10101","17.10781"
"218.40000","109.20103","17.11658"
"218.60000","109.30106","17.12770"
"218.80000","109.40104","17.13870"
"219.00000","109.50107","17.15070"
"219.20000","109.60091","17.16627"
"219.40000","109.70100","17.18122"
"219.60000","109.80103","17.19305"
"219.80000","109.90099","17.20500"
"220.00000","110.00103","17.21500"
"220.20000","110.10092","17.22599"
"220.40000","110.20102","17.23887"
"220.60000","110.30105","17.25604"
"220.80000","110.40114","17.26825"
"221.00000","110.50105","17.28194"
"221.20000","110.60107","17.29722"
"221.40000","110.70099","17.30649"
"221.60000","110.80101","17.31265"
"221.80000","110.90110","17.31691"
"222.00000","111.00100","17.32276"
"222.20000","111.10098","17.32762"
"222.40000","111.20100","17.33421"
"222.60000","111.30103","17.34134"
"222.80000","111.40100","17.35665"
"223.00000","111.50103","17.36868"
"223.20000","111.60099","17.38034"
"223.40000","111.70103","17.39543"
"223.60000","111.80093","17.40921"
"223.80000","111.90102","17.42387"
"224.00000","112.00098","17.43722"
"224.20000","112.10102","17.44968"
"224.40000","112.20110","17.46375"
"224.60000","112.30096","17.47760"
"224.80000","112.40103","17.48804"
"225.00000","112.50107","17.50012"
"225.20000","112.60104","17.50892"
"225.40000","112.70094","17.51574"
"225.60000","112.80097","17.52246"
"225.80000","112.90094","17.53097"
"226.00000","113.00102","17.54005"
"226.20000","113.10100","17.54999"
"226.40000","113.20102","17.55668"
"226.60000","113.30106","17.56757"
"226.80000","113.40108","17.57922"
"227.00000","113.50099","17.58804"
"227.20000","113.60101","17.60015"
"227.40000","113.70103","17.60723"
"227.60000","113.80095","17.61569"
"227.80000","113.90098","17.62431"
"228.00000","114.00100","17.63257"
"228.20000","114.10098","17.64421"
"228.40000","114.20106","17.65577"
"228.60000","114.30096","17.66711"
"228.80000","114.40099","17.67957"
"229.00000","114.50097","17.69196"
"229.20000","114.60099","17.70328"
"229.40000","114.70102","17.71640"
"229.60000","114.80104","17.72307"
"229.80000","114.90090","17.73258"
"230.00000","115.00110","17.74079"
"230.20000","115.10101","17.74851"
"230.40000","115.20098","17.75858"
"230.60000","115.30095","17.76502"
"230.80000","115.40109","17.77947"
"231.00000","115.50106","17.79371"
"231.20000","115.60104","17.80097"
"231.40000","115.70094","17.81338"
"231.60000","115.80096","17.82357"
"231.80000","115.90105","17.83562"
"232.00000","116.00108","17.84688"
"232.20000","116.10099","17.85787"
"232.40000","116.20096","17.86920"
"232.60000","116.30099","17.87870"
"232.80000","116.40108","17.88789"
"233.00000","116.50104","17.89746"
"233.20000","116.60101","17.90732"
"233.40000","116.70110","17.91306"
"233.60000","116.80100","17.91793"
"233.80000","116.90098","17.92295"
"234.00000","117.00101","17.92791"
"234.20000","117.10109","17.93233"
"234.40000","117.20113","17.94379"
"234.60000","117.30103","17.95459"
"234.80000","117.40099","17.95897"
"235.00000","117.50102","17.97499"
"235.20000","117.60105","17.99053"
"235.40000","117.70107","18.00465"
"235.60000","117.80106","18.01955"
"235.80000","117.90096","18.02752"
"236.00000","118.00111","18.04217"
"236.20000","118.10095","18.04851"
"236.40000","118.20104","18.06275"
"236.60000","118.30106","18.07314"
"236.80000","118.40116","18.08306"
"237.00000","118.50100","18.09985"
"237.20000","118.60110","18.11067"
"237.40000","118.70100","18.12164"
"237.60000","118.80103","18.13154"
"237.80000","118.90112","18.13518"
"238.00000","119.00108","18.14202"
"238.20000","119.10110","18.14862"
"238.40000","119.20096","18.15312"
"238.60000","119.30099","18.16097"
"238.80000","119.40102","18.16479"
"239.00000","119.50110","18.17296"
"239.20000","119.60101","18.18106"
"239.40000","119.70110","18.18892"
"239.60000","119.80107","18.19788"
"239.80000","119.90104","18.20895"
"240.00000","120.00095","18.21731"
"240.20000","120.10109","18.22618"
"240.40000","120.20112","18.23719"
"240.60000","120.30109","18.24819"
"240.80000","120.40100","18.25731"
"241.00000","120.50103","18.26744"
"241.20000","120.60106","18.28187"
"241.40000","120.70101","18.29386"
"241.60000","120.80111","18.30753"
"241.80000","120.90102","18.31580"
"242.00000","121.00105","18.32390"
"242.20000","121.10095","18.33703"
"242.40000","121.20110","18.34142"
"242.60000","121.30100","18.34786"
"242.80000","121.40110","18.35564"
"243.00000","121.50094","18.35973"
"243.20000","121.60104","18.36842"
"243.40000","121.70107","18.37808"
"243.60000","121.80109","18.39084"
"243.80000","121.90105","18.40236"
"244.00000","122.00096","18.41357"
"244.20000","122.10111","18.42433"
"244.40000","122.20103","18.43523"
"244.60000","122.30093","18.43970"
"244.80000","122.40096","18.44997"
"245.00000","122.50098","18.45677"
"245.20000","122.60095","18.46319"
"245.40000","122.70104","18.47349"
"245.60000","122.80100","18.48077"
"245.80000","122.90104","18.49080"
"246.00000","123.00107","18.49804"
"246.20000","123.10114","18.50765"
"246.40000","123.20106","18.51579"
"246.60000","123.30103","18.52456"
"246.80000","123.40099","18.53045"
"247.00000","123.50101","18.53909"
"247.20000","123.60100","18.54464"
"247.40000","123.70084","18.55107"
"247.60000","123.80099","18.56231"
"247.80000","123.90101","18.56673"
"248.00000","124.00098","18.57581"
"248.20000","124.10101","18.58637"
"248.40000","124.20116","18.59538"
"248.60000","124.30101","18.60735"
"248.80000","124.40109","18.62067"
"249.00000","124.50095","18.63169"
"249.20000","124.60104","18.64322"
"249.40000","124.70105","18.65200"
"249.60000","124.80103","18.66097"
"249.80000","124.90094","18.67150"
"250.00000","125.00095","18.68119"
"250.20000","125.10104","18.69269"
"250.40000","125.20102","18.70229"
"250.60000","125.30097","18.71311"
"250.80000","125.40101","18.72027"
"251.00000","125.50092","18.72743"
"251.20000","125.60101","18.73735"
"251.40000","125.70104","18.74204"
"251.60000","125.80093","18.74623"
"251.80000","125.90108","18.74945"
"252.00000","126.00106","18.75229"
"252.20000","126.10103","18.75640"
"252.40000","126.20099","18.76290"
"252.60000","126.30102","18.76417"
"252.80000","126.40105","18.76942"
"253.00000","126.50096","18.77834"
"253.20000","126.60092","18.78582"
"253.40000","126.70089","18.79496"
"253.60000","126.80110","18.80484"
"253.80000","126.90102","18.81623"
"254.00000","127.00103","18.82487"
"254.20000","127.10107","18.83748"
"254.40000","127.20103","18.84648"
"254.60000","127.30101","18.85365"
"254.80000","127.40108","18.85770"
"255.00000","127.50100","18.86309"
"255.20000","127.60091","18.87265"
"255.40000","127.70100","18.88045"
"255.60000","127.80096","18.88824"
"255.80000","127.90099","18.90230"
"256.00000","128.00096","18.91299"
"256.20000","128.10100","18.92466"
"256.40000","128.20107","18.93361"
"256.60000","128.30110","18.93839"
"256.80000","128.40089","18.95281"
"257.00000","128.50104","18.96401"
"257.20000","128.60106","18.96733"
"257.40000","128.70103","18.97291"
"257.60000","128.80106","18.97774"
"257.80000","128.90103","18.98218"
"258.00000","129.00099","18.98933"
"258.20000","129.10103","18.99535"
"258.40000","129.20088","19.00213"
"258.60000","129.30109","19.00927"
"258.80000","129.40105","19.01848"
"259.00000","129.50096","19.02637"
"259.20000","129.60098","19.03384"
"259.40000","129.70102","19.03898"
"259.60000","129.80104","19.04641"
"259.80000","129.90100","19.05399"
"260.00000","130.00110","19.05936"
"260.20000","130.10095","19.06858"
"260.40000","130.20097","19.07290"
"260.60000","130.30093","19.07960"
"260.80000","130.40103","19.08968"
"261.00000","130.50101","19.09935"
"261.20000","130.60101","19.10956"
"261.40000","130.70105","19.11967"
"261.60000","130.80103","19.12499"
"261.80000","130.90094","19.13828"
"262.00000","131.00095","19.14286"
"262.20000","131.10110","19.14721"
"262.40000","131.20102","19.15918"
"262.60000","131.30104","19.16102"
"262.80000","131.40106","19.16636"
"263.00000","131.50104","19.17421"
"263.20000","131.60095","19.17285"
"263.40000","131.70097","19.18232"
"263.60000","131.80112","19.18932"
"263.80000","131.90097","19.19421"
"264.00000","132.00099","19.20788"
"264.20000","132.10103","19.21741"
"264.40000","132.20093","19.22754"
"264.60000","132.30101","19.24062"
"264.80000","132.40111","19.24913"
"265.00000","132.50102","19.25821"
"265.20000","132.60098","19.26566"
"265.40000","132.70100","19.27339"
"265.60000","132.80098","19.27923"
"265.80000","132.90102","19.28522"
"266.00000","133.00110","19.29059"
"266.20000","133.10100","19.29726"
"266.40000","133.20103","19.30514"
"266.60000","133.30095","19.31186"
"266.80000","133.40091","19.31871"
"267.00000","133.50099","19.32358"
"267.20000","133.60103","19.33142"
"267.40000","133.70105","19.33770"
"267.60000","133.80096","19.34135"
"267.80000","133.90111","19.34732"
"268.00000","134.00108","19.35317"
"268.20000","134.10104","19.35775"
"268.40000","134.20096","19.36247"
"268.60000","134.30110","19.36644"
"268.80000","134.40100","19.37104"
"269.00000","134.50098","19.37771"
"269.20000","134.60101","19.37952"
"269.40000","134.70097","19.38618"
"269.60000","134.80106","19.39683"
"269.80000","134.90097","19.40456"
"270.00000","135.00101","19.40800"
"270.20000","135.10101","19.41679"
"270.40000","135.20099","19.42486"
"270.60000","135.30103","19.43169"
"270.80000","135.40106","19.43840"
"271.00000","135.50090","19.44954"
"271.20000","135.60104","19.45479"
"271.40000","135.70102","19.46128"
"271.60000","135.80099","19.46680"
"271.80000","135.90100","19.47540"
"272.00000","136.00104","19.47897"
"272.20000","136.10095","19.48971"
"272.40000","136.20097","19.49519"
"272.60000","136.30099","19.50557"
"272.80000","136.40091","19.51516"
"273.00000","136.50099","19.52378"
"273.20000","136.60103","19.52809"
"273.40000","136.70099","19.54214"
"273.60000","136.80109","19.55290"
"273.80000","136.90111","19.56031"
"274.00000","137.00102","19.56451"
"274.20000","137.10104","19.56728"
"274.40000","137.20100","19.57760"
"274.60000","137.30092","19.57859"
"274.80000","137.40102","19.58088"
"275.00000","137.50098","19.58315"
"275.20000","137.60106","19.58530"
"275.40000","137.70103","19.58805"
"275.60000","137.80095","19.58809"
"275.80000","137.90102","19.58848"
"276.00000","138.00111","19.59338"
"276.20000","138.10109","19.59099"
"276.40000","138.20107","19.59527"
"276.60000","138.30101","19.59900"
"276.80000","138.40105","19.60389"
"277.00000","138.50108","19.60824"
"277.20000","138.60104","19.61290"
"277.40000","138.70100","19.61996"
"277.60000","138.80098","19.62660"
"277.80000","138.90096","19.63135"
"278.00000","139.00104","19.63775"
"278.20000","139.10100","19.64475"
"278.40000","139.20110","19.65036"
"278.60000","139.30106","19.65764"
"278.80000","139.40097","19.66428"
"279.00000","139.50105","19.67052"
"279.20000","139.60103","19.67689"
"279.40000","139.70117","19.68182"
"279.60000","139.80096","19.68753"
"279.80000","139.90105","19.69317"
"280.00000","140.00101","19.69908"
"280.20000","140.10117","19.70471"
"280.40000","140.20096","19.71008"
"280.60000","140.30098","19.71564"
"280.80000","140.40106","19.72137"
"281.00000","140.50092","19.72290"
"281.20000","140.60107","19.72816"
"281.40000","140.70103","19.73372"
"281.60000","140.80106","19.73792"
"281.80000","140.90109","19.74484"
"282.00000","141.00107","19.74967"
"282.20000","141.10097","19.75260"
"282.40000","141.20105","19.75697"
"282.60000","141.30103","19.75905"
"282.80000","141.40105","19.76402"
"283.00000","141.50102","19.76739"
"283.20000","141.60098","19.77114"
"283.40000","141.70102","19.77471"
"283.60000","141.80092","19.77826"
"283.80000","141.90089","19.77844"
"284.00000","142.00110","19.78251"
"284.20000","142.10106","19.78501"
"284.40000","142.20097","19.78713"
"284.60000","142.30107","19.78924"
"284.80000","142.40108","19.79061"
"285.00000","142.50099","19.79261"
"285.20000","142.60097","19.79613"
"285.40000","142.70113","19.79707"
"285.60000","142.80096","19.80242"
"285.80000","142.90105","19.80422"
"286.00000","143.00102","19.80096"
"286.20000","143.10106","19.80515"
"286.40000","143.20088","19.81126"
"286.60000","143.30098","19.81010"
"286.80000","143.40102","19.81038"
"287.00000","143.50098","19.81350"
"287.20000","143.60100","19.81771"
"287.40000","143.70097","19.81803"
"287.60000","143.80106","19.81905"
"287.80000","143.90103","19.82073"
"288.00000","144.00093","19.82299"
"288.20000","144.10097","19.82497"
"288.40000","144.20099","19.82660"
"288.60000","144.30096","19.82806"
"288.80000","144.40092","19.82738"
"289.00000","144.50107","19.82780"
"289.20000","144.60104","19.82691"
"289.40000","144.70102","19.82667"
"289.60000","144.80098","19.82465"
"289.80000","144.90096","19.82357"
"290.00000","145.00098","19.81956"
"290.20000","145.10101","19.81758"
"290.40000","145.20097","19.81094"
"290.60000","145.30106","19.80793"
"290.80000","145.40103","19.80338"
"291.00000","145.50101","19.79982"
"291.20000","145.60107","19.79411"
"291.40000","145.70099","19.79135"
"291.60000","145.80103","19.78256"
"291.80000","145.90111","19.77671"
"292.00000","146.00095","19.76875"
"292.20000","146.10098","19.76221"
"292.40000","146.20096","19.75352"
"292.60000","146.30104","19.74007"
"292.80000","146.40106","19.72577"
"293.00000","146.50104","19.71114"
"293.20000","146.60101","19.69427"
"293.40000","146.70103","19.67563"
"293.60000","146.80099","19.65696"
"293.80000","146.90097","19.63217"
"294.00000","147.00099","19.60925"
"294.20000","147.10097","19.59415"
"294.40000","147.20111","19.58273"
"294.60000","147.30103","19.54668"
"294.80000","147.40092","19.41152"
"294.98800","147.49503","19.20054"
"295.05000","147.52608","18.90600"
"295.05400","147.52803","17.94796"
"295.05800","147.53001","16.16209"
"295.06200","147.53198","14.19280"
"295.06600","147.53397","11.96003"
"295.06800","147.53499","10.93174"