File: MT-DataAnalysis-JupyterNotebook/TensionPlots/TensionTests/TurnNumber/Specimen_RawData_7.csv
End date,"8/16/2018"
Specimen label,"D32L50N10d4"
Maximum Load,"14.91684",N
Extension at Maximum Load,"127.15092",mm
Maximum Slope (Automatic Young's),"0.12976",N/mm
Rate 1,"30.00000",mm/min

Time,Extension,Load
(s),(mm),(N)
"0.00000","0.00000","0.00086"
"0.20000","0.09016","0.00945"
"0.40000","0.20179","0.02949"
"0.60000","0.30128","0.04553"
"0.80000","0.40101","0.05859"
"1.00000","0.50098","0.07235"
"1.20000","0.60094","0.09228"
"1.40000","0.70109","0.10696"
"1.60000","0.80100","0.12261"
"1.80000","0.90103","0.14021"
"2.00000","1.00112","0.15264"
"2.20000","1.10102","0.16661"
"2.40000","1.20099","0.17864"
"2.60000","1.30102","0.18658"
"2.80000","1.40111","0.19439"
"3.00000","1.50102","0.20110"
"3.20000","1.60098","0.21359"
"3.40000","1.70095","0.22585"
"3.60000","1.80098","0.23776"
"3.80000","1.90101","0.25715"
"4.00000","2.00104","0.26717"
"4.20000","2.10106","0.28453"
"4.40000","2.20097","0.29688"
"4.60000","2.30100","0.31307"
"4.80000","2.40103","0.32697"
"5.00000","2.50100","0.34152"
"5.20000","2.60102","0.35639"
"5.40000","2.70111","0.37255"
"5.60000","2.80096","0.38463"
"5.80000","2.90099","0.39737"
"6.00000","3.00090","0.40824"
"6.20000","3.10092","0.41797"
"6.40000","3.20101","0.42625"
"6.60000","3.30098","0.44353"
"6.80000","3.40101","0.45777"
"7.00000","3.50110","0.47022"
"7.20000","3.60100","0.48033"
"7.40000","3.70103","0.49834"
"7.60000","3.80094","0.51212"
"7.80000","3.90103","0.52706"
"8.00000","4.00100","0.54279"
"8.20000","4.10108","0.55836"
"8.40000","4.20093","0.57210"
"8.60000","4.30096","0.58364"
"8.80000","4.40105","0.59327"
"9.00000","4.50102","0.60304"
"9.20000","4.60104","0.61255"
"9.40000","4.70107","0.62154"
"9.60000","4.80098","0.63606"
"9.80000","4.90107","0.64564"
"10.00000","5.00098","0.66219"
"10.20000","5.10106","0.67571"
"10.40000","5.20103","0.69237"
"10.60000","5.30106","0.70627"
"10.80000","5.40103","0.71849"
"11.00000","5.50100","0.73365"
"11.20000","5.60102","0.74391"
"11.40000","5.70105","0.76365"
"11.60000","5.80096","0.77447"
"11.80000","5.90099","0.78848"
"12.00000","6.00096","0.79686"
"12.20000","6.10110","0.80716"
"12.40000","6.20095","0.81981"
"12.60000","6.30092","0.83078"
"12.80000","6.40101","0.84373"
"13.00000","6.50104","0.85896"
"13.20000","6.60100","0.87193"
"13.40000","6.70097","0.88780"
"13.60000","6.80106","0.90104"
"13.80000","6.90103","0.91454"
"14.00000","7.00100","0.92824"
"14.20000","7.10096","0.94070"
"14.40000","7.20105","0.95884"
"14.60000","7.30102","0.97509"
"14.80000","7.40105","0.99018"
"15.00000","7.50090","1.00137"
"15.20000","7.60104","1.00934"
"15.40000","7.70101","1.01817"
"15.60000","7.80098","1.02372"
"15.80000","7.90113","1.03803"
"16.00000","8.00098","1.04716"
"16.20000","8.10094","1.06124"
"16.40000","8.20103","1.07615"
"16.60000","8.30112","1.09114"
"16.80000","8.40097","1.10780"
"17.00000","8.50105","1.12441"
"17.20000","8.60102","1.13813"
"17.40000","8.70111","1.15550"
"17.60000","8.80102","1.16791"
"17.80000","8.90099","1.18364"
"18.00000","9.00108","1.19865"
"18.20000","9.10104","1.20838"
"18.40000","9.20101","1.21648"
"18.60000","9.30104","1.22774"
"18.80000","9.40101","1.23744"
"19.00000","9.50098","1.24678"
"19.20000","9.60106","1.25844"
"19.40000","9.70097","1.26977"
"19.60000","9.80112","1.28943"
"19.80000","9.90097","1.29890"
"20.00000","10.00105","1.31205"
"20.20000","10.10102","1.32572"
"20.40000","10.20111","1.33914"
"20.60000","10.30102","1.35475"
"20.80000","10.40111","1.37005"
"21.00000","10.50101","1.38829"
"21.20000","10.60098","1.39995"
"21.40000","10.70101","1.41361"
"21.60000","10.80092","1.42410"
"21.80000","10.90095","1.43510"
"22.00000","11.00097","1.44634"
"22.20000","11.10106","1.45777"
"22.40000","11.20109","1.46822"
"22.60000","11.30106","1.48289"
"22.80000","11.40103","1.49716"
"23.00000","11.50105","1.51189"
"23.20000","11.60102","1.52597"
"23.40000","11.70105","1.54022"
"23.60000","11.80102","1.55241"
"23.80000","11.90111","1.56508"
"24.00000","12.00101","1.57908"
"24.20000","12.10098","1.59230"
"24.40000","12.20095","1.60631"
"24.60000","12.30104","1.61503"
"24.80000","12.40101","1.62464"
"25.00000","12.50098","1.62984"
"25.20000","12.60094","1.64689"
"25.40000","12.70097","1.65866"
"25.60000","12.80106","1.67444"
"25.80000","12.90103","1.68992"
"26.00000","13.00111","1.70495"
"26.20000","13.10102","1.72240"
"26.40000","13.20105","1.73724"
"26.60000","13.30090","1.75110"
"26.80000","13.40105","1.76716"
"27.00000","13.50102","1.78405"
"27.20000","13.60098","1.79690"
"27.40000","13.70107","1.81307"
"27.60000","13.80098","1.82214"
"27.80000","13.90095","1.83288"
"28.00000","14.00103","1.84030"
"28.20000","14.10106","1.84685"
"28.40000","14.20097","1.85289"
"28.60000","14.30100","1.86182"
"28.80000","14.40097","1.87236"
"29.00000","14.50100","1.88616"
"29.20000","14.60102","1.89905"
"29.40000","14.70099","1.91328"
"29.60000","14.80102","1.92839"
"29.80000","14.90099","1.94634"
"30.00000","15.00095","1.96165"
"30.20000","15.10098","1.98178"
"30.40000","15.20095","1.99652"
"30.60000","15.30104","2.01219"
"30.80000","15.40095","2.02660"
"31.00000","15.50092","2.04145"
"31.20000","15.60100","2.05048"
"31.40000","15.70097","2.06033"
"31.60000","15.80094","2.06944"
"31.80000","15.90103","2.08271"
"32.00000","16.00099","2.09572"
"32.20000","16.10108","2.10904"
"32.40000","16.20105","2.12019"
"32.60000","16.30096","2.13212"
"32.80000","16.40099","2.14209"
"33.00000","16.50107","2.15407"
"33.20000","16.60086","2.16806"
"33.40000","16.70095","2.18221"
"33.60000","16.80098","2.19693"
"33.80000","16.90095","2.21246"
"34.00000","17.00097","2.22208"
"34.20000","17.10100","2.23706"
"34.40000","17.20091","2.24974"
"34.60000","17.30112","2.26072"
"34.80000","17.40097","2.27354"
"35.00000","17.50100","2.28542"
"35.20000","17.60096","2.29709"
"35.40000","17.70099","2.31523"
"35.60000","17.80102","2.32952"
"35.80000","17.90099","2.34617"
"36.00000","18.00096","2.36192"
"36.20000","18.10098","2.37969"
"36.40000","18.20107","2.39076"
"36.60000","18.30098","2.40375"
"36.80000","18.40095","2.41607"
"37.00000","18.50097","2.42685"
"37.20000","18.60106","2.43824"
"37.40000","18.70097","2.44413"
"37.60000","18.80100","2.45119"
"37.80000","18.90115","2.45843"
"38.00000","19.00105","2.46603"
"38.20000","19.10108","2.47982"
"38.40000","19.20099","2.49439"
"38.60000","19.30102","2.51228"
"38.80000","19.40099","2.53024"
"39.00000","19.50101","2.54254"
"39.20000","19.60104","2.55778"
"39.40000","19.70107","2.57419"
"39.60000","19.80098","2.59090"
"39.80000","19.90100","2.60834"
"40.00000","20.00103","2.62345"
"40.20000","20.10112","2.63849"
"40.40000","20.20103","2.65572"
"40.60000","20.30100","2.66684"
"40.80000","20.40102","2.67466"
"41.00000","20.50093","2.68378"
"41.20000","20.60102","2.69076"
"41.40000","20.70093","2.69853"
"41.60000","20.80102","2.71018"
"41.80000","20.90099","2.71921"
"42.00000","21.00101","2.73051"
"42.20000","21.10104","2.74320"
"42.40000","21.20101","2.75778"
"42.60000","21.30104","2.77087"
"42.80000","21.40112","2.78923"
"43.00000","21.50097","2.80578"
"43.20000","21.60100","2.82202"
"43.40000","21.70109","2.83449"
"43.60000","21.80100","2.85093"
"43.80000","21.90096","2.86351"
"44.00000","22.00105","2.87621"
"44.20000","22.10102","2.88671"
"44.40000","22.20105","2.89865"
"44.60000","22.30096","2.90827"
"44.80000","22.40099","2.92394"
"45.00000","22.50113","2.94200"
"45.20000","22.60104","2.95505"
"45.40000","22.70101","2.97128"
"45.60000","22.80104","2.98164"
"45.80000","22.90101","2.99283"
"46.00000","23.00103","3.00578"
"46.20000","23.10106","3.01715"
"46.40000","23.20097","3.02743"
"46.60000","23.30094","3.03818"
"46.80000","23.40103","3.05035"
"47.00000","23.50099","3.06022"
"47.20000","23.60108","3.07055"
"47.40000","23.70099","3.08126"
"47.60000","23.80107","3.09283"
"47.80000","23.90099","3.10387"
"48.00000","24.00113","3.11665"
"48.20000","24.10098","3.13369"
"48.40000","24.20101","3.14858"
"48.60000","24.30098","3.16663"
"48.80000","24.40107","3.18260"
"49.00000","24.50097","3.19987"
"49.20000","24.60094","3.21502"
"49.40000","24.70103","3.23066"
"49.60000","24.80100","3.24528"
"49.80000","24.90090","3.26072"
"50.00000","25.00099","3.27175"
"50.20000","25.10114","3.28022"
"50.40000","25.20105","3.28698"
"50.60000","25.30114","3.29434"
"50.80000","25.40099","3.30006"
"51.00000","25.50101","3.30900"
"51.20000","25.60104","3.32211"
"51.40000","25.70113","3.33810"
"51.60000","25.80110","3.35317"
"51.80000","25.90107","3.36885"
"52.00000","26.00103","3.38503"
"52.20000","26.10100","3.39937"
"52.40000","26.20103","3.41493"
"52.60000","26.30100","3.42939"
"52.80000","26.40108","3.44535"
"53.00000","26.50099","3.46064"
"53.20000","26.60102","3.47583"
"53.40000","26.70099","3.48742"
"53.60000","26.80114","3.50086"
"53.80000","26.90110","3.50928"
"54.00000","27.00107","3.51971"
"54.20000","27.10104","3.52788"
"54.40000","27.20113","3.54075"
"54.60000","27.30098","3.55473"
"54.80000","27.40100","3.56658"
"55.00000","27.50097","3.57865"
"55.20000","27.60100","3.59009"
"55.40000","27.70103","3.60305"
"55.60000","27.80094","3.61582"
"55.80000","27.90103","3.62892"
"56.00000","28.00105","3.64419"
"56.20000","28.10108","3.65934"
"56.40000","28.20099","3.67118"
"56.60000","28.30108","3.68075"
"56.80000","28.40104","3.69298"
"57.00000","28.50107","3.70308"
"57.20000","28.60110","3.71538"
"57.40000","28.70107","3.72735"
"57.60000","28.80110","3.74331"
"57.80000","28.90106","3.75955"
"58.00000","29.00097","3.77831"
"58.20000","29.10100","3.79075"
"58.40000","29.20103","3.80940"
"58.60000","29.30094","3.81962"
"58.80000","29.40109","3.83467"
"59.00000","29.50105","3.84435"
"59.20000","29.60096","3.85811"
"59.40000","29.70099","3.87115"
"59.60000","29.80114","3.88234"
"59.80000","29.90099","3.89155"
"60.00000","30.00107","3.89953"
"60.20000","30.10098","3.91102"
"60.40000","30.20107","3.92026"
"60.60000","30.30092","3.93254"
"60.80000","30.40088","3.94415"
"61.00000","30.50103","3.95804"
"61.20000","30.60100","3.97238"
"61.40000","30.70103","3.98932"
"61.60000","30.80094","4.00294"
"61.80000","30.90108","4.01937"
"62.00000","31.00105","4.03437"
"62.20000","31.10108","4.05105"
"62.40000","31.20093","4.06667"
"62.60000","31.30113","4.08270"
"62.80000","31.40098","4.09464"
"63.00000","31.50095","4.10688"
"63.20000","31.60098","4.11348"
"63.40000","31.70095","4.12188"
"63.60000","31.80091","4.12587"
"63.80000","31.90106","4.14585"
"64.00000","32.00103","4.15258"
"64.20000","32.10100","4.16570"
"64.40000","32.20103","4.18139"
"64.60000","32.30093","4.19615"
"64.80000","32.40108","4.21138"
"65.00000","32.50099","4.22175"
"65.20000","32.60102","4.23770"
"65.40000","32.70105","4.25160"
"65.60000","32.80107","4.26613"
"65.80000","32.90086","4.27724"
"66.00000","33.00101","4.29241"
"66.20000","33.10104","4.30297"
"66.40000","33.20095","4.31434"
"66.60000","33.30098","4.32520"
"66.80000","33.40100","4.33683"
"67.00000","33.50097","4.34703"
"67.20000","33.60106","4.35838"
"67.40000","33.70091","4.37483"
"67.60000","33.80100","4.38937"
"67.80000","33.90102","4.40351"
"68.00000","34.00099","4.41458"
"68.20000","34.10096","4.42618"
"68.40000","34.20099","4.44038"
"68.60000","34.30102","4.45669"
"68.80000","34.40104","4.47158"
"69.00000","34.50089","4.48748"
"69.20000","34.60104","4.50289"
"69.40000","34.70095","4.50981"
"69.60000","34.80109","4.52151"
"69.80000","34.90100","4.52970"
"70.00000","35.00097","4.53976"
"70.20000","35.10100","4.54995"
"70.40000","35.20103","4.56228"
"70.60000","35.30094","4.57712"
"70.80000","35.40102","4.59247"
"71.00000","35.50099","4.61010"
"71.20000","35.60102","4.62571"
"71.40000","35.70099","4.63860"
"71.60000","35.80096","4.65425"
"71.80000","35.90099","4.66270"
"72.00000","36.00107","4.68079"
"72.20000","36.10104","4.69569"
"72.40000","36.20095","4.70852"
"72.60000","36.30104","4.71665"
"72.80000","36.40100","4.72471"
"73.00000","36.50109","4.73209"
"73.20000","36.60100","4.74379"
"73.40000","36.70097","4.75440"
"73.60000","36.80099","4.76968"
"73.80000","36.90102","4.78377"
"74.00000","37.00093","4.79923"
"74.20000","37.10108","4.81109"
"74.40000","37.20099","4.82323"
"74.60000","37.30101","4.83784"
"74.80000","37.40110","4.85161"
"75.00000","37.50101","4.86909"
"75.20000","37.60098","4.88023"
"75.40000","37.70107","4.90087"
"75.60000","37.80109","4.90945"
"75.80000","37.90106","4.92479"
"76.00000","38.00103","4.93190"
"76.20000","38.10094","4.94141"
"76.40000","38.20103","4.94796"
"76.60000","38.30099","4.95614"
"76.80000","38.40096","4.96643"
"77.00000","38.50099","4.98316"
"77.20000","38.60102","4.99887"
"77.40000","38.70105","5.01314"
"77.60000","38.80096","5.02940"
"77.80000","38.90104","5.04432"
"78.00000","39.00107","5.06057"
"78.20000","39.10110","5.07599"
"78.40000","39.20101","5.09209"
"78.60000","39.30103","5.10493"
"78.80000","39.40106","5.12014"
"79.00000","39.50103","5.12791"
"79.20000","39.60099","5.13854"
"79.40000","39.70096","5.14495"
"79.60000","39.80106","5.15528"
"79.80000","39.90102","5.16986"
"80.00000","40.00099","5.17968"
"80.20000","40.10096","5.19227"
"80.40000","40.20099","5.20639"
"80.60000","40.30101","5.21971"
"80.80000","40.40110","5.23332"
"81.00000","40.50095","5.24467"
"81.20000","40.60116","5.25733"
"81.40000","40.70107","5.26669"
"81.60000","40.80098","5.28315"
"81.80000","40.90100","5.29880"
"82.00000","41.00109","5.31713"
"82.20000","41.10100","5.33025"
"82.40000","41.20103","5.34115"
"82.60000","41.30106","5.35150"
"82.80000","41.40091","5.36235"
"83.00000","41.50105","5.37309"
"83.20000","41.60102","5.38825"
"83.40000","41.70105","5.39879"
"83.60000","41.80102","5.41449"
"83.80000","41.90104","5.42767"
"84.00000","42.00095","5.44231"
"84.20000","42.10104","5.45712"
"84.40000","42.20100","5.47252"
"84.60000","42.30110","5.48468"
"84.80000","42.40100","5.49703"
"85.00000","42.50097","5.51015"
"85.20000","42.60100","5.51788"
"85.40000","42.70103","5.53171"
"85.60000","42.80106","5.53954"
"85.80000","42.90096","5.54662"
"86.00000","43.00099","5.55781"
"86.20000","43.10102","5.56105"
"86.40000","43.20098","5.57820"
"86.60000","43.30102","5.59501"
"86.80000","43.40104","5.61214"
"87.00000","43.50101","5.63019"
"87.20000","43.60115","5.64305"
"87.40000","43.70101","5.65849"
"87.60000","43.80104","5.67182"
"87.80000","43.90100","5.68719"
"88.00000","44.00109","5.70238"
"88.20000","44.10100","5.71604"
"88.40000","44.20097","5.73196"
"88.60000","44.30106","5.74513"
"88.80000","44.40096","5.75433"
"89.00000","44.50093","5.76309"
"89.20000","44.60102","5.76903"
"89.40000","44.70093","5.77779"
"89.60000","44.80101","5.78839"
"89.80000","44.90104","5.79334"
"90.00000","45.00101","5.80933"
"90.20000","45.10104","5.82365"
"90.40000","45.20094","5.83815"
"90.60000","45.30091","5.85075"
"90.80000","45.40100","5.86490"
"91.00000","45.50109","5.88263"
"91.20000","45.60088","5.89811"
"91.40000","45.70103","5.91747"
"91.60000","45.80093","5.93184"
"91.80000","45.90102","5.94356"
"92.00000","46.00105","5.95503"
"92.20000","46.10096","5.96518"
"92.40000","46.20105","5.97649"
"92.60000","46.30101","5.98596"
"92.80000","46.40098","5.99743"
"93.00000","46.50101","6.01210"
"93.20000","46.60104","6.02597"
"93.40000","46.70101","6.03838"
"93.60000","46.80109","6.05015"
"93.80000","46.90106","6.06352"
"94.00000","47.00103","6.07475"
"94.20000","47.10106","6.08524"
"94.40000","47.20103","6.09836"
"94.60000","47.30106","6.10658"
"94.80000","47.40096","6.12252"
"95.00000","47.50093","6.13689"
"95.20000","47.60101","6.14872"
"95.40000","47.70111","6.15915"
"95.60000","47.80095","6.16958"
"95.80000","47.90098","6.18481"
"96.00000","48.00101","6.19457"
"96.20000","48.10110","6.21127"
"96.40000","48.20095","6.22562"
"96.60000","48.30109","6.23941"
"96.80000","48.40100","6.25563"
"97.00000","48.50103","6.27123"
"97.20000","48.60100","6.28610"
"97.40000","48.70103","6.30368"
"97.60000","48.80106","6.31693"
"97.80000","48.90102","6.33080"
"98.00000","49.00099","6.34311"
"98.20000","49.10102","6.35731"
"98.40000","49.20105","6.36415"
"98.60000","49.30096","6.37066"
"98.80000","49.40110","6.37626"
"99.00000","49.50101","6.38145"
"99.20000","49.60098","6.39087"
"99.40000","49.70095","6.39988"
"99.60000","49.80104","6.41318"
"99.80000","49.90100","6.43007"
"100.00000","50.00103","6.44402"
"100.20000","50.10112","6.46025"
"100.40000","50.20097","6.47622"
"100.60000","50.30105","6.49279"
"100.80000","50.40102","6.50889"
"101.00000","50.50099","6.52631"
"101.20000","50.60096","6.54280"
"101.40000","50.70098","6.55466"
"101.60000","50.80083","6.56929"
"101.80000","50.90104","6.58356"
"102.00000","51.00095","6.59204"
"102.20000","51.10098","6.60234"
"102.40000","51.20100","6.61043"
"102.60000","51.30109","6.61993"
"102.80000","51.40100","6.63169"
"103.00000","51.50103","6.64215"
"103.20000","51.60100","6.65512"
"103.40000","51.70103","6.66493"
"103.60000","51.80099","6.67652"
"103.80000","51.90096","6.68835"
"104.00000","52.00099","6.70005"
"104.20000","52.10107","6.71992"
"104.40000","52.20093","6.73335"
"104.60000","52.30101","6.75281"
"104.80000","52.40098","6.76358"
"105.00000","52.50101","6.77417"
"105.20000","52.60098","6.78214"
"105.40000","52.70094","6.79579"
"105.60000","52.80104","6.80612"
"105.80000","52.90100","6.81779"
"106.00000","53.00097","6.83080"
"106.20000","53.10099","6.84747"
"106.40000","53.20096","6.86276"
"106.60000","53.30105","6.88081"
"106.80000","53.40102","6.89463"
"107.00000","53.50099","6.90722"
"107.20000","53.60096","6.91995"
"107.40000","53.70099","6.92977"
"107.60000","53.80096","6.94187"
"107.80000","53.90110","6.95209"
"108.00000","54.00095","6.96431"
"108.20000","54.10092","6.97245"
"108.40000","54.20107","6.98118"
"108.60000","54.30109","6.99134"
"108.80000","54.40100","6.99717"
"109.00000","54.50109","7.01216"
"109.20000","54.60100","7.02699"
"109.40000","54.70103","7.03840"
"109.60000","54.80099","7.05525"
"109.80000","54.90090","7.06997"
"110.00000","55.00105","7.08539"
"110.20000","55.10101","7.10197"
"110.40000","55.20098","7.11801"
"110.60000","55.30101","7.13479"
"110.80000","55.40105","7.15052"
"111.00000","55.50107","7.16553"
"111.20000","55.60104","7.18026"
"111.40000","55.70101","7.19332"
"111.60000","55.80098","7.20574"
"111.80000","55.90113","7.20841"
"112.00000","56.00097","7.21564"
"112.20000","56.10100","7.21977"
"112.40000","56.20103","7.22877"
"112.60000","56.30117","7.23930"
"112.80000","56.40108","7.25196"
"113.00000","56.50111","7.26451"
"113.20000","56.60096","7.28064"
"113.40000","56.70098","7.29458"
"113.60000","56.80101","7.30921"
"113.80000","56.90105","7.32368"
"114.00000","57.00101","7.34013"
"114.20000","57.10098","7.35477"
"114.40000","57.20101","7.36759"
"114.60000","57.30104","7.38300"
"114.80000","57.40106","7.39668"
"115.00000","57.50103","7.40555"
"115.20000","57.60112","7.42032"
"115.40000","57.70109","7.43035"
"115.60000","57.80105","7.44227"
"115.80000","57.90096","7.45353"
"116.00000","58.00099","7.46552"
"116.20000","58.10102","7.47856"
"116.40000","58.20105","7.49319"
"116.60000","58.30102","7.50445"
"116.80000","58.40104","7.51536"
"117.00000","58.50107","7.52687"
"117.20000","58.60104","7.53719"
"117.40000","58.70100","7.55345"
"117.60000","58.80103","7.56682"
"117.80000","58.90112","7.58100"
"118.00000","59.00091","7.59469"
"118.20000","59.10100","7.60116"
"118.40000","59.20097","7.61248"
"118.60000","59.30099","7.61961"
"118.80000","59.40102","7.63186"
"119.00000","59.50105","7.64439"
"119.20000","59.60096","7.65426"
"119.40000","59.70105","7.67267"
"119.60000","59.80101","7.68584"
"119.80000","59.90092","7.70442"
"120.00000","60.00107","7.72506"
"120.20000","60.10098","7.73562"
"120.40000","60.20089","7.75030"
"120.60000","60.30098","7.76345"
"120.80000","60.40100","7.77658"
"121.00000","60.50097","7.78741"
"121.20000","60.60106","7.80077"
"121.40000","60.70103","7.80953"
"121.60000","60.80106","7.81737"
"121.80000","60.90108","7.82444"
"122.00000","61.00099","7.83305"
"122.20000","61.10107","7.84175"
"122.40000","61.20099","7.85814"
"122.60000","61.30101","7.87109"
"122.80000","61.40104","7.88605"
"123.00000","61.50101","7.90047"
"123.20000","61.60092","7.91410"
"123.40000","61.70101","7.92772"
"123.60000","61.80104","7.94047"
"123.80000","61.90106","7.95746"
"124.00000","62.00097","7.97167"
"124.20000","62.10112","7.98794"
"124.40000","62.20102","8.00069"
"124.60000","62.30111","8.01393"
"124.80000","62.40090","8.02687"
"125.00000","62.50104","8.03665"
"125.20000","62.60096","8.04356"
"125.40000","62.70098","8.04944"
"125.60000","62.80095","8.05636"
"125.80000","62.90097","8.07238"
"126.00000","63.00107","8.07897"
"126.20000","63.10097","8.09390"
"126.40000","63.20094","8.10986"
"126.60000","63.30097","8.12242"
"126.80000","63.40100","8.13598"
"127.00000","63.50103","8.15126"
"127.20000","63.60099","8.16606"
"127.40000","63.70090","8.17967"
"127.60000","63.80111","8.19386"
"127.80000","63.90102","8.20403"
"128.00000","64.00105","8.21566"
"128.20000","64.10107","8.22653"
"128.40000","64.20092","8.23420"
"128.60000","64.30107","8.24652"
"128.80000","64.40104","8.25815"
"129.00000","64.50101","8.27011"
"129.20000","64.60091","8.28543"
"129.40000","64.70107","8.30110"
"129.60000","64.80103","8.31492"
"129.80000","64.90106","8.32987"
"130.00000","65.00102","8.34007"
"130.20000","65.10106","8.35325"
"130.40000","65.20108","8.36188"
"130.60000","65.30111","8.37724"
"130.80000","65.40096","8.38984"
"131.00000","65.50099","8.40658"
"131.20000","65.60101","8.41794"
"131.40000","65.70099","8.42690"
"131.60000","65.80101","8.43828"
"131.80000","65.90092","8.44691"
"132.00000","66.00101","8.45488"
"132.20000","66.10104","8.46448"
"132.40000","66.20112","8.47469"
"132.60000","66.30091","8.48914"
"132.80000","66.40105","8.50170"
"133.00000","66.50103","8.51659"
"133.20000","66.60105","8.53019"
"133.40000","66.70103","8.54508"
"133.60000","66.80099","8.55920"
"133.80000","66.90102","8.57459"
"134.00000","67.00105","8.58705"
"134.20000","67.10090","8.60077"
"134.40000","67.20104","8.61314"
"134.60000","67.30107","8.62673"
"134.80000","67.40098","8.63586"
"135.00000","67.50101","8.64342"
"135.20000","67.60091","8.65068"
"135.40000","67.70107","8.65754"
"135.60000","67.80103","8.66743"
"135.80000","67.90106","8.68502"
"136.00000","68.00102","8.69805"
"136.20000","68.10106","8.71201"
"136.40000","68.20096","8.73182"
"136.60000","68.30099","8.74295"
"136.80000","68.40096","8.75600"
"137.00000","68.50105","8.76817"
"137.20000","68.60101","8.78096"
"137.40000","68.70093","8.79499"
"137.60000","68.80095","8.80902"
"137.80000","68.90092","8.82312"
"138.00000","69.00101","8.83573"
"138.20000","69.10104","8.84811"
"138.40000","69.20106","8.85507"
"138.60000","69.30103","8.86446"
"138.80000","69.40099","8.87225"
"139.00000","69.50091","8.87984"
"139.20000","69.60105","8.89400"
"139.40000","69.70103","8.90256"
"139.60000","69.80099","8.92001"
"139.80000","69.90102","8.93002"
"140.00000","70.00105","8.94514"
"140.20000","70.10090","8.95700"
"140.40000","70.20104","8.97311"
"140.60000","70.30107","8.98959"
"140.80000","70.40098","9.00532"
"141.00000","70.50101","9.02056"
"141.20000","70.60091","9.03429"
"141.40000","70.70094","9.04551"
"141.60000","70.80096","9.05523"
"141.80000","70.90106","9.06207"
"142.00000","71.00103","9.07163"
"142.20000","71.10105","9.07537"
"142.40000","71.20096","9.08898"
"142.60000","71.30105","9.10171"
"142.80000","71.40096","9.11532"
"143.00000","71.50098","9.13246"
"143.20000","71.60096","9.14475"
"143.40000","71.70092","9.15720"
"143.60000","71.80102","9.17074"
"143.80000","71.90104","9.17969"
"144.00000","72.00101","9.18930"
"144.20000","72.10104","9.20353"
"144.40000","72.20107","9.21440"
"144.60000","72.30097","9.23061"
"144.80000","72.40100","9.24329"
"145.00000","72.50097","9.25253"
"145.20000","72.60094","9.26332"
"145.40000","72.70108","9.27367"
"145.60000","72.80099","9.28434"
"145.80000","72.90096","9.29353"
"146.00000","73.00099","9.30786"
"146.20000","73.10095","9.32223"
"146.40000","73.20104","9.33456"
"146.60000","73.30101","9.34913"
"146.80000","73.40098","9.36189"
"147.00000","73.50107","9.37579"
"147.20000","73.60104","9.38853"
"147.40000","73.70094","9.40259"
"147.60000","73.80103","9.41620"
"147.80000","73.90100","9.43371"
"148.00000","74.00097","9.44329"
"148.20000","74.10099","9.45341"
"148.40000","74.20097","9.45931"
"148.60000","74.30093","9.46807"
"148.80000","74.40102","9.47354"
"149.00000","74.50098","9.48251"
"149.20000","74.60096","9.48838"
"149.40000","74.70104","9.49763"
"149.60000","74.80101","9.51834"
"149.80000","74.90098","9.53556"
"150.00000","75.00101","9.55075"
"150.20000","75.10098","9.56861"
"150.40000","75.20100","9.58151"
"150.60000","75.30097","9.59461"
"150.80000","75.40100","9.60815"
"151.00000","75.50102","9.62373"
"151.20000","75.60100","9.63616"
"151.40000","75.70108","9.65055"
"151.60000","75.80099","9.66135"
"151.80000","75.90102","9.67167"
"152.00000","76.00105","9.68043"
"152.20000","76.10107","9.69042"
"152.40000","76.20104","9.69736"
"152.60000","76.30112","9.70725"
"152.80000","76.40104","9.71421"
"153.00000","76.50101","9.72341"
"153.20000","76.60104","9.73462"
"153.40000","76.70106","9.74584"
"153.60000","76.80109","9.75800"
"153.80000","76.90094","9.76930"
"154.00000","77.00097","9.78364"
"154.20000","77.10105","9.79338"
"154.40000","77.20108","9.80470"
"154.60000","77.30099","9.82672"
"154.80000","77.40102","9.84066"
"155.00000","77.50105","9.86140"
"155.20000","77.60107","9.87290"
"155.40000","77.70098","9.88067"
"155.60000","77.80107","9.88889"
"155.80000","77.90104","9.89711"
"156.00000","78.00101","9.90579"
"156.20000","78.10091","9.92101"
"156.40000","78.20100","9.93468"
"156.60000","78.30096","9.94979"
"156.80000","78.40094","9.96265"
"157.00000","78.50102","9.97581"
"157.20000","78.60099","9.99029"
"157.40000","78.70102","10.00098"
"157.60000","78.80105","10.01152"
"157.80000","78.90120","10.02216"
"158.00000","79.00105","10.03266"
"158.20000","79.10107","10.04349"
"158.40000","79.20104","10.05346"
"158.60000","79.30101","10.06655"
"158.80000","79.40098","10.07445"
"159.00000","79.50095","10.08440"
"159.20000","79.60097","10.09365"
"159.40000","79.70094","10.09981"
"159.60000","79.80097","10.11748"
"159.80000","79.90100","10.13186"
"160.00000","80.00108","10.14662"
"160.20000","80.10100","10.16218"
"160.40000","80.20102","10.17489"
"160.60000","80.30099","10.18774"
"160.80000","80.40101","10.19989"
"161.00000","80.50092","10.21536"
"161.20000","80.60107","10.23085"
"161.40000","80.70098","10.24605"
"161.60000","80.80107","10.26128"
"161.80000","80.90099","10.27088"
"162.00000","81.00101","10.28312"
"162.20000","81.10092","10.29282"
"162.40000","81.20094","10.29544"
"162.60000","81.30096","10.30178"
"162.80000","81.40094","10.30720"
"163.00000","81.50109","10.31250"
"163.20000","81.60099","10.32767"
"163.40000","81.70103","10.33574"
"163.60000","81.80105","10.34784"
"163.80000","81.90108","10.36219"
"164.00000","82.00098","10.37701"
"164.20000","82.10107","10.39058"
"164.40000","82.20103","10.40540"
"164.60000","82.30101","10.42110"
"164.80000","82.40104","10.43303"
"165.00000","82.50101","10.45139"
"165.20000","82.60109","10.46811"
"165.40000","82.70094","10.48010"
"165.60000","82.80097","10.48916"
"165.80000","82.90105","10.49908"
"166.00000","83.00108","10.51005"
"166.20000","83.10106","10.51960"
"166.40000","83.20108","10.53033"
"166.60000","83.30099","10.54071"
"166.80000","83.40107","10.55246"
"167.00000","83.50105","10.56175"
"167.20000","83.60101","10.57208"
"167.40000","83.70104","10.58305"
"167.60000","83.80112","10.59254"
"167.80000","83.90098","10.60060"
"168.00000","84.00101","10.61190"
"168.20000","84.10097","10.62315"
"168.40000","84.20106","10.63678"
"168.60000","84.30103","10.64924"
"168.80000","84.40099","10.66730"
"169.00000","84.50109","10.68107"
"169.20000","84.60105","10.69605"
"169.40000","84.70103","10.70258"
"169.60000","84.80105","10.71170"
"169.80000","84.90102","10.71852"
"170.00000","85.00098","10.73072"
"170.20000","85.10114","10.74283"
"170.40000","85.20104","10.75755"
"170.60000","85.30095","10.76903"
"170.80000","85.40098","10.78635"
"171.00000","85.50101","10.80136"
"171.20000","85.60103","10.81605"
"171.40000","85.70100","10.83016"
"171.60000","85.80096","10.83942"
"171.80000","85.90106","10.85289"
"172.00000","86.00108","10.86309"
"172.20000","86.10093","10.87541"
"172.40000","86.20102","10.88212"
"172.60000","86.30105","10.89302"
"172.80000","86.40108","10.89940"
"173.00000","86.50098","10.90531"
"173.20000","86.60094","10.91221"
"173.40000","86.70098","10.91787"
"173.60000","86.80106","10.92983"
"173.80000","86.90104","10.93815"
"174.00000","87.00101","10.95034"
"174.20000","87.10103","10.96804"
"174.40000","87.20100","10.97965"
"174.60000","87.30109","10.99504"
"174.80000","87.40100","11.00689"
"175.00000","87.50108","11.01999"
"175.20000","87.60099","11.03264"
"175.40000","87.70097","11.04679"
"175.60000","87.80093","11.06649"
"175.80000","87.90102","11.08155"
"176.00000","88.00098","11.09461"
"176.20000","88.10107","11.10980"
"176.40000","88.20105","11.11936"
"176.60000","88.30094","11.12638"
"176.80000","88.40103","11.13411"
"177.00000","88.50101","11.14014"
"177.20000","88.60104","11.14551"
"177.40000","88.70100","11.15311"
"177.60000","88.80103","11.15942"
"177.80000","88.90093","11.17434"
"178.00000","89.00097","11.18415"
"178.20000","89.10094","11.19720"
"178.40000","89.20097","11.20923"
"178.60000","89.30099","11.22333"
"178.80000","89.40102","11.23597"
"179.00000","89.50104","11.24914"
"179.20000","89.60107","11.26400"
"179.40000","89.70092","11.27758"
"179.60000","89.80107","11.29215"
"179.80000","89.90091","11.30369"
"180.00000","90.00101","11.31431"
"180.20000","90.10104","11.32133"
"180.40000","90.20100","11.33137"
"180.60000","90.30097","11.33961"
"180.80000","90.40094","11.35377"
"181.00000","90.50097","11.36459"
"181.20000","90.60106","11.37616"
"181.40000","90.70107","11.38977"
"181.60000","90.80099","11.40211"
"181.80000","90.90096","11.41529"
"182.00000","91.00105","11.42536"
"182.20000","91.10094","11.43373"
"182.40000","91.20103","11.44368"
"182.60000","91.30101","11.45254"
"182.80000","91.40097","11.46417"
"183.00000","91.50100","11.47602"
"183.20000","91.60098","11.48840"
"183.40000","91.70100","11.49958"
"183.60000","91.80103","11.51089"
"183.80000","91.90087","11.52131"
"184.00000","92.00097","11.52975"
"184.20000","92.10099","11.53661"
"184.40000","92.20108","11.54499"
"184.60000","92.30099","11.55080"
"184.80000","92.40090","11.56357"
"185.00000","92.50105","11.57697"
"185.20000","92.60101","11.58911"
"185.40000","92.70110","11.60497"
"185.60000","92.80107","11.61819"
"185.80000","92.90098","11.63134"
"186.00000","93.00106","11.64662"
"186.20000","93.10098","11.66173"
"186.40000","93.20094","11.67725"
"186.60000","93.30097","11.69071"
"186.80000","93.40100","11.70431"
"187.00000","93.50102","11.71026"
"187.20000","93.60106","11.72204"
"187.40000","93.70108","11.72939"
"187.60000","93.80099","11.73631"
"187.80000","93.90108","11.74124"
"188.00000","94.00104","11.74587"
"188.20000","94.10094","11.75369"
"188.40000","94.20097","11.76368"
"188.60000","94.30102","11.77277"
"188.80000","94.40098","11.78835"
"189.00000","94.50107","11.80052"
"189.20000","94.60098","11.81165"
"189.40000","94.70100","11.82753"
"189.60000","94.80109","11.83748"
"189.80000","94.90094","11.85080"
"190.00000","95.00102","11.85978"
"190.20000","95.10100","11.87225"
"190.40000","95.20102","11.88739"
"190.60000","95.30105","11.90260"
"190.80000","95.40096","11.91664"
"191.00000","95.50098","11.92779"
"191.20000","95.60101","11.93818"
"191.40000","95.70110","11.94806"
"191.60000","95.80094","11.95773"
"191.80000","95.90110","11.96517"
"192.00000","96.00107","11.97443"
"192.20000","96.10103","11.98118"
"192.40000","96.20107","11.98814"
"192.60000","96.30097","12.00321"
"192.80000","96.40105","12.01149"
"193.00000","96.50108","12.02297"
"193.20000","96.60105","12.03476"
"193.40000","96.70102","12.04604"
"193.60000","96.80111","12.05712"
"193.80000","96.90102","12.06898"
"194.00000","97.00092","12.08192"
"194.20000","97.10102","12.09526"
"194.40000","97.20110","12.10958"
"194.60000","97.30112","12.11743"
"194.80000","97.40110","12.12970"
"195.00000","97.50106","12.13860"
"195.20000","97.60091","12.14441"
"195.40000","97.70107","12.15198"
"195.60000","97.80115","12.15668"
"195.80000","97.90100","12.16922"
"196.00000","98.00108","12.17915"
"196.20000","98.10099","12.19073"
"196.40000","98.20096","12.20445"
"196.60000","98.30099","12.21793"
"196.80000","98.40101","12.23234"
"197.00000","98.50105","12.24380"
"197.20000","98.60107","12.25551"
"197.40000","98.70104","12.26554"
"197.60000","98.80095","12.27742"
"197.80000","98.90109","12.28656"
"198.00000","99.00101","12.29918"
"198.20000","99.10103","12.31015"
"198.40000","99.20100","12.32026"
"198.60000","99.30109","12.33187"
"198.80000","99.40099","12.34073"
"199.00000","99.50102","12.35161"
"199.20000","99.60099","12.35943"
"199.40000","99.70103","12.36748"
"199.60000","99.80105","12.37627"
"199.80000","99.90096","12.38479"
"200.00000","100.00104","12.39422"
"200.20000","100.10101","12.40737"
"200.40000","100.20110","12.41879"
"200.60000","100.30101","12.43116"
"200.80000","100.40097","12.44230"
"201.00000","100.50107","12.45544"
"201.20000","100.60103","12.46517"
"201.40000","100.70100","12.47926"
"201.60000","100.80103","12.49329"
"201.80000","100.90094","12.50573"
"202.00000","101.00096","12.51950"
"202.20000","101.10099","12.53020"
"202.40000","101.20095","12.53837"
"202.60000","101.30099","12.54781"
"202.80000","101.40095","12.55636"
"203.00000","101.50098","12.56413"
"203.20000","101.60101","12.56970"
"203.40000","101.70103","12.57617"
"203.60000","101.80094","12.58413"
"203.80000","101.90103","12.59174"
"204.00000","102.00100","12.59890"
"204.20000","102.10097","12.61437"
"204.40000","102.20107","12.62730"
"204.60000","102.30109","12.64213"
"204.80000","102.40093","12.65550"
"205.00000","102.50096","12.66525"
"205.20000","102.60099","12.67510"
"205.40000","102.70097","12.68607"
"205.60000","102.80099","12.69724"
"205.80000","102.90096","12.70887"
"206.00000","103.00099","12.71958"
"206.20000","103.10094","12.73057"
"206.40000","103.20098","12.74191"
"206.60000","103.30100","12.75326"
"206.80000","103.40121","12.76363"
"207.00000","103.50101","12.77087"
"207.20000","103.60103","12.77911"
"207.40000","103.70100","12.78683"
"207.60000","103.80103","12.79575"
"207.80000","103.90099","12.80390"
"208.00000","104.00097","12.81238"
"208.20000","104.10100","12.82203"
"208.40000","104.20096","12.83175"
"208.60000","104.30105","12.84443"
"208.80000","104.40102","12.85668"
"209.00000","104.50110","12.86674"
"209.20000","104.60095","12.87804"
"209.40000","104.70103","12.88769"
"209.60000","104.80095","12.89995"
"209.80000","104.90104","12.91299"
"210.00000","105.00107","12.92642"
"210.20000","105.10103","12.93956"
"210.40000","105.20100","12.95419"
"210.60000","105.30103","12.96450"
"210.80000","105.40099","12.97108"
"211.00000","105.50097","12.97962"
"211.20000","105.60094","12.98452"
"211.40000","105.70096","12.99184"
"211.60000","105.80099","12.99893"
"211.80000","105.90095","13.00457"
"212.00000","106.00105","13.01946"
"212.20000","106.10101","13.02881"
"212.40000","106.20110","13.04021"
"212.60000","106.30107","13.05263"
"212.80000","106.40098","13.06196"
"213.00000","106.50095","13.07515"
"213.20000","106.60104","13.08505"
"213.40000","106.70100","13.09514"
"213.60000","106.80097","13.10525"
"213.80000","106.90100","13.11284"
"214.00000","107.00096","13.12442"
"214.20000","107.10098","13.13400"
"214.40000","107.20103","13.14587"
"214.60000","107.30099","13.15531"
"214.80000","107.40102","13.16359"
"215.00000","107.50104","13.17179"
"215.20000","107.60095","13.18335"
"215.40000","107.70104","13.18937"
"215.60000","107.80100","13.19845"
"215.80000","107.90098","13.20478"
"216.00000","108.00101","13.21612"
"216.20000","108.10097","13.22968"
"216.40000","108.20094","13.24042"
"216.60000","108.30103","13.25589"
"216.80000","108.40094","13.26442"
"217.00000","108.50101","13.27420"
"217.20000","108.60100","13.28469"
"217.40000","108.70095","13.29516"
"217.60000","108.80105","13.30780"
"217.80000","108.90096","13.31903"
"218.00000","109.00099","13.32978"
"218.20000","109.10101","13.34274"
"218.40000","109.20098","13.35312"
"218.60000","109.30100","13.36479"
"218.80000","109.40097","13.37229"
"219.00000","109.50107","13.38083"
"219.20000","109.60103","13.38424"
"219.40000","109.70107","13.39026"
"219.60000","109.80091","13.39475"
"219.80000","109.90099","13.40361"
"220.00000","110.00103","13.40507"
"220.20000","110.10106","13.41344"
"220.40000","110.20096","13.42459"
"220.60000","110.30099","13.43696"
"220.80000","110.40096","13.44535"
"221.00000","110.50105","13.46023"
"221.20000","110.60095","13.47440"
"221.40000","110.70104","13.48816"
"221.60000","110.80107","13.49899"
"221.80000","110.90099","13.51077"
"222.00000","111.00095","13.52291"
"222.20000","111.10104","13.53129"
"222.40000","111.20100","13.54436"
"222.60000","111.30109","13.55425"
"222.80000","111.40105","13.56784"
"223.00000","111.50103","13.57615"
"223.20000","111.60099","13.58162"
"223.40000","111.70103","13.59313"
"223.60000","111.80104","13.60030"
"223.80000","111.90102","13.60745"
"224.00000","112.00104","13.61506"
"224.20000","112.10107","13.62236"
"224.40000","112.20097","13.62972"
"224.60000","112.30101","13.63868"
"224.80000","112.40103","13.64841"
"225.00000","112.50112","13.65918"
"225.20000","112.60104","13.66795"
"225.40000","112.70113","13.67677"
"225.60000","112.80097","13.68721"
"225.80000","112.90106","13.69497"
"226.00000","113.00102","13.70311"
"226.20000","113.10105","13.71174"
"226.40000","113.20102","13.72018"
"226.60000","113.30112","13.73257"
"226.80000","113.40096","13.74516"
"227.00000","113.50099","13.75616"
"227.20000","113.60107","13.76978"
"227.40000","113.70099","13.78198"
"227.60000","113.80106","13.78654"
"227.80000","113.90098","13.80065"
"228.00000","114.00100","13.80641"
"228.20000","114.10103","13.81399"
"228.40000","114.20112","13.82045"
"228.60000","114.30109","13.82650"
"228.80000","114.40105","13.83745"
"229.00000","114.50097","13.84639"
"229.20000","114.60104","13.85453"
"229.40000","114.70102","13.86847"
"229.60000","114.80099","13.87922"
"229.80000","114.90102","13.89234"
"230.00000","115.00105","13.90431"
"230.20000","115.10107","13.91109"
"230.40000","115.20098","13.92161"
"230.60000","115.30095","13.93053"
"230.80000","115.40097","13.94170"
"231.00000","115.50100","13.95034"
"231.20000","115.60104","13.95761"
"231.40000","115.70100","13.96638"
"231.60000","115.80096","13.97316"
"231.80000","115.90105","13.98265"
"232.00000","116.00102","13.98843"
"232.20000","116.10099","13.99478"
"232.40000","116.20101","14.00035"
"232.60000","116.30105","14.00643"
"232.80000","116.40095","14.01193"
"233.00000","116.50093","14.02101"
"233.20000","116.60095","14.03436"
"233.40000","116.70092","14.04409"
"233.60000","116.80107","14.05656"
"233.80000","116.90103","14.06779"
"234.00000","117.00101","14.08700"
"234.20000","117.10104","14.09613"
"234.40000","117.20118","14.10397"
"234.60000","117.30103","14.11613"
"234.80000","117.40093","14.12340"
"235.00000","117.50096","14.13334"
"235.20000","117.60105","14.14427"
"235.40000","117.70107","14.15388"
"235.60000","117.80092","14.16909"
"235.80000","117.90101","14.17838"
"236.00000","118.00105","14.19086"
"236.20000","118.10101","14.20214"
"236.40000","118.20104","14.20545"
"236.60000","118.30113","14.21341"
"236.80000","118.40098","14.22192"
"237.00000","118.50112","14.22403"
"237.20000","118.60103","14.22957"
"237.40000","118.70106","14.23338"
"237.60000","118.80103","14.23617"
"237.80000","118.90106","14.24815"
"238.00000","119.00103","14.24794"
"238.20000","119.10100","14.25636"
"238.40000","119.20102","14.26663"
"238.60000","119.30104","14.27786"
"238.80000","119.40096","14.28754"
"239.00000","119.50098","14.29784"
"239.20000","119.60089","14.30648"
"239.40000","119.70103","14.31849"
"239.60000","119.80095","14.32720"
"239.80000","119.90097","14.34022"
"240.00000","120.00106","14.35433"
"240.20000","120.10104","14.36218"
"240.40000","120.20100","14.37754"
"240.60000","120.30096","14.38791"
"240.80000","120.40112","14.39776"
"241.00000","120.50103","14.40888"
"241.20000","120.60094","14.41428"
"241.40000","120.70101","14.42123"
"241.60000","120.80099","14.42860"
"241.80000","120.90108","14.43448"
"242.00000","121.00105","14.44370"
"242.20000","121.10101","14.45127"
"242.40000","121.20110","14.46135"
"242.60000","121.30107","14.46958"
"242.80000","121.40092","14.48041"
"243.00000","121.50106","14.48982"
"243.20000","121.60097","14.50066"
"243.40000","121.70100","14.50780"
"243.60000","121.80103","14.51672"
"243.80000","121.90100","14.52317"
"244.00000","122.00102","14.52964"
"244.20000","122.10099","14.53691"
"244.40000","122.20103","14.54471"
"244.60000","122.30098","14.55124"
"244.80000","122.40108","14.56058"
"245.00000","122.50092","14.56832"
"245.20000","122.60107","14.57857"
"245.40000","122.70104","14.58710"
"245.60000","122.80100","14.59652"
"245.80000","122.90098","14.60578"
"246.00000","123.00100","14.61475"
"246.20000","123.10097","14.61812"
"246.40000","123.20100","14.62723"
"246.60000","123.30091","14.63266"
"246.80000","123.40112","14.63850"
"247.00000","123.50101","14.64935"
"247.20000","123.60100","14.65209"
"247.40000","123.70102","14.66281"
"247.60000","123.80099","14.67561"
"247.80000","123.90107","14.68343"
"248.00000","124.00105","14.69573"
"248.20000","124.10107","14.70584"
"248.40000","124.20092","14.71567"
"248.60000","124.30101","14.72720"
"248.80000","124.40092","14.73442"
"249.00000","124.50095","14.74500"
"249.20000","124.60098","14.75412"
"249.40000","124.70100","14.76232"
"249.60000","124.80103","14.77198"
"249.80000","124.90105","14.78211"
"250.00000","125.00095","14.79118"
"250.20000","125.10098","14.79904"
"250.40000","125.20107","14.80703"
"250.60000","125.30105","14.81113"
"250.80000","125.40106","14.81815"
"251.00000","125.50104","14.82071"
"251.20000","125.60107","14.82509"
"251.40000","125.70090","14.82862"
"251.60000","125.80093","14.83134"
"251.80000","125.90103","14.83487"
"252.00000","126.00106","14.83794"
"252.20000","126.10103","14.84086"
"252.40000","126.20099","14.85059"
"252.60000","126.30090","14.85532"
"252.80000","126.40105","14.86068"
"253.00000","126.50114","14.86913"
"253.20000","126.60092","14.87966"
"253.40000","126.70107","14.88673"
"253.60000","126.80104","14.89728"
"253.80000","126.90102","14.90228"
"254.00000","127.00097","14.90707"
"254.20000","127.10107","14.91518"
"254.40000","127.20097","14.91492"
"254.60000","127.30101","14.90901"
"254.80000","127.40096","14.90741"
"255.00000","127.50094","14.89652"
"255.20000","127.60103","14.88000"
"255.31000","127.65597","14.26323"
"255.31400","127.65801","11.75052"
"255.31800","127.65997","9.41538"
"255.32000","127.66099","8.28310"