File: MT-DataAnalysis-JupyterNotebook/BaselinePlots/BaselineTests/0_Degree/i100_0_2.csv
Specimen label,"i100_0_2"
End date,"8/16/2018 4:47 PM"
Area,"13.20254",mm^2
Axial Gauge Length,"16.02686",mm
Maximum Load,"607.43774",N
Tensile stress at Yield (Offset 0.2 %),"44.81992",MPa
Modulus,"2585.18591",MPa
Tensile strain (Video axial strain) at Maximum Load,"0.02062",mm/mm
Tensile stress at Maximum Load,"46.00915",MPa
Specimen note 1,""

Time,Extension,Load,Tensile Stress,Axial Strain
(s),(mm),(N),(MPa),(mm/mm)
"0.00000","0.00000","1.59064","0.12048","-0.00008"
"0.10000","0.00855","5.77739","0.43760","0.00016"
"0.20000","0.02954","24.84834","1.88209","0.00068"
"0.30000","0.04957","44.72834","3.38786","0.00131"
"0.40000","0.06726","61.63956","4.66876","0.00184"
"0.50000","0.08382","76.64369","5.80522","0.00225"
"0.60000","0.10045","91.29436","6.91491","0.00272"
"0.70000","0.11707","106.08272","8.03502","0.00307"
"0.80000","0.13369","120.74407","9.14552","0.00354"
"0.90000","0.15031","135.14095","10.23598","0.00388"
"1.00000","0.16705","149.60316","11.33139","0.00424"
"1.10000","0.18361","163.76933","12.40438","0.00480"
"1.20000","0.20035","177.77382","13.46512","0.00521"
"1.30000","0.21698","191.75642","14.52420","0.00562"
"1.40000","0.23372","205.62204","15.57443","0.00596"
"1.50000","0.25034","219.23351","16.60540","0.00635"
"1.60000","0.26696","232.60283","17.61803","0.00686"
"1.70000","0.28364","245.96664","18.63025","0.00738"
"1.80000","0.30032","258.94196","19.61304","0.00751"
"1.90000","0.31694","271.73239","20.58182","0.00808"
"2.00000","0.33363","284.52512","21.55078","0.00841"
"2.10000","0.35031","297.21536","22.51198","0.00876"
"2.20000","0.36699","309.66525","23.45497","0.00914"
"2.30000","0.38361","321.94424","24.38502","0.00952"
"2.40000","0.40029","334.11334","25.30674","0.00981"
"2.50000","0.41697","346.06354","26.21188","0.01022"
"2.60000","0.43365","357.93695","27.11121","0.01061"
"2.70000","0.45022","369.57135","27.99244","0.01104"
"2.80000","0.46702","381.04453","28.86145","0.01137"
"2.90000","0.48358","392.20996","29.70715","0.01185"
"3.00000","0.50020","403.25571","30.54379","0.01236"
"3.10000","0.51694","413.99530","31.35724","0.01239"
"3.20000","0.53356","424.61929","32.16193","0.01274"
"3.30000","0.55024","435.03369","32.95075","0.01318"
"3.40000","0.56686","445.38110","33.73449","0.01348"
"3.50000","0.58355","455.31375","34.48682","0.01382"
"3.60000","0.60023","465.22961","35.23788","0.01412"
"3.70000","0.61691","474.83261","35.96524","0.01452"
"3.80000","0.63359","484.20624","36.67522","0.01489"
"3.90000","0.65021","493.36145","37.36867","0.01513"
"4.00000","0.66689","502.38895","38.05244","0.01553"
"4.10000","0.68363","511.22885","38.72200","0.01584"
"4.20000","0.70020","519.59351","39.35556","0.01615"
"4.30000","0.71688","527.93866","39.98765","0.01651"
"4.40000","0.73362","535.91541","40.59183","0.01674"
"4.50000","0.75024","543.47357","41.16431","0.01701"
"4.60000","0.76698","550.86658","41.72428","0.01741"
"4.70000","0.78360","558.00476","42.26495","0.01769"
"4.80000","0.80028","564.79095","42.77895","0.01792"
"4.90000","0.81696","571.23053","43.26670","0.01819"
"5.00000","0.83359","577.52863","43.74374","0.01854"
"5.10000","0.85027","583.14575","44.16920","0.01883"
"5.20000","0.86689","588.39008","44.56642","0.01900"
"5.30000","0.88363","593.36755","44.94343","0.01944"
"5.40000","0.90025","597.69031","45.27085","0.01974"
"5.50000","0.91699","601.35461","45.54839","0.01994"
"5.60000","0.93361","603.88574","45.74011","0.02012"
"5.70000","0.95029","606.46857","45.93574","0.02045"
"5.80000","0.96698","607.43774","46.00915","0.02062"
"5.90000","0.98366","607.35742","46.00306","0.02095"
"6.00000","1.00034","605.57672","45.86819","0.02110"
"6.10000","1.01696","602.75684","45.65460","0.02139"
"6.20000","1.03364","598.08112","45.30045","0.02156"
"6.30000","1.05026","592.54010","44.88075","0.02177"
"6.40000","1.06694","586.61688","44.43211","0.02196"
"6.50000","1.08357","580.37079","43.95901","0.02212"
"6.60000","1.10031","574.31018","43.49997","0.02242"
"6.70000","1.11693","568.41064","43.05312","0.02247"
"6.80000","1.13361","562.60681","42.61352","0.02268"
"6.90000","1.15029","557.13373","42.19897","0.02294"
"7.00000","1.16691","551.75378","41.79148","0.02302"
"7.10000","1.18365","546.21759","41.37215","0.02312"
"7.20000","1.20027","540.89819","40.96924","0.02311"
"7.30000","1.21690","535.42297","40.55453","0.02324"
"7.40000","1.23364","529.60449","40.11382","0.02326"
"7.50000","1.25020","523.77045","39.67194","0.02335"
"7.60000","1.26700","517.57739","39.20285","0.02332"
"7.70000","1.28362","511.36511","38.73232","0.02327"
"7.80000","1.30024","504.53418","38.21492","0.02315"
"7.90000","1.31692","497.43567","37.67726","0.02310"
"8.00000","1.33373","490.35687","37.14109","0.02299"
"8.10000","1.35023","482.61948","36.55504","0.02272"
"8.20000","1.36691","474.33801","35.92778","0.02240"
"8.30000","1.38359","465.66315","35.27071","0.02214"
"8.40000","1.40033","456.03262","34.54127","0.02188"
"8.50000","1.41695","444.86481","33.69539","0.02172"
"8.60000","1.43363","430.73483","32.62514","0.02126"
"8.70000","1.45025","410.56000","31.09704","0.02069"
"8.80000","1.46694","381.65671","28.90782","0.01984"
"8.90000","1.48362","344.04367","26.05889","0.01854"
"9.00000","1.50024","288.67996","21.86548","0.01721"
"9.10000","1.51698","242.00958","18.33053","0.01670"
"9.20000","1.53360","221.51898","16.77851","0.01619"
"9.30000","1.55022","212.20825","16.07329","0.01596"
"9.40000","1.56696","206.99120","15.67813","0.01573"
"9.50000","1.58365","203.37289","15.40407","0.01568"
"9.60000","1.60033","200.37109","15.17670","0.01523"
"9.61600","1.60296","199.76787","15.13101","0.01533"