File: MT-DataAnalysis-JupyterNotebook/BaselinePlots/BaselineTests/45_Degree/i020_45_1.csv
Specimen label,"i20_45_1"
End date,"8/17/2018 5:49 PM"
Area,"13.20254",mm^2
Axial Gauge Length,"14.69697",mm
Maximum Load,"73.70555",N
Tensile stress at Yield (Offset 0.2 %),,MPa
Modulus,"2166.82306",MPa
Tensile strain (Video axial strain) at Maximum Load,"-0.00009",mm/mm
Tensile stress at Maximum Load,"5.58268",MPa
Specimen note 1,""

Time,Extension,Load,Tensile Stress,Axial Strain
(s),(mm),(N),(MPa),(mm/mm)
"0.00000","0.00000","-1.43769","-0.10889","-0.00008"
"0.10000","0.00783","0.13120","0.00994","0.00017"
"0.20000","0.02876","7.93794","0.60124","0.00049"
"0.30000","0.04945","16.80199","1.27263","0.00093"
"0.40000","0.06720","23.77847","1.80105","0.00131"
"0.50000","0.08394","30.00397","2.27259","0.00151"
"0.60000","0.10033","35.91553","2.72035","0.00182"
"0.70000","0.11701","41.97084","3.17900","0.00213"
"0.80000","0.13375","47.61743","3.60669","0.00230"
"0.90000","0.15037","53.29479","4.03671","0.00252"
"1.00000","0.16699","58.68525","4.44500","0.00286"
"1.10000","0.18367","63.74051","4.82790","0.00311"
"1.20000","0.20035","68.25264","5.16966","0.00327"
"1.30000","0.21710","70.44314","5.33557","0.00295"
"1.40000","0.23366","65.46001","4.95814","0.00207"
"1.50000","0.25040","68.74519","5.20697","0.00203"
"1.60000","0.26702","71.68540","5.42967","0.00183"
"1.70000","0.28358","72.56806","5.49652","0.00158"
"1.80000","0.30032","72.58975","5.49816","0.00135"
"1.90000","0.31700","72.82639","5.51609","0.00088"
"2.00000","0.33363","73.15621","5.54107","0.00074"
"2.10000","0.35043","73.63660","5.57746","0.00045"
"2.20000","0.36687","73.66804","5.57984","0.00017"
"2.30000","0.38367","73.70555","5.58268","-0.00009"
"2.40000","0.40029","73.15675","5.54111","-0.00039"
"2.50000","0.41697","70.89615","5.36989","-0.00062"
"2.60000","0.43365","70.78082","5.36115","-0.00094"
"2.70000","0.45033","71.08171","5.38394","-0.00123"
"2.80000","0.46690","70.77511","5.36072","-0.00090"
"2.90000","0.48370","70.85766","5.36697","-0.00121"
"3.00000","0.50026","71.07489","5.38342","-0.00119"
"3.10000","0.51694","71.35397","5.40456","-0.00133"
"3.20000","0.53362","71.49471","5.41522","-0.00140"
"3.30000","0.55024","71.22227","5.39459","-0.00132"
"3.40000","0.56698","70.89804","5.37003","-0.00126"
"3.50000","0.58361","69.70331","5.27954","-0.00121"
"3.60000","0.60029","68.53405","5.19097","-0.00121"
"3.70000","0.61703","67.51930","5.11411","-0.00111"
"3.80000","0.63365","66.51817","5.03828","-0.00094"
"3.90000","0.65027","64.51234","4.88636","-0.00096"
"4.00000","0.66695","62.37064","4.72414","-0.00081"
"4.10000","0.68363","58.86649","4.45872","-0.00083"
"4.20000","0.70031","53.81517","4.07612","-0.00070"
"4.30000","0.71700","47.25790","3.57945","-0.00048"
"4.40000","0.73362","39.24389","2.97245","-0.00025"
"4.50000","0.75024","37.58287","2.84664","-0.00019"
"4.60000","0.76698","36.49906","2.76455","-0.00014"
"4.70000","0.78360","34.47880","2.61153","0.00001"
"4.80000","0.80028","33.86526","2.56506","0.00004"
"4.90000","0.81690","32.33451","2.44911","-0.00022"
"5.00000","0.83359","30.79566","2.33256","0.00001"
"5.10000","0.85033","29.78829","2.25625","-0.00009"
"5.20000","0.86701","28.77748","2.17969","0.00000"
"5.30000","0.88369","27.90549","2.11365","-0.00014"
"5.40000","0.90031","28.01047","2.12160","-0.00001"
"5.50000","0.91699","28.30532","2.14393","0.00001"
"5.60000","0.93367","28.74110","2.17694","0.00001"
"5.70000","0.95029","29.39021","2.22610","0.00012"
"5.80000","0.96698","29.67150","2.24741","0.00021"
"5.90000","0.98372","29.87521","2.26284","0.00018"
"6.00000","1.00022","29.97227","2.27019","0.00015"
"6.10000","1.01702","30.22812","2.28957","0.00033"
"6.20000","1.03364","30.65187","2.32166","0.00032"
"6.30000","1.05020","31.29897","2.37068","0.00038"
"6.40000","1.06700","31.78177","2.40725","0.00041"
"6.50000","1.08357","32.18599","2.43786","0.00046"
"6.60000","1.10025","32.59142","2.46857","0.00049"
"6.70000","1.11699","33.07588","2.50527","0.00043"
"6.80000","1.13355","33.48242","2.53606","0.00044"
"6.90000","1.15029","34.04625","2.57876","0.00042"
"7.00000","1.16691","34.33375","2.60054","0.00046"
"7.10000","1.18359","34.57434","2.61876","0.00038"
"7.20000","1.20033","35.00816","2.65162","0.00032"
"7.30000","1.21708","35.42141","2.68292","0.00032"
"7.40000","1.23358","35.69721","2.70381","0.00029"
"7.50000","1.25038","35.78102","2.71016","0.00039"
"7.60000","1.26694","35.72928","2.70624","0.00038"
"7.70000","1.28362","35.76617","2.70904","0.00032"
"7.80000","1.30024","35.93453","2.72179","0.00035"
"7.90000","1.31698","36.17406","2.73993","0.00038"
"8.00000","1.33367","36.32103","2.75106","0.00033"
"8.10000","1.35029","36.32682","2.75150","0.00033"
"8.20000","1.36697","36.20324","2.74214","0.00026"
"8.30000","1.38365","36.05916","2.73123","0.00031"
"8.40000","1.40033","36.11432","2.73541","0.00044"
"8.50000","1.41701","36.21857","2.74330","0.00031"
"8.60000","1.43363","36.27237","2.74738","0.00035"
"8.70000","1.45025","36.06604","2.73175","0.00030"
"8.80000","1.46700","35.78685","2.71060","0.00033"
"8.90000","1.48362","35.48041","2.68739","0.00022"
"9.00000","1.50030","34.90075","2.64349","0.00029"
"9.10000","1.51698","34.35086","2.60184","0.00023"
"9.20000","1.53354","33.97643","2.57348","0.00013"
"9.30000","1.55034","33.35525","2.52643","0.00010"
"9.40000","1.56696","32.70863","2.47745","0.00018"
"9.50000","1.58359","32.12223","2.43303","0.00024"
"9.60000","1.60027","31.64990","2.39726","0.00016"
"9.70000","1.61695","31.01686","2.34931","0.00021"
"9.80000","1.63357","30.39850","2.30247","0.00032"
"9.90000","1.65037","29.75901","2.25404","0.00025"
"10.00000","1.66699","29.34389","2.22259","0.00020"
"10.10000","1.68367","28.95645","2.19325","0.00028"
"10.20000","1.70035","28.62933","2.16847","0.00025"
"10.30000","1.71686","28.46174","2.15578","0.00019"
"10.40000","1.73366","28.24372","2.13926","0.00041"
"10.50000","1.75028","27.87891","2.11163","0.00055"
"10.60000","1.76696","27.44721","2.07893","0.00050"
"10.70000","1.78370","26.79930","2.02986","0.00031"
"10.80000","1.80020","26.39875","1.99952","0.00048"
"10.90000","1.81694","26.05164","1.97323","0.00048"
"11.00000","1.83369","25.81098","1.95500","0.00042"
"11.10000","1.85025","25.68188","1.94522","0.00065"
"11.20000","1.86693","25.61313","1.94002","0.00044"
"11.30000","1.88367","25.55083","1.93530","0.00076"
"11.40000","1.90023","25.46179","1.92855","0.00033"
"11.50000","1.91697","25.40441","1.92421","0.00050"
"11.60000","1.93365","25.40670","1.92438","0.00059"
"11.70000","1.95027","25.36516","1.92123","0.00052"
"11.80000","1.96702","25.33579","1.91901","0.00050"
"11.90000","1.98358","25.33331","1.91882","0.00048"
"12.00000","2.00032","25.37143","1.92171","0.00065"
"12.10000","2.01694","25.28909","1.91547","0.00063"
"12.20000","2.03368","25.09297","1.90062","0.00059"
"12.30000","2.05030","24.74036","1.87391","0.00064"
"12.40000","2.06698","24.26832","1.83816","0.00075"
"12.50000","2.08355","23.56808","1.78512","0.00075"
"12.60000","2.10029","22.11416","1.67499","0.00083"