File: MT-DataAnalysis-JupyterNotebook/TensionPlots/TensionTests/WireDiameter/Specimen_RawData_27.csv
End date,"8/16/2018"
Specimen label,"D32L50N5d7-6"
Maximum Load,"120.67461",N
Extension at Maximum Load,"24.56800",mm
Maximum Slope (Automatic Young's),"6.12002",N/mm
Rate 1,"30.00000",mm/min

Time,Extension,Load
(s),(mm),(N)
"0.00000","0.00000","0.04174"
"0.10000","0.02822","0.12996"
"0.17600","0.07492","0.25564"
"0.23600","0.11252","0.38149"
"0.30600","0.15270","0.50980"
"0.36600","0.18439","0.63742"
"0.42200","0.21267","0.76462"
"0.50000","0.25147","0.89109"
"0.54400","0.27330","1.01625"
"0.58200","0.29213","1.14420"
"0.60800","0.30511","1.27936"
"0.63800","0.32005","1.40998"
"0.68000","0.34104","1.53784"
"0.71200","0.35694","1.67037"
"0.73600","0.36896","1.80437"
"0.78800","0.39503","1.93004"
"0.82600","0.41404","2.05818"
"0.85200","0.42702","2.18452"
"0.88600","0.44406","2.31471"
"0.92000","0.46092","2.44383"
"0.97400","0.48788","2.57295"
"1.00000","0.50092","2.70370"
"1.02400","0.51287","2.83246"
"1.04800","0.52495","2.95872"
"1.07000","0.53595","3.08439"
"1.10800","0.55491","3.21169"
"1.15200","0.57697","3.33849"
"1.18400","0.59287","3.46425"
"1.21400","0.60800","3.59227"
"1.24800","0.62492","3.72079"
"1.28200","0.64190","3.85496"
"1.31800","0.65996","3.98174"
"1.35600","0.67897","4.11168"
"1.38600","0.69392","4.24536"
"1.42000","0.71090","4.37382"
"1.45400","0.72794","4.50715"
"1.48600","0.74396","4.63702"
"1.53400","0.76800","4.76412"
"1.58000","0.79096","4.89087"
"1.64000","0.82097","5.01677"
"1.71600","0.85900","5.14204"
"1.79200","0.89708","5.26981"
"1.85200","0.92698","5.39500"
"1.90200","0.95191","5.52529"
"1.97000","0.98593","5.65280"
"2.01400","1.00799","5.78387"
"2.05400","1.02796","5.91032"
"2.10400","1.05301","6.03795"
"2.14400","1.07298","6.16383"
"2.18800","1.09493","6.29130"
"2.24400","1.12291","6.42089"
"2.28600","1.14395","6.55029"
"2.32400","1.16291","6.68000"
"2.36200","1.18192","6.80859"
"2.41000","1.20590","6.93438"
"2.44000","1.22102","7.05958"
"2.47800","1.23998","7.18565"
"2.51600","1.25893","7.31980"
"2.53400","1.26790","7.44519"
"2.56000","1.28093","7.57588"
"2.58800","1.29498","7.70248"
"2.62400","1.31286","7.82812"
"2.65000","1.32601","7.95506"
"2.67600","1.33893","8.08587"
"2.71000","1.35591","8.21459"
"2.76400","1.38281","8.34123"
"2.81200","1.40685","8.47252"
"2.86000","1.43094","8.59990"
"2.91000","1.45588","8.72833"
"2.95800","1.47997","8.85745"
"3.01000","1.50604","8.98583"
"3.05800","1.53001","9.11220"
"3.11200","1.55686","9.24001"
"3.16200","1.58191","9.36682"
"3.21800","1.61001","9.49596"
"3.25000","1.62592","9.62647"
"3.29000","1.64601","9.75717"
"3.32200","1.66203","9.89144"
"3.34800","1.67506","10.02228"
"3.38400","1.69294","10.15571"
"3.40800","1.70490","10.28398"
"3.43800","1.71997","10.40912"
"3.46800","1.73497","10.53560"
"3.49400","1.74801","10.66441"
"3.52800","1.76493","10.79595"
"3.57600","1.78890","10.92287"
"3.61800","1.80995","11.05131"
"3.66000","1.83099","11.17637"
"3.70600","1.85395","11.30270"
"3.75600","1.87901","11.43020"
"3.81400","1.90800","11.55856"
"3.85600","1.92893","11.68389"
"3.90600","1.95404","11.81189"
"3.95000","1.97592","11.93832"
"4.00800","2.00486","12.06529"
"4.04000","2.02095","12.19108"
"4.09000","2.04600","12.31965"
"4.15600","2.07894","12.44727"
"4.21400","2.10794","12.57594"
"4.27200","2.13688","12.70265"
"4.34200","2.17191","12.83074"
"4.38200","2.19188","12.95741"
"4.43000","2.21592","13.08287"
"4.47800","2.23996","13.21306"
"4.51800","2.25998","13.34313"
"4.55400","2.27798","13.47055"
"4.59400","2.29795","13.59700"
"4.63400","2.31798","13.72359"
"4.66400","2.33311","13.85510"
"4.69600","2.34895","13.98372"
"4.72600","2.36390","14.11164"
"4.75800","2.37992","14.24197"
"4.78200","2.39188","14.37386"
"4.82400","2.41287","14.49956"
"4.86000","2.43092","14.62720"
"4.89400","2.44796","14.75347"
"4.92800","2.46500","14.88527"
"4.96400","2.48288","15.01150"
"5.00000","2.50100","15.13667"
"5.03000","2.51600","15.26385"
"5.05800","2.52993","15.39199"
"5.09400","2.54799","15.51856"
"5.12000","2.56102","15.64390"
"5.15800","2.57986","15.77757"
"5.19000","2.59600","15.90437"
"5.22200","2.61191","16.03712"
"5.25800","2.63002","16.16281"
"5.29800","2.64987","16.28968"
"5.32800","2.66500","16.42098"
"5.36200","2.68198","16.54770"
"5.39600","2.69896","16.67279"
"5.44200","2.72192","16.79791"
"5.48000","2.74093","16.93115"
"5.52000","2.76096","17.05894"
"5.60800","2.80485","17.18469"
"5.70800","2.85495","17.27697"
"5.80000","2.90099","17.40208"
"5.87200","2.93692","17.52925"
"5.92800","2.96502","17.65436"
"5.97400","2.98792","17.78279"
"6.01800","3.00992","17.90840"
"6.05400","3.02798","18.03956"
"6.10000","3.05100","18.16462"
"6.13000","3.06601","18.29533"
"6.16200","3.08191","18.42593"
"6.19400","3.09799","18.55166"
"6.22600","3.11402","18.67830"
"6.26200","3.13196","18.80949"
"6.30600","3.15390","18.93867"
"6.34400","3.17297","19.06565"
"6.38800","3.19491","19.19982"
"6.41800","3.21010","19.33146"
"6.45600","3.22899","19.45892"
"6.50200","3.25201","19.58680"
"6.53400","3.26798","19.71362"
"6.57000","3.28597","19.84308"
"6.59200","3.29697","19.96980"
"6.62800","3.31497","20.10320"
"6.65400","3.32794","20.23155"
"6.68400","3.34295","20.36427"
"6.71200","3.35682","20.49180"
"6.74600","3.37404","20.62169"
"6.80600","3.40412","20.74914"
"6.85400","3.42803","20.87519"
"6.88600","3.44400","21.00316"
"6.93000","3.46594","21.13364"
"6.97600","3.48890","21.26011"
"7.01600","3.50893","21.39227"
"7.06000","3.53093","21.51806"
"7.11800","3.55993","21.64664"
"7.18000","3.59096","21.77547"
"7.24800","3.62504","21.90432"
"7.28600","3.64405","22.02947"
"7.31200","3.65691","22.15889"
"7.34400","3.67293","22.28876"
"7.38800","3.69505","22.41661"
"7.42400","3.71299","22.54307"
"7.45600","3.72889","22.67850"
"7.48200","3.74199","22.80767"
"7.55000","3.77583","22.93758"
"7.60400","3.80297","23.06331"
"7.64600","3.82396","23.18884"
"7.68400","3.84291","23.31692"
"7.74000","3.87095","23.44338"
"7.78800","3.89493","23.56991"
"7.83400","3.91789","23.69933"
"7.87600","3.93887","23.82870"
"7.91800","3.95992","23.95603"
"7.96200","3.98198","24.08932"
"7.99000","3.99591","24.21707"
"8.02400","4.01295","24.34687"
"8.06000","4.03107","24.47513"
"8.09800","4.04990","24.60506"
"8.13000","4.06605","24.73097"
"8.18400","4.09295","24.85707"
"8.23400","4.11794","24.98207"
"8.29600","4.14892","25.10989"
"8.36000","4.18090","25.23783"
"8.41000","4.20595","25.36632"
"8.45200","4.22694","25.49368"
"8.51400","4.25791","25.62192"
"8.55400","4.27788","25.74970"
"8.59800","4.30006","25.87712"
"8.63600","4.31890","26.00583"
"8.68200","4.34204","26.13252"
"8.71000","4.35597","26.25954"
"8.74800","4.37492","26.38730"
"8.78600","4.39387","26.51544"
"8.81400","4.40792","26.64297"
"8.84200","4.42191","26.77283"
"8.87600","4.43895","26.90475"
"8.90400","4.45295","27.03676"
"8.93000","4.46598","27.16241"
"8.96400","4.48302","27.28935"
"8.99400","4.49797","27.42302"
"9.03400","4.51800","27.55198"
"9.08400","4.54281","27.68215"
"9.11800","4.55985","27.81388"
"9.17000","4.58592","27.94209"
"9.21600","4.60894","28.07311"
"9.26800","4.63494","28.20243"
"9.30000","4.65097","28.32751"
"9.33800","4.66998","28.45340"
"9.36600","4.68385","28.58511"
"9.39800","4.70006","28.71189"
"9.44400","4.72301","28.84352"
"9.48000","4.74095","28.96872"
"9.53400","4.76780","29.09569"
"9.59800","4.79990","29.22359"
"9.66400","4.83303","29.34881"
"9.73200","4.86699","29.47660"
"9.78800","4.89497","29.60338"
"9.86200","4.93198","29.73226"
"9.90800","4.95506","29.86209"
"9.96200","4.98202","29.99106"
"10.00000","5.00098","30.11980"
"10.04600","5.02405","30.24600"
"10.09400","5.04803","30.37874"
"10.12000","5.06100","30.51227"
"10.15400","5.07793","30.64208"
"10.19000","5.09598","30.76948"
"10.23400","5.11798","30.90019"
"10.26400","5.13287","31.02966"
"10.30400","5.15296","31.15837"
"10.34600","5.17383","31.28440"
"10.38800","5.19493","31.41397"
"10.43000","5.21592","31.54056"
"10.46600","5.23404","31.67044"
"10.50400","5.25293","31.80328"
"10.53800","5.26997","31.93299"
"10.57200","5.28695","32.06383"
"10.61400","5.30794","32.19544"
"10.64600","5.32396","32.33200"
"10.67000","5.33604","32.46094"
"10.70000","5.35086","32.59028"
"10.72200","5.36204","32.71746"
"10.74600","5.37388","32.84346"
"10.79200","5.39696","32.97342"
"10.83800","5.41998","33.10619"
"10.87600","5.43893","33.23134"
"10.91800","5.45998","33.35652"
"10.95800","5.48001","33.48841"
"10.99800","5.49998","33.61413"
"11.07200","5.53699","33.73933"
"11.15600","5.57902","33.86485"
"11.25600","5.62895","33.96749"
"11.31200","5.65699","34.09751"
"11.36200","5.68198","34.22515"
"11.40000","5.70087","34.35945"
"11.44200","5.72192","34.48754"
"11.48000","5.74099","34.61566"
"11.51200","5.75695","34.74347"
"11.54600","5.77399","34.87286"
"11.57600","5.78906","35.00696"
"11.62000","5.81095","35.13375"
"11.66400","5.83295","35.26541"
"11.70800","5.85495","35.39798"
"11.74000","5.87097","35.52861"
"11.78200","5.89196","35.65838"
"11.82400","5.91295","35.79247"
"11.85400","5.92801","35.92411"
"11.89600","5.94888","36.05382"
"11.95000","5.97590","36.17889"
"12.00800","6.00490","36.30535"
"12.03000","6.01596","36.43171"
"12.06400","6.03294","36.56124"
"12.10600","6.05393","36.69140"
"12.14600","6.07396","36.81973"
"12.17600","6.08903","36.95250"
"12.21200","6.10696","37.08039"
"12.26200","6.13195","37.20730"
"12.30000","6.15097","37.33684"
"12.36800","6.18499","37.46311"
"12.41400","6.20789","37.59228"
"12.47000","6.23599","37.72178"
"12.51600","6.25901","37.84901"
"12.56400","6.28298","37.97832"
"12.61000","6.30588","38.10536"
"12.64600","6.32394","38.23339"
"12.69800","6.35001","38.36273"
"12.74000","6.37093","38.48798"
"12.79600","6.39903","38.61749"
"12.84200","6.42205","38.74730"
"12.87200","6.43694","38.88380"
"12.89600","6.44902","39.01722"
"12.93400","6.46797","39.14419"
"12.96600","6.48400","39.27158"
"12.99800","6.49996","39.39996"
"13.02800","6.51497","39.53180"
"13.07800","6.53996","39.65733"
"13.13000","6.56597","39.78466"
"13.18200","6.59198","39.91506"
"13.24200","6.62193","40.04225"
"13.28400","6.64286","40.17300"
"13.31000","6.65607","40.30438"
"13.37600","6.68901","40.43391"
"13.40200","6.70205","40.55895"
"13.42800","6.71490","40.68803"
"13.46200","6.73200","40.81330"
"13.49800","6.74994","40.93994"
"13.52400","6.76285","41.07220"
"13.55600","6.77900","41.19817"
"13.59400","6.79795","41.32613"
"13.65400","6.82796","41.45210"
"13.69000","6.84602","41.57822"
"13.72800","6.86497","41.70789"
"13.79400","6.89798","41.83291"
"13.86800","6.93493","41.96084"
"13.94000","6.97092","42.08612"
"14.01000","7.00596","42.21159"
"14.07800","7.03986","42.33731"
"14.12200","7.06192","42.46746"
"14.16800","7.08500","42.59572"
"14.20200","7.10198","42.72550"
"14.23800","7.11998","42.85509"
"14.28400","7.14288","42.98304"
"14.32400","7.16297","43.11424"
"14.35000","7.17600","43.24479"
"14.39000","7.19591","43.37346"
"14.42400","7.21295","43.50500"
"14.45600","7.22891","43.63523"
"14.49200","7.24691","43.76706"
"14.52400","7.26299","43.89897"
"14.56800","7.28494","44.02768"
"14.59800","7.30000","44.15833"
"14.63000","7.31597","44.28623"
"14.68000","7.34102","44.41600"
"14.71600","7.35896","44.54802"
"14.75800","7.38000","44.67387"
"14.80600","7.40398","44.79902"
"14.83800","7.41994","44.92530"
"14.87800","7.43997","45.05334"
"14.91400","7.45791","45.17929"
"14.95600","7.47895","45.30840"
"15.00200","7.50185","45.43642"
"15.04800","7.52493","45.56728"
"15.09000","7.54598","45.69231"
"15.15200","7.57701","45.81940"
"15.25200","7.62705","45.94551"
"15.33400","7.66795","46.07462"
"15.38000","7.69097","46.19983"
"15.42400","7.71297","46.32502"
"15.47200","7.73695","46.45846"
"15.50600","7.75398","46.58682"
"15.53800","7.76983","46.71704"
"15.56800","7.78502","46.85164"
"15.60000","7.80092","46.98338"
"15.63200","7.81688","47.11378"
"15.67000","7.83590","47.24192"
"15.70200","7.85198","47.37041"
"15.75200","7.87685","47.50051"
"15.78600","7.89401","47.62934"
"15.81400","7.90794","47.75790"
"15.85600","7.92899","47.89148"
"15.91600","7.95900","48.01898"
"15.95200","7.97694","48.14621"
"15.99800","7.99984","48.27509"
"16.04800","8.02495","48.40331"
"16.08600","8.04384","48.53246"
"16.13200","8.06692","48.66031"
"16.18400","8.09287","48.78807"
"16.21800","8.10991","48.91391"
"16.25000","8.12594","49.04431"
"16.28000","8.14082","49.17836"
"16.31400","8.15798","49.30912"
"16.34600","8.17401","49.43769"
"16.38600","8.19386","49.56732"
"16.42000","8.21090","49.69251"
"16.47400","8.23792","49.81797"
"16.51400","8.25795","49.94349"
"16.56800","8.28498","50.07184"
"16.62200","8.31200","50.20099"
"16.69600","8.34895","50.32876"
"16.76800","8.38494","50.45409"
"16.84400","8.42297","50.58189"
"16.91800","8.45992","50.71443"
"16.95800","8.48001","50.84705"
"16.99200","8.49699","50.97461"
"17.02800","8.51493","51.10048"
"17.08200","8.54201","51.22824"
"17.10600","8.55397","51.35430"
"17.13600","8.56910","51.48139"
"17.18000","8.59098","51.61121"
"17.23200","8.61705","51.73789"
"17.27000","8.63600","51.86395"
"17.30000","8.65095","51.99335"
"17.35800","8.68001","52.12621"
"17.39800","8.69991","52.25209"
"17.43800","8.71988","52.38249"
"17.46600","8.73388","52.51497"
"17.49400","8.74787","52.64713"
"17.52600","8.76389","52.78010"
"17.55400","8.77806","52.90821"
"17.58600","8.79396","53.03436"
"17.61400","8.80789","53.16690"
"17.65000","8.82607","53.29505"
"17.69000","8.84586","53.42247"
"17.73200","8.86691","53.55097"
"17.77000","8.88592","53.67878"
"17.79800","8.89991","53.81251"
"17.85400","8.92795","53.94144"
"17.91000","8.95599","54.07144"
"17.97400","8.98792","54.19825"
"18.07200","9.03683","54.32453"
"18.14800","9.07498","54.44981"
"18.19000","9.09596","54.57735"
"18.26400","9.13291","54.70718"
"18.30600","9.15390","54.83612"
"18.34600","9.17393","54.96410"
"18.37800","9.18995","55.09019"
"18.42000","9.21100","55.21608"
"18.46400","9.23300","55.34639"
"18.49600","9.24902","55.47816"
"18.54200","9.27204","55.61055"
"18.57800","9.28998","55.74246"
"18.62400","9.31294","55.87038"
"18.65800","9.32992","56.00145"
"18.69600","9.34893","56.12860"
"18.74400","9.37297","56.25663"
"18.77800","9.38989","56.38421"
"18.83800","9.41996","56.51186"
"18.89400","9.44806","56.63826"
"18.94400","9.47305","56.76750"
"19.01600","9.50905","56.89772"
"19.05200","9.52692","57.03157"
"19.08000","9.54097","57.15877"
"19.11000","9.55592","57.28662"
"19.14200","9.57195","57.41295"
"19.17200","9.58689","57.54278"
"19.20600","9.60399","57.67156"
"19.24800","9.62498","57.79738"
"19.31000","9.65601","57.93169"
"19.34400","9.67299","58.05882"
"19.40000","9.70097","58.18485"
"19.45600","9.72895","58.31133"
"19.50800","9.75490","58.43816"
"19.56600","9.78396","58.56561"
"19.60600","9.80393","58.69437"
"19.66200","9.83191","58.82170"
"19.71200","9.85696","58.95104"
"19.76000","9.88100","59.07739"
"19.80600","9.90402","59.20679"
"19.85000","9.92590","59.33667"
"19.89600","9.94898","59.46395"
"19.93400","9.96799","59.59763"
"19.96200","9.98192","59.72771"
"20.00400","10.00297","59.85735"
"20.03000","10.01600","59.98458"
"20.08400","10.04303","60.11193"
"20.12800","10.06497","60.23991"
"20.17200","10.08691","60.37005"
"20.22000","10.11101","60.50057"
"20.26000","10.13098","60.62566"
"20.29800","10.14999","60.75742"
"20.34200","10.17193","60.88245"
"20.38600","10.19388","61.00945"
"20.43400","10.21797","61.14013"
"20.46600","10.23382","61.27238"
"20.50800","10.25492","61.39945"
"20.55000","10.27603","61.53075"
"20.58400","10.29301","61.65931"
"20.63800","10.32003","61.78876"
"20.67600","10.33899","61.91410"
"20.73000","10.36601","62.04445"
"20.79000","10.39590","62.16996"
"20.85400","10.42795","62.29581"
"20.92000","10.46090","62.42202"
"21.02000","10.51088","62.54893"
"21.11600","10.55901","62.67933"
"21.16200","10.58203","62.81014"
"21.21600","10.60894","62.93948"
"21.25200","10.62693","63.07253"
"21.29000","10.64594","63.19761"
"21.31600","10.65892","63.32724"
"21.33800","10.66992","63.46098"
"21.36800","10.68487","63.59171"
"21.40200","10.70197","63.71898"
"21.42600","10.71405","63.85142"
"21.45200","10.72702","63.97747"
"21.49200","10.74699","64.10667"
"21.53800","10.77001","64.23705"
"21.57400","10.78794","64.36440"
"21.62800","10.81497","64.49049"
"21.66800","10.83500","64.62060"
"21.70400","10.85294","64.74906"
"21.74400","10.87291","64.88239"
"21.77200","10.88696","65.00740"
"21.81600","10.90890","65.13291"
"21.85400","10.92797","65.26028"
"21.89600","10.94896","65.38835"
"21.93000","10.96600","65.51437"
"21.97200","10.98686","65.64174"
"22.02200","11.01198","65.77223"
"22.05600","11.02902","65.90458"
"22.09600","11.04899","66.03363"
"22.13800","11.06997","66.16142"
"22.18000","11.09090","66.29090"
"22.23600","11.11888","66.41821"
"22.27800","11.13993","66.54636"
"22.32800","11.16498","66.67375"
"22.42200","11.21203","66.80068"
"22.51800","11.25998","66.92767"
"22.59400","11.29795","67.05380"
"22.66200","11.33191","67.18030"
"22.73200","11.36701","67.30558"
"22.78400","11.39290","67.43104"
"22.84600","11.42393","67.56328"
"22.88400","11.44300","67.69286"
"22.93000","11.46596","67.82379"
"22.97200","11.48694","67.95489"
"23.00800","11.50494","68.08179"
"23.05200","11.52694","68.20840"
"23.10000","11.55086","68.33447"
"23.14400","11.57292","68.46409"
"23.19400","11.59791","68.58983"
"23.24000","11.62099","68.71919"
"23.28800","11.64503","68.84497"
"23.33600","11.66900","68.97057"
"23.37600","11.68891","69.09983"
"23.40000","11.70087","69.23524"
"23.42200","11.71187","69.36108"
"23.45400","11.72790","69.49435"
"23.48800","11.74500","69.62363"
"23.51000","11.75594","69.74951"
"23.53000","11.76598","69.87498"
"23.56400","11.78290","70.00061"
"23.62200","11.81196","70.12933"
"23.65800","11.83002","70.26066"
"23.71200","11.85692","70.38610"
"23.77200","11.88700","70.51215"
"23.83800","11.91994","70.63975"
"23.90200","11.95187","70.76839"
"23.95600","11.97883","70.89542"
"24.01600","12.00897","71.02064"
"24.07800","12.03994","71.14723"
"24.12800","12.06499","71.27923"
"24.17000","12.08598","71.40786"
"24.24400","12.12293","71.54316"
"24.28200","12.14188","71.67149"
"24.31000","12.15593","71.80544"
"24.34000","12.17094","71.93118"
"24.37600","12.18893","72.06326"
"24.41600","12.20896","72.19030"
"24.45800","12.23001","72.31533"
"24.51000","12.25602","72.44112"
"24.54400","12.27300","72.56625"
"24.58200","12.29195","72.69344"
"24.63400","12.31796","72.81965"
"24.69800","12.34995","72.94491"
"24.75600","12.37894","73.07384"
"24.81800","12.40998","73.20026"
"24.87800","12.43999","73.32807"
"24.94600","12.47401","73.45573"
"24.99400","12.49799","73.58167"
"25.04200","12.52196","73.70881"
"25.08400","12.54295","73.83565"
"25.12000","12.56094","73.96272"
"25.16800","12.58486","74.09102"
"25.21800","12.60985","74.21858"
"25.26000","12.63096","74.34824"
"25.30400","12.65296","74.47469"
"25.37400","12.68800","74.60043"
"25.44600","12.72399","74.72809"
"25.50400","12.75299","74.85326"
"25.56400","12.78294","74.97911"
"25.62200","12.81194","75.10793"
"25.67000","12.83592","75.23328"
"25.71000","12.85600","75.36568"
"25.74800","12.87496","75.49501"
"25.78600","12.89397","75.62441"
"25.82800","12.91490","75.75018"
"25.87600","12.93899","75.87899"
"25.91400","12.95795","76.01150"
"25.95200","12.97696","76.13924"
"25.99400","12.99795","76.27010"
"26.04000","13.02090","76.39701"
"26.08800","13.04494","76.52518"
"26.12400","13.06288","76.65360"
"26.16400","13.08297","76.77876"
"26.20800","13.10503","76.90487"
"26.24400","13.12297","77.03274"
"26.28400","13.14300","77.16268"
"26.33800","13.16990","77.29191"
"26.36800","13.18497","77.41956"
"26.40400","13.20302","77.54547"
"26.44400","13.22287","77.67259"
"26.48800","13.24488","77.80264"
"26.53000","13.26592","77.93439"
"26.56600","13.28398","78.06150"
"26.60200","13.30198","78.18984"
"26.64400","13.32302","78.32095"
"26.67600","13.33904","78.44746"
"26.72800","13.36499","78.57529"
"26.79600","13.39890","78.70260"
"26.86000","13.43094","78.83031"
"26.96000","13.48087","78.90495"
"27.06000","13.53097","79.01307"
"27.16000","13.58095","79.09853"
"27.26000","13.63100","79.21848"
"27.33400","13.66789","79.34509"
"27.39400","13.69790","79.47578"
"27.44400","13.72289","79.60231"
"27.48000","13.74095","79.73520"
"27.52800","13.76499","79.86513"
"27.56000","13.78095","79.99557"
"27.58600","13.79398","80.12250"
"27.61600","13.80899","80.25234"
"27.66000","13.83099","80.37956"
"27.69400","13.84797","80.50644"
"27.73400","13.86794","80.63203"
"27.77400","13.88791","80.75799"
"27.82600","13.91386","80.88651"
"27.86800","13.93497","81.01344"
"27.91200","13.95697","81.13905"
"27.95400","13.97796","81.26743"
"27.99400","13.99804","81.39323"
"28.04600","14.02393","81.52134"
"28.08000","14.04103","81.64698"
"28.12000","14.06100","81.77920"
"28.15400","14.07792","81.90443"
"28.19400","14.09789","82.03264"
"28.22800","14.11481","82.15825"
"28.26000","14.13090","82.28822"
"28.31600","14.15900","82.41781"
"28.36600","14.18393","82.54655"
"28.41000","14.20599","82.67317"
"28.46800","14.23493","82.80173"
"28.52000","14.26100","82.93089"
"28.58000","14.29095","83.06002"
"28.63000","14.31589","83.18860"
"28.68000","14.34094","83.31612"
"28.72800","14.36491","83.44508"
"28.80600","14.40396","83.57143"
"28.87200","14.43696","83.69991"
"28.95400","14.47798","83.82655"
"29.00600","14.50398","83.95562"
"29.07000","14.53585","84.08436"
"29.12400","14.56288","84.21172"
"29.18400","14.59307","84.34091"
"29.23400","14.61806","84.46806"
"29.30400","14.65304","84.59498"
"29.35400","14.67785","84.72162"
"29.43800","14.71994","84.84718"
"29.50400","14.75295","84.97249"
"29.55800","14.77997","85.10203"
"29.63600","14.81896","85.23097"
"29.68600","14.84395","85.35970"
"29.72600","14.86404","85.48901"
"29.79400","14.89800","85.61423"
"29.82400","14.91294","85.74888"
"29.86400","14.93297","85.87528"
"29.90400","14.95294","86.00076"
"29.93600","14.96891","86.13081"
"29.96600","14.98391","86.25895"
"29.99600","14.99892","86.39089"
"30.02600","15.01387","86.51968"
"30.06000","15.03103","86.65179"
"30.09200","15.04693","86.78001"
"30.15800","15.07994","86.90532"
"30.22600","15.11390","87.03137"
"30.31000","15.15581","87.15718"
"30.39600","15.19892","87.28522"
"30.46400","15.23300","87.41034"
"30.52800","15.26499","87.54108"
"30.59000","15.29596","87.66995"
"30.64800","15.32489","87.79551"
"30.68800","15.34492","87.92304"
"30.75000","15.37595","88.05099"
"30.79200","15.39694","88.18069"
"30.86600","15.43389","88.31299"
"30.89000","15.44585","88.44945"
"30.92000","15.46103","88.58120"
"30.96000","15.48095","88.70741"
"30.99800","15.50002","88.83758"
"31.02800","15.51491","88.96368"
"31.07200","15.53691","89.09335"
"31.11000","15.55592","89.21860"
"31.15000","15.57595","89.34646"
"31.18200","15.59197","89.47167"
"31.22400","15.61284","89.59773"
"31.30400","15.65296","89.72638"
"31.36400","15.68297","89.85296"
"31.41600","15.70904","89.98143"
"31.49200","15.74701","90.10889"
"31.55000","15.77595","90.23504"
"31.59800","15.79986","90.36233"
"31.66800","15.83496","90.49036"
"31.71600","15.85899","90.61814"
"31.79000","15.89588","90.74453"
"31.87800","15.93995","90.86971"
"31.97800","15.98999","90.99769"
"32.06600","16.03394","91.12331"
"32.16600","16.08398","91.24506"
"32.26200","16.13205","91.37106"
"32.33800","16.16996","91.49688"
"32.40600","16.20398","91.62521"
"32.44000","16.22096","91.75062"
"32.49200","16.24685","91.87583"
"32.53600","16.26891","92.00313"
"32.57600","16.28894","92.12862"
"32.61600","16.30891","92.25506"
"32.66000","16.33097","92.38634"
"32.70600","16.35405","92.51461"
"32.74000","16.37091","92.64201"
"32.80200","16.40194","92.77009"
"32.84600","16.42394","92.89626"
"32.90200","16.45199","93.02434"
"32.94600","16.47393","93.15093"
"33.00000","16.50095","93.27930"
"33.06800","16.53492","93.40849"
"33.10800","16.55506","93.53709"
"33.14800","16.57497","93.66703"
"33.19600","16.59895","93.79348"
"33.23400","16.61790","93.92293"
"33.27000","16.63590","94.05029"
"33.32600","16.66394","94.18110"
"33.35400","16.67793","94.30621"
"33.40200","16.70185","94.43346"
"33.42800","16.71488","94.56548"
"33.46400","16.73294","94.69298"
"33.52400","16.76289","94.82095"
"33.56800","16.78502","94.94663"
"33.60800","16.80498","95.07967"
"33.66200","16.83195","95.20522"
"33.71600","16.85886","95.33162"
"33.76800","16.88492","95.45744"
"33.82600","16.91398","95.58502"
"33.92600","16.96391","95.67784"
"34.02600","17.01401","95.79575"
"34.12600","17.06393","95.85897"
"34.22600","17.11392","95.97665"
"34.32000","17.16103","96.10369"
"34.40600","17.20390","96.23201"
"34.45000","17.22590","96.35767"
"34.51000","17.25598","96.48832"
"34.56200","17.28193","96.61453"
"34.62000","17.31092","96.74182"
"34.66200","17.33191","96.86810"
"34.72200","17.36192","96.99485"
"34.77200","17.38697","97.12059"
"34.82600","17.41388","97.24640"
"34.87200","17.43696","97.37540"
"34.93200","17.46703","97.50446"
"34.97800","17.48999","97.62987"
"35.03000","17.51588","97.75739"
"35.09000","17.54590","97.88685"
"35.14200","17.57190","98.01253"
"35.21200","17.60700","98.14336"
"35.23200","17.61699","98.27104"
"35.26000","17.63110","98.39670"
"35.31400","17.65794","98.52719"
"35.36600","17.68383","98.65718"
"35.39000","17.69585","98.78773"
"35.43400","17.71791","98.91459"
"35.52000","17.76096","99.04248"
"35.56600","17.78392","99.17126"
"35.63000","17.81603","99.29893"
"35.71200","17.85704","99.42478"
"35.78200","17.89202","99.55346"
"35.88200","17.94188","99.67795"
"35.94200","17.97202","99.80326"
"35.99200","17.99695","99.93191"
"36.05000","18.02600","100.05850"
"36.11400","18.05793","100.18420"
"36.18400","18.09303","100.31291"
"36.25400","18.12789","100.44057"
"36.31200","18.15689","100.56630"
"36.38000","18.19097","100.69371"
"36.44200","18.22194","100.82012"
"36.47800","18.24005","100.95197"
"36.53200","18.26690","101.07832"
"36.58000","18.29087","101.20589"
"36.62000","18.31096","101.33408"
"36.68000","18.34098","101.46168"
"36.73000","18.36591","101.58891"
"36.82400","18.41290","101.71404"
"36.92400","18.46301","101.82982"
"36.99200","18.49703","101.95544"
"37.07200","18.53697","102.08200"
"37.14400","18.57296","102.20865"
"37.20600","18.60381","102.33760"
"37.25400","18.62791","102.46316"
"37.30600","18.65398","102.59050"
"37.35800","18.67998","102.71942"
"37.41400","18.70797","102.84748"
"37.46800","18.73493","102.97415"
"37.53400","18.76787","103.10092"
"37.59800","18.79998","103.22746"
"37.66600","18.83406","103.35520"
"37.73000","18.86599","103.48238"
"37.81200","18.90695","103.61089"
"37.91200","18.95687","103.71059"
"38.01200","19.00691","103.81845"
"38.10600","19.05391","103.94430"
"38.19400","19.09803","104.07272"
"38.26000","19.13092","104.20091"
"38.31000","19.15591","104.32912"
"38.36400","19.18299","104.45877"
"38.40600","19.20392","104.58479"
"38.46200","19.23202","104.71579"
"38.50800","19.25498","104.84232"
"38.56600","19.28392","104.96878"
"38.61800","19.30993","105.10047"
"38.66800","19.33498","105.22559"
"38.72800","19.36505","105.35339"
"38.76200","19.38191","105.48009"
"38.81400","19.40798","105.60858"
"38.86000","19.43094","105.73553"
"38.90400","19.45282","105.86255"
"38.96200","19.48188","105.99121"
"39.00600","19.50394","106.12144"
"39.06000","19.53103","106.25121"
"39.13400","19.56792","106.37978"
"39.16400","19.58298","106.50760"
"39.24600","19.62400","106.63430"
"39.30200","19.65192","106.76337"
"39.37400","19.68797","106.88996"
"39.42200","19.71195","107.01921"
"39.49400","19.74794","107.14636"
"39.55600","19.77892","107.27145"
"39.62600","19.81401","107.39835"
"39.70200","19.85198","107.52586"
"39.78800","19.89491","107.65270"
"39.88200","19.94190","107.77924"
"39.98200","19.99200","107.85150"
"40.08200","20.04205","107.91911"
"40.18200","20.09191","108.01659"
"40.28200","20.14196","108.12035"
"40.36600","20.18399","108.24670"
"40.45400","20.22787","108.37305"
"40.49600","20.24898","108.50147"
"40.57800","20.28988","108.62946"
"40.62800","20.31493","108.75639"
"40.68200","20.34189","108.88407"
"40.73600","20.36892","109.01222"
"40.79200","20.39690","109.13885"
"40.85600","20.42901","109.26801"
"40.90800","20.45501","109.39368"
"40.97600","20.48898","109.52319"
"41.03800","20.51989","109.65067"
"41.13000","20.56592","109.77742"
"41.19000","20.59600","109.90380"
"41.26600","20.63403","110.03098"
"41.34800","20.67504","110.15984"
"41.38000","20.69094","110.28554"
"41.46200","20.73196","110.41177"
"41.51000","20.75594","110.53894"
"41.56000","20.78099","110.66554"
"41.61400","20.80801","110.79224"
"41.65800","20.83002","110.92242"
"41.71000","20.85602","111.05056"
"41.77200","20.88694","111.17977"
"41.81000","20.90601","111.30994"
"41.86000","20.93094","111.43598"
"41.94200","20.97184","111.56371"
"42.00600","21.00394","111.68964"
"42.08000","21.04101","111.81716"
"42.17000","21.08597","111.94392"
"42.24000","21.12089","112.07116"
"42.31600","21.15892","112.19809"
"42.41600","21.20890","112.27902"
"42.50400","21.25303","112.40597"
"42.60400","21.30295","112.47833"
"42.70400","21.35288","112.55535"
"42.80400","21.40292","112.65495"
"42.90400","21.45296","112.77496"
"42.99200","21.49697","112.90170"
"43.04400","21.52292","113.02751"
"43.09800","21.54994","113.15671"
"43.16600","21.58396","113.28368"
"43.21800","21.60997","113.40967"
"43.30400","21.65290","113.53612"
"43.35600","21.67896","113.66186"
"43.43400","21.71789","113.78926"
"43.51600","21.75903","113.91648"
"43.61600","21.80889","114.04141"
"43.68600","21.84387","114.16652"
"43.78200","21.89194","114.29270"
"43.82400","21.91292","114.41918"
"43.90800","21.95502","114.54418"
"43.97600","21.98892","114.67126"
"44.05200","22.02700","114.80025"
"44.09600","22.04901","114.92581"
"44.17600","22.08894","115.05251"
"44.23600","22.11890","115.17911"
"44.31400","22.15788","115.30463"
"44.39000","22.19591","115.43253"
"44.48200","22.24201","115.55821"
"44.58200","22.29193","115.66325"
"44.66600","22.33390","115.78845"
"44.76600","22.38400","115.88667"
"44.86600","22.43405","115.96378"
"44.96600","22.48397","116.06432"
"45.06600","22.53402","116.14432"
"45.16600","22.58394","116.23359"
"45.26600","22.63392","116.33968"
"45.32400","22.66292","116.46759"
"45.40000","22.70089","116.59502"
"45.46800","22.73491","116.72258"
"45.54200","22.77204","116.84765"
"45.62400","22.81300","116.97327"
"45.70000","22.85096","117.09828"
"45.78200","22.89192","117.22339"
"45.86800","22.93497","117.35037"
"45.93800","22.96994","117.47642"
"46.02200","23.01203","117.60553"
"46.08800","23.04492","117.73355"
"46.17400","23.08791","117.85856"
"46.24400","23.12294","117.98496"
"46.31800","23.15995","118.11151"
"46.40200","23.20198","118.23900"
"46.50200","23.25191","118.34328"
"46.60200","23.30195","118.45203"
"46.70200","23.35188","118.52974"
"46.80200","23.40198","118.62395"
"46.90200","23.45191","118.71890"
"46.96800","23.48503","118.84618"
"47.06800","23.53502","118.93177"
"47.15600","23.57896","119.06190"
"47.24800","23.62512","119.18880"
"47.30400","23.65304","119.31516"
"47.39400","23.69794","119.44164"
"47.47000","23.73597","119.56715"
"47.55600","23.77896","119.69280"
"47.65600","23.82894","119.77985"
"47.73400","23.86804","119.90602"
"47.83400","23.91796","119.99181"
"47.93400","23.96795","120.06348"
"48.03400","24.01793","120.15096"
"48.13400","24.06798","120.22297"
"48.23400","24.11802","120.29094"
"48.33400","24.16801","120.37277"
"48.43400","24.21799","120.44891"
"48.53400","24.26785","120.49344"
"48.63400","24.31796","120.53423"
"48.73400","24.36800","120.58794"
"48.83400","24.41799","120.61936"
"48.93400","24.46797","120.65497"
"49.03400","24.51801","120.67155"
"49.13400","24.56800","120.67461"
"49.23400","24.61792","120.58356"
"49.25000","24.62599","120.16537"
"49.25200","24.62695","118.83153"
"49.25400","24.62790","115.86562"
"49.25600","24.62892","111.47523"
"49.25800","24.62988","106.23035"
"49.26000","24.63096","100.36816"
"49.26200","24.63197","94.00291"
"49.26400","24.63299","87.28925"
"49.26600","24.63400","80.39034"
"49.26800","24.63502","73.47609"
"49.27000","24.63604","66.62297"