File: MT-DataAnalysis-JupyterNotebook/TensionPlots/TensionTests/WireDiameter/Specimen_RawData_12.csv
End date,"8/16/2018"
Specimen label,"D32L50N5d3-4"
Maximum Load,"12.22661",N
Extension at Maximum Load,"112.40103",mm
Maximum Slope (Automatic Young's),"0.12699",N/mm
Rate 1,"30.00000",mm/min

Time,Extension,Load
(s),(mm),(N)
"0.00000","0.00000","0.00041"
"0.20000","0.09034","0.00171"
"0.40000","0.20173","0.01417"
"0.60000","0.30128","0.03379"
"0.80000","0.40107","0.04952"
"1.00000","0.50104","0.06478"
"1.20000","0.60100","0.07540"
"1.40000","0.70103","0.09101"
"1.60000","0.80100","0.10671"
"1.80000","0.90115","0.12129"
"2.00000","1.00106","0.13251"
"2.20000","1.10096","0.14322"
"2.40000","1.20105","0.15416"
"2.60000","1.30102","0.17034"
"2.80000","1.40111","0.18466"
"3.00000","1.50108","0.19178"
"3.20000","1.60110","0.19773"
"3.40000","1.70101","0.21759"
"3.60000","1.80104","0.22751"
"3.80000","1.90101","0.23755"
"4.00000","2.00104","0.25266"
"4.20000","2.10100","0.26229"
"4.40000","2.20103","0.27593"
"4.60000","2.30112","0.28976"
"4.80000","2.40103","0.30294"
"5.00000","2.50106","0.31762"
"5.20000","2.60102","0.33072"
"5.40000","2.70111","0.34507"
"5.60000","2.80108","0.35935"
"5.80000","2.90111","0.37388"
"6.00000","3.00108","0.38744"
"6.20000","3.10104","0.39876"
"6.40000","3.20095","0.40935"
"6.60000","3.30104","0.42112"
"6.80000","3.40107","0.43252"
"7.00000","3.50110","0.44479"
"7.20000","3.60100","0.45451"
"7.40000","3.70103","0.46835"
"7.60000","3.80094","0.47923"
"7.80000","3.90109","0.49622"
"8.00000","4.00117","0.50746"
"8.20000","4.10096","0.52399"
"8.40000","4.20111","0.53961"
"8.60000","4.30108","0.55308"
"8.80000","4.40105","0.56523"
"9.00000","4.50102","0.57706"
"9.20000","4.60116","0.58889"
"9.40000","4.70095","0.59820"
"9.60000","4.80104","0.60843"
"9.80000","4.90101","0.61985"
"10.00000","5.00098","0.63016"
"10.20000","5.10106","0.64412"
"10.40000","5.20103","0.65410"
"10.60000","5.30106","0.66739"
"10.80000","5.40103","0.68125"
"11.00000","5.50112","0.69405"
"11.20000","5.60108","0.70977"
"11.40000","5.70099","0.72206"
"11.60000","5.80102","0.73759"
"11.80000","5.90111","0.74892"
"12.00000","6.00108","0.76283"
"12.20000","6.10098","0.77351"
"12.40000","6.20101","0.78529"
"12.60000","6.30104","0.79661"
"12.80000","6.40107","0.80970"
"13.00000","6.50098","0.82024"
"13.20000","6.60100","0.83060"
"13.40000","6.70103","0.84392"
"13.60000","6.80100","0.85732"
"13.80000","6.90103","0.87038"
"14.00000","7.00111","0.88349"
"14.20000","7.10096","0.89894"
"14.40000","7.20111","0.91219"
"14.60000","7.30102","0.92436"
"14.80000","7.40105","0.93986"
"15.00000","7.50102","0.95502"
"15.20000","7.60110","0.96961"
"15.40000","7.70095","0.97869"
"15.60000","7.80104","0.99537"
"15.80000","7.90095","1.00707"
"16.00000","8.00098","1.01288"
"16.20000","8.10106","1.02322"
"16.40000","8.20097","1.03440"
"16.60000","8.30100","1.04365"
"16.80000","8.40109","1.05486"
"17.00000","8.50111","1.06690"
"17.20000","8.60102","1.07927"
"17.40000","8.70105","1.09581"
"17.60000","8.80108","1.11153"
"17.80000","8.90099","1.12862"
"18.00000","9.00102","1.14235"
"18.20000","9.10104","1.15810"
"18.40000","9.20101","1.16980"
"18.60000","9.30110","1.18214"
"18.80000","9.40095","1.19859"
"19.00000","9.50109","1.20692"
"19.20000","9.60118","1.21760"
"19.40000","9.70103","1.22710"
"19.60000","9.80112","1.23749"
"19.80000","9.90103","1.24585"
"20.00000","10.00105","1.25737"
"20.20000","10.10108","1.27120"
"20.40000","10.20111","1.28428"
"20.60000","10.30108","1.29531"
"20.80000","10.40111","1.31008"
"21.00000","10.50107","1.32025"
"21.20000","10.60104","1.33350"
"21.40000","10.70095","1.34769"
"21.60000","10.80104","1.36539"
"21.80000","10.90113","1.37842"
"22.00000","11.00103","1.39245"
"22.20000","11.10106","1.40885"
"22.40000","11.20109","1.41724"
"22.60000","11.30118","1.43036"
"22.80000","11.40103","1.44063"
"23.00000","11.50105","1.45125"
"23.20000","11.60102","1.46204"
"23.40000","11.70117","1.47607"
"23.60000","11.80102","1.48811"
"23.80000","11.90105","1.50151"
"24.00000","12.00107","1.51533"
"24.20000","12.10104","1.52801"
"24.40000","12.20101","1.54130"
"24.60000","12.30104","1.55525"
"24.80000","12.40107","1.56495"
"25.00000","12.50110","1.58162"
"25.20000","12.60106","1.59203"
"25.40000","12.70103","1.60661"
"25.60000","12.80112","1.61420"
"25.80000","12.90103","1.62589"
"26.00000","13.00105","1.63026"
"26.20000","13.10108","1.64304"
"26.40000","13.20111","1.65914"
"26.60000","13.30102","1.67305"
"26.80000","13.40105","1.68812"
"27.00000","13.50102","1.70243"
"27.20000","13.60110","1.71928"
"27.40000","13.70107","1.73286"
"27.60000","13.80098","1.75073"
"27.80000","13.90107","1.76204"
"28.00000","14.00103","1.77845"
"28.20000","14.10100","1.79095"
"28.40000","14.20103","1.80798"
"28.60000","14.30112","1.81516"
"28.80000","14.40097","1.82626"
"29.00000","14.50105","1.83659"
"29.20000","14.60102","1.84346"
"29.40000","14.70111","1.85081"
"29.60000","14.80102","1.86123"
"29.80000","14.90105","1.86557"
"30.00000","15.00107","1.88173"
"30.20000","15.10104","1.89149"
"30.40000","15.20101","1.90879"
"30.60000","15.30104","1.92212"
"30.80000","15.40101","1.93643"
"31.00000","15.50109","1.95138"
"31.20000","15.60100","1.96658"
"31.40000","15.70103","1.98617"
"31.60000","15.80100","1.99833"
"31.80000","15.90103","2.01453"
"32.00000","16.00093","2.02659"
"32.20000","16.10108","2.03974"
"32.40000","16.20111","2.05163"
"32.60000","16.30102","2.06086"
"32.80000","16.40104","2.07204"
"33.00000","16.50101","2.08352"
"33.20000","16.60104","2.09661"
"33.40000","16.70101","2.10828"
"33.60000","16.80104","2.11886"
"33.80000","16.90107","2.13225"
"34.00000","17.00103","2.14391"
"34.20000","17.10106","2.15646"
"34.40000","17.20103","2.16815"
"34.60000","17.30100","2.18114"
"34.80000","17.40103","2.19335"
"35.00000","17.50111","2.20704"
"35.20000","17.60102","2.22260"
"35.40000","17.70105","2.23383"
"35.60000","17.80114","2.24645"
"35.80000","17.90105","2.25789"
"36.00000","18.00107","2.26908"
"36.20000","18.10104","2.28106"
"36.40000","18.20107","2.29729"
"36.60000","18.30104","2.31045"
"36.80000","18.40107","2.32371"
"37.00000","18.50097","2.34040"
"37.20000","18.60106","2.35427"
"37.40000","18.70109","2.36966"
"37.60000","18.80106","2.38405"
"37.80000","18.90103","2.39679"
"38.00000","19.00105","2.40906"
"38.20000","19.10102","2.42130"
"38.40000","19.20111","2.43099"
"38.60000","19.30108","2.44050"
"38.80000","19.40111","2.44700"
"39.00000","19.50107","2.45337"
"39.20000","19.60098","2.45934"
"39.40000","19.70107","2.46814"
"39.60000","19.80098","2.48627"
"39.80000","19.90113","2.49962"
"40.00000","20.00115","2.51215"
"40.20000","20.10106","2.52881"
"40.40000","20.20103","2.54652"
"40.60000","20.30100","2.56153"
"40.80000","20.40102","2.57728"
"41.00000","20.50117","2.59323"
"41.20000","20.60102","2.60813"
"41.40000","20.70093","2.62508"
"41.60000","20.80114","2.63754"
"41.80000","20.90111","2.65225"
"42.00000","21.00101","2.66099"
"42.20000","21.10104","2.67489"
"42.40000","21.20113","2.68336"
"42.60000","21.30110","2.69072"
"42.80000","21.40107","2.70184"
"43.00000","21.50092","2.70911"
"43.20000","21.60106","2.71907"
"43.40000","21.70103","2.73036"
"43.60000","21.80106","2.74185"
"43.80000","21.90103","2.75544"
"44.00000","22.00099","2.76959"
"44.20000","22.10108","2.78642"
"44.40000","22.20105","2.80412"
"44.60000","22.30102","2.82017"
"44.80000","22.40105","2.83204"
"45.00000","22.50113","2.84655"
"45.20000","22.60092","2.86004"
"45.40000","22.70107","2.87034"
"45.60000","22.80098","2.88550"
"45.80000","22.90101","2.89423"
"46.00000","23.00103","2.90436"
"46.20000","23.10106","2.92210"
"46.40000","23.20103","2.93520"
"46.60000","23.30106","2.95169"
"46.80000","23.40103","2.96316"
"47.00000","23.50105","2.97726"
"47.20000","23.60102","2.98832"
"47.40000","23.70099","2.99913"
"47.60000","23.80102","3.01116"
"47.80000","23.90104","3.02291"
"48.00000","24.00095","3.03245"
"48.20000","24.10098","3.04514"
"48.40000","24.20113","3.05385"
"48.60000","24.30104","3.06531"
"48.80000","24.40107","3.07546"
"49.00000","24.50103","3.08612"
"49.20000","24.60100","3.09715"
"49.40000","24.70109","3.10915"
"49.60000","24.80100","3.12183"
"49.80000","24.90109","3.14173"
"50.00000","25.00105","3.15551"
"50.20000","25.10102","3.16944"
"50.40000","25.20105","3.18807"
"50.60000","25.30102","3.20354"
"50.80000","25.40104","3.22076"
"51.00000","25.50113","3.23318"
"51.20000","25.60098","3.25001"
"51.40000","25.70107","3.26323"
"51.60000","25.80098","3.27623"
"51.80000","25.90118","3.28133"
"52.00000","26.00103","3.28885"
"52.20000","26.10106","3.29612"
"52.40000","26.20097","3.30182"
"52.60000","26.30100","3.31667"
"52.80000","26.40102","3.32166"
"53.00000","26.50099","3.34052"
"53.20000","26.60102","3.35401"
"53.40000","26.70105","3.37024"
"53.60000","26.80102","3.38498"
"53.80000","26.90105","3.40148"
"54.00000","27.00119","3.41674"
"54.20000","27.10104","3.43125"
"54.40000","27.20101","3.44918"
"54.60000","27.30098","3.46202"
"54.80000","27.40112","3.47312"
"55.00000","27.50097","3.48855"
"55.20000","27.60106","3.49610"
"55.40000","27.70115","3.50938"
"55.60000","27.80100","3.51713"
"55.80000","27.90103","3.52610"
"56.00000","28.00105","3.54003"
"56.20000","28.10102","3.55182"
"56.40000","28.20105","3.56703"
"56.60000","28.30096","3.57624"
"56.80000","28.40111","3.58911"
"57.00000","28.50113","3.60091"
"57.20000","28.60104","3.61312"
"57.40000","28.70101","3.62559"
"57.60000","28.80110","3.64246"
"57.80000","28.90113","3.65405"
"58.00000","29.00103","3.66995"
"58.20000","29.10106","3.67978"
"58.40000","29.20097","3.68975"
"58.60000","29.30106","3.70043"
"58.80000","29.40102","3.71346"
"59.00000","29.50099","3.72264"
"59.20000","29.60114","3.73944"
"59.40000","29.70105","3.75298"
"59.60000","29.80108","3.77008"
"59.80000","29.90104","3.78855"
"60.00000","30.00119","3.80418"
"60.20000","30.10104","3.81668"
"60.40000","30.20113","3.82865"
"60.60000","30.30104","3.84300"
"60.80000","30.40107","3.85400"
"61.00000","30.50109","3.86471"
"61.20000","30.60106","3.87707"
"61.40000","30.70097","3.88774"
"61.60000","30.80100","3.89587"
"61.80000","30.90108","3.90610"
"62.00000","31.00111","3.91577"
"62.20000","31.10114","3.92571"
"62.40000","31.20105","3.93631"
"62.60000","31.30113","3.95076"
"62.80000","31.40110","3.96600"
"63.00000","31.50113","3.98143"
"63.20000","31.60098","3.99581"
"63.40000","31.70119","4.01155"
"63.60000","31.80103","4.02619"
"63.80000","31.90100","4.04170"
"64.00000","32.00103","4.05780"
"64.20000","32.10112","4.07305"
"64.40000","32.20109","4.08939"
"64.60000","32.30099","4.09582"
"64.80000","32.40096","4.11207"
"65.00000","32.50099","4.11649"
"65.20000","32.60108","4.12241"
"65.40000","32.70111","4.13820"
"65.60000","32.80114","4.14509"
"65.80000","32.90110","4.15607"
"66.00000","33.00107","4.17071"
"66.20000","33.10098","4.18458"
"66.40000","33.20107","4.19912"
"66.60000","33.30104","4.21382"
"66.80000","33.40107","4.22687"
"67.00000","33.50109","4.23972"
"67.20000","33.60100","4.25584"
"67.40000","33.70097","4.26749"
"67.60000","33.80100","4.28015"
"67.80000","33.90108","4.29332"
"68.00000","34.00105","4.30622"
"68.20000","34.10108","4.31762"
"68.40000","34.20099","4.32908"
"68.60000","34.30102","4.33954"
"68.80000","34.40104","4.35236"
"69.00000","34.50107","4.36482"
"69.20000","34.60104","4.37612"
"69.40000","34.70113","4.38931"
"69.60000","34.80098","4.40260"
"69.80000","34.90106","4.41454"
"70.00000","35.00097","4.42917"
"70.20000","35.10106","4.44142"
"70.40000","35.20103","4.45944"
"70.60000","35.30094","4.47351"
"70.80000","35.40108","4.49128"
"71.00000","35.50105","4.50344"
"71.20000","35.60096","4.50986"
"71.40000","35.70099","4.52173"
"71.60000","35.80101","4.53124"
"71.80000","35.90104","4.53987"
"72.00000","36.00107","4.54974"
"72.20000","36.10098","4.56313"
"72.40000","36.20101","4.57899"
"72.60000","36.30104","4.59297"
"72.80000","36.40094","4.61073"
"73.00000","36.50103","4.62648"
"73.20000","36.60094","4.64075"
"73.40000","36.70097","4.65283"
"73.60000","36.80106","4.66736"
"73.80000","36.90102","4.68003"
"74.00000","37.00099","4.69210"
"74.20000","37.10108","4.70150"
"74.40000","37.20099","4.71515"
"74.60000","37.30101","4.72344"
"74.80000","37.40104","4.73107"
"75.00000","37.50101","4.74289"
"75.20000","37.60104","4.75329"
"75.40000","37.70101","4.76742"
"75.60000","37.80103","4.78077"
"75.80000","37.90100","4.79433"
"76.00000","38.00103","4.80921"
"76.20000","38.10100","4.82229"
"76.40000","38.20103","4.83486"
"76.60000","38.30106","4.85162"
"76.80000","38.40108","4.86361"
"77.00000","38.50099","4.87953"
"77.20000","38.60102","4.89289"
"77.40000","38.70116","4.91092"
"77.60000","38.80107","4.92221"
"77.80000","38.90098","4.93263"
"78.00000","39.00107","4.93822"
"78.20000","39.10104","4.94733"
"78.40000","39.20107","4.95266"
"78.60000","39.30103","4.96800"
"78.80000","39.40100","4.97587"
"79.00000","39.50109","4.99146"
"79.20000","39.60106","5.00766"
"79.40000","39.70102","5.02222"
"79.60000","39.80106","5.03980"
"79.80000","39.90114","5.05550"
"80.00000","40.00105","5.07076"
"80.20000","40.10108","5.08599"
"80.40000","40.20099","5.10014"
"80.60000","40.30101","5.11434"
"80.80000","40.40104","5.12399"
"81.00000","40.50095","5.13488"
"81.20000","40.60104","5.14205"
"81.40000","40.70107","5.14991"
"81.60000","40.80104","5.16095"
"81.80000","40.90100","5.17381"
"82.00000","41.00109","5.18655"
"82.20000","41.10106","5.19918"
"82.40000","41.20115","5.21156"
"82.60000","41.30094","5.22787"
"82.80000","41.40108","5.23772"
"83.00000","41.50105","5.25100"
"83.20000","41.60102","5.25943"
"83.40000","41.70105","5.27761"
"83.60000","41.80107","5.29125"
"83.80000","41.90099","5.30971"
"84.00000","42.00101","5.31661"
"84.20000","42.10098","5.33311"
"84.40000","42.20095","5.34319"
"84.60000","42.30116","5.35496"
"84.80000","42.40107","5.36590"
"85.00000","42.50103","5.38007"
"85.20000","42.60112","5.39038"
"85.40000","42.70109","5.40343"
"85.60000","42.80106","5.41791"
"85.80000","42.90108","5.43220"
"86.00000","43.00099","5.44509"
"86.20000","43.10102","5.45953"
"86.40000","43.20105","5.47341"
"86.60000","43.30095","5.48729"
"86.80000","43.40104","5.49919"
"87.00000","43.50095","5.51157"
"87.20000","43.60104","5.52346"
"87.40000","43.70107","5.53212"
"87.60000","43.80109","5.54007"
"87.80000","43.90106","5.54933"
"88.00000","44.00109","5.56074"
"88.20000","44.10094","5.56719"
"88.40000","44.20109","5.58039"
"88.60000","44.30106","5.59707"
"88.80000","44.40114","5.61129"
"89.00000","44.50111","5.62783"
"89.20000","44.60102","5.64136"
"89.40000","44.70093","5.65852"
"89.60000","44.80101","5.67431"
"89.80000","44.90116","5.68820"
"90.00000","45.00107","5.70260"
"90.20000","45.10110","5.71717"
"90.40000","45.20100","5.73050"
"90.60000","45.30109","5.74269"
"90.80000","45.40106","5.75358"
"91.00000","45.50115","5.76334"
"91.20000","45.60100","5.76997"
"91.40000","45.70108","5.77813"
"91.60000","45.80105","5.78533"
"91.80000","45.90108","5.79503"
"92.00000","46.00105","5.80918"
"92.20000","46.10102","5.82192"
"92.40000","46.20116","5.83684"
"92.60000","46.30101","5.84968"
"92.80000","46.40110","5.86180"
"93.00000","46.50101","5.87706"
"93.20000","46.60109","5.89612"
"93.40000","46.70113","5.91825"
"93.60000","46.80116","5.92322"
"93.80000","46.90106","5.93764"
"94.00000","47.00115","5.95134"
"94.20000","47.10106","5.96252"
"94.40000","47.20103","5.97283"
"94.60000","47.30106","5.98299"
"94.80000","47.40115","5.99360"
"95.00000","47.50111","6.00609"
"95.20000","47.60108","6.01833"
"95.40000","47.70098","6.03017"
"95.60000","47.80102","6.04486"
"95.80000","47.90116","6.05498"
"96.00000","48.00107","6.06863"
"96.20000","48.10110","6.07889"
"96.40000","48.20107","6.08999"
"96.60000","48.30103","6.09904"
"96.80000","48.40106","6.11206"
"97.00000","48.50115","6.12979"
"97.20000","48.60106","6.14240"
"97.40000","48.70115","6.15223"
"97.60000","48.80106","6.16209"
"97.80000","48.90102","6.17405"
"98.00000","49.00099","6.18403"
"98.20000","49.10102","6.19771"
"98.40000","49.20110","6.21360"
"98.60000","49.30101","6.22830"
"98.80000","49.40098","6.24317"
"99.00000","49.50107","6.25657"
"99.20000","49.60122","6.27056"
"99.40000","49.70100","6.28733"
"99.60000","49.80110","6.30229"
"99.80000","49.90112","6.31676"
"100.00000","50.00115","6.33064"
"100.20000","50.10094","6.34199"
"100.40000","50.20097","6.35689"
"100.60000","50.30105","6.36448"
"100.80000","50.40102","6.37032"
"101.00000","50.50105","6.37550"
"101.20000","50.60102","6.38350"
"101.40000","50.70105","6.38760"
"101.60000","50.80102","6.39825"
"101.80000","50.90104","6.41198"
"102.00000","51.00101","6.42506"
"102.20000","51.10115","6.44035"
"102.40000","51.20107","6.45505"
"102.60000","51.30097","6.46992"
"102.80000","51.40100","6.48752"
"103.00000","51.50103","6.50199"
"103.20000","51.60094","6.51814"
"103.40000","51.70109","6.53548"
"103.60000","51.80099","6.54723"
"103.80000","51.90102","6.56293"
"104.00000","52.00105","6.57498"
"104.20000","52.10102","6.58586"
"104.40000","52.20104","6.59949"
"104.60000","52.30101","6.60479"
"104.80000","52.40104","6.61519"
"105.00000","52.50107","6.62290"
"105.20000","52.60104","6.63446"
"105.40000","52.70101","6.64517"
"105.60000","52.80104","6.65620"
"105.80000","52.90106","6.67034"
"106.00000","53.00103","6.67913"
"106.20000","53.10099","6.69693"
"106.40000","53.20109","6.70788"
"106.60000","53.30093","6.71754"
"106.80000","53.40108","6.73499"
"107.00000","53.50093","6.75146"
"107.20000","53.60102","6.76555"
"107.40000","53.70105","6.77366"
"107.60000","53.80107","6.78493"
"107.80000","53.90098","6.79424"
"108.00000","54.00095","6.80532"
"108.20000","54.10104","6.81658"
"108.40000","54.20100","6.83123"
"108.60000","54.30103","6.84552"
"108.80000","54.40106","6.85976"
"109.00000","54.50097","6.87483"
"109.20000","54.60111","6.88977"
"109.40000","54.70108","6.90304"
"109.60000","54.80099","6.91353"
"109.80000","54.90096","6.92617"
"110.00000","55.00105","6.93673"
"110.20000","55.10101","6.94771"
"110.40000","55.20105","6.96033"
"110.60000","55.30095","6.96851"
"110.80000","55.40105","6.97626"
"111.00000","55.50101","6.98467"
"111.20000","55.60098","6.99401"
"111.40000","55.70101","7.00488"
"111.60000","55.80109","7.01460"
"111.80000","55.90100","7.03001"
"112.00000","56.00097","7.04485"
"112.20000","56.10112","7.05874"
"112.40000","56.20097","7.07309"
"112.60000","56.30106","7.08984"
"112.80000","56.40108","7.10387"
"113.00000","56.50099","7.11839"
"113.20000","56.60108","7.13503"
"113.40000","56.70105","7.15086"
"113.60000","56.80095","7.16568"
"113.80000","56.90105","7.18086"
"114.00000","57.00101","7.19238"
"114.20000","57.10110","7.20468"
"114.40000","57.20107","7.21045"
"114.60000","57.30109","7.21327"
"114.80000","57.40100","7.22237"
"115.00000","57.50109","7.22948"
"115.20000","57.60106","7.23841"
"115.40000","57.70109","7.25470"
"115.60000","57.80112","7.26372"
"115.80000","57.90096","7.27452"
"116.00000","58.00105","7.28816"
"116.20000","58.10102","7.30181"
"116.40000","58.20099","7.31581"
"116.60000","58.30102","7.32786"
"116.80000","58.40110","7.34331"
"117.00000","58.50101","7.36165"
"117.20000","58.60104","7.37683"
"117.40000","58.70100","7.38599"
"117.60000","58.80116","7.39556"
"117.80000","58.90112","7.40850"
"118.00000","59.00097","7.42327"
"118.20000","59.10106","7.43006"
"118.40000","59.20108","7.44189"
"118.60000","59.30105","7.45198"
"118.80000","59.40102","7.46621"
"119.00000","59.50111","7.47825"
"119.20000","59.60107","7.49329"
"119.40000","59.70098","7.50349"
"119.60000","59.80101","7.51208"
"119.80000","59.90104","7.52364"
"120.00000","60.00101","7.53677"
"120.20000","60.10104","7.54478"
"120.40000","60.20118","7.55963"
"120.60000","60.30103","7.57498"
"120.80000","60.40112","7.58816"
"121.00000","60.50103","7.59542"
"121.20000","60.60094","7.60687"
"121.40000","60.70103","7.61573"
"121.60000","60.80117","7.62679"
"121.80000","60.90108","7.63735"
"122.00000","61.00105","7.64717"
"122.20000","61.10096","7.66010"
"122.40000","61.20093","7.67222"
"122.60000","61.30107","7.68817"
"122.80000","61.40110","7.70444"
"123.00000","61.50095","7.72403"
"123.20000","61.60110","7.73819"
"123.40000","61.70101","7.74996"
"123.60000","61.80104","7.75934"
"123.80000","61.90106","7.77350"
"124.00000","62.00103","7.78572"
"124.20000","62.10106","7.79788"
"124.40000","62.20108","7.80518"
"124.60000","62.30105","7.81460"
"124.80000","62.40102","7.82028"
"125.00000","62.50104","7.82696"
"125.20000","62.60101","7.84047"
"125.40000","62.70104","7.84774"
"125.60000","62.80095","7.85947"
"125.80000","62.90110","7.87535"
"126.00000","63.00101","7.89026"
"126.20000","63.10104","7.90253"
"126.40000","63.20100","7.91441"
"126.60000","63.30103","7.92618"
"126.80000","63.40118","7.93961"
"127.00000","63.50103","7.95422"
"127.20000","63.60106","7.97099"
"127.40000","63.70103","7.98379"
"127.60000","63.80111","8.00011"
"127.80000","63.90096","8.01134"
"128.00000","64.00098","8.02355"
"128.20000","64.10107","8.03193"
"128.40000","64.20098","8.04134"
"128.60000","64.30101","8.04562"
"128.80000","64.40110","8.05161"
"129.00000","64.50095","8.05905"
"129.20000","64.60104","8.07359"
"129.40000","64.70107","8.08595"
"129.60000","64.80097","8.09849"
"129.80000","64.90106","8.11127"
"130.00000","65.00097","8.12386"
"130.20000","65.10094","8.13873"
"130.40000","65.20114","8.15136"
"130.60000","65.30117","8.16448"
"130.80000","65.40096","8.17843"
"131.00000","65.50105","8.19029"
"131.20000","65.60101","8.20408"
"131.40000","65.70104","8.21467"
"131.60000","65.80107","8.22210"
"131.80000","65.90104","8.23164"
"132.00000","66.00107","8.23946"
"132.20000","66.10104","8.25379"
"132.40000","66.20094","8.26286"
"132.60000","66.30103","8.27656"
"132.80000","66.40105","8.28911"
"133.00000","66.50097","8.30371"
"133.20000","66.60111","8.31704"
"133.40000","66.70103","8.33197"
"133.60000","66.80105","8.34359"
"133.80000","66.90102","8.35266"
"134.00000","67.00117","8.36093"
"134.20000","67.10107","8.37568"
"134.40000","67.20104","8.38727"
"134.60000","67.30101","8.39892"
"134.80000","67.40109","8.41375"
"135.00000","67.50107","8.42584"
"135.20000","67.60098","8.43283"
"135.40000","67.70100","8.44273"
"135.60000","67.80103","8.45031"
"135.80000","67.90112","8.45744"
"136.00000","68.00102","8.46598"
"136.20000","68.10106","8.47733"
"136.40000","68.20108","8.49095"
"136.60000","68.30111","8.50129"
"136.80000","68.40102","8.51566"
"137.00000","68.50111","8.52825"
"137.20000","68.60107","8.54361"
"137.40000","68.70110","8.55703"
"137.60000","68.80101","8.57077"
"137.80000","68.90098","8.58393"
"138.00000","69.00101","8.59587"
"138.20000","69.10104","8.60884"
"138.40000","69.20100","8.61925"
"138.60000","69.30109","8.62363"
"138.80000","69.40105","8.63757"
"139.00000","69.50103","8.64615"
"139.20000","69.60105","8.65123"
"139.40000","69.70103","8.65793"
"139.60000","69.80111","8.66729"
"139.80000","69.90114","8.68321"
"140.00000","70.00111","8.69554"
"140.20000","70.10107","8.70896"
"140.40000","70.20104","8.72274"
"140.60000","70.30101","8.73662"
"140.80000","70.40103","8.74890"
"141.00000","70.50107","8.76112"
"141.20000","70.60098","8.77196"
"141.40000","70.70100","8.78421"
"141.60000","70.80103","8.79630"
"141.80000","70.90100","8.80959"
"142.00000","71.00103","8.82223"
"142.20000","71.10111","8.83289"
"142.40000","71.20096","8.84223"
"142.60000","71.30111","8.85098"
"142.80000","71.40108","8.85954"
"143.00000","71.50105","8.86834"
"143.20000","71.60102","8.87595"
"143.40000","71.70104","8.88217"
"143.60000","71.80096","8.89294"
"143.80000","71.90104","8.90366"
"144.00000","72.00095","8.91753"
"144.20000","72.10104","8.92861"
"144.40000","72.20100","8.94141"
"144.60000","72.30103","8.95493"
"144.80000","72.40100","8.96944"
"145.00000","72.50097","8.98544"
"145.20000","72.60112","8.99623"
"145.40000","72.70102","9.01483"
"145.60000","72.80099","9.02496"
"145.80000","72.90108","9.03692"
"146.00000","73.00111","9.04623"
"146.20000","73.10114","9.05614"
"146.40000","73.20104","9.06224"
"146.60000","73.30101","9.06830"
"146.80000","73.40092","9.07700"
"147.00000","73.50101","9.08804"
"147.20000","73.60104","9.09590"
"147.40000","73.70112","9.10996"
"147.60000","73.80097","9.12174"
"147.80000","73.90094","9.13519"
"148.00000","74.00115","9.14879"
"148.20000","74.10105","9.15846"
"148.40000","74.20109","9.16915"
"148.60000","74.30111","9.17762"
"148.80000","74.40108","9.18878"
"149.00000","74.50105","9.19954"
"149.20000","74.60107","9.21185"
"149.40000","74.70092","9.22222"
"149.60000","74.80113","9.23115"
"149.80000","74.90115","9.24169"
"150.00000","75.00107","9.25498"
"150.20000","75.10104","9.26430"
"150.40000","75.20107","9.27263"
"150.60000","75.30109","9.28111"
"150.80000","75.40106","9.28966"
"151.00000","75.50102","9.30146"
"151.20000","75.60111","9.31477"
"151.40000","75.70108","9.32707"
"151.60000","75.80106","9.33801"
"151.80000","75.90102","9.34967"
"152.00000","76.00099","9.36261"
"152.20000","76.10119","9.37491"
"152.40000","76.20110","9.38551"
"152.60000","76.30107","9.39806"
"152.80000","76.40098","9.41039"
"153.00000","76.50101","9.42349"
"153.20000","76.60104","9.43405"
"153.40000","76.70112","9.44451"
"153.60000","76.80103","9.45302"
"153.80000","76.90105","9.46084"
"154.00000","77.00114","9.46673"
"154.20000","77.10105","9.47235"
"154.40000","77.20108","9.47820"
"154.60000","77.30111","9.48262"
"154.80000","77.40114","9.49901"
"155.00000","77.50105","9.50903"
"155.20000","77.60107","9.51912"
"155.40000","77.70098","9.53824"
"155.60000","77.80107","9.55289"
"155.80000","77.90104","9.56569"
"156.00000","78.00107","9.57686"
"156.20000","78.10103","9.58727"
"156.40000","78.20107","9.59943"
"156.60000","78.30103","9.61154"
"156.80000","78.40105","9.62395"
"157.00000","78.50102","9.63512"
"157.20000","78.60110","9.64837"
"157.40000","78.70115","9.65814"
"157.60000","78.80099","9.66747"
"157.80000","78.90102","9.67586"
"158.00000","79.00098","9.68590"
"158.20000","79.10102","9.69181"
"158.40000","79.20104","9.69841"
"158.60000","79.30107","9.70390"
"158.80000","79.40103","9.71167"
"159.00000","79.50106","9.71888"
"159.20000","79.60097","9.72768"
"159.40000","79.70107","9.73704"
"159.60000","79.80103","9.74775"
"159.80000","79.90106","9.75810"
"160.00000","80.00097","9.76714"
"160.20000","80.10112","9.77799"
"160.40000","80.20097","9.79011"
"160.60000","80.30099","9.79904"
"160.80000","80.40114","9.80724"
"161.00000","80.50105","9.82590"
"161.20000","80.60107","9.84619"
"161.40000","80.70110","9.85473"
"161.60000","80.80107","9.86717"
"161.80000","80.90104","9.87636"
"162.00000","81.00094","9.88220"
"162.20000","81.10103","9.88850"
"162.40000","81.20106","9.89703"
"162.60000","81.30096","9.90985"
"162.80000","81.40099","9.91670"
"163.00000","81.50097","9.92869"
"163.20000","81.60099","9.93691"
"163.40000","81.70113","9.95316"
"163.60000","81.80098","9.96660"
"163.80000","81.90114","9.97555"
"164.00000","82.00098","9.98668"
"164.20000","82.10120","9.99546"
"164.40000","82.20098","10.00497"
"164.60000","82.30106","10.01343"
"164.80000","82.40097","10.02283"
"165.00000","82.50107","10.03127"
"165.20000","82.60103","10.04141"
"165.40000","82.70100","10.05021"
"165.60000","82.80103","10.06065"
"165.80000","82.90105","10.06735"
"166.00000","83.00097","10.07442"
"166.20000","83.10099","10.08155"
"166.40000","83.20108","10.08832"
"166.60000","83.30111","10.09382"
"166.80000","83.40102","10.10308"
"167.00000","83.50098","10.11798"
"167.20000","83.60114","10.12966"
"167.40000","83.70104","10.14239"
"167.60000","83.80112","10.15387"
"167.80000","83.90110","10.16747"
"168.00000","84.00101","10.17715"
"168.20000","84.10104","10.18683"
"168.40000","84.20106","10.20075"
"168.60000","84.30103","10.21121"
"168.80000","84.40099","10.22189"
"169.00000","84.50109","10.23338"
"169.20000","84.60105","10.24702"
"169.40000","84.70103","10.25826"
"169.60000","84.80110","10.26957"
"169.80000","84.90108","10.28041"
"170.00000","85.00104","10.28705"
"170.20000","85.10114","10.29398"
"170.40000","85.20104","10.29579"
"170.60000","85.30107","10.30023"
"170.80000","85.40103","10.30609"
"171.00000","85.50107","10.31134"
"171.20000","85.60098","10.31346"
"171.40000","85.70100","10.31988"
"171.60000","85.80108","10.32663"
"171.80000","85.90111","10.34132"
"172.00000","86.00108","10.35380"
"172.20000","86.10100","10.36585"
"172.40000","86.20114","10.37747"
"172.60000","86.30105","10.38692"
"172.80000","86.40108","10.39795"
"173.00000","86.50105","10.40962"
"173.20000","86.60101","10.41795"
"173.40000","86.70110","10.43188"
"173.60000","86.80119","10.44359"
"173.80000","86.90097","10.45630"
"174.00000","87.00107","10.46779"
"174.20000","87.10110","10.47925"
"174.40000","87.20107","10.48711"
"174.60000","87.30097","10.49450"
"174.80000","87.40100","10.50316"
"175.00000","87.50114","10.51098"
"175.20000","87.60111","10.51983"
"175.40000","87.70108","10.52722"
"175.60000","87.80112","10.53559"
"175.80000","87.90114","10.54405"
"176.00000","88.00105","10.55206"
"176.20000","88.10101","10.55922"
"176.40000","88.20099","10.56816"
"176.60000","88.30107","10.57589"
"176.80000","88.40110","10.58441"
"177.00000","88.50101","10.59102"
"177.20000","88.60104","10.59879"
"177.40000","88.70100","10.60606"
"177.60000","88.80103","10.61228"
"177.80000","88.90112","10.62059"
"178.00000","89.00114","10.63171"
"178.20000","89.10111","10.64293"
"178.40000","89.20103","10.65559"
"178.60000","89.30099","10.66526"
"178.80000","89.40108","10.68019"
"179.00000","89.50111","10.68719"
"179.20000","89.60114","10.69457"
"179.40000","89.70104","10.70124"
"179.60000","89.80101","10.70790"
"179.80000","89.90091","10.71339"
"180.00000","90.00107","10.71878"
"180.20000","90.10109","10.72845"
"180.40000","90.20100","10.73984"
"180.60000","90.30103","10.74872"
"180.80000","90.40099","10.75898"
"181.00000","90.50101","10.76847"
"181.20000","90.60100","10.78174"
"181.40000","90.70107","10.79251"
"181.60000","90.80106","10.80372"
"181.80000","90.90102","10.81467"
"182.00000","91.00099","10.82486"
"182.20000","91.10107","10.83483"
"182.40000","91.20103","10.84481"
"182.60000","91.30101","10.85083"
"182.80000","91.40104","10.85921"
"183.00000","91.50095","10.86687"
"183.20000","91.60103","10.87592"
"183.40000","91.70100","10.88006"
"183.60000","91.80103","10.88515"
"183.80000","91.90105","10.89178"
"184.00000","92.00108","10.89796"
"184.20000","92.10099","10.90361"
"184.40000","92.20102","10.90815"
"184.60000","92.30104","10.91258"
"184.80000","92.40096","10.91996"
"185.00000","92.50111","10.92574"
"185.20000","92.60096","10.92875"
"185.40000","92.70098","10.93833"
"185.60000","92.80101","10.94676"
"185.80000","92.90092","10.95805"
"186.00000","93.00106","10.96939"
"186.20000","93.10103","10.97886"
"186.40000","93.20094","10.98915"
"186.60000","93.30109","10.99823"
"186.80000","93.40106","11.00686"
"187.00000","93.50095","11.01517"
"187.20000","93.60106","11.02689"
"187.40000","93.70102","11.03599"
"187.60000","93.80099","11.04886"
"187.80000","93.90101","11.05894"
"188.00000","94.00098","11.06995"
"188.20000","94.10094","11.08160"
"188.40000","94.20104","11.08648"
"188.60000","94.30102","11.09650"
"188.80000","94.40098","11.11184"
"189.00000","94.50107","11.11782"
"189.20000","94.60110","11.12340"
"189.40000","94.70100","11.12786"
"189.60000","94.80103","11.13342"
"189.80000","94.90099","11.13758"
"190.00000","95.00097","11.14269"
"190.20000","95.10100","11.14645"
"190.40000","95.20107","11.15289"
"190.60000","95.30105","11.15901"
"190.80000","95.40096","11.16755"
"191.00000","95.50111","11.17416"
"191.20000","95.60107","11.18031"
"191.40000","95.70110","11.19094"
"191.60000","95.80106","11.19558"
"191.80000","95.90104","11.20534"
"192.00000","96.00107","11.21369"
"192.20000","96.10109","11.22196"
"192.40000","96.20107","11.23190"
"192.60000","96.30097","11.23930"
"192.80000","96.40099","11.24971"
"193.00000","96.50108","11.25872"
"193.20000","96.60105","11.26801"
"193.40000","96.70109","11.27958"
"193.60000","96.80099","11.28546"
"193.80000","96.90102","11.29544"
"194.00000","97.00098","11.30358"
"194.20000","97.10102","11.30903"
"194.40000","97.20110","11.31471"
"194.60000","97.30107","11.32220"
"194.80000","97.40115","11.32938"
"195.00000","97.50106","11.33600"
"195.20000","97.60109","11.34028"
"195.40000","97.70107","11.34781"
"195.60000","97.80109","11.35739"
"195.80000","97.90100","11.36513"
"196.00000","98.00102","11.37268"
"196.20000","98.10105","11.38006"
"196.40000","98.20107","11.38836"
"196.60000","98.30106","11.39583"
"196.80000","98.40101","11.40504"
"197.00000","98.50105","11.41171"
"197.20000","98.60107","11.42049"
"197.40000","98.70116","11.42739"
"197.60000","98.80107","11.43225"
"197.80000","98.90109","11.43844"
"198.00000","99.00107","11.44450"
"198.20000","99.10115","11.45055"
"198.40000","99.20100","11.46036"
"198.60000","99.30096","11.46601"
"198.80000","99.40105","11.47015"
"199.00000","99.50102","11.47958"
"199.20000","99.60104","11.48809"
"199.40000","99.70103","11.49534"
"199.60000","99.80105","11.50216"
"199.80000","99.90102","11.50922"
"200.00000","100.00110","11.51364"
"200.20000","100.10101","11.52153"
"200.40000","100.20103","11.52757"
"200.60000","100.30101","11.53090"
"200.80000","100.40108","11.53717"
"201.00000","100.50100","11.54214"
"201.20000","100.60115","11.54787"
"201.40000","100.70107","11.55450"
"201.60000","100.80103","11.55820"
"201.80000","100.90099","11.56540"
"202.00000","101.00102","11.57149"
"202.20000","101.10106","11.58151"
"202.40000","101.20108","11.59096"
"202.60000","101.30111","11.60021"
"202.80000","101.40102","11.60767"
"203.00000","101.50098","11.61560"
"203.20000","101.60107","11.62190"
"203.40000","101.70116","11.63555"
"203.60000","101.80112","11.64266"
"203.80000","101.90110","11.65298"
"204.00000","102.00106","11.66118"
"204.20000","102.10104","11.66928"
"204.40000","102.20107","11.67881"
"204.60000","102.30109","11.68759"
"204.80000","102.40106","11.69465"
"205.00000","102.50108","11.70245"
"205.20000","102.60099","11.70911"
"205.40000","102.70107","11.71264"
"205.60000","102.80111","11.71793"
"205.80000","102.90101","11.72182"
"206.00000","103.00111","11.72716"
"206.20000","103.10107","11.73160"
"206.40000","103.20110","11.73365"
"206.60000","103.30100","11.73824"
"206.80000","103.40116","11.74230"
"207.00000","103.50107","11.74509"
"207.20000","103.60115","11.74827"
"207.40000","103.70100","11.75368"
"207.60000","103.80109","11.75816"
"207.80000","103.90099","11.76589"
"208.00000","104.00109","11.76785"
"208.20000","104.10111","11.77490"
"208.40000","104.20103","11.78476"
"208.60000","104.30111","11.79247"
"208.80000","104.40108","11.80079"
"209.00000","104.50104","11.80783"
"209.20000","104.60107","11.81358"
"209.40000","104.70110","11.82440"
"209.60000","104.80102","11.82978"
"209.80000","104.90109","11.83739"
"210.00000","105.00100","11.84284"
"210.20000","105.10103","11.84884"
"210.40000","105.20107","11.85708"
"210.60000","105.30114","11.86485"
"210.80000","105.40112","11.87186"
"211.00000","105.50102","11.87972"
"211.20000","105.60099","11.88814"
"211.40000","105.70108","11.89580"
"211.60000","105.80105","11.90576"
"211.80000","105.90102","11.91163"
"212.00000","106.00111","11.91814"
"212.20000","106.10113","11.92618"
"212.40000","106.20110","11.93110"
"212.60000","106.30094","11.93643"
"212.80000","106.40098","11.94377"
"213.00000","106.50106","11.95015"
"213.20000","106.60109","11.95494"
"213.40000","106.70106","11.95983"
"213.60000","106.80103","11.96373"
"213.80000","106.90105","11.96879"
"214.00000","107.00108","11.97376"
"214.20000","107.10098","11.97733"
"214.40000","107.20097","11.98129"
"214.60000","107.30110","11.98602"
"214.80000","107.40108","11.99284"
"215.00000","107.50098","11.99835"
"215.20000","107.60095","12.00104"
"215.40000","107.70097","12.00809"
"215.60000","107.80096","12.01580"
"215.80000","107.90109","12.02182"
"216.00000","108.00101","12.02887"
"216.20000","108.10104","12.03561"
"216.40000","108.20106","12.04117"
"216.60000","108.30108","12.04710"
"216.80000","108.40106","12.05257"
"217.00000","108.50101","12.05781"
"217.20000","108.60100","12.06501"
"217.40000","108.70102","12.07161"
"217.60000","108.80111","12.07804"
"217.80000","108.90089","12.08519"
"218.00000","109.00099","12.09206"
"218.20000","109.10107","12.09731"
"218.40000","109.20103","12.10457"
"218.60000","109.30106","12.11438"
"218.80000","109.40109","12.11887"
"219.00000","109.50100","12.11900"
"219.20000","109.60110","12.12700"
"219.40000","109.70094","12.13207"
"219.60000","109.80103","12.13521"
"219.80000","109.90105","12.13775"
"220.00000","110.00103","12.14118"
"220.20000","110.10092","12.14552"
"220.40000","110.20102","12.14829"
"220.60000","110.30099","12.15052"
"220.80000","110.40107","12.15292"
"221.00000","110.50105","12.16200"
"221.20000","110.60101","12.16641"
"221.40000","110.70092","12.16846"
"221.60000","110.80101","12.17176"
"221.80000","110.90104","12.17381"
"222.00000","111.00100","12.18014"
"222.20000","111.10104","12.18433"
"222.40000","111.20107","12.19116"
"222.60000","111.30109","12.19441"
"222.80000","111.40100","12.19893"
"223.00000","111.50103","12.20396"
"223.20000","111.60105","12.20784"
"223.40000","111.70097","12.21181"
"223.60000","111.80099","12.21535"
"223.80000","111.90096","12.21889"
"224.00000","112.00111","12.22005"
"224.20000","112.10107","12.22372"
"224.40000","112.20097","12.22573"
"224.60000","112.30107","12.22594"
"224.80000","112.40103","12.22661"
"225.00000","112.50101","12.22491"
"225.20000","112.60109","12.22009"
"225.40000","112.70106","12.20730"
"225.60000","112.80097","12.18810"
"225.79600","112.89902","11.92049"
"225.80000","112.90099","11.00846"
"225.80400","112.90297","9.90164"
"225.80800","112.90505","8.50295"
"225.81200","112.90703","7.15752"