File: MT-DataAnalysis-JupyterNotebook/TensionPlots/TensionTests/WireDiameter/Specimen_RawData_17.csv
End date,"8/16/2018"
Specimen label,"D32L50N5d6-2"
Maximum Load,"65.60906",N
Extension at Maximum Load,"40.08703",mm
Maximum Slope (Automatic Young's),"2.07736",N/mm
Rate 1,"30.00000",mm/min

Time,Extension,Load
(s),(mm),(N)
"0.00000","0.00000","-0.00675"
"0.10000","0.02852","0.05990"
"0.20000","0.09076","0.11552"
"0.30000","0.14947","0.18428"
"0.40000","0.20149","0.24512"
"0.50000","0.25153","0.32061"
"0.60000","0.30122","0.36637"
"0.70000","0.35114","0.40254"
"0.80000","0.40101","0.45377"
"0.90000","0.45093","0.49474"
"1.00000","0.50098","0.53283"
"1.10000","0.55096","0.58841"
"1.20000","0.60100","0.62522"
"1.30000","0.65099","0.69827"
"1.40000","0.70103","0.77658"
"1.50000","0.75108","0.84206"
"1.60000","0.80100","0.97027"
"1.70000","0.85098","1.05919"
"1.80000","0.90103","1.16100"
"1.86000","0.93104","1.28733"
"1.96000","0.98085","1.39047"
"2.02400","1.01301","1.51980"
"2.11400","1.05804","1.64498"
"2.18400","1.09295","1.77263"
"2.25600","1.12907","1.90162"
"2.33200","1.16703","2.02684"
"2.43200","1.21696","2.13929"
"2.53200","1.26694","2.19109"
"2.63200","1.31698","2.30302"
"2.73200","1.36703","2.36352"
"2.83000","1.41606","2.49113"
"2.91600","1.45898","2.61816"
"3.01400","1.50807","2.74427"
"3.08600","1.54400","2.86956"
"3.18600","1.59399","2.99415"
"3.25200","1.62699","3.11974"
"3.34000","1.67094","3.24638"
"3.44000","1.72104","3.32351"
"3.54000","1.77103","3.45135"
"3.64000","1.82107","3.55967"
"3.71800","1.85999","3.68476"
"3.81800","1.90998","3.80241"
"3.91800","1.96002","3.91229"
"4.00400","2.00301","4.03783"
"4.10000","2.05108","4.16348"
"4.20000","2.10100","4.28088"
"4.29000","2.14597","4.40701"
"4.37600","2.18895","4.53410"
"4.47600","2.23900","4.63764"
"4.53800","2.26991","4.76375"
"4.63800","2.31995","4.84427"
"4.73800","2.37000","4.94000"
"4.83800","2.41998","4.96771"
"4.93800","2.47003","5.02983"
"5.03800","2.51989","5.07540"
"5.13800","2.56993","5.15695"
"5.23800","2.61998","5.19317"
"5.33800","2.66996","5.25237"
"5.43800","2.72007","5.31839"
"5.53800","2.76993","5.38631"
"5.63800","2.81997","5.45990"
"5.73800","2.86996","5.52957"
"5.83800","2.92000","5.62966"
"5.93800","2.96999","5.70108"
"6.03800","3.01997","5.81067"
"6.13800","3.06989","5.89248"
"6.23800","3.12012","5.99654"
"6.33800","3.16992","6.11411"
"6.43800","3.22003","6.18666"
"6.53800","3.26995","6.28555"
"6.63800","3.31999","6.37180"
"6.73800","3.36980","6.45602"
"6.83800","3.42002","6.55743"
"6.93800","3.47006","6.66026"
"7.03800","3.52011","6.76471"
"7.13800","3.56997","6.86774"
"7.23800","3.61990","6.97958"
"7.33800","3.66988","7.07186"
"7.37000","3.68602","7.19794"
"7.45400","3.72812","7.32328"
"7.55400","3.77804","7.40326"
"7.65400","3.82797","7.52531"
"7.72000","3.86091","7.65305"
"7.78200","3.89200","7.77813"
"7.85200","3.92698","7.90727"
"7.95200","3.97702","7.96278"
"8.04400","4.02306","8.08821"
"8.10800","4.05505","8.21348"
"8.20800","4.10503","8.29706"
"8.30800","4.15513","8.38250"
"8.40800","4.20500","8.47626"
"8.50800","4.25498","8.55361"
"8.60800","4.30497","8.62463"
"8.70800","4.35507","8.72217"
"8.80800","4.40499","8.81436"
"8.90800","4.45498","8.89182"
"9.00800","4.50496","8.98020"
"9.10800","4.55495","9.07998"
"9.20800","4.60505","9.16002"
"9.30800","4.65503","9.24225"
"9.40800","4.70496","9.31963"
"9.50800","4.75494","9.39851"
"9.58200","4.79195","9.52509"
"9.68200","4.84200","9.60342"
"9.78200","4.89198","9.69370"
"9.88200","4.94196","9.81879"
"9.98000","4.99099","9.94715"
"10.06600","5.03404","10.07457"
"10.15200","5.07703","10.20368"
"10.21000","5.10603","10.32952"
"10.30000","5.15093","10.45580"
"10.40000","5.20097","10.53397"
"10.45200","5.22704","10.66188"
"10.55200","5.27708","10.77792"
"10.65200","5.32701","10.83146"
"10.75000","5.37604","10.95753"
"10.85000","5.42590","11.06756"
"10.95000","5.47612","11.15847"
"11.05000","5.52605","11.25593"
"11.15000","5.57597","11.34601"
"11.25000","5.62596","11.44374"
"11.35000","5.67606","11.51319"
"11.45000","5.72604","11.60509"
"11.55000","5.77597","11.70009"
"11.65000","5.82601","11.80081"
"11.75000","5.87606","11.85931"
"11.85000","5.92598","11.96890"
"11.95000","5.97596","12.05142"
"12.05000","6.02595","12.16556"
"12.15000","6.07599","12.23664"
"12.25000","6.12604","12.33670"
"12.35000","6.17602","12.38917"
"12.45000","6.22594","12.48326"
"12.55000","6.27593","12.55255"
"12.65000","6.32597","12.62247"
"12.75000","6.37608","12.68040"
"12.85000","6.42594","12.75216"
"12.95000","6.47598","12.83254"
"13.05000","6.52603","12.92251"
"13.15000","6.57601","12.97968"
"13.25000","6.62594","13.08357"
"13.35000","6.67610","13.17907"
"13.45000","6.72596","13.28107"
"13.55000","6.77607","13.38550"
"13.65000","6.82593","13.50237"
"13.75000","6.87598","13.60844"
"13.84000","6.92100","13.73440"
"13.94000","6.97098","13.83194"
"14.01000","7.00608","13.95837"
"14.11000","7.05594","14.08457"
"14.21000","7.10599","14.21182"
"14.31000","7.15603","14.31679"
"14.39600","7.19902","14.44481"
"14.49600","7.24906","14.54622"
"14.59600","7.29899","14.67507"
"14.69600","7.34897","14.78702"
"14.79200","7.39710","14.91333"
"14.89000","7.44601","15.03881"
"14.96800","7.48499","15.16743"
"15.05800","7.53007","15.29438"
"15.15800","7.57994","15.39919"
"15.25400","7.62795","15.52604"
"15.35200","7.67692","15.65408"
"15.45200","7.72696","15.77357"
"15.54200","7.77198","15.90079"
"15.64200","7.82197","16.02566"
"15.73600","7.86908","16.15201"
"15.82800","7.91500","16.27738"
"15.92800","7.96504","16.37946"
"16.00000","8.00098","16.50623"
"16.10000","8.05102","16.59752"
"16.19400","8.09807","16.72382"
"16.29400","8.14794","16.81432"
"16.39400","8.19798","16.90310"
"16.49400","8.24797","16.98008"
"16.59400","8.29801","17.07154"
"16.69400","8.34799","17.14531"
"16.79400","8.39798","17.17551"
"16.89400","8.44802","17.20704"
"16.99400","8.49806","17.23885"
"17.09400","8.54805","17.27328"
"17.19400","8.59797","17.34313"
"17.29400","8.64790","17.37338"
"17.39400","8.69806","17.42655"
"17.49400","8.74793","17.48472"
"17.59400","8.79797","17.54895"
"17.69400","8.84795","17.62186"
"17.79400","8.89800","17.69319"
"17.88600","8.94404","17.82073"
"17.98600","8.99402","17.86241"
"18.08600","9.04400","17.97766"
"18.18600","9.09405","18.09843"
"18.28600","9.14403","18.20257"
"18.36000","9.18110","18.33017"
"18.46000","9.23097","18.43534"
"18.56000","9.28101","18.56110"
"18.66000","9.33093","18.68733"
"18.76000","9.38104","18.79994"
"18.86000","9.43102","18.90938"
"18.96000","9.48095","19.02568"
"19.06000","9.53105","19.13410"
"19.16000","9.58103","19.24096"
"19.26000","9.63108","19.31847"
"19.35000","9.67604","19.44666"
"19.45000","9.72596","19.54934"
"19.54800","9.77487","19.67627"
"19.61600","9.80895","19.80368"
"19.70800","9.85505","19.93191"
"19.80600","9.90396","20.06166"
"19.88000","9.94103","20.18786"
"19.98000","9.99107","20.25892"
"20.03000","10.01594","20.38538"
"20.13000","10.06599","20.51276"
"20.23000","10.11603","20.63367"
"20.33000","10.16607","20.69870"
"20.43000","10.21594","20.77473"
"20.53000","10.26604","20.90164"
"20.63000","10.31591","20.97122"
"20.73000","10.36589","21.09880"
"20.83000","10.41599","21.21087"
"20.93000","10.46604","21.28579"
"21.03000","10.51596","21.37903"
"21.12800","10.56499","21.50497"
"21.22800","10.61503","21.57491"
"21.32800","10.66496","21.64071"
"21.42800","10.71500","21.71068"
"21.52800","10.76499","21.77753"
"21.62800","10.81503","21.86911"
"21.72800","10.86501","21.92091"
"21.82800","10.91500","22.00858"
"21.92800","10.96486","22.13710"
"22.02800","11.01503","22.20325"
"22.08200","11.04199","22.33096"
"22.18200","11.09203","22.43788"
"22.28200","11.14196","22.53336"
"22.34800","11.17496","22.66694"
"22.44800","11.22501","22.69777"
"22.48400","11.24300","22.82646"
"22.58400","11.29305","22.89135"
"22.68400","11.34297","22.95905"
"22.78400","11.39290","23.03849"
"22.88400","11.44288","23.14334"
"22.98400","11.49304","23.25571"
"23.08400","11.54303","23.33348"
"23.18400","11.59301","23.42138"
"23.28400","11.64293","23.52517"
"23.38400","11.69304","23.59033"
"23.48400","11.74290","23.68558"
"23.58400","11.79301","23.77205"
"23.68400","11.84293","23.84359"
"23.78400","11.89304","23.95020"
"23.87600","11.93901","24.07923"
"23.97600","11.98894","24.18133"
"24.06800","12.03491","24.30714"
"24.16800","12.08496","24.42905"
"24.25200","12.12699","24.55479"
"24.35200","12.17704","24.66601"
"24.45200","12.22702","24.71987"
"24.55200","12.27700","24.83345"
"24.65200","12.32687","24.91273"
"24.75200","12.37703","25.00244"
"24.85200","12.42707","25.07642"
"24.95200","12.47700","25.14200"
"25.05200","12.52698","25.20704"
"25.15200","12.57703","25.27458"
"25.25200","12.62701","25.33813"
"25.34800","12.67496","25.46419"
"25.44800","12.72507","25.53315"
"25.54800","12.77499","25.61893"
"25.64800","12.82503","25.70716"
"25.74800","12.87502","25.82800"
"25.84800","12.92488","25.88996"
"25.94800","12.97505","25.99838"
"26.04800","13.02509","26.09285"
"26.14800","13.07501","26.18290"
"26.24800","13.12500","26.27102"
"26.32200","13.16201","26.39813"
"26.36600","13.18395","26.52705"
"26.46600","13.23400","26.59212"
"26.55000","13.27609","26.71782"
"26.64800","13.32506","26.84315"
"26.71400","13.35788","26.96874"
"26.79000","13.39597","27.09695"
"26.89000","13.44607","27.18312"
"26.95200","13.47704","27.30937"
"27.05200","13.52696","27.41516"
"27.15200","13.57701","27.53328"
"27.24000","13.62107","27.66049"
"27.34000","13.67106","27.72671"
"27.44000","13.72098","27.79957"
"27.52400","13.76295","27.92655"
"27.62400","13.81294","27.98749"
"27.72400","13.86298","28.09608"
"27.82400","13.91302","28.18880"
"27.92400","13.96295","28.29861"
"28.02400","14.01293","28.38282"
"28.12400","14.06304","28.48076"
"28.20000","14.10106","28.60658"
"28.30000","14.15105","28.68195"
"28.39000","14.19601","28.80969"
"28.49000","14.24605","28.92373"
"28.59000","14.29604","29.00666"
"28.69000","14.34590","29.08016"
"28.79000","14.39594","29.15104"
"28.89000","14.44593","29.21626"
"28.99000","14.49603","29.27003"
"29.09000","14.54596","29.34023"
"29.19000","14.59600","29.39038"
"29.29000","14.64592","29.45235"
"29.39000","14.69597","29.51519"
"29.49000","14.74601","29.55024"
"29.59000","14.79600","29.65166"
"29.69000","14.84598","29.72628"
"29.79000","14.89596","29.78136"
"29.89000","14.94613","29.89358"
"29.99000","14.99593","29.98346"
"30.09000","15.04604","30.05618"
"30.19000","15.09596","30.15761"
"30.29000","15.14600","30.25354"
"30.39000","15.19605","30.36274"
"30.49000","15.24597","30.43646"
"30.59000","15.29608","30.55923"
"30.67200","15.33697","30.68536"
"30.77200","15.38690","30.78462"
"30.85600","15.42899","30.91353"
"30.95600","15.47897","30.98931"
"31.05200","15.52698","31.11551"
"31.15200","15.57691","31.21178"
"31.25200","15.62689","31.30966"
"31.35200","15.67693","31.42570"
"31.45200","15.72704","31.52521"
"31.55200","15.77702","31.62596"
"31.64800","15.82503","31.75168"
"31.74800","15.87496","31.83936"
"31.82800","15.91496","31.96905"
"31.92800","15.96500","32.07435"
"32.00200","16.00207","32.20186"
"32.10200","16.05205","32.31631"
"32.20200","16.10198","32.43705"
"32.29200","16.14694","32.56255"
"32.39200","16.19699","32.68484"
"32.45800","16.22993","32.81026"
"32.55800","16.28003","32.89863"
"32.65800","16.32996","33.01385"
"32.75800","16.37994","33.10142"
"32.85800","16.42999","33.17245"
"32.95800","16.48003","33.28010"
"33.05800","16.52995","33.39220"
"33.15800","16.57994","33.47931"
"33.25800","16.62998","33.57352"
"33.35600","16.67895","33.70240"
"33.45600","16.72893","33.72184"
"33.55600","16.77898","33.77599"
"33.65600","16.82902","33.81768"
"33.75600","16.87900","33.85444"
"33.85600","16.92911","33.87858"
"33.95600","16.97891","33.93742"
"34.05600","17.02901","33.95227"
"34.15600","17.07900","34.02868"
"34.25600","17.12904","34.07195"
"34.35600","17.17897","34.18369"
"34.45600","17.22895","34.25752"
"34.55600","17.27900","34.34745"
"34.61400","17.30811","34.47263"
"34.71400","17.35798","34.54177"
"34.81400","17.40796","34.62185"
"34.90200","17.45203","34.75055"
"35.00000","17.50100","34.87663"
"35.10000","17.55110","34.97812"
"35.20000","17.60096","35.05925"
"35.30000","17.65107","35.17566"
"35.40000","17.70099","35.27177"
"35.50000","17.75109","35.36534"
"35.60000","17.80096","35.47804"
"35.70000","17.85094","35.58955"
"35.80000","17.90099","35.70443"
"35.90000","17.95097","35.79092"
"35.97200","17.98708","35.91646"
"36.07200","18.03707","35.97807"
"36.14800","18.07503","36.10342"
"36.24800","18.12508","36.12915"
"36.34800","18.17494","36.22699"
"36.43400","18.21799","36.35374"
"36.53400","18.26791","36.43939"
"36.63400","18.31790","36.52311"
"36.73400","18.36806","36.63132"
"36.83400","18.41805","36.73803"
"36.93400","18.46797","36.84895"
"37.03400","18.51795","36.96386"
"37.13400","18.56794","37.06323"
"37.23400","18.61786","37.16461"
"37.33400","18.66803","37.24389"
"37.43400","18.71801","37.32603"
"37.53400","18.76799","37.39027"
"37.63400","18.81810","37.45092"
"37.73400","18.86796","37.51820"
"37.83400","18.91789","37.62214"
"37.93400","18.96799","37.65766"
"38.03400","19.01797","37.74913"
"38.13400","19.06802","37.85046"
"38.23400","19.11794","37.94324"
"38.33400","19.16793","38.02353"
"38.43400","19.21797","38.14211"
"38.53400","19.26801","38.19695"
"38.63400","19.31800","38.30514"
"38.73400","19.36792","38.37737"
"38.83400","19.41796","38.44884"
"38.93400","19.46795","38.56321"
"39.03400","19.51799","38.63689"
"39.13400","19.56798","38.73272"
"39.23400","19.61802","38.82545"
"39.32000","19.66101","38.95156"
"39.42000","19.71105","39.06387"
"39.49000","19.74597","39.18930"
"39.59000","19.79601","39.26912"
"39.66600","19.83404","39.39537"
"39.76600","19.88403","39.50217"
"39.86600","19.93395","39.57658"
"39.96600","19.98405","39.64579"
"40.06600","20.03403","39.71904"
"40.16600","20.08396","39.79245"
"40.26600","20.13400","39.86763"
"40.36600","20.18399","39.94017"
"40.46600","20.23397","40.00073"
"40.56600","20.28402","40.07918"
"40.66600","20.33406","40.16185"
"40.76600","20.38404","40.25324"
"40.86600","20.43391","40.35569"
"40.96600","20.48395","40.43999"
"41.04800","20.52497","40.56734"
"41.14400","20.57298","40.69554"
"41.24400","20.62296","40.78279"
"41.34400","20.67295","40.90570"
"41.43600","20.71899","41.03438"
"41.53600","20.76897","41.12347"
"41.63600","20.81895","41.22549"
"41.73600","20.86906","41.33974"
"41.83600","20.91910","41.43695"
"41.93600","20.96903","41.53430"
"42.03600","21.01907","41.61681"
"42.13600","21.06899","41.70426"
"42.23600","21.11892","41.74518"
"42.33600","21.16890","41.83847"
"42.43600","21.21901","41.87931"
"42.53600","21.26899","41.94095"
"42.63600","21.31897","41.97606"
"42.73600","21.36902","41.96880"
"42.83600","21.41906","42.05671"
"42.93600","21.46892","42.10142"
"43.03600","21.51897","42.16541"
"43.13600","21.56901","42.20611"
"43.23600","21.61900","42.26320"
"43.33600","21.66904","42.35048"
"43.43600","21.71903","42.41088"
"43.53600","21.76901","42.49810"
"43.63600","21.81906","42.55143"
"43.73600","21.86892","42.66763"
"43.83600","21.91896","42.74461"
"43.93600","21.96895","42.84884"
"44.03600","22.01905","42.95443"
"44.13600","22.06898","43.06176"
"44.23600","22.11902","43.15364"
"44.33600","22.16894","43.23936"
"44.43600","22.21910","43.36534"
"44.53600","22.26903","43.48635"
"44.63600","22.31902","43.57671"
"44.73600","22.36894","43.68536"
"44.83600","22.41898","43.80299"
"44.93600","22.46909","43.89902"
"45.03600","22.51901","44.01630"
"45.13200","22.56696","44.14167"
"45.23200","22.61695","44.19357"
"45.33200","22.66705","44.29921"
"45.43200","22.71691","44.42152"
"45.53200","22.76696","44.51394"
"45.63200","22.81700","44.58109"
"45.73200","22.86699","44.67393"
"45.83200","22.91697","44.73073"
"45.93200","22.96701","44.84110"
"46.03200","23.01694","44.91902"
"46.13200","23.06698","45.02176"
"46.23200","23.11696","45.09843"
"46.33200","23.16701","45.20157"
"46.43200","23.21700","45.29878"
"46.53200","23.26698","45.37352"
"46.63200","23.31708","45.46119"
"46.73200","23.36701","45.54868"
"46.83200","23.41711","45.61872"
"46.93200","23.46697","45.68257"
"47.03200","23.51702","45.75109"
"47.13200","23.56712","45.77270"
"47.23200","23.61699","45.84645"
"47.33200","23.66703","45.87635"
"47.43200","23.71707","45.91338"
"47.53200","23.76700","45.94756"
"47.63200","23.81692","45.99794"
"47.73200","23.86697","46.01732"
"47.83200","23.91695","46.08661"
"47.93200","23.96705","46.13726"
"48.03200","24.01698","46.23776"
"48.13200","24.06696","46.30065"
"48.23200","24.11695","46.40531"
"48.33200","24.16705","46.48437"
"48.43200","24.21703","46.59649"
"48.53200","24.26708","46.68266"
"48.63200","24.31694","46.78936"
"48.73000","24.36597","46.91459"
"48.83000","24.41595","47.01321"
"48.93000","24.46600","47.13992"
"49.03000","24.51598","47.25242"
"49.13000","24.56602","47.32055"
"49.22000","24.61105","47.44614"
"49.32000","24.66097","47.55122"
"49.42000","24.71095","47.58567"
"49.52000","24.76094","47.68325"
"49.62000","24.81104","47.73874"
"49.72000","24.86109","47.85090"
"49.82000","24.91107","47.92853"
"49.92000","24.96099","47.99770"
"50.02000","25.01098","48.09030"
"50.12000","25.06096","48.15383"
"50.22000","25.11089","48.23038"
"50.32000","25.16099","48.31958"
"50.42000","25.21103","48.39299"
"50.52000","25.26096","48.47882"
"50.62000","25.31100","48.54512"
"50.72000","25.36098","48.64061"
"50.82000","25.41097","48.73992"
"50.92000","25.46107","48.78331"
"51.02000","25.51100","48.89244"
"51.12000","25.56098","48.94932"
"51.22000","25.61103","49.07456"
"51.32000","25.66089","49.16060"
"51.42000","25.71105","49.26307"
"51.52000","25.76098","49.36036"
"51.62000","25.81102","49.47731"
"51.72000","25.86095","49.52964"
"51.82000","25.91105","49.64517"
"51.92000","25.96097","49.69360"
"52.02000","26.01102","49.78638"
"52.12000","26.06100","49.84760"
"52.22000","26.11105","49.91375"
"52.32000","26.16097","49.98183"
"52.42000","26.21095","50.04249"
"52.52000","26.26106","50.12262"
"52.62000","26.31104","50.20418"
"52.72000","26.36103","50.20969"
"52.82000","26.41095","50.27626"
"52.92000","26.46087","50.30181"
"53.02000","26.51092","50.36633"
"53.12000","26.56102","50.41117"
"53.22000","26.61107","50.45552"
"53.32000","26.66099","50.48939"
"53.42000","26.71097","50.52340"
"53.52000","26.76096","50.56281"
"53.62000","26.81100","50.60287"
"53.72000","26.86105","50.65174"
"53.82000","26.91097","50.70274"
"53.92000","26.96102","50.72916"
"54.02000","27.01106","50.79929"
"54.12000","27.06098","50.91443"
"54.22000","27.11097","50.95710"
"54.30800","27.15497","51.08386"
"54.40800","27.20502","51.14445"
"54.50800","27.25506","51.26683"
"54.60400","27.30301","51.39309"
"54.70400","27.35300","51.41861"
"54.74400","27.37296","51.54621"
"54.84400","27.42301","51.57539"
"54.94400","27.47305","51.67369"
"55.04400","27.52298","51.71284"
"55.14400","27.57296","51.77016"
"55.24400","27.62306","51.85133"
"55.34400","27.67305","51.90845"
"55.44400","27.72309","51.97126"
"55.53000","27.76596","52.09651"
"55.63000","27.81601","52.11372"
"55.73000","27.86605","52.21405"
"55.83000","27.91603","52.27587"
"55.88400","27.94300","52.40189"
"55.98400","27.99298","52.43927"
"56.08400","28.04308","52.55545"
"56.18400","28.09307","52.66841"
"56.28400","28.14293","52.76537"
"56.38400","28.19304","52.89029"
"56.48400","28.24296","52.97399"
"56.58400","28.29300","53.08618"
"56.68400","28.34293","53.15870"
"56.78400","28.39303","53.23707"
"56.88400","28.44296","53.34335"
"56.98400","28.49300","53.43302"
"57.08400","28.54292","53.52888"
"57.18400","28.59297","53.59138"
"57.28400","28.64295","53.67783"
"57.38400","28.69306","53.73886"
"57.48400","28.74310","53.81612"
"57.58400","28.79296","53.90022"
"57.68400","28.84301","53.93759"
"57.78400","28.89293","54.01093"
"57.88400","28.94292","54.05549"
"57.98400","28.99302","54.07475"
"58.08400","29.04294","54.15985"
"58.18400","29.09293","54.17101"
"58.28400","29.14297","54.23418"
"58.38400","29.19308","54.28304"
"58.48400","29.24300","54.30494"
"58.58400","29.29305","54.34826"
"58.68400","29.34297","54.35975"
"58.78400","29.39301","54.37520"
"58.88400","29.44300","54.48033"
"58.98400","29.49298","54.44954"
"59.08400","29.54296","54.50598"
"59.18400","29.59313","54.55455"
"59.28400","29.64305","54.60719"
"59.38400","29.69298","54.67501"
"59.48400","29.74302","54.73790"
"59.58400","29.79306","54.80365"
"59.68400","29.84293","54.88785"
"59.78400","29.89291","54.95333"
"59.88400","29.94296","55.01799"
"59.98400","29.99300","55.09061"
"60.08400","30.04299","55.15649"
"60.18400","30.09297","55.23909"
"60.28400","30.14295","55.32376"
"60.38400","30.19306","55.41111"
"60.48400","30.24298","55.47436"
"60.58400","30.29303","55.56376"
"60.68400","30.34295","55.61185"
"60.78400","30.39293","55.69005"
"60.88400","30.44292","55.78115"
"60.98400","30.49302","55.86743"
"61.08400","30.54300","55.91641"
"61.18400","30.59299","55.96908"
"61.28400","30.64297","56.07192"
"61.38400","30.69314","56.15095"
"61.48400","30.74294","56.20615"
"61.58400","30.79305","56.26714"
"61.68400","30.84309","56.30132"
"61.78400","30.89307","56.40553"
"61.88400","30.94300","56.46104"
"61.98400","30.99298","56.51740"
"62.08400","31.04291","56.55397"
"62.18400","31.09301","56.60799"
"62.28400","31.14305","56.65465"
"62.38400","31.19298","56.69609"
"62.48400","31.24296","56.73982"
"62.58400","31.29295","56.78609"
"62.68400","31.34305","56.85585"
"62.78400","31.39303","56.89372"
"62.88400","31.44301","57.00699"
"62.98400","31.49294","57.05308"
"63.08400","31.54298","57.14780"
"63.18400","31.59297","57.22851"
"63.28400","31.64301","57.29535"
"63.38400","31.69300","57.37401"
"63.48400","31.74298","57.50114"
"63.58400","31.79302","57.58109"
"63.68400","31.84289","57.65055"
"63.78400","31.89299","57.68175"
"63.88400","31.94304","57.77754"
"63.98400","31.99308","57.84988"
"64.08400","32.04288","57.87887"
"64.18400","32.09293","57.93092"
"64.28400","32.14309","57.99351"
"64.38400","32.19302","58.07064"
"64.48400","32.24306","58.11577"
"64.58400","32.29298","58.14182"
"64.68400","32.34303","58.20341"
"64.78400","32.39301","58.25164"
"64.88400","32.44294","58.29909"
"64.98400","32.49292","58.32666"
"65.08400","32.54308","58.39233"
"65.18400","32.59307","58.43995"
"65.28400","32.64299","58.47975"
"65.38400","32.69298","58.53025"
"65.48400","32.74302","58.58775"
"65.58400","32.79300","58.60787"
"65.68400","32.84304","58.69078"
"65.78400","32.89297","58.73366"
"65.88400","32.94289","58.80256"
"65.98400","32.99300","58.83264"
"66.08400","33.04304","58.89410"
"66.18400","33.09303","58.95416"
"66.28400","33.14295","59.00920"
"66.38400","33.19294","59.05796"
"66.48400","33.24292","59.12551"
"66.58400","33.29308","59.18293"
"66.68400","33.34295","59.22253"
"66.78400","33.39293","59.26957"
"66.88400","33.44304","59.35118"
"66.98400","33.49296","59.37688"
"67.08400","33.54294","59.48036"
"67.18400","33.59305","59.49525"
"67.28400","33.64297","59.60591"
"67.38400","33.69308","59.69102"
"67.48400","33.74294","59.72221"
"67.58400","33.79298","59.79131"
"67.68400","33.84303","59.91576"
"67.78400","33.89301","59.91540"
"67.88400","33.94306","59.99239"
"67.98400","33.99298","60.07059"
"68.08400","34.04303","60.11642"
"68.18400","34.09295","60.16409"
"68.28400","34.14305","60.18916"
"68.38400","34.19304","60.25152"
"68.48400","34.24302","60.30550"
"68.58400","34.29312","60.37722"
"68.68400","34.34305","60.42987"
"68.78400","34.39309","60.50904"
"68.88400","34.44296","60.56319"
"68.98400","34.49300","60.61325"
"69.08400","34.54298","60.66474"
"69.18400","34.59291","60.75146"
"69.28400","34.64307","60.80005"
"69.38400","34.69305","60.85293"
"69.48400","34.74298","60.91243"
"69.58400","34.79302","60.96815"
"69.68400","34.84295","61.01525"
"69.78400","34.89299","61.04404"
"69.88400","34.94298","61.12938"
"69.98400","34.99308","61.17676"
"70.08400","35.04288","61.24917"
"70.18400","35.09299","61.30656"
"70.28400","35.14303","61.37004"
"70.38400","35.19302","61.43700"
"70.48400","35.24306","61.49920"
"70.58400","35.29298","61.54381"
"70.68400","35.34297","61.61736"
"70.78400","35.39301","61.69492"
"70.88400","35.44306","61.67994"
"70.98400","35.49304","61.76588"
"71.08400","35.54303","61.81863"
"71.18400","35.59307","61.86491"
"71.28400","35.64293","61.90336"
"71.38400","35.69297","61.96051"
"71.48400","35.74296","62.00445"
"71.58400","35.79306","62.04571"
"71.68400","35.84305","62.07976"
"71.78400","35.89297","62.12465"
"71.88400","35.94302","62.17022"
"71.98400","35.99306","62.20407"
"72.08400","36.04305","62.25299"
"72.18400","36.09309","62.25828"
"72.28400","36.14295","62.31949"
"72.38400","36.19305","62.31841"
"72.48400","36.24286","62.36810"
"72.58400","36.29308","62.37885"
"72.68400","36.34295","62.39147"
"72.78400","36.39299","62.43110"
"72.88400","36.44304","62.45021"
"72.98400","36.49296","62.47514"
"73.08400","36.54295","62.48845"
"73.18400","36.59299","62.51005"
"73.28400","36.64303","62.52293"
"73.38400","36.69302","62.55827"
"73.48400","36.74300","62.56511"
"73.58400","36.79298","62.61265"
"73.68400","36.84297","62.62580"
"73.78400","36.89307","62.69478"
"73.88400","36.94300","62.66835"
"73.98400","36.99298","62.71705"
"74.08400","37.04290","62.82283"
"74.18400","37.09301","62.78859"
"74.28400","37.14299","62.81728"
"74.38400","37.19304","62.85654"
"74.48400","37.24302","62.91931"
"74.58400","37.29313","62.99160"
"74.68400","37.34305","63.06499"
"74.78400","37.39303","63.13612"
"74.88400","37.44296","63.16436"
"74.98400","37.49300","63.26988"
"75.08400","37.54298","63.31690"
"75.18400","37.59297","63.33554"
"75.26200","37.63201","63.46120"
"75.36200","37.68199","63.49619"
"75.46200","37.73210","63.55005"
"75.56200","37.78202","63.62290"
"75.66200","37.83207","63.69334"
"75.76200","37.88199","63.79602"
"75.86200","37.93198","63.81981"
"75.96200","37.98214","63.86615"
"76.06200","38.03188","63.94654"
"76.11800","38.05993","64.07350"
"76.17200","38.08701","63.94744"
"76.27200","38.13699","64.04771"
"76.37200","38.18710","64.13798"
"76.47200","38.23702","64.19338"
"76.57200","38.28695","64.22678"
"76.67200","38.33699","64.25208"
"76.77200","38.38704","64.27790"
"76.87200","38.43696","64.35107"
"76.97200","38.48700","64.40017"
"77.07200","38.53693","64.45086"
"77.17200","38.58703","64.46586"
"77.27200","38.63695","64.50863"
"77.37200","38.68706","64.53915"
"77.47200","38.73698","64.58249"
"77.57200","38.78697","64.64406"
"77.67200","38.83701","64.69282"
"77.77200","38.88694","64.72988"
"77.87200","38.93698","64.79248"
"77.97200","38.98702","64.81332"
"78.07200","39.03700","64.88454"
"78.17200","39.08711","64.93058"
"78.27200","39.13697","64.96227"
"78.37200","39.18702","64.99407"
"78.47200","39.23700","65.04974"
"78.57200","39.28710","65.11252"
"78.67200","39.33696","65.14359"
"78.77200","39.38707","65.16048"
"78.87200","39.43700","65.20098"
"78.97200","39.48698","65.25010"
"79.07200","39.53696","65.29083"
"79.17200","39.58695","65.29664"
"79.27200","39.63699","65.34052"
"79.37200","39.68704","65.37644"
"79.47200","39.73702","65.42628"
"79.57200","39.78706","65.45359"
"79.67200","39.83693","65.51313"
"79.77200","39.88703","65.49779"
"79.87200","39.93690","65.54876"
"79.97200","39.98694","65.54768"
"80.07200","40.03698","65.59122"
"80.17200","40.08703","65.60906"
"80.27200","40.13695","65.59451"
"80.37200","40.18706","65.58356"
"80.47200","40.23692","65.50610"
"80.50800","40.25504","65.35149"
"80.51000","40.25599","64.83197"
"80.51200","40.25695","63.46321"
"80.51400","40.25797","61.22788"
"80.51600","40.25892","58.46225"
"80.51800","40.25994","55.35160"
"80.52000","40.26089","51.94698"
"80.52200","40.26191","48.33125"
"80.52400","40.26299","44.58865"
"80.52600","40.26400","40.82154"
"80.52800","40.26497","37.08630"