File: MT-DataAnalysis-JupyterNotebook/TensionPlots/TensionTests/WireDiameter/Specimen_RawData_16.csv
End date,"8/16/2018"
Specimen label,"D32L50N5d4-8"
Maximum Load,"32.98239",N
Extension at Maximum Load,"64.30096",mm
Maximum Slope (Automatic Young's),"0.59884",N/mm
Rate 1,"30.00000",mm/min

Time,Extension,Load
(s),(mm),(N)
"0.00000","-0.00006","0.00435"
"0.10000","0.02768","0.01669"
"0.20000","0.08998","0.05341"
"0.30000","0.14935","0.09925"
"0.40000","0.20167","0.14184"
"0.50000","0.25153","0.16864"
"0.60000","0.30122","0.19340"
"0.70000","0.35108","0.21812"
"0.80000","0.40107","0.24578"
"0.90000","0.45099","0.28082"
"1.00000","0.50110","0.31135"
"1.10000","0.55090","0.34541"
"1.20000","0.60100","0.37976"
"1.30000","0.65093","0.40521"
"1.40000","0.70091","0.43626"
"1.50000","0.75096","0.46270"
"1.60000","0.80100","0.49225"
"1.70000","0.85098","0.53019"
"1.80000","0.90091","0.57054"
"1.90000","0.95107","0.59340"
"2.00000","1.00094","0.61730"
"2.10000","1.05092","0.64616"
"2.20000","1.10096","0.67544"
"2.30000","1.15095","0.70927"
"2.40000","1.20093","0.74289"
"2.50000","1.25104","0.77512"
"2.60000","1.30102","0.80058"
"2.70000","1.35100","0.82966"
"2.80000","1.40099","0.85845"
"2.90000","1.45091","0.88947"
"3.00000","1.50096","0.92249"
"3.10000","1.55094","0.95705"
"3.20000","1.60104","0.98990"
"3.30000","1.65085","1.01357"
"3.40000","1.70101","1.03944"
"3.50000","1.75106","1.06441"
"3.60000","1.80104","1.10131"
"3.70000","1.85090","1.13577"
"3.80000","1.90101","1.17330"
"3.90000","1.95093","1.20092"
"4.00000","2.00098","1.22713"
"4.10000","2.05096","1.25172"
"4.20000","2.10094","1.27968"
"4.30000","2.15093","1.31101"
"4.40000","2.20091","1.34111"
"4.50000","2.25102","1.38154"
"4.60000","2.30106","1.41257"
"4.70000","2.35092","1.43751"
"4.80000","2.40091","1.46275"
"4.90000","2.45095","1.49449"
"5.00000","2.50100","1.52817"
"5.10000","2.55092","1.55782"
"5.20000","2.60102","1.59049"
"5.30000","2.65101","1.61575"
"5.40000","2.70093","1.63732"
"5.50000","2.75092","1.67202"
"5.60000","2.80090","1.70769"
"5.70000","2.85094","1.74469"
"5.80000","2.90105","1.77718"
"5.90000","2.95091","1.80964"
"6.00000","3.00102","1.83308"
"6.10000","3.05088","1.85364"
"6.20000","3.10104","1.87508"
"6.30000","3.15097","1.90437"
"6.40000","3.20101","1.94326"
"6.50000","3.25088","1.98045"
"6.60000","3.30092","2.01509"
"6.70000","3.35096","2.04418"
"6.80000","3.40107","2.07239"
"6.90000","3.45099","2.10012"
"7.00000","3.50110","2.12766"
"7.10000","3.55096","2.15634"
"7.20000","3.60088","2.18564"
"7.30000","3.65093","2.21965"
"7.40000","3.70103","2.24839"
"7.50000","3.75096","2.27566"
"7.60000","3.80100","2.31039"
"7.70000","3.85092","2.34368"
"7.80000","3.90097","2.37821"
"7.90000","3.95101","2.41025"
"8.00000","4.00100","2.43706"
"8.10000","4.05092","2.45178"
"8.20000","4.10096","2.47523"
"8.30000","4.15101","2.50768"
"8.40000","4.20105","2.54428"
"8.50000","4.25098","2.58227"
"8.60000","4.30102","2.61844"
"8.70000","4.35094","2.65453"
"8.80000","4.40093","2.67949"
"8.90000","4.45091","2.69765"
"9.00000","4.50096","2.71827"
"9.10000","4.55094","2.74966"
"9.20000","4.60110","2.78374"
"9.30000","4.65097","2.82172"
"9.40000","4.70095","2.85375"
"9.50000","4.75100","2.88133"
"9.60000","4.80098","2.90873"
"9.70000","4.85096","2.94433"
"9.80000","4.90095","2.97290"
"9.90000","4.95093","3.00377"
"10.00000","5.00110","3.03023"
"10.10000","5.05102","3.05622"
"10.20000","5.10100","3.07987"
"10.30000","5.15099","3.10694"
"10.40000","5.20103","3.14256"
"10.50000","5.25102","3.17954"
"10.60000","5.30100","3.21874"
"10.70000","5.35104","3.25040"
"10.80000","5.40091","3.27447"
"10.90000","5.45101","3.29698"
"11.00000","5.50100","3.31938"
"11.10000","5.55104","3.35119"
"11.20000","5.60108","3.38647"
"11.30000","5.65101","3.42302"
"11.40000","5.70105","3.45761"
"11.50000","5.75098","3.49025"
"11.60000","5.80096","3.51313"
"11.70000","5.85100","3.53921"
"11.80000","5.90099","3.56657"
"11.90000","5.95103","3.59577"
"12.00000","6.00096","3.62742"
"12.10000","6.05100","3.66160"
"12.20000","6.10098","3.68644"
"12.30000","6.15097","3.71085"
"12.40000","6.20095","3.74313"
"12.50000","6.25100","3.78313"
"12.60000","6.30104","3.81601"
"12.70000","6.35102","3.84607"
"12.80000","6.40101","3.87180"
"12.90000","6.45099","3.89798"
"13.00000","6.50098","3.92040"
"13.10000","6.55096","3.94520"
"13.20000","6.60088","3.98175"
"13.30000","6.65099","4.01696"
"13.40000","6.70103","4.05448"
"13.50000","6.75108","4.09129"
"13.60000","6.80094","4.11498"
"13.70000","6.85098","4.12864"
"13.80000","6.90091","4.16019"
"13.90000","6.95101","4.19444"
"14.00000","7.00100","4.22623"
"14.10000","7.05092","4.25919"
"14.20000","7.10096","4.28957"
"14.30000","7.15107","4.31639"
"14.40000","7.20093","4.34214"
"14.50000","7.25104","4.36976"
"14.60000","7.30096","4.40408"
"14.70000","7.35106","4.43278"
"14.80000","7.40099","4.46868"
"14.90000","7.45091","4.50433"
"15.00000","7.50102","4.52613"
"15.10000","7.55100","4.54701"
"15.20000","7.60092","4.57696"
"15.30000","7.65097","4.61760"
"15.40000","7.70083","4.65002"
"15.50000","7.75106","4.68109"
"15.60000","7.80092","4.70570"
"15.70000","7.85102","4.73241"
"15.80000","7.90095","4.75631"
"15.90000","7.95093","4.78902"
"16.00000","8.00092","4.82297"
"16.10000","8.05096","4.85315"
"16.20000","8.10100","4.88841"
"16.30000","8.15105","4.92068"
"16.40000","8.20097","4.93928"
"16.50000","8.25113","4.95849"
"16.60000","8.30100","4.99179"
"16.70000","8.35104","5.02813"
"16.80000","8.40097","5.06644"
"16.90000","8.45107","5.10129"
"17.00000","8.50088","5.13085"
"17.10000","8.55098","5.14980"
"17.20000","8.60096","5.17389"
"17.30000","8.65101","5.20549"
"17.40000","8.70099","5.23474"
"17.50000","8.75097","5.26096"
"17.60000","8.80096","5.29709"
"17.70000","8.85100","5.33311"
"17.80000","8.90093","5.35792"
"17.90000","8.95097","5.38321"
"18.00000","9.00096","5.41850"
"18.10000","9.05094","5.45069"
"18.20000","9.10092","5.48248"
"18.30000","9.15097","5.51072"
"18.40000","9.20095","5.53471"
"18.50000","9.25100","5.55691"
"18.60000","9.30092","5.57970"
"18.70000","9.35108","5.62324"
"18.80000","9.40095","5.65533"
"18.90000","9.45099","5.69062"
"19.00000","9.50104","5.72825"
"19.10000","9.55102","5.75414"
"19.20000","9.60088","5.77300"
"19.30000","9.65099","5.79108"
"19.40000","9.70097","5.82505"
"19.50000","9.75107","5.85454"
"19.60000","9.80094","5.89232"
"19.70000","9.85086","5.93262"
"19.80000","9.90091","5.95869"
"19.90000","9.95089","5.98364"
"20.00000","10.00105","6.00933"
"20.10000","10.05098","6.04313"
"20.20000","10.10096","6.06936"
"20.30000","10.15095","6.09571"
"20.40000","10.20093","6.12424"
"20.50000","10.25103","6.15318"
"20.60000","10.30096","6.18197"
"20.70000","10.35100","6.21202"
"20.80000","10.40099","6.24943"
"20.90000","10.45091","6.28295"
"21.00000","10.50090","6.31855"
"21.10000","10.55100","6.35170"
"21.20000","10.60092","6.36681"
"21.30000","10.65097","6.38111"
"21.40000","10.70089","6.40707"
"21.50000","10.75088","6.44487"
"21.60000","10.80092","6.47775"
"21.70000","10.85108","6.51695"
"21.80000","10.90101","6.55154"
"21.90000","10.95099","6.58461"
"22.00000","11.00091","6.60771"
"22.10000","11.05096","6.62797"
"22.20000","11.10094","6.65675"
"22.30000","11.15099","6.68165"
"22.40000","11.20103","6.71319"
"22.50000","11.25102","6.75244"
"22.60000","11.30100","6.77876"
"22.70000","11.35092","6.80345"
"22.80000","11.40097","6.83283"
"22.90000","11.45107","6.87158"
"23.00000","11.50094","6.90377"
"23.10000","11.55092","6.93123"
"23.20000","11.60096","6.95757"
"23.30000","11.65101","6.97957"
"23.40000","11.70093","7.00060"
"23.50000","11.75104","7.03181"
"23.60000","11.80102","7.06830"
"23.70000","11.85094","7.10231"
"23.80000","11.90099","7.14127"
"23.90000","11.95103","7.17853"
"24.00000","12.00096","7.20211"
"24.10000","12.05088","7.21971"
"24.20000","12.10092","7.23573"
"24.30000","12.15091","7.26757"
"24.40000","12.20101","7.30127"
"24.50000","12.25099","7.33359"
"24.60000","12.30104","7.37135"
"24.70000","12.35108","7.40151"
"24.80000","12.40101","7.42752"
"24.90000","12.45093","7.45441"
"25.00000","12.50103","7.48797"
"25.10000","12.55096","7.51362"
"25.20000","12.60094","7.54294"
"25.30000","12.65099","7.57484"
"25.40000","12.70097","7.60252"
"25.50000","12.75101","7.62430"
"25.60000","12.80106","7.64880"
"25.70000","12.85092","7.68660"
"25.80000","12.90097","7.72813"
"25.90000","12.95107","7.75635"
"26.00000","13.00094","7.78763"
"26.10000","13.05098","7.81037"
"26.20000","13.10102","7.82944"
"26.30000","13.15101","7.85460"
"26.40000","13.20105","7.89150"
"26.50000","13.25086","7.92096"
"26.60000","13.30096","7.95631"
"26.70000","13.35094","7.99327"
"26.80000","13.40099","8.02138"
"26.90000","13.45103","8.04186"
"27.00000","13.50095","8.05949"
"27.10000","13.55100","8.09144"
"27.20000","13.60098","8.12632"
"27.30000","13.65091","8.15758"
"27.40000","13.70095","8.19196"
"27.50000","13.75094","8.21727"
"27.60000","13.80098","8.24301"
"27.70000","13.85102","8.27168"
"27.80000","13.90095","8.30483"
"27.90000","13.95099","8.33827"
"28.00000","14.00103","8.36215"
"28.10000","14.05090","8.39653"
"28.20000","14.10106","8.42830"
"28.30000","14.15099","8.44954"
"28.40000","14.20091","8.47213"
"28.50000","14.25089","8.50139"
"28.60000","14.30100","8.53636"
"28.70000","14.35104","8.57061"
"28.80000","14.40103","8.60184"
"28.90000","14.45101","8.62998"
"29.00000","14.50100","8.65007"
"29.10000","14.55092","8.66975"
"29.20000","14.60090","8.71064"
"29.30000","14.65095","8.74296"
"29.40000","14.70093","8.77376"
"29.50000","14.75098","8.80608"
"29.60000","14.80090","8.83423"
"29.70000","14.85094","8.86049"
"29.80000","14.90099","8.87918"
"29.90000","14.95097","8.90522"
"30.00000","15.00095","8.93985"
"30.10000","15.05088","8.97617"
"30.20000","15.10098","9.01243"
"30.30000","15.15097","9.03648"
"30.40000","15.20101","9.06470"
"30.50000","15.25099","9.08521"
"30.60000","15.30104","9.11785"
"30.70000","15.35096","9.14739"
"30.80000","15.40101","9.17635"
"30.90000","15.45087","9.20575"
"31.00000","15.50097","9.23542"
"31.10000","15.55108","9.26467"
"31.20000","15.60106","9.28780"
"31.30000","15.65099","9.31895"
"31.40000","15.70091","9.35053"
"31.50000","15.75101","9.38315"
"31.60000","15.80100","9.41636"
"31.70000","15.85104","9.44811"
"31.80000","15.90097","9.46624"
"31.90000","15.95101","9.48036"
"32.00000","16.00093","9.51563"
"32.10000","16.05098","9.55481"
"32.20000","16.10102","9.58906"
"32.30000","16.15100","9.62126"
"32.40000","16.20093","9.65489"
"32.50000","16.25097","9.68218"
"32.60000","16.30096","9.69818"
"32.70000","16.35100","9.71887"
"32.80000","16.40099","9.74537"
"32.90000","16.45097","9.77413"
"33.00000","16.50095","9.80958"
"33.10000","16.55088","9.85105"
"33.20000","16.60098","9.87968"
"33.30000","16.65109","9.89924"
"33.40000","16.70095","9.92894"
"33.50000","16.75093","9.95912"
"33.60000","16.80092","9.99259"
"33.70000","16.85102","10.01820"
"33.80000","16.90095","10.04412"
"33.90000","16.95099","10.06824"
"34.00000","17.00097","10.09297"
"34.10000","17.05102","10.11984"
"34.20000","17.10100","10.15488"
"34.30000","17.15092","10.19229"
"34.40000","17.20091","10.22446"
"34.50000","17.25101","10.26090"
"34.60000","17.30100","10.28939"
"34.70000","17.35098","10.30089"
"34.80000","17.40097","10.31881"
"34.90000","17.45101","10.34562"
"35.00000","17.50100","10.38012"
"35.10000","17.55098","10.41471"
"35.20000","17.60090","10.45036"
"35.30000","17.65089","10.48432"
"35.40000","17.70099","10.51007"
"35.50000","17.75097","10.53514"
"35.60000","17.80096","10.56159"
"35.70000","17.85094","10.58475"
"35.80000","17.90105","10.60850"
"35.90000","17.95091","10.63853"
"36.00000","18.00101","10.67314"
"36.10000","18.05094","10.70028"
"36.20000","18.10098","10.72324"
"36.30000","18.15103","10.75712"
"36.40000","18.20089","10.79395"
"36.50000","18.25099","10.82990"
"36.60000","18.30104","10.85811"
"36.70000","18.35090","10.88401"
"36.80000","18.40101","10.90118"
"36.90000","18.45093","10.91730"
"37.00000","18.50097","10.94290"
"37.10000","18.55102","10.97893"
"37.20000","18.60100","11.00992"
"37.30000","18.65099","11.04485"
"37.40000","18.70097","11.08559"
"37.50000","18.75095","11.11562"
"37.60000","18.80094","11.13682"
"37.70000","18.85098","11.15145"
"37.80000","18.90103","11.17854"
"37.90000","18.95101","11.20964"
"38.00000","19.00111","11.23983"
"38.10000","19.05098","11.27695"
"38.20000","19.10108","11.30236"
"38.30000","19.15101","11.32864"
"38.40000","19.20099","11.35826"
"38.50000","19.25097","11.38930"
"38.60000","19.30096","11.41834"
"38.70000","19.35100","11.44385"
"38.80000","19.40099","11.47286"
"38.90000","19.45097","11.50139"
"39.00000","19.50101","11.52620"
"39.10000","19.55094","11.54537"
"39.20000","19.60098","11.57280"
"39.30000","19.65096","11.60924"
"39.40000","19.70107","11.64607"
"39.50000","19.75087","11.68085"
"39.60000","19.80098","11.70907"
"39.70000","19.85102","11.73060"
"39.80000","19.90106","11.74713"
"39.90000","19.95105","11.77365"
"40.00000","20.00097","11.80425"
"40.10000","20.05108","11.83675"
"40.20000","20.10100","11.86705"
"40.30000","20.15104","11.90243"
"40.40000","20.20103","11.93524"
"40.50000","20.25095","11.95904"
"40.60000","20.30106","11.97845"
"40.70000","20.35086","12.00665"
"40.80000","20.40096","12.03346"
"40.90000","20.45095","12.06402"
"41.00000","20.50105","12.09759"
"41.10000","20.55110","12.12939"
"41.20000","20.60096","12.14720"
"41.30000","20.65094","12.17199"
"41.40000","20.70099","12.20159"
"41.50000","20.75097","12.23574"
"41.60000","20.80102","12.26454"
"41.70000","20.85094","12.29203"
"41.80000","20.90099","12.32319"
"41.90000","20.95085","12.34765"
"42.00000","21.00101","12.37166"
"42.10000","21.05094","12.39917"
"42.20000","21.10098","12.42837"
"42.30000","21.15103","12.46159"
"42.40000","21.20095","12.49450"
"42.50000","21.25093","12.52858"
"42.60000","21.30098","12.55245"
"42.70000","21.35102","12.57001"
"42.80000","21.40101","12.59269"
"42.90000","21.45093","12.62248"
"43.00000","21.50097","12.65948"
"43.10000","21.55096","12.68602"
"43.20000","21.60106","12.71802"
"43.30000","21.65099","12.74889"
"43.40000","21.70097","12.77214"
"43.50000","21.75089","12.79353"
"43.60000","21.80100","12.81786"
"43.70000","21.85104","12.84674"
"43.80000","21.90103","12.87805"
"43.90000","21.95101","12.91454"
"44.00000","22.00111","12.94999"
"44.10000","22.05092","12.97325"
"44.20000","22.10102","12.99401"
"44.30000","22.15095","13.01390"
"44.40000","22.20105","13.04942"
"44.50000","22.25097","13.07886"
"44.60000","22.30096","13.10676"
"44.70000","22.35100","13.13409"
"44.80000","22.40099","13.16212"
"44.90000","22.45091","13.18759"
"45.00000","22.50107","13.21028"
"45.10000","22.55088","13.24427"
"45.20000","22.60098","13.27493"
"45.30000","22.65102","13.30866"
"45.40000","22.70107","13.34043"
"45.50000","22.75093","13.36761"
"45.60000","22.80098","13.38686"
"45.70000","22.85090","13.39949"
"45.80000","22.90094","13.42191"
"45.90000","22.95099","13.46031"
"46.00000","23.00091","13.49703"
"46.10000","23.05096","13.53097"
"46.20000","23.10100","13.56035"
"46.30000","23.15099","13.59201"
"46.40000","23.20091","13.61231"
"46.50000","23.25095","13.63756"
"46.60000","23.30106","13.66276"
"46.70000","23.35092","13.68957"
"46.80000","23.40097","13.71631"
"46.90000","23.45095","13.74811"
"47.00000","23.50099","13.78569"
"47.10000","23.55103","13.80748"
"47.20000","23.60096","13.83084"
"47.30000","23.65088","13.85895"
"47.40000","23.70105","13.89160"
"47.50000","23.75091","13.92291"
"47.60000","23.80096","13.94948"
"47.70000","23.85100","13.97331"
"47.80000","23.90092","13.99352"
"47.90000","23.95085","14.02070"
"48.00000","24.00101","14.04620"
"48.10000","24.05094","14.08140"
"48.20000","24.10098","14.11572"
"48.30000","24.15096","14.14851"
"48.40000","24.20089","14.18164"
"48.50000","24.25087","14.21111"
"48.60000","24.30086","14.22339"
"48.70000","24.35102","14.23914"
"48.80000","24.40095","14.26299"
"48.90000","24.45099","14.29412"
"49.00000","24.50091","14.32685"
"49.10000","24.55090","14.36275"
"49.20000","24.60100","14.39164"
"49.30000","24.65098","14.42268"
"49.40000","24.70097","14.44861"
"49.50000","24.75095","14.47546"
"49.60000","24.80100","14.50724"
"49.70000","24.85086","14.52874"
"49.80000","24.90103","14.55304"
"49.90000","24.95095","14.58083"
"50.00000","25.00105","14.60931"
"50.10000","25.05098","14.63284"
"50.20000","25.10090","14.65289"
"50.30000","25.15095","14.69090"
"50.40000","25.20099","14.72464"
"50.50000","25.25109","14.75694"
"50.60000","25.30102","14.78765"
"50.70000","25.35094","14.81428"
"50.80000","25.40093","14.82847"
"50.90000","25.45091","14.84213"
"51.00000","25.50095","14.87520"
"51.10000","25.55094","14.90539"
"51.20000","25.60086","14.93888"
"51.30000","25.65103","14.97117"
"51.40000","25.70095","15.00614"
"51.50000","25.75100","15.04072"
"51.60000","25.80098","15.05848"
"51.70000","25.85096","15.07724"
"51.80000","25.90095","15.10089"
"51.90000","25.95099","15.12813"
"52.00000","26.00097","15.15737"
"52.10000","26.05096","15.18851"
"52.20000","26.10100","15.21267"
"52.30000","26.15099","15.24303"
"52.40000","26.20091","15.27352"
"52.50000","26.25096","15.29884"
"52.60000","26.30106","15.33231"
"52.70000","26.35104","15.36101"
"52.80000","26.40091","15.38541"
"52.90000","26.45095","15.41127"
"53.00000","26.50099","15.43393"
"53.10000","26.55098","15.45602"
"53.20000","26.60102","15.48163"
"53.30000","26.65095","15.50854"
"53.40000","26.70099","15.54047"
"53.50000","26.75103","15.57788"
"53.60000","26.80090","15.61556"
"53.70000","26.85100","15.63989"
"53.80000","26.90093","15.65787"
"53.90000","26.95097","15.67623"
"54.00000","27.00095","15.70035"
"54.10000","27.05100","15.73085"
"54.20000","27.10098","15.76366"
"54.30000","27.15102","15.79358"
"54.40000","27.20089","15.82228"
"54.50000","27.25105","15.85016"
"54.60000","27.30098","15.87657"
"54.70000","27.35096","15.89907"
"54.80000","27.40094","15.92478"
"54.90000","27.45099","15.95119"
"55.00000","27.50097","15.98031"
"55.10000","27.55090","16.00949"
"55.20000","27.60088","16.03709"
"55.30000","27.65104","16.06283"
"55.40000","27.70091","16.08297"
"55.50000","27.75089","16.11314"
"55.60000","27.80106","16.14335"
"55.70000","27.85092","16.17617"
"55.80000","27.90103","16.20468"
"55.90000","27.95101","16.23416"
"56.00000","28.00099","16.25665"
"56.10000","28.05103","16.28011"
"56.20000","28.10090","16.30007"
"56.30000","28.15095","16.32931"
"56.40000","28.20099","16.35865"
"56.50000","28.25104","16.38716"
"56.60000","28.30102","16.42134"
"56.70000","28.35100","16.44780"
"56.80000","28.40087","16.47791"
"56.90000","28.45103","16.49497"
"57.00000","28.50095","16.51940"
"57.10000","28.55094","16.54480"
"57.20000","28.60086","16.57462"
"57.30000","28.65103","16.60936"
"57.40000","28.70107","16.63796"
"57.50000","28.75105","16.66447"
"57.60000","28.80098","16.68798"
"57.70000","28.85096","16.71300"
"57.80000","28.90101","16.73565"
"57.90000","28.95093","16.76126"
"58.00000","29.00097","16.78972"
"58.10000","29.05096","16.82057"
"58.20000","29.10094","16.85116"
"58.30000","29.15105","16.87748"
"58.40000","29.20091","16.90185"
"58.50000","29.25095","16.92615"
"58.60000","29.30106","16.95417"
"58.70000","29.35098","16.98559"
"58.80000","29.40097","17.01199"
"58.90000","29.45101","17.03906"
"59.00000","29.50093","17.06150"
"59.10000","29.55110","17.08687"
"59.20000","29.60096","17.10651"
"59.30000","29.65095","17.13267"
"59.40000","29.70093","17.16464"
"59.50000","29.75109","17.19320"
"59.60000","29.80102","17.22678"
"59.70000","29.85100","17.25665"
"59.80000","29.90099","17.28389"
"59.90000","29.95103","17.30887"
"60.00000","30.00096","17.32558"
"60.10000","30.05094","17.33969"
"60.20000","30.10098","17.37600"
"60.30000","30.15103","17.40714"
"60.40000","30.20101","17.44234"
"60.50000","30.25093","17.47123"
"60.60000","30.30086","17.50278"
"60.70000","30.35090","17.52313"
"60.80000","30.40100","17.54110"
"60.90000","30.45105","17.56927"
"61.00000","30.50097","17.59302"
"61.10000","30.55090","17.61836"
"61.20000","30.60100","17.64870"
"61.30000","30.65098","17.67284"
"61.40000","30.70103","17.70266"
"61.50000","30.75095","17.72816"
"61.60000","30.80100","17.75546"
"61.70000","30.85104","17.78154"
"61.80000","30.90097","17.81230"
"61.90000","30.95095","17.84502"
"62.00000","31.00099","17.87307"
"62.10000","31.05104","17.89766"
"62.20000","31.10084","17.91465"
"62.30000","31.15101","17.93116"
"62.40000","31.20099","17.95765"
"62.50000","31.25097","17.98692"
"62.60000","31.30107","18.01958"
"62.70000","31.35094","18.05208"
"62.80000","31.40092","18.08520"
"62.90000","31.45103","18.12192"
"63.00000","31.50095","18.13549"
"63.10000","31.55094","18.15656"
"63.20000","31.60098","18.17463"
"63.30000","31.65096","18.20052"
"63.40000","31.70107","18.22353"
"63.50000","31.75093","18.25370"
"63.60000","31.80097","18.28957"
"63.70000","31.85096","18.32096"
"63.80000","31.90100","18.34114"
"63.90000","31.95087","18.36672"
"64.00000","32.00085","18.39430"
"64.10000","32.05096","18.42782"
"64.20000","32.10094","18.44865"
"64.30000","32.15099","18.47364"
"64.40000","32.20097","18.49735"
"64.50000","32.25095","18.52212"
"64.60000","32.30093","18.54630"
"64.70000","32.35104","18.56871"
"64.80000","32.40096","18.59728"
"64.90000","32.45095","18.63205"
"65.00000","32.50099","18.66658"
"65.10000","32.55098","18.69714"
"65.20000","32.60102","18.72703"
"65.30000","32.65106","18.74436"
"65.40000","32.70099","18.75621"
"65.50000","32.75103","18.77475"
"65.60000","32.80096","18.79982"
"65.70000","32.85094","18.83177"
"65.80000","32.90099","18.86297"
"65.90000","32.95103","18.89281"
"66.00000","33.00101","18.92716"
"66.10000","33.05093","18.95866"
"66.20000","33.10098","18.97798"
"66.30000","33.15096","19.00089"
"66.40000","33.20095","19.02392"
"66.50000","33.25093","19.05017"
"66.60000","33.30104","19.07564"
"66.70000","33.35090","19.10254"
"66.80000","33.40100","19.13016"
"66.90000","33.45105","19.16181"
"67.00000","33.50097","19.18042"
"67.10000","33.55096","19.20457"
"67.20000","33.60094","19.23501"
"67.30000","33.65092","19.26969"
"67.40000","33.70109","19.29590"
"67.50000","33.75101","19.32058"
"67.60000","33.80100","19.34370"
"67.70000","33.85104","19.36268"
"67.80000","33.90097","19.38153"
"67.90000","33.95101","19.40757"
"68.00000","34.00099","19.43944"
"68.10000","34.05103","19.46665"
"68.20000","34.10090","19.50066"
"68.30000","34.15100","19.53521"
"68.40000","34.20099","19.55292"
"68.50000","34.25103","19.58292"
"68.60000","34.30107","19.59769"
"68.70000","34.35094","19.61326"
"68.80000","34.40092","19.64487"
"68.90000","34.45091","19.67580"
"69.00000","34.50107","19.70720"
"69.10000","34.55106","19.73559"
"69.20000","34.60098","19.76323"
"69.30000","34.65102","19.78681"
"69.40000","34.70095","19.81245"
"69.50000","34.75099","19.83858"
"69.60000","34.80098","19.86781"
"69.70000","34.85096","19.89140"
"69.80000","34.90106","19.91544"
"69.90000","34.95098","19.94463"
"70.00000","35.00091","19.97118"
"70.10000","35.05101","19.98983"
"70.20000","35.10094","20.00959"
"70.30000","35.15098","20.03812"
"70.40000","35.20097","20.06498"
"70.50000","35.25095","20.09780"
"70.60000","35.30088","20.12761"
"70.70000","35.35104","20.15894"
"70.80000","35.40108","20.18072"
"70.90000","35.45095","20.19764"
"71.00000","35.50093","20.21952"
"71.10000","35.55103","20.24701"
"71.20000","35.60096","20.27522"
"71.30000","35.65100","20.30451"
"71.40000","35.70093","20.33310"
"71.50000","35.75097","20.36389"
"71.60000","35.80114","20.39391"
"71.70000","35.85100","20.41173"
"71.80000","35.90099","20.42727"
"71.90000","35.95103","20.45482"
"72.00000","36.00101","20.48060"
"72.10000","36.05099","20.50879"
"72.20000","36.10098","20.54067"
"72.30000","36.15090","20.56783"
"72.40000","36.20101","20.59487"
"72.50000","36.25093","20.61326"
"72.60000","36.30098","20.63332"
"72.70000","36.35096","20.66442"
"72.80000","36.40094","20.69290"
"72.90000","36.45105","20.71973"
"73.00000","36.50097","20.74318"
"73.10000","36.55102","20.77432"
"73.20000","36.60094","20.80233"
"73.30000","36.65099","20.82367"
"73.40000","36.70097","20.84254"
"73.50000","36.75101","20.86982"
"73.60000","36.80094","20.89832"
"73.70000","36.85104","20.92957"
"73.80000","36.90108","20.95905"
"73.90000","36.95095","20.98637"
"74.00000","37.00099","21.00651"
"74.10000","37.05104","21.02222"
"74.20000","37.10090","21.04302"
"74.30000","37.15100","21.07663"
"74.40000","37.20099","21.10669"
"74.50000","37.25097","21.13570"
"74.60000","37.30101","21.16089"
"74.70000","37.35088","21.19555"
"74.80000","37.40086","21.22096"
"74.90000","37.45091","21.23756"
"75.00000","37.50101","21.25708"
"75.10000","37.55100","21.27348"
"75.20000","37.60098","21.30130"
"75.30000","37.65097","21.32965"
"75.40000","37.70095","21.36523"
"75.50000","37.75099","21.39656"
"75.60000","37.80098","21.42459"
"75.70000","37.85096","21.44604"
"75.80000","37.90100","21.46317"
"75.90000","37.95105","21.49461"
"76.00000","38.00091","21.52383"
"76.10000","38.05090","21.54621"
"76.20000","38.10094","21.56836"
"76.30000","38.15099","21.59505"
"76.40000","38.20103","21.61898"
"76.50000","38.25089","21.64404"
"76.60000","38.30088","21.67040"
"76.70000","38.35110","21.69480"
"76.80000","38.40096","21.72530"
"76.90000","38.45101","21.75550"
"77.00000","38.50093","21.78518"
"77.10000","38.55092","21.80907"
"77.20000","38.60090","21.83832"
"77.30000","38.65094","21.84806"
"77.40000","38.70105","21.85889"
"77.50000","38.75097","21.88932"
"77.60000","38.80107","21.92435"
"77.70000","38.85088","21.95832"
"77.80000","38.90098","21.98873"
"77.90000","38.95103","22.01801"
"78.00000","39.00101","22.04282"
"78.10000","39.05099","22.06658"
"78.20000","39.10098","22.08411"
"78.30000","39.15091","22.10487"
"78.40000","39.20089","22.12739"
"78.50000","39.25105","22.15261"
"78.60000","39.30098","22.18381"
"78.70000","39.35090","22.21256"
"78.80000","39.40094","22.24211"
"78.90000","39.45093","22.26750"
"79.00000","39.50097","22.28337"
"79.10000","39.55096","22.32002"
"79.20000","39.60094","22.34713"
"79.30000","39.65099","22.37752"
"79.40000","39.70090","22.39880"
"79.50000","39.75089","22.42305"
"79.60000","39.80099","22.44178"
"79.70000","39.85098","22.46033"
"79.80000","39.90108","22.48587"
"79.90000","39.95083","22.51131"
"80.00000","40.00099","22.54256"
"80.10000","40.05091","22.57485"
"80.20000","40.10102","22.60690"
"80.30000","40.15106","22.63991"
"80.40000","40.20099","22.66552"
"80.50000","40.25091","22.67706"
"80.60000","40.30101","22.69271"
"80.70000","40.35100","22.71093"
"80.80000","40.40098","22.74306"
"80.90000","40.45097","22.77385"
"81.00000","40.50101","22.80338"
"81.10000","40.55087","22.83281"
"81.20000","40.60092","22.86144"
"81.30000","40.65102","22.88813"
"81.40000","40.70101","22.90950"
"81.50000","40.75093","22.93357"
"81.60000","40.80098","22.96120"
"81.70000","40.85096","22.97850"
"81.80000","40.90100","23.00496"
"81.90000","40.95093","23.03213"
"82.00000","41.00097","23.06216"
"82.10000","41.05095","23.08525"
"82.20000","41.10100","23.10082"
"82.30000","41.15092","23.12409"
"82.40000","41.20103","23.16306"
"82.50000","41.25089","23.19635"
"82.60000","41.30094","23.22578"
"82.70000","41.35092","23.24933"
"82.80000","41.40102","23.27094"
"82.90000","41.45107","23.28532"
"83.00000","41.50105","23.30156"
"83.10000","41.55091","23.33015"
"83.20000","41.60108","23.36069"
"83.30000","41.65100","23.38751"
"83.40000","41.70099","23.41996"
"83.50000","41.75097","23.45293"
"83.60000","41.80102","23.48626"
"83.70000","41.85106","23.50605"
"83.80000","41.90092","23.51954"
"83.90000","41.95091","23.54347"
"84.00000","42.00113","23.56601"
"84.10000","42.05099","23.59278"
"84.20000","42.10092","23.62360"
"84.30000","42.15096","23.65794"
"84.40000","42.20100","23.68083"
"84.50000","42.25099","23.70030"
"84.60000","42.30104","23.72484"
"84.70000","42.35089","23.74726"
"84.80000","42.40089","23.78193"
"84.90000","42.45093","23.80779"
"85.00000","42.50097","23.82747"
"85.10000","42.55096","23.85617"
"85.20000","42.60094","23.88330"
"85.30000","42.65098","23.90633"
"85.40000","42.70103","23.92436"
"85.50000","42.75089","23.94964"
"85.60000","42.80099","23.97703"
"85.70000","42.85092","24.01359"
"85.80000","42.90096","24.04046"
"85.90000","42.95089","24.07257"
"86.00000","43.00093","24.09355"
"86.10000","43.05103","24.11419"
"86.20000","43.10102","24.12923"
"86.30000","43.15094","24.15026"
"86.40000","43.20098","24.18431"
"86.50000","43.25091","24.21188"
"86.60000","43.30102","24.24240"
"86.70000","43.35100","24.27151"
"86.80000","43.40098","24.30113"
"86.90000","43.45097","24.32409"
"87.00000","43.50095","24.33772"
"87.10000","43.55112","24.36479"
"87.20000","43.60098","24.38836"
"87.30000","43.65102","24.41744"
"87.40000","43.70095","24.44460"
"87.50000","43.75093","24.47645"
"87.60000","43.80091","24.50638"
"87.70000","43.85096","24.52363"
"87.80000","43.90106","24.54382"
"87.90000","43.95092","24.56744"
"88.00000","44.00103","24.59738"
"88.10000","44.05089","24.62528"
"88.20000","44.10088","24.64876"
"88.30000","44.15099","24.67840"
"88.40000","44.20102","24.70825"
"88.50000","44.25095","24.72822"
"88.60000","44.30106","24.75201"
"88.70000","44.35098","24.77690"
"88.80000","44.40090","24.80256"
"88.90000","44.45100","24.83295"
"89.00000","44.50093","24.86173"
"89.10000","44.55098","24.89264"
"89.20000","44.60108","24.91408"
"89.30000","44.65107","24.93116"
"89.40000","44.70093","24.94720"
"89.50000","44.75103","24.97405"
"89.60000","44.80101","25.00129"
"89.70000","44.85100","25.03570"
"89.80000","44.90092","25.06192"
"89.90000","44.95097","25.09175"
"90.00000","45.00095","25.11847"
"90.10000","45.05100","25.14248"
"90.20000","45.10092","25.16508"
"90.30000","45.15091","25.18398"
"90.40000","45.20089","25.20998"
"90.50000","45.25093","25.23364"
"90.60000","45.30098","25.26170"
"90.70000","45.35102","25.29658"
"90.80000","45.40094","25.32916"
"90.90000","45.45093","25.34519"
"91.00000","45.50097","25.36628"
"91.10000","45.55102","25.38740"
"91.20000","45.60094","25.41949"
"91.30000","45.65104","25.45086"
"91.40000","45.70103","25.47287"
"91.50000","45.75095","25.49765"
"91.60000","45.80093","25.51853"
"91.70000","45.85092","25.54262"
"91.80000","45.90090","25.56024"
"91.90000","45.95101","25.58943"
"92.00000","46.00093","25.62169"
"92.10000","46.05104","25.64978"
"92.20000","46.10096","25.68066"
"92.30000","46.15106","25.71082"
"92.40000","46.20098","25.74352"
"92.50000","46.25091","25.76196"
"92.60000","46.30089","25.77159"
"92.70000","46.35094","25.79137"
"92.80000","46.40098","25.81543"
"92.90000","46.45102","25.84654"
"93.00000","46.50095","25.87809"
"93.10000","46.55106","25.91289"
"93.20000","46.60104","25.94253"
"93.30000","46.65096","25.96714"
"93.40000","46.70095","25.98608"
"93.50000","46.75105","26.00802"
"93.60000","46.80098","26.03107"
"93.70000","46.85096","26.05447"
"93.80000","46.90088","26.07448"
"93.90000","46.95105","26.10227"
"94.00000","47.00097","26.13248"
"94.10000","47.05096","26.15968"
"94.20000","47.10094","26.18217"
"94.30000","47.15092","26.20614"
"94.40000","47.20103","26.23397"
"94.50000","47.25101","26.26455"
"94.60000","47.30093","26.29451"
"94.70000","47.35104","26.32046"
"94.80000","47.40096","26.34348"
"94.90000","47.45100","26.36394"
"95.00000","47.50099","26.37948"
"95.10000","47.55098","26.40265"
"95.20000","47.60096","26.42876"
"95.30000","47.65118","26.46491"
"95.40000","47.70098","26.49095"
"95.50000","47.75097","26.52316"
"95.60000","47.80102","26.55563"
"95.70000","47.85094","26.58139"
"95.80000","47.90092","26.60099"
"95.90000","47.95097","26.61032"
"96.00000","48.00083","26.62878"
"96.10000","48.05105","26.65488"
"96.20000","48.10098","26.68098"
"96.30000","48.15096","26.71373"
"96.40000","48.20101","26.74073"
"96.50000","48.25105","26.77137"
"96.60000","48.30103","26.79433"
"96.70000","48.35096","26.81828"
"96.80000","48.40100","26.84275"
"96.90000","48.45092","26.87385"
"97.00000","48.50097","26.89421"
"97.10000","48.55101","26.92069"
"97.20000","48.60100","26.94277"
"97.30000","48.65104","26.97208"
"97.40000","48.70103","26.99421"
"97.50000","48.75095","27.01526"
"97.60000","48.80093","27.03456"
"97.70000","48.85098","27.06640"
"97.80000","48.90102","27.09305"
"97.90000","48.95100","27.12819"
"98.00000","49.00105","27.15770"
"98.10000","49.05091","27.18379"
"98.20000","49.10096","27.19702"
"98.30000","49.15100","27.21437"
"98.40000","49.20099","27.23343"
"98.50000","49.25097","27.25777"
"98.60000","49.30090","27.28905"
"98.70000","49.35106","27.31631"
"98.80000","49.40098","27.34003"
"98.90000","49.45103","27.37354"
"99.00000","49.50101","27.40566"
"99.10000","49.55099","27.42311"
"99.20000","49.60098","27.44549"
"99.30000","49.65090","27.45996"
"99.40000","49.70100","27.48503"
"99.50000","49.75105","27.50951"
"99.60000","49.80098","27.53843"
"99.70000","49.85096","27.56847"
"99.80000","49.90094","27.59405"
"99.90000","49.95093","27.61807"
"100.00000","50.00103","27.63407"
"100.10000","50.05095","27.65881"
"100.20000","50.10088","27.69087"
"100.30000","50.15092","27.72361"
"100.40000","50.20102","27.74557"
"100.50000","50.25095","27.76611"
"100.60000","50.30099","27.79132"
"100.70000","50.35098","27.81220"
"100.80000","50.40096","27.83128"
"100.90000","50.45094","27.85170"
"101.00000","50.50093","27.87590"
"101.10000","50.55098","27.90344"
"101.20000","50.60096","27.93243"
"101.30000","50.65100","27.96360"
"101.40000","50.70098","27.99158"
"101.50000","50.75085","28.02278"
"101.60000","50.80107","28.03741"
"101.70000","50.85094","28.04645"
"101.80000","50.90099","28.06670"
"101.90000","50.95096","28.09650"
"102.00000","51.00095","28.12578"
"102.10000","51.05099","28.15486"
"102.20000","51.10098","28.18065"
"102.30000","51.15096","28.20961"
"102.40000","51.20095","28.23399"
"102.50000","51.25099","28.25102"
"102.60000","51.30097","28.27299"
"102.70000","51.35102","28.29298"
"102.80000","51.40100","28.31645"
"102.90000","51.45098","28.34256"
"103.00000","51.50115","28.36355"
"103.10000","51.55090","28.39446"
"103.20000","51.60100","28.42282"
"103.30000","51.65098","28.43993"
"103.40000","51.70097","28.46131"
"103.50000","51.75101","28.47691"
"103.60000","51.80094","28.50594"
"103.70000","51.85098","28.54143"
"103.80000","51.90096","28.56193"
"103.90000","51.95094","28.58627"
"104.00000","52.00099","28.60871"
"104.10000","52.05098","28.63058"
"104.20000","52.10096","28.64926"
"104.30000","52.15094","28.66384"
"104.40000","52.20104","28.69244"
"104.50000","52.25091","28.71927"
"104.60000","52.30095","28.74338"
"104.70000","52.35088","28.76911"
"104.80000","52.40104","28.79847"
"104.90000","52.45091","28.82790"
"105.00000","52.50101","28.84882"
"105.10000","52.55099","28.86208"
"105.20000","52.60098","28.86852"
"105.30000","52.65084","28.89510"
"105.40000","52.70101","28.92225"
"105.50000","52.75099","28.95122"
"105.60000","52.80104","28.97984"
"105.70000","52.85096","29.00473"
"105.80000","52.90088","29.02919"
"105.90000","52.95087","29.04979"
"106.00000","53.00097","29.07038"
"106.10000","53.05102","29.09042"
"106.20000","53.10088","29.11011"
"106.30000","53.15092","29.13089"
"106.40000","53.20091","29.15273"
"106.50000","53.25089","29.17403"
"106.60000","53.30105","29.19803"
"106.70000","53.35092","29.22857"
"106.80000","53.40096","29.25607"
"106.90000","53.45095","29.27455"
"107.00000","53.50099","29.29284"
"107.10000","53.55092","29.30842"
"107.20000","53.60102","29.33586"
"107.30000","53.65094","29.36750"
"107.40000","53.70099","29.39099"
"107.50000","53.75085","29.41310"
"107.60000","53.80096","29.43026"
"107.70000","53.85100","29.44950"
"107.80000","53.90098","29.46513"
"107.90000","53.95097","29.47601"
"108.00000","54.00095","29.50172"
"108.10000","54.05094","29.53150"
"108.20000","54.10092","29.55230"
"108.30000","54.15097","29.57952"
"108.40000","54.20100","29.60921"
"108.50000","54.25099","29.63397"
"108.60000","54.30091","29.66194"
"108.70000","54.35096","29.68223"
"108.80000","54.40094","29.68961"
"108.90000","54.45098","29.70728"
"109.00000","54.50103","29.71921"
"109.10000","54.55090","29.74014"
"109.20000","54.60094","29.76488"
"109.30000","54.65092","29.78951"
"109.40000","54.70103","29.82126"
"109.50000","54.75101","29.85175"
"109.60000","54.80105","29.86838"
"109.70000","54.85092","29.88899"
"109.80000","54.90096","29.90317"
"109.90000","54.95095","29.92076"
"110.00000","55.00099","29.94427"
"110.10000","55.05092","29.96698"
"110.20000","55.10090","29.98481"
"110.30000","55.15094","30.00703"
"110.40000","55.20098","30.02514"
"110.50000","55.25097","30.04814"
"110.60000","55.30101","30.07032"
"110.70000","55.35106","30.08695"
"110.80000","55.40098","30.10856"
"110.90000","55.45097","30.12863"
"111.00000","55.50095","30.15347"
"111.10000","55.55105","30.17706"
"111.20000","55.60098","30.20359"
"111.30000","55.65096","30.22430"
"111.40000","55.70101","30.25003"
"111.50000","55.75099","30.27102"
"111.60000","55.80103","30.28135"
"111.70000","55.85102","30.29475"
"111.80000","55.90088","30.30550"
"111.90000","55.95099","30.31884"
"112.00000","56.00103","30.34318"
"112.10000","56.05096","30.36900"
"112.20000","56.10100","30.39704"
"112.30000","56.15099","30.41839"
"112.40000","56.20103","30.44640"
"112.50000","56.25101","30.46675"
"112.60000","56.30094","30.49714"
"112.70000","56.35092","30.51162"
"112.80000","56.40090","30.52313"
"112.90000","56.45100","30.53631"
"113.00000","56.50099","30.55117"
"113.10000","56.55097","30.56948"
"113.20000","56.60102","30.58990"
"113.30000","56.65094","30.60991"
"113.40000","56.70093","30.63420"
"113.50000","56.75091","30.65611"
"113.60000","56.80090","30.68045"
"113.70000","56.85100","30.69777"
"113.80000","56.90105","30.71586"
"113.90000","56.95097","30.73128"
"114.00000","57.00101","30.75260"
"114.10000","57.05099","30.77356"
"114.20000","57.10092","30.79743"
"114.30000","57.15102","30.81798"
"114.40000","57.20095","30.83258"
"114.50000","57.25093","30.85259"
"114.60000","57.30098","30.86870"
"114.70000","57.35102","30.88504"
"114.80000","57.40106","30.90214"
"114.90000","57.45098","30.91732"
"115.00000","57.50103","30.93416"
"115.10000","57.55095","30.95265"
"115.20000","57.60088","30.97221"
"115.30000","57.65092","30.99390"
"115.40000","57.70097","31.01851"
"115.50000","57.75095","31.04225"
"115.60000","57.80099","31.06655"
"115.70000","57.85086","31.08712"
"115.80000","57.90096","31.10628"
"115.90000","57.95095","31.11942"
"116.00000","58.00099","31.12914"
"116.10000","58.05091","31.13887"
"116.20000","58.10090","31.14532"
"116.30000","58.15094","31.16712"
"116.40000","58.20092","31.19057"
"116.50000","58.25103","31.21199"
"116.60000","58.30102","31.23179"
"116.70000","58.35099","31.25312"
"116.80000","58.40104","31.27228"
"116.90000","58.45096","31.29355"
"117.00000","58.50089","31.31630"
"117.10000","58.55099","31.33546"
"117.20000","58.60104","31.35085"
"117.30000","58.65102","31.36569"
"117.40000","58.70100","31.38152"
"117.50000","58.75093","31.39685"
"117.60000","58.80103","31.41412"
"117.70000","58.85096","31.43026"
"117.80000","58.90094","31.44753"
"117.90000","58.95093","31.46501"
"118.00000","59.00091","31.48623"
"118.10000","59.05090","31.50863"
"118.20000","59.10100","31.52673"
"118.30000","59.15104","31.53950"
"118.40000","59.20103","31.54998"
"118.50000","59.25089","31.55815"
"118.60000","59.30094","31.57555"
"118.70000","59.35091","31.60019"
"118.80000","59.40096","31.62033"
"118.90000","59.45094","31.64283"
"119.00000","59.50099","31.66480"
"119.10000","59.55091","31.68144"
"119.20000","59.60096","31.69723"
"119.30000","59.65094","31.71099"
"119.40000","59.70098","31.72129"
"119.50000","59.75091","31.73597"
"119.60000","59.80089","31.74709"
"119.70000","59.85088","31.76189"
"119.80000","59.90104","31.77980"
"119.90000","59.95097","31.79869"
"120.00000","60.00095","31.82059"
"120.10000","60.05093","31.83554"
"120.20000","60.10104","31.85512"
"120.30000","60.15096","31.87162"
"120.40000","60.20095","31.89507"
"120.50000","60.25093","31.91439"
"120.60000","60.30103","31.93147"
"120.70000","60.35102","31.94140"
"120.80000","60.40100","31.95678"
"120.90000","60.45099","31.96736"
"121.00000","60.50103","31.97522"
"121.10000","60.55102","31.98707"
"121.20000","60.60100","32.00364"
"121.30000","60.65092","32.02496"
"121.40000","60.70085","32.04175"
"121.50000","60.75095","32.06367"
"121.60000","60.80093","32.08105"
"121.70000","60.85098","32.09958"
"121.80000","60.90090","32.11722"
"121.90000","60.95107","32.13455"
"122.00000","61.00093","32.14750"
"122.10000","61.05097","32.16090"
"122.20000","61.10096","32.17191"
"122.30000","61.15094","32.18888"
"122.40000","61.20104","32.19820"
"122.50000","61.25097","32.21424"
"122.60000","61.30101","32.23232"
"122.70000","61.35106","32.24713"
"122.80000","61.40098","32.26345"
"122.90000","61.45103","32.27900"
"123.00000","61.50095","32.29698"
"123.10000","61.55100","32.31073"
"123.20000","61.60098","32.32784"
"123.30000","61.65102","32.34407"
"123.40000","61.70101","32.35743"
"123.50000","61.75099","32.36696"
"123.60000","61.80097","32.37799"
"123.70000","61.85096","32.39154"
"123.80000","61.90100","32.40208"
"123.90000","61.95098","32.41905"
"124.00000","62.00109","32.44027"
"124.10000","62.05101","32.45585"
"124.20000","62.10100","32.47143"
"124.30000","62.15104","32.48991"
"124.40000","62.20097","32.50204"
"124.50000","62.25101","32.51779"
"124.60000","62.30093","32.53366"
"124.70000","62.35092","32.54816"
"124.80000","62.40108","32.55853"
"124.90000","62.45095","32.56790"
"125.00000","62.50098","32.57807"
"125.10000","62.55097","32.59042"
"125.20000","62.60096","32.59942"
"125.30000","62.65100","32.61469"
"125.40000","62.70092","32.63437"
"125.50000","62.75103","32.65283"
"125.60000","62.80089","32.66171"
"125.70000","62.85094","32.68090"
"125.80000","62.90097","32.69540"
"125.90000","62.95108","32.70766"
"126.00000","63.00095","32.72438"
"126.10000","63.05099","32.73988"
"126.20000","63.10104","32.75588"
"126.30000","63.15096","32.77060"
"126.40000","63.20100","32.77525"
"126.50000","63.25099","32.78342"
"126.60000","63.30097","32.79060"
"126.70000","63.35107","32.79740"
"126.80000","63.40088","32.80559"
"126.90000","63.45098","32.81733"
"127.00000","63.50103","32.83141"
"127.10000","63.55107","32.84394"
"127.20000","63.60099","32.85987"
"127.30000","63.65092","32.87383"
"127.40000","63.70090","32.88554"
"127.50000","63.75100","32.90155"
"127.60000","63.80099","32.91265"
"127.70000","63.85098","32.92432"
"127.80000","63.90096","32.93703"
"127.90000","63.95100","32.94640"
"128.00000","64.00087","32.95394"
"128.10000","64.05103","32.96144"
"128.20000","64.10102","32.96994"
"128.30000","64.15099","32.97414"
"128.40000","64.20104","32.97906"
"128.50000","64.25097","32.98215"
"128.60000","64.30096","32.98239"
"128.70000","64.35099","32.98034"
"128.80000","64.40098","32.97714"
"128.90000","64.45103","32.96875"
"129.00000","64.50095","32.93608"
"129.10000","64.55099","32.81763"
"129.12000","64.56091","32.64780"
"129.12200","64.56187","32.13832"
"129.12400","64.56295","30.88852"
"129.12600","64.56396","29.12349"
"129.12800","64.56498","27.51773"
"129.13000","64.56600","26.09061"
"129.13200","64.56702","24.22437"
"129.13400","64.56803","22.00888"
"129.13600","64.56899","20.14748"
"129.13800","64.57000","18.58694"