File: MT-DataAnalysis-JupyterNotebook/TensionPlots/TensionTests/WireDiameter/Specimen_RawData_1.csv
End date,"8/16/2018"
Specimen label,"D32L50N5d2"
Maximum Load,"1.85787",N
Extension at Maximum Load,"153.77586",mm
Maximum Slope (Automatic Young's),"0.01484",N/mm
Rate 1,"30.00000",mm/min

Time,Extension,Load
(s),(mm),(N)
"0.00000","-0.00006","0.01030"
"0.30000","0.14929","0.01155"
"0.60000","0.30122","0.01409"
"0.90000","0.45093","0.01500"
"1.20000","0.60100","0.01850"
"1.50000","0.75090","0.02130"
"1.80000","0.90097","0.02626"
"2.10000","1.05098","0.02717"
"2.40000","1.20087","0.03016"
"2.70000","1.35094","0.03319"
"3.00000","1.50096","0.03518"
"3.30000","1.65097","0.03813"
"3.60000","1.80092","0.03995"
"3.90000","1.95105","0.04224"
"4.20000","2.10094","0.04532"
"4.50000","2.25108","0.05000"
"4.80000","2.40085","0.05307"
"5.10000","2.55098","0.05338"
"5.40000","2.70099","0.05666"
"5.70000","2.85094","0.05950"
"6.00000","3.00102","0.06125"
"6.30000","3.15103","0.06427"
"6.60000","3.30092","0.06454"
"6.90000","3.45099","0.06754"
"7.20000","3.60094","0.07123"
"7.50000","3.75096","0.07414"
"7.80000","3.90103","0.07462"
"8.10000","4.05098","0.07868"
"8.40000","4.20105","0.08021"
"8.70000","4.35100","0.08390"
"9.00000","4.50096","0.08772"
"9.30000","4.65103","0.08872"
"9.60000","4.80092","0.09173"
"9.90000","4.95099","0.09643"
"10.20000","5.10094","0.09599"
"10.50000","5.25102","0.09868"
"10.80000","5.40103","0.10347"
"11.10000","5.55098","0.10347"
"11.40000","5.70099","0.10827"
"11.70000","5.85100","0.10845"
"12.00000","6.00090","0.11220"
"12.30000","6.15097","0.11459"
"12.60000","6.30098","0.11757"
"12.90000","6.45093","0.12034"
"13.20000","6.60100","0.12291"
"13.50000","6.75102","0.12408"
"13.80000","6.90103","0.12546"
"14.10000","7.05086","0.12906"
"14.40000","7.20105","0.12863"
"14.70000","7.35094","0.13436"
"15.00000","7.50096","0.13537"
"15.30000","7.65103","0.14082"
"15.60000","7.80104","0.14108"
"15.90000","7.95093","0.14577"
"16.20000","8.10094","0.14705"
"16.50000","8.25096","0.14900"
"16.80000","8.40103","0.15202"
"17.10000","8.55092","0.15289"
"17.40000","8.70099","0.15524"
"17.70000","8.85100","0.15694"
"18.00000","9.00096","0.15888"
"18.30000","9.15103","0.16631"
"18.60000","9.30104","0.16827"
"18.90000","9.45093","0.17008"
"19.20000","9.60100","0.17180"
"19.50000","9.75102","0.17078"
"19.80000","9.90091","0.17584"
"20.10000","10.05098","0.17653"
"20.40000","10.20093","0.17738"
"20.70000","10.35094","0.17940"
"21.00000","10.50101","0.18050"
"21.30000","10.65103","0.18184"
"21.60000","10.80104","0.18097"
"21.90000","10.95099","0.18341"
"22.20000","11.10100","0.18366"
"22.50000","11.25107","0.18628"
"22.80000","11.40097","0.18691"
"23.10000","11.55092","0.18864"
"23.40000","11.70099","0.18926"
"23.70000","11.85106","0.19077"
"24.00000","12.00096","0.19176"
"24.30000","12.15109","0.19348"
"24.60000","12.30104","0.19484"
"24.90000","12.45099","0.19695"
"25.20000","12.60088","0.19610"
"25.50000","12.75107","0.19958"
"25.80000","12.90097","0.20110"
"26.10000","13.05098","0.20214"
"26.40000","13.20093","0.20485"
"26.70000","13.35094","0.20456"
"27.00000","13.50095","0.20703"
"27.30000","13.65115","0.20815"
"27.60000","13.80104","0.21045"
"27.90000","13.95105","0.21170"
"28.20000","14.10100","0.21404"
"28.50000","14.25101","0.21652"
"28.80000","14.40097","0.21877"
"29.10000","14.55092","0.21907"
"29.40000","14.70093","0.22114"
"29.70000","14.85100","0.22359"
"30.00000","15.00095","0.22451"
"30.30000","15.15109","0.22670"
"30.60000","15.30098","0.22874"
"30.90000","15.45099","0.23342"
"31.20000","15.60094","0.23632"
"31.50000","15.75101","0.23720"
"31.80000","15.90091","0.24004"
"32.10000","16.05104","0.24201"
"32.40000","16.20087","0.24295"
"32.70000","16.35100","0.24554"
"33.00000","16.50089","0.24797"
"33.30000","16.65096","0.24921"
"33.60000","16.80098","0.25297"
"33.90000","16.95099","0.25507"
"34.20000","17.10094","0.25673"
"34.50000","17.25107","0.26066"
"34.80000","17.40097","0.26125"
"35.10000","17.55098","0.26464"
"35.40000","17.70093","0.26686"
"35.70000","17.85088","0.26751"
"36.00000","18.00096","0.27204"
"36.30000","18.15097","0.27325"
"36.60000","18.30104","0.27645"
"36.90000","18.45099","0.27680"
"37.20000","18.60100","0.28027"
"37.50000","18.75095","0.28337"
"37.80000","18.90103","0.28512"
"38.10000","19.05092","0.28683"
"38.40000","19.20093","0.28917"
"38.70000","19.35100","0.29165"
"39.00000","19.50101","0.29284"
"39.30000","19.65091","0.29577"
"39.60000","19.80092","0.29923"
"39.90000","19.95093","0.30215"
"40.20000","20.10100","0.30405"
"40.50000","20.25095","0.30652"
"40.80000","20.40096","0.30747"
"41.10000","20.55104","0.30985"
"41.40000","20.70111","0.31295"
"41.70000","20.85088","0.31552"
"42.00000","21.00107","0.31900"
"42.30000","21.15103","0.32048"
"42.60000","21.30098","0.32340"
"42.90000","21.45099","0.32426"
"43.20000","21.60094","0.32774"
"43.50000","21.75089","0.32934"
"43.80000","21.90096","0.33204"
"44.10000","22.05104","0.33616"
"44.40000","22.20105","0.33816"
"44.70000","22.35100","0.33934"
"45.00000","22.50095","0.34208"
"45.30000","22.65102","0.34324"
"45.60000","22.80092","0.34652"
"45.90000","22.95105","0.34920"
"46.20000","23.10100","0.35088"
"46.50000","23.25101","0.35569"
"46.80000","23.40097","0.35687"
"47.10000","23.55098","0.35965"
"47.40000","23.70105","0.36122"
"47.70000","23.85094","0.36435"
"48.00000","24.00101","0.36628"
"48.30000","24.15102","0.36917"
"48.60000","24.30098","0.37060"
"48.90000","24.45093","0.37333"
"49.20000","24.60106","0.37341"
"49.50000","24.75095","0.37787"
"49.80000","24.90103","0.37958"
"50.10000","25.05098","0.38176"
"50.40000","25.20099","0.38401"
"50.70000","25.35100","0.38627"
"51.00000","25.50095","0.38862"
"51.30000","25.65103","0.38825"
"51.60000","25.80098","0.39364"
"51.90000","25.95111","0.39508"
"52.20000","26.10112","0.39648"
"52.50000","26.25096","0.39912"
"52.80000","26.40096","0.39741"
"53.10000","26.55110","0.39988"
"53.40000","26.70099","0.40488"
"53.70000","26.85094","0.40328"
"54.00000","27.00107","0.40641"
"54.30000","27.15102","0.40812"
"54.60000","27.30098","0.41020"
"54.90000","27.45093","0.41225"
"55.20000","27.60106","0.41259"
"55.50000","27.75095","0.41395"
"55.80000","27.90108","0.41688"
"56.10000","28.05103","0.41824"
"56.40000","28.20105","0.41932"
"56.70000","28.35094","0.42315"
"57.00000","28.50095","0.42351"
"57.30000","28.65096","0.42841"
"57.60000","28.80098","0.42876"
"57.90000","28.95105","0.42928"
"58.20000","29.10112","0.42940"
"58.50000","29.25101","0.43391"
"58.80000","29.40097","0.43517"
"59.10000","29.55104","0.44019"
"59.40000","29.70087","0.44203"
"59.70000","29.85100","0.44436"
"60.00000","30.00101","0.44576"
"60.30000","30.15096","0.44831"
"60.60000","30.30098","0.44904"
"60.90000","30.45093","0.45399"
"61.20000","30.60106","0.45397"
"61.50000","30.75095","0.45582"
"61.80000","30.90091","0.46050"
"62.10000","31.05110","0.46277"
"62.40000","31.20105","0.46554"
"62.70000","31.35094","0.46813"
"63.00000","31.50101","0.47000"
"63.30000","31.65096","0.46903"
"63.60000","31.80097","0.47248"
"63.90000","31.95093","0.47339"
"64.20000","32.10100","0.47723"
"64.50000","32.25107","0.47774"
"64.80000","32.40102","0.48017"
"65.10000","32.55104","0.48056"
"65.40000","32.70099","0.48477"
"65.70000","32.85100","0.48587"
"66.00000","33.00089","0.48882"
"66.30000","33.15096","0.49094"
"66.60000","33.30098","0.49313"
"66.90000","33.45105","0.49695"
"67.20000","33.60100","0.49896"
"67.50000","33.75101","0.50141"
"67.80000","33.90102","0.50329"
"68.10000","34.05103","0.50484"
"68.40000","34.20099","0.50733"
"68.70000","34.35088","0.50980"
"69.00000","34.50095","0.51179"
"69.30000","34.65096","0.51507"
"69.60000","34.80092","0.51871"
"69.90000","34.95105","0.52048"
"70.20000","35.10094","0.52303"
"70.50000","35.25095","0.52561"
"70.80000","35.40096","0.52816"
"71.10000","35.55103","0.53007"
"71.40000","35.70093","0.53326"
"71.70000","35.85100","0.53476"
"72.00000","36.00095","0.53883"
"72.30000","36.15102","0.54129"
"72.60000","36.30091","0.54456"
"72.90000","36.45099","0.54586"
"73.20000","36.60094","0.54806"
"73.50000","36.75095","0.55217"
"73.80000","36.90091","0.55365"
"74.10000","37.05104","0.55545"
"74.40000","37.20099","0.55952"
"74.70000","37.35088","0.55948"
"75.00000","37.50101","0.56610"
"75.30000","37.65091","0.56611"
"75.60000","37.80098","0.57130"
"75.90000","37.95099","0.57307"
"76.20000","38.10094","0.57215"
"76.50000","38.25089","0.57463"
"76.80000","38.40108","0.57714"
"77.10000","38.55092","0.57973"
"77.40000","38.70105","0.58132"
"77.70000","38.85106","0.58175"
"78.00000","39.00095","0.58292"
"78.30000","39.15102","0.58505"
"78.60000","39.30098","0.58613"
"78.90000","39.45105","0.58675"
"79.20000","39.60099","0.59055"
"79.50000","39.75101","0.59189"
"79.80000","39.90108","0.59328"
"80.10000","40.05097","0.59502"
"80.40000","40.20099","0.59685"
"80.70000","40.35100","0.59788"
"81.00000","40.50095","0.59984"
"81.30000","40.65096","0.60179"
"81.60000","40.80104","0.60282"
"81.90000","40.95104","0.60457"
"82.20000","41.10094","0.60608"
"82.50000","41.25095","0.60789"
"82.80000","41.40102","0.60938"
"83.10000","41.55091","0.61078"
"83.40000","41.70099","0.61347"
"83.70000","41.85106","0.61491"
"84.00000","42.00101","0.61718"
"84.30000","42.15102","0.61747"
"84.60000","42.30092","0.61934"
"84.90000","42.45105","0.62081"
"85.20000","42.60094","0.62223"
"85.50000","42.75101","0.62385"
"85.80000","42.90108","0.62570"
"86.10000","43.05103","0.62666"
"86.40000","43.20093","0.62898"
"86.70000","43.35106","0.63014"
"87.00000","43.50095","0.63363"
"87.30000","43.65096","0.63479"
"87.60000","43.80091","0.63840"
"87.90000","43.95092","0.63765"
"88.20000","44.10100","0.64067"
"88.50000","44.25089","0.64771"
"88.80000","44.40102","0.64786"
"89.10000","44.55092","0.65087"
"89.40000","44.70099","0.64827"
"89.70000","44.85100","0.65181"
"90.00000","45.00101","0.65481"
"90.30000","45.15091","0.65897"
"90.60000","45.30109","0.66203"
"90.90000","45.45093","0.66371"
"91.20000","45.60094","0.66600"
"91.50000","45.75107","0.66800"
"91.80000","45.90096","0.67074"
"92.10000","46.05098","0.67422"
"92.40000","46.20098","0.67680"
"92.70000","46.35100","0.67835"
"93.00000","46.50095","0.68451"
"93.30000","46.65090","0.68454"
"93.60000","46.80098","0.68693"
"93.90000","46.95099","0.68932"
"94.20000","47.10094","0.69241"
"94.50000","47.25101","0.69362"
"94.80000","47.40108","0.69805"
"95.10000","47.55098","0.69963"
"95.40000","47.70105","0.70125"
"95.70000","47.85100","0.70482"
"96.00000","48.00101","0.70585"
"96.30000","48.15091","0.70942"
"96.60000","48.30098","0.71085"
"96.90000","48.45105","0.71313"
"97.20000","48.60094","0.71512"
"97.50000","48.75101","0.71794"
"97.80000","48.90102","0.71841"
"98.10000","49.05097","0.72070"
"98.40000","49.20093","0.72455"
"98.70000","49.35100","0.72533"
"99.00000","49.50095","0.72872"
"99.30000","49.65096","0.73028"
"99.60000","49.80098","0.73279"
"99.90000","49.95104","0.73355"
"100.20000","50.10082","0.73945"
"100.50000","50.25107","0.74046"
"100.80000","50.40102","0.73816"
"101.10000","50.55091","0.74519"
"101.40000","50.70098","0.74658"
"101.70000","50.85094","0.75100"
"102.00000","51.00095","0.75069"
"102.30000","51.15096","0.75490"
"102.60000","51.30097","0.75691"
"102.90000","51.45098","0.75900"
"103.20000","51.60100","0.76148"
"103.50000","51.75095","0.76487"
"103.80000","51.90096","0.76664"
"104.10000","52.05085","0.76726"
"104.40000","52.20098","0.76854"
"104.70000","52.35100","0.77616"
"105.00000","52.50095","0.77387"
"105.30000","52.65108","0.77939"
"105.60000","52.80098","0.78033"
"105.90000","52.95098","0.78336"
"106.20000","53.10094","0.78285"
"106.50000","53.25095","0.78343"
"106.80000","53.40090","0.78788"
"107.10000","53.55103","0.78987"
"107.40000","53.70099","0.79183"
"107.70000","53.85094","0.79255"
"108.00000","54.00101","0.79462"
"108.30000","54.15097","0.79577"
"108.60000","54.30103","0.79723"
"108.90000","54.45093","0.80004"
"109.20000","54.60094","0.80028"
"109.50000","54.75101","0.80215"
"109.80000","54.90102","0.80613"
"110.10000","55.05092","0.80770"
"110.40000","55.20105","0.80993"
"110.70000","55.35100","0.81280"
"111.00000","55.50101","0.81081"
"111.30000","55.65096","0.81427"
"111.60000","55.80103","0.81564"
"111.90000","55.95105","0.81845"
"112.20000","56.10094","0.82013"
"112.50000","56.25095","0.82244"
"112.80000","56.40097","0.82382"
"113.10000","56.55097","0.82727"
"113.40000","56.70105","0.82808"
"113.70000","56.85100","0.83036"
"114.00000","57.00101","0.83270"
"114.30000","57.15096","0.83542"
"114.60000","57.30098","0.83715"
"114.90000","57.45092","0.83964"
"115.20000","57.60094","0.84018"
"115.50000","57.75095","0.84204"
"115.80000","57.90102","0.84436"
"116.10000","58.05091","0.84810"
"116.40000","58.20110","0.84755"
"116.70000","58.35094","0.85417"
"117.00000","58.50101","0.85235"
"117.30000","58.65090","0.85421"
"117.60000","58.80097","0.85896"
"117.90000","58.95086","0.86062"
"118.20000","59.10106","0.86442"
"118.50000","59.25095","0.86652"
"118.80000","59.40096","0.86948"
"119.10000","59.55097","0.87072"
"119.40000","59.70092","0.87334"
"119.70000","59.85100","0.87489"
"120.00000","60.00107","0.87847"
"120.30000","60.15096","0.88234"
"120.60000","60.30098","0.88471"
"120.90000","60.45093","0.88636"
"121.20000","60.60100","0.88904"
"121.50000","60.75095","0.89102"
"121.80000","60.90090","0.89378"
"122.10000","61.05097","0.89534"
"122.40000","61.20104","0.89792"
"122.70000","61.35100","0.90006"
"123.00000","61.50095","0.90237"
"123.30000","61.65097","0.90569"
"123.60000","61.80104","0.90675"
"123.90000","61.95098","0.91035"
"124.20000","62.10094","0.91290"
"124.50000","62.25095","0.91480"
"124.80000","62.40096","0.91653"
"125.10000","62.55103","0.91941"
"125.40000","62.70104","0.92171"
"125.70000","62.85100","0.92421"
"126.00000","63.00089","0.92630"
"126.30000","63.15102","0.92969"
"126.60000","63.30103","0.93077"
"126.90000","63.45092","0.93340"
"127.20000","63.60099","0.93496"
"127.50000","63.75100","0.93689"
"127.80000","63.90084","0.94096"
"128.10000","64.05103","0.94203"
"128.40000","64.20098","0.94727"
"128.70000","64.35099","0.94967"
"129.00000","64.50101","0.95209"
"129.30000","64.65090","0.95295"
"129.60000","64.80097","0.95731"
"129.90000","64.95092","0.95992"
"130.20000","65.10100","0.96130"
"130.50000","65.25101","0.96517"
"130.80000","65.40108","0.96703"
"131.10000","65.55096","0.97011"
"131.40000","65.70110","0.97219"
"131.70000","65.85100","0.97780"
"132.00000","66.00095","0.97799"
"132.30000","66.15102","0.98263"
"132.60000","66.30103","0.98495"
"132.90000","66.45092","0.98560"
"133.20000","66.60099","0.98902"
"133.50000","66.75101","0.98682"
"133.80000","66.90090","0.99171"
"134.10000","67.05103","0.99384"
"134.40000","67.20104","0.99731"
"134.70000","67.35100","0.99699"
"135.00000","67.50095","1.00056"
"135.30000","67.65102","1.00268"
"135.60000","67.80103","1.00132"
"135.90000","67.95099","1.00472"
"136.20000","68.10094","1.00537"
"136.50000","68.25101","1.00932"
"136.80000","68.40102","1.00939"
"137.10000","68.55097","1.01241"
"137.40000","68.70093","1.00937"
"137.70000","68.85094","1.01301"
"138.00000","69.00101","1.01425"
"138.30000","69.15102","1.01723"
"138.60000","69.30097","1.01753"
"138.90000","69.45098","1.01895"
"139.20000","69.60105","1.02026"
"139.50000","69.75095","1.02070"
"139.80000","69.90090","1.02302"
"140.10000","70.05109","1.02142"
"140.40000","70.20104","1.02623"
"140.70000","70.35100","1.02443"
"141.00000","70.50095","1.03021"
"141.30000","70.65108","1.03224"
"141.60000","70.80091","1.03472"
"141.90000","70.95099","1.03751"
"142.20000","71.10105","1.03795"
"142.50000","71.25107","1.04338"
"142.80000","71.40096","1.04126"
"143.10000","71.55097","1.04228"
"143.40000","71.70098","1.04471"
"143.70000","71.85099","1.04737"
"144.00000","72.00107","1.04985"
"144.30000","72.15102","1.05159"
"144.60000","72.30097","1.05367"
"144.90000","72.45104","1.05540"
"145.20000","72.60100","1.05790"
"145.50000","72.75089","1.05961"
"145.80000","72.90096","1.06291"
"146.10000","73.05097","1.06504"
"146.40000","73.20093","1.06797"
"146.70000","73.35100","1.07047"
"147.00000","73.50095","1.07271"
"147.30000","73.65102","1.07456"
"147.60000","73.80097","1.07808"
"147.90000","73.95098","1.07872"
"148.20000","74.10099","1.08207"
"148.50000","74.25101","1.08419"
"148.80000","74.40096","1.08697"
"149.10000","74.55103","1.09024"
"149.40000","74.70098","1.09555"
"149.70000","74.85099","1.09586"
"150.00000","75.00101","1.09906"
"150.30000","75.15102","1.10140"
"150.60000","75.30103","1.10519"
"150.90000","75.45099","1.10746"
"151.20000","75.60111","1.11084"
"151.50000","75.75089","1.11113"
"151.80000","75.90102","1.11589"
"152.10000","76.05097","1.11884"
"152.40000","76.20093","1.12215"
"152.70000","76.35105","1.12272"
"153.00000","76.50101","1.12703"
"153.30000","76.65096","1.12938"
"153.60000","76.80103","1.12980"
"153.90000","76.95098","1.13770"
"154.20000","77.10105","1.13659"
"154.50000","77.25101","1.13785"
"154.80000","77.40090","1.13959"
"155.10000","77.55091","1.14357"
"155.40000","77.70092","1.14723"
"155.70000","77.85094","1.14851"
"156.00000","78.00107","1.15262"
"156.30000","78.15096","1.15521"
"156.60000","78.30103","1.15849"
"156.90000","78.45098","1.16190"
"157.20000","78.60099","1.16341"
"157.50000","78.75082","1.16590"
"157.80000","78.90102","1.16638"
"158.10000","79.05096","1.16904"
"158.40000","79.20098","1.17274"
"158.70000","79.35093","1.17486"
"159.00000","79.50101","1.17663"
"159.30000","79.65102","1.17822"
"159.60000","79.80090","1.18418"
"159.90000","79.95098","1.18225"
"160.20000","80.10105","1.18444"
"160.50000","80.25101","1.18587"
"160.80000","80.40090","1.19061"
"161.10000","80.55097","1.19229"
"161.40000","80.70093","1.19622"
"161.70000","80.85094","1.19801"
"162.00000","81.00101","1.19982"
"162.30000","81.15089","1.20289"
"162.60000","81.30096","1.20444"
"162.90000","81.45104","1.20603"
"163.20000","81.60093","1.20820"
"163.50000","81.75101","1.20991"
"163.80000","81.90108","1.20900"
"164.10000","82.05097","1.21252"
"164.40000","82.20103","1.21480"
"164.70000","82.35093","1.21602"
"165.00000","82.50107","1.21636"
"165.30000","82.65096","1.21900"
"165.60000","82.80097","1.22077"
"165.90000","82.95105","1.22173"
"166.20000","83.10106","1.22375"
"166.50000","83.25094","1.22524"
"166.80000","83.40095","1.22734"
"167.10000","83.55096","1.22919"
"167.40000","83.70098","1.23115"
"167.70000","83.85100","1.23241"
"168.00000","84.00101","1.23460"
"168.30000","84.15096","1.23535"
"168.60000","84.30097","1.23793"
"168.90000","84.45098","1.24014"
"169.20000","84.60093","1.24090"
"169.50000","84.75095","1.24286"
"169.80000","84.90102","1.24522"
"170.10000","85.05097","1.24774"
"170.40000","85.20104","1.24760"
"170.70000","85.35088","1.25306"
"171.00000","85.50101","1.25182"
"171.30000","85.65102","1.25495"
"171.60000","85.80090","1.25691"
"171.90000","85.95104","1.25781"
"172.20000","86.10100","1.26252"
"172.50000","86.25095","1.25993"
"172.80000","86.40096","1.26069"
"173.10000","86.55097","1.26673"
"173.40000","86.70098","1.26770"
"173.70000","86.85094","1.27137"
"174.00000","87.00095","1.27478"
"174.30000","87.15096","1.27647"
"174.60000","87.30091","1.27832"
"174.90000","87.45104","1.28106"
"175.20000","87.60094","1.28815"
"175.50000","87.75101","1.28479"
"175.80000","87.90096","1.28735"
"176.10000","88.05103","1.29244"
"176.40000","88.20099","1.29434"
"176.70000","88.35111","1.29818"
"177.00000","88.50095","1.29895"
"177.30000","88.65096","1.30034"
"177.60000","88.80103","1.30193"
"177.90000","88.95103","1.30427"
"178.20000","89.10105","1.30472"
"178.50000","89.25100","1.30964"
"178.80000","89.40102","1.31093"
"179.10000","89.55097","1.31388"
"179.40000","89.70092","1.31692"
"179.70000","89.85093","1.31893"
"180.00000","90.00101","1.31903"
"180.30000","90.15102","1.32041"
"180.60000","90.30103","1.32385"
"180.90000","90.45105","1.32878"
"181.20000","90.60093","1.32909"
"181.50000","90.75101","1.33153"
"181.80000","90.90096","1.33544"
"182.10000","91.05103","1.33658"
"182.40000","91.20086","1.33812"
"182.70000","91.35099","1.34193"
"183.00000","91.50107","1.34345"
"183.30000","91.65096","1.34914"
"183.60000","91.80103","1.35002"
"183.90000","91.95104","1.35238"
"184.20000","92.10099","1.35464"
"184.50000","92.25095","1.35758"
"184.80000","92.40096","1.35963"
"185.10000","92.55090","1.36295"
"185.40000","92.70098","1.36552"
"185.70000","92.85093","1.36736"
"186.00000","93.00106","1.37048"
"186.30000","93.15089","1.37367"
"186.60000","93.30102","1.37668"
"186.90000","93.45103","1.37840"
"187.20000","93.60094","1.38184"
"187.50000","93.75100","1.38472"
"187.80000","93.90095","1.38695"
"188.10000","94.05097","1.38789"
"188.40000","94.20086","1.39300"
"188.70000","94.35094","1.39551"
"189.00000","94.50101","1.39625"
"189.30000","94.65096","1.39981"
"189.60000","94.80096","1.40091"
"189.90000","94.95098","1.40339"
"190.20000","95.10093","1.40370"
"190.50000","95.25101","1.40563"
"190.80000","95.40096","1.40854"
"191.10000","95.55097","1.41026"
"191.40000","95.70104","1.41346"
"191.70000","95.85099","1.41621"
"192.00000","96.00095","1.41777"
"192.30000","96.15095","1.41873"
"192.60000","96.30092","1.42121"
"192.90000","96.45093","1.42203"
"193.20000","96.60105","1.42481"
"193.50000","96.75101","1.42653"
"193.80000","96.90090","1.42770"
"194.10000","97.05103","1.42942"
"194.40000","97.20091","1.43237"
"194.70000","97.35104","1.43363"
"195.00000","97.50089","1.43599"
"195.30000","97.65096","1.43749"
"195.60000","97.80103","1.43846"
"195.90000","97.95103","1.44138"
"196.20000","98.10087","1.44199"
"196.50000","98.25107","1.44454"
"196.80000","98.40101","1.44625"
"197.10000","98.55091","1.44758"
"197.40000","98.70098","1.45048"
"197.70000","98.85105","1.45386"
"198.00000","99.00101","1.45426"
"198.30000","99.15090","1.45570"
"198.60000","99.30103","1.45849"
"198.90000","99.45091","1.45922"
"199.20000","99.60099","1.46254"
"199.50000","99.75095","1.46228"
"199.80000","99.90096","1.46545"
"200.10000","100.05103","1.46765"
"200.40000","100.20092","1.47068"
"200.70000","100.35094","1.47178"
"201.00000","100.50095","1.47398"
"201.30000","100.65101","1.47762"
"201.60000","100.80091","1.47809"
"201.90000","100.95098","1.48241"
"202.20000","101.10088","1.48250"
"202.50000","101.25107","1.48473"
"202.80000","101.40095","1.48668"
"203.10000","101.55090","1.48977"
"203.40000","101.70098","1.49170"
"203.70000","101.85099","1.49442"
"204.00000","102.00095","1.49754"
"204.30000","102.15102","1.49959"
"204.60000","102.30097","1.50104"
"204.90000","102.45092","1.50439"
"205.20000","102.60099","1.50634"
"205.50000","102.75095","1.50858"
"205.80000","102.90101","1.51075"
"206.10000","103.05096","1.51334"
"206.40000","103.20105","1.51557"
"206.70000","103.35099","1.51833"
"207.00000","103.50094","1.52005"
"207.30000","103.65102","1.52260"
"207.60000","103.80103","1.52606"
"207.90000","103.95092","1.52815"
"208.20000","104.10093","1.53104"
"208.50000","104.25106","1.53179"
"208.80000","104.40102","1.53546"
"209.10000","104.55097","1.53640"
"209.40000","104.70098","1.53990"
"209.70000","104.85105","1.54130"
"210.00000","105.00095","1.54430"
"210.30000","105.15096","1.54664"
"210.60000","105.30096","1.54741"
"210.90000","105.45091","1.55132"
"211.20000","105.60106","1.55211"
"211.50000","105.75112","1.55574"
"211.80000","105.90102","1.55786"
"212.10000","106.05090","1.55906"
"212.40000","106.20099","1.56079"
"212.70000","106.35100","1.56236"
"213.00000","106.50095","1.56474"
"213.30000","106.65096","1.56444"
"213.60000","106.80109","1.57036"
"213.90000","106.95092","1.57247"
"214.20000","107.10098","1.57546"
"214.50000","107.25101","1.57561"
"214.80000","107.40096","1.57732"
"215.10000","107.55109","1.58107"
"215.40000","107.70086","1.58324"
"215.70000","107.85099","1.58491"
"216.00000","108.00094","1.58668"
"216.30000","108.15090","1.58943"
"216.60000","108.30097","1.59012"
"216.90000","108.45104","1.59095"
"217.20000","108.60100","1.59470"
"217.50000","108.75106","1.59628"
"217.80000","108.90101","1.59826"
"218.10000","109.05103","1.60094"
"218.40000","109.20098","1.60249"
"218.70000","109.35105","1.60563"
"219.00000","109.50095","1.60741"
"219.30000","109.65096","1.60400"
"219.60000","109.80096","1.61003"
"219.90000","109.95097","1.60869"
"220.20000","110.10099","1.61239"
"220.50000","110.25107","1.61380"
"220.80000","110.40096","1.61471"
"221.10000","110.55097","1.61597"
"221.40000","110.70104","1.61770"
"221.70000","110.85105","1.61921"
"222.00000","111.00100","1.62071"
"222.30000","111.15096","1.62062"
"222.60000","111.30103","1.62243"
"222.90000","111.45103","1.61841"
"223.15000","111.57613","1.41998"
"223.45000","111.72589","1.42433"
"223.75000","111.87597","1.42660"
"224.05000","112.02598","1.43024"
"224.35000","112.17599","1.43303"
"224.65000","112.32594","1.43390"
"224.95000","112.47601","1.43579"
"225.25000","112.62603","1.43831"
"225.55000","112.77604","1.43941"
"225.85000","112.92593","1.44271"
"226.15000","113.07605","1.44314"
"226.45000","113.22589","1.44539"
"226.75000","113.37602","1.44721"
"227.05000","113.52598","1.44934"
"227.35000","113.67598","1.45193"
"227.65000","113.82600","1.45331"
"227.95000","113.97607","1.45544"
"228.25000","114.12597","1.45792"
"228.55000","114.27597","1.46027"
"228.85000","114.42599","1.46094"
"229.15000","114.57612","1.46408"
"229.45000","114.72601","1.46550"
"229.75000","114.87595","1.46855"
"230.05000","115.02604","1.47018"
"230.35000","115.17599","1.47282"
"230.65000","115.32600","1.47444"
"230.95000","115.47595","1.47761"
"231.25000","115.62602","1.48070"
"231.55000","115.77598","1.48233"
"231.85000","115.92598","1.48396"
"232.15000","116.07595","1.48791"
"232.45000","116.22596","1.48844"
"232.75000","116.37602","1.49252"
"233.05000","116.52610","1.49393"
"233.35000","116.67606","1.49552"
"233.65000","116.82607","1.49847"
"233.95000","116.97590","1.50208"
"234.25000","117.12596","1.50226"
"234.55000","117.27598","1.50548"
"234.85000","117.42606","1.50879"
"235.15000","117.57600","1.51190"
"235.45000","117.72595","1.51352"
"235.75000","117.87597","1.51643"
"236.05000","118.02603","1.51958"
"236.35000","118.17604","1.52154"
"236.65000","118.32600","1.52371"
"236.95000","118.47601","1.52534"
"237.25000","118.62614","1.52666"
"237.55000","118.77585","1.52979"
"237.85000","118.92598","1.53213"
"238.15000","119.07600","1.53339"
"238.45000","119.22595","1.53444"
"238.75000","119.37602","1.53710"
"239.05000","119.52605","1.53700"
"239.35000","119.67606","1.54066"
"239.65000","119.82600","1.54482"
"239.95000","119.97601","1.54573"
"240.25000","120.12602","1.54829"
"240.55000","120.27603","1.55089"
"240.85000","120.42599","1.55177"
"241.15000","120.57594","1.55437"
"241.45000","120.72589","1.55673"
"241.75000","120.87597","1.55891"
"242.05000","121.02604","1.56162"
"242.35000","121.17598","1.56180"
"242.65000","121.32600","1.56686"
"242.95000","121.47607","1.56493"
"243.25000","121.62603","1.57012"
"243.55000","121.77586","1.57287"
"243.85000","121.92599","1.57401"
"244.15000","122.07600","1.57657"
"244.45000","122.22595","1.57616"
"244.75000","122.37601","1.57923"
"245.05000","122.52603","1.58238"
"245.35000","122.67605","1.58388"
"245.65000","122.82600","1.58583"
"245.95000","122.97601","1.58708"
"246.25000","123.12602","1.58896"
"246.55000","123.27597","1.59131"
"246.85000","123.42598","1.59269"
"247.15000","123.57600","1.59370"
"247.45000","123.72590","1.59622"
"247.75000","123.87590","1.59911"
"248.05000","124.02598","1.60294"
"248.35000","124.17593","1.60480"
"248.65000","124.32606","1.59897"
"248.95000","124.47601","1.60480"
"249.25000","124.62601","1.60390"
"249.55000","124.77599","1.60491"
"249.85000","124.92593","1.61161"
"250.15000","125.07594","1.61294"
"250.45000","125.22601","1.61480"
"250.75000","125.37595","1.61614"
"251.05000","125.52602","1.61663"
"251.35000","125.67598","1.61811"
"251.65000","125.82604","1.61936"
"251.95000","125.97601","1.62053"
"252.25000","126.12596","1.62308"
"252.55000","126.27597","1.62303"
"252.85000","126.42592","1.62367"
"253.15000","126.57594","1.62554"
"253.45000","126.72594","1.62599"
"253.75000","126.87601","1.62744"
"254.05000","127.02609","1.62990"
"254.35000","127.17593","1.63413"
"254.65000","127.32594","1.63067"
"254.95000","127.47601","1.63439"
"255.25000","127.62595","1.63626"
"255.55000","127.77597","1.64006"
"255.85000","127.92598","1.64617"
"256.15000","128.07593","1.64428"
"256.45000","128.22601","1.64879"
"256.75000","128.37596","1.64913"
"257.05000","128.52603","1.65055"
"257.35000","128.67598","1.65244"
"257.65000","128.82599","1.65674"
"257.95000","128.97594","1.65783"
"258.25000","129.12595","1.65886"
"258.55000","129.27602","1.66169"
"258.85000","129.42593","1.66364"
"259.15000","129.57594","1.66635"
"259.45000","129.72595","1.66942"
"259.75000","129.87608","1.67018"
"260.05000","130.02591","1.67279"
"260.35000","130.17598","1.67418"
"260.65000","130.32605","1.67745"
"260.95000","130.47606","1.67918"
"261.25000","130.62590","1.68171"
"261.55000","130.77603","1.68336"
"261.85000","130.92604","1.68435"
"262.15000","131.07593","1.68690"
"262.45000","131.22600","1.69020"
"262.75000","131.37607","1.69189"
"263.05000","131.52602","1.69357"
"263.35000","131.67604","1.69554"
"263.65000","131.82600","1.69733"
"263.95000","131.97614","1.69978"
"264.25000","132.12608","1.70288"
"264.55000","132.27597","1.70469"
"264.85000","132.42598","1.70575"
"265.15000","132.57587","1.70765"
"265.45000","132.72600","1.71012"
"265.75000","132.87602","1.71261"
"266.05000","133.02597","1.71539"
"266.35000","133.17604","1.71724"
"266.65000","133.32611","1.72200"
"266.95000","133.47606","1.72188"
"267.25000","133.62596","1.72384"
"267.55000","133.77603","1.72834"
"267.85000","133.92598","1.73039"
"268.15000","134.07594","1.73174"
"268.45000","134.22595","1.73394"
"268.75000","134.37596","1.73579"
"269.05000","134.52603","1.73599"
"269.35000","134.67598","1.73882"
"269.65000","134.82599","1.74113"
"269.95000","134.97606","1.74528"
"270.25000","135.12602","1.74833"
"270.55000","135.27591","1.74828"
"270.85000","135.42604","1.74895"
"271.15000","135.57588","1.75124"
"271.45000","135.72600","1.75368"
"271.75000","135.87596","1.75453"
"272.05000","136.02591","1.75609"
"272.35000","136.17598","1.75894"
"272.65000","136.32600","1.76390"
"272.95000","136.47601","1.76601"
"273.25000","136.62596","1.76551"
"273.55000","136.77597","1.76828"
"273.85000","136.92598","1.76915"
"274.15000","137.07599","1.77095"
"274.45000","137.22588","1.77330"
"274.75000","137.37601","1.77426"
"275.05000","137.52591","1.77708"
"275.35000","137.67598","1.77629"
"275.65000","137.82599","1.77732"
"275.95000","137.97595","1.77895"
"276.25000","138.12602","1.78392"
"276.55000","138.27597","1.78653"
"276.85000","138.42598","1.78576"
"277.15000","138.57599","1.79015"
"277.45000","138.72595","1.79165"
"277.75000","138.87602","1.79025"
"278.05000","139.02591","1.79351"
"278.35000","139.17592","1.79493"
"278.65000","139.32611","1.79688"
"278.95000","139.47594","1.79816"
"279.25000","139.62595","1.80041"
"279.55000","139.77603","1.80049"
"279.85000","139.92593","1.80408"
"280.15000","140.07594","1.80412"
"280.45000","140.22595","1.80855"
"280.75000","140.37602","1.80558"
"281.05000","140.52597","1.81081"
"281.35000","140.67598","1.80962"
"281.65000","140.82605","1.81267"
"281.95000","140.97601","1.81582"
"282.25000","141.12596","1.81267"
"282.55000","141.27597","1.81854"
"282.85000","141.42592","1.81803"
"283.15000","141.57593","1.82131"
"283.45000","141.72606","1.82158"
"283.75000","141.87595","1.82244"
"284.05000","142.02602","1.82115"
"284.35000","142.17593","1.82458"
"284.65000","142.32605","1.82631"
"284.95000","142.47595","1.82654"
"285.25000","142.62602","1.82722"
"285.55000","142.77597","1.82381"
"285.85000","142.92592","1.82673"
"286.15000","143.07593","1.82426"
"286.45000","143.22607","1.82985"
"286.75000","143.37590","1.83099"
"287.05000","143.52603","1.82400"
"287.35000","143.67604","1.83346"
"287.65000","143.82593","1.83222"
"287.95000","143.97600","1.83409"
"288.25000","144.12590","1.83560"
"288.55000","144.27602","1.83486"
"288.85000","144.42593","1.83699"
"289.15000","144.57600","1.83561"
"289.45000","144.72601","1.83676"
"289.75000","144.87596","1.83730"
"290.05000","145.02597","1.83748"
"290.35000","145.17610","1.83866"
"290.65000","145.32599","1.83922"
"290.95000","145.47588","1.83890"
"291.25000","145.62602","1.83894"
"291.55000","145.77609","1.83726"
"291.85000","145.92598","1.83751"
"292.15000","146.07599","1.83829"
"292.45000","146.22600","1.83629"
"292.75000","146.37596","1.83654"
"293.05000","146.52585","1.83659"
"293.35000","146.67606","1.83469"
"293.65000","146.82600","1.83523"
"293.95000","146.97607","1.83329"
"294.25000","147.12590","1.83280"
"294.55000","147.27609","1.83297"
"294.85000","147.42592","1.83263"
"295.15000","147.57599","1.83332"
"295.45000","147.72600","1.83247"
"295.75000","147.87596","1.83213"
"296.05000","148.02597","1.83240"
"296.35000","148.17604","1.83252"
"296.65000","148.32593","1.83281"
"296.95000","148.47595","1.83067"
"297.25000","148.62601","1.83285"
"297.55000","148.77608","1.83260"
"297.85000","148.92598","1.83309"
"298.15000","149.07594","1.83326"
"298.45000","149.22607","1.83307"
"298.75000","149.37596","1.83453"
"299.05000","149.52597","1.83429"
"299.35000","149.67592","1.83488"
"299.65000","149.82593","1.83524"
"299.95000","149.97594","1.83548"
"300.25000","150.12589","1.83704"
"300.55000","150.27603","1.83738"
"300.85000","150.42587","1.83915"
"301.15000","150.57599","1.83864"
"301.45000","150.72595","1.83997"
"301.75000","150.87596","1.83856"
"302.05000","151.02585","1.84145"
"302.35000","151.17598","1.84179"
"302.65000","151.32587","1.84219"
"302.95000","151.47595","1.84325"
"303.25000","151.62596","1.84257"
"303.55000","151.77597","1.84451"
"303.85000","151.92604","1.84479"
"304.15000","152.07599","1.84547"
"304.45000","152.22588","1.84613"
"304.75000","152.37595","1.84756"
"305.05000","152.52597","1.84820"
"305.35000","152.67598","1.85006"
"305.65000","152.82599","1.85035"
"305.95000","152.97589","1.85003"
"306.25000","153.12602","1.85125"
"306.55000","153.27603","1.85156"
"306.85000","153.42604","1.85343"
"307.15000","153.57593","1.85303"
"307.45000","153.72601","1.85438"
"307.75000","153.87596","1.85483"
"307.76600","153.88391","1.85490"